Workbook
Name \c: [1]BS!#REF!
Name \c: [1]BS!#REF!
Name \p: [1]BS!#REF!
Name \p: [1]BS!#REF!
Name \s: [1]BS!#REF!
Name \z: [1]BS!#REF!
Name ___INDEX_SHEET___ASAP_Utilities: #REF!
Name ___INDEX_SHEET___ASAP_Utilities: #REF!
Name ___INDEX_SHEET___ASAP_Utilities: #REF!
Name ___INDEX_SHEET___ASAP_Utilities: #REF!
Name _155___1702: '[2]PE CHARGES'!#REF!
Name _155___1702: '[2]PE CHARGES'!#REF!
Name _155___1703: '[2]PE CHARGES'!#REF!
Name _155___1703: '[2]PE CHARGES'!#REF!
Name _155___1704: '[2]PE CHARGES'!#REF!
Name _155___1704: '[2]PE CHARGES'!#REF!
Name _tax: #REF!
Name A: #REF!
Name A: #REF!
Name A: #REF!
Name A: #REF!
Name A: #REF!
Name A: #REF!
Name A: #REF!
Name AdminExp: #REF!
Name AdminExp: #REF!
Name ARA_Threshold: #REF!
Name ARA_Threshold: #REF!
Name ARP_Threshold: #REF!
Name ARP_Threshold: #REF!
Name asdf: #REF!
Name AY: #REF!
Name AY: '[3]Client''s Details'!$B$20
Name AY: #REF!
Name BAA: #REF!
Name BAA: #REF!
Name BS_310399: #REF!
Name BS_310399: #REF!
Name BuiltIn_AutoFilter___10: #REF!
Name BuiltIn_AutoFilter___10: #REF!
Name BuiltIn_AutoFilter___11: #REF!
Name BuiltIn_AutoFilter___11: #REF!
Name BusproExp: #REF!
Name BusproExp: #REF!
Name BusproExp: #REF!
Name Capital: #REF!
Name Capital: #REF!
Name Capital: #REF!
Name cccccc: #REF!
Name cccccccc: [1]BS!#REF!
Name CIN: #REF!
Name CIN: '[3]Client''s Details'!$B$6
Name CIN: #REF!
Name cmb_QDFinishrByProd.UnitOfMeasure: [4]QUANTITATIVE_DETAILS!$C$77:$C$99
Name cmb_QDRawMaterial.UnitOfMeasure: [4]QUANTITATIVE_DETAILS!$B$77:$B$99
Name COAdd: '[3]Client''s Details'!#REF!
Name CommExp: #REF!
Name CommExp: #REF!
Name CommExp: #REF!
Name CoName: #REF!

Sheet Relief
C2: Tax Relief u/s 90/91 | D2: AY 2024-25
C4: Indian Income | D4: =#REF! -> #REF!
C5: Foreign Income | D5: =#REF! -> #REF!
C6: Gross Total Income | D6: =D4+D5 -> #REF!
C7: Deduction | D7: 0
C8: Total Income | D8: =D6-D7 -> #REF!
C9: Tax on Total Income | D9: ='IT computation'!G35 -> 5133
C10: Surcharge | D10: =D9*10% -> 513.3
C11: Education Cess | D11: =(D9+D10)*4% -> 225.852
C12: Total Tax | D12: =ROUND(SUM(D9:D11),0) -> 5872
C13: Average Rate of Tax | D13: =D12/D8*100 -> #REF!
C14: Average tax on Foreign Income | D14: =D5*D13/100 -> #REF!
C15: Tax Paid in Foreign Income | D15: =#REF! -> #REF!
C16: Releif u/s 90 | D16: =IF(D15<D14,D15,D14) -> #REF!

Sheet Income (2)
B2: S No | C2: Invoice No | D2: Party Name | E2: Date of Invoice | F2: Invoice Value | G2: Upwork Commission | H2: Exchange rate | I2: Invoice Value in Rs. | J2: Amount Receivable | K2: Date of receipt | L2: Amount Received in Bank | M2: TDS | N2: Foreign Exchange fluctuation | O2: Sundry Debtors
B3: 1 | D3: Third Bridge | E3: 44335 | F3: =150 -> 150 | H3: 72.967 | I3: =F3*H3 -> 10945.05 | K3: 44348 | L3: =9842.24 -> 9842.24 | M3: =I3*10% -> 1094.505 | N3: =I3-L3-M3 -> 8.305
B4: 2 | C4: CH202102AV | D4: Avis Enertech | E4: 44348 | F4: 30000 | H4: 0 | I4: 30000 | K4: 44362 | L4: 27000 | M4: =I4*10% -> 3000 | N4: =I4-L4-M4 -> 0
B5: 3 | C5: CH202103AV | D5: Avis Enertech | E5: 44370 | F5: 30000 | H5: 0 | I5: 30000 | K5: 44386 | L5: 27000 | M5: =I5*10% -> 3000 | N5: =I5-L5-M5 -> 0
B6: 4 | C6: T400821622 | D6: Infinitalab | E6: 44404 | F6: 40 | G6: 8 | H6: 74.416 | I6: =F6*H6 -> 2976.64 | J6: =+(F6-G6)*H6 -> 2381.312 | K6: 44410 | L6: =2224.08 -> 2224.08 | M6: =I6*1% -> 29.7664 | N6: =+J6-L6-M6 -> 127.4656
B7: 5 | C7: T409471436 | D7: Infinitalab | E7: 44439 | F7: 160 | G7: 32 | H7: 73.1536 | I7: =F7*H7 -> 11704.576 | J7: =+(F7-G7)*H7 -> 9363.6608 | K7: 44446 | M7: =I7*1% -> 117.04576
C8: T409471442 | D8: Infinitalab | E8: 44439 | F8: 50 | G8: 10 | H8: 73.1536 | I8: =F8*H8 -> 3657.68 | J8: =+(F8-G8)*H8 -> 2926.144 | K8: 44446 | L8: =11793.87 -> 11793.87 | M8: =I8*1% -> 36.5768 | N8: =+J7+J8-L8-M7-M8 -> 342.31224
B9: 6 | C9: T415500978 | D9: Infinitalab | E9: 44465 | F9: 105 | G9: 21 | H9: 73.6567 | I9: =F9*H9 -> 7733.9535 | J9: =+(F9-G9)*H9 -> 6187.1628 | K9: 44475 | L9: =5969.73 -> 5969.73 | M9: =I9*1% -> 77.339535 | N9: =+J9-L9-M9 -> 140.09327
B10: 7 | D10: Third Bridge | E10: 44484 | F10: 37.5 | H10: 75.3039 | I10: =F10*H10 -> 2823.8962 | J10: =+(F10-G10)*H10 -> 2823.8962 | K10: 44494 | L10: =2531.27 -> 2531.27 | M10: =I10*10% -> 282.38962 | N10: =+J10-L10-M10 -> 10.236625
B11: 8 | C11: T423261749 | D11: Infinitalab | E11: 44494 | F11: 110 | G11: 22 | H11: 75.1019 | I11: =F11*H11 -> 8261.209 | J11: =+(F11-G11)*H11 -> 6608.9672 | K11: 44501 | L11: =6289.5 -> 6289.5 | M11: =I11*1% -> 82.61209 | N11: =+J11-L11-M11 -> 236.85511
B12: 9 | D12: Infinitalab (USA) | H12: 73.9191 | I12: 9570 | J12: =+(F12-G12)*H12 -> 0 | K12: 44509 | L12: 9570
B13: 10 | C13: T429500160 | D13: Jan ng Anna | E13: 44516 | F13: 9.99 | G13: 2 | H13: 74.4535 | I13: =F13*H13 -> 743.79047 | J13: =+(F13-G13)*H13 -> 594.88347 | K13: 44523 | L13: 501.54 | M13: =I13*1% -> 7.4379047 | N13: =+J13-L13-M13 -> 85.90556
D14: Jan ng Anna | E14: 44528 | F14: 10 | G14: 2 | H14: 75.091 | I14: =H14*F14 -> 750.91 | J14: =+(F14-G14)*H14 -> 600.728 | O14: =+I14 -> 750.91 | P14: Have Invoice and not reflected in bank and TDS
B15: 11 | C15: T433046958 | D15: IG Petrochem | E15: 44530 | F15: 50 | G15: 10 | H15: 75.0885 | I15: =F15*H15 -> 3754.425 | J15: =+(F15-G15)*H15 -> 3003.54 | K15: 44537 | L15: =3414 -> 3414 | M15: =I15*1% -> 37.54425 | N15: =+J15-L15-M15 -> -448.00425
B16: 12 | D16: Infinitalab (USA) | H16: 75.4733 | I16: 7425 | J16: =+(F16-G16)*H16 -> 0 | K16: 44538 | L16: 7425
B17: 13 | C17: T435022339 | D17: IG Petrochem | E17: 44537 | F17: 50 | G17: 10 | H17: 75.3532 | I17: =F17*H17 -> 3767.66 | J17: =+(F17-G17)*H17 -> 3014.128 | K17: 44546 | L17: 2864.38 | M17: =I17*1% -> 37.6766 | N17: =+J17-L17-M17 -> 112.0714
B18: 14 | C18: T441863783 | D18: IG Petrochem | E18: 44550 | F18: 50 | G18: 10 | H18: 75.9865 | I18: =F18*H18 -> 3799.325 | J18: =+(F18-G18)*H18 -> 3039.46 | K18: 44565 | L18: 2802.58 | M18: =I18*1% -> 37.99325 | N18: =+J18-L18-M18 -> 198.88675
B19: 15 | D19: Third Bridge | E19: 44574 | F19: 300 | H19: 73.9348 | I19: =+F19*H19 -> 22180.44 | J19: =+(F19-G19)*H19 -> 22180.44 | K19: 44585 | L19: 17851.33
B20: 16 | C20: T441863783 | D20: IG Petrochem | E20: 44565 | F20: 50 | G20: 10 | H20: 74.5717 | I20: =F20*H20 -> 3728.585 | J20: =+(F20-G20)*H20 -> 2982.868 | K20: 44588 | L20: 2824.51 | M20: =I20*1% -> 37.28585 | N20: =+J20-L20-M20 -> 121.07215
B21: 17 | C21: T447608594 | D21: IG Petrochem | E21: 44588 | F21: 50 | G21: 10 | H21: 75.1724 | I21: =F21*H21 -> 3758.62 | J21: =+(F21-G21)*H21 -> 3006.896 | K21: 44595 | L21: 2814.58 | M21: =I21*1% -> 37.5862 | N21: =+J21-L21-M21 -> 154.7298
B22: 18 | C22: T449115329 | D22: Usman Ali Khan | E22: 44593 | F22: 30 | G22: 6 | H22: 74.5295 | I22: =F22*H22 -> 2235.885 | J22: =+(F22-G22)*H22 -> 1788.708 | K22: 44599 | L22: 1656.25 | M22: =I22*1% -> 22.35885 | N22: =+J22-L22-M22 -> 110.09915
C23: T450002021 | D23: Usman Ali Khan | E23: 44599 | F23: 45 | G23: 9 | H23: 74.69 | I23: =F23*H23 -> 3361.05 | J23: =+(F23-G23)*H23 -> 2688.84 | K23: 44606 | M23: =I23*1% -> 33.6105
C24: T450002025 | D24: Usman Ali Khan | E24: 44599 | F24: 5 | G24: 1 | H24: 74.69 | I24: =F24*H24 -> 373.45 | J24: =+(F24-G24)*H24 -> 298.76 | K24: 44606 | L24: 2841.44 | M24: =I24*1% -> 3.7345 | N24: =+J23+J24-L24-M23-M24 -> 108.815
B25: 19 | C25: T451672954 | D25: James R Grable | E25: 44603 | F25: 250 | G25: 50 | H25: 75.3542 | I25: =F25*H25 -> 18838.55 | J25: =+(F25-G25)*H25 -> 15070.84 | K25: 44608 | L25: 14398.59 | M25: =I25*1% -> 188.3855 | N25: =+J25-L25-M25 -> 483.8645
C26: T453826015 | D26: James R Grable | E26: 44612 | F26: 250 | G26: 50 | H26: 74.4797 | I26: =F26*H26 -> 18619.925 | J26: =+(F26-G26)*H26 -> 14895.94 | K26: 44620 | M26: =I26*1% -> 186.19925
C27: T453826019 | D27: James R Grable | E27: 44612 | F27: 100 | G27: 10 | H27: 74.4797 | I27: =F27*H27 -> 7447.97 | J27: =+(F27-G27)*H27 -> 6703.173 | K27: 44620 | L27: 20931.23 | M27: =I27*1% -> 74.4797 | N27: =+J26+J27-L27-M27-M26 -> 407.20405
E28: 44631 | F28: 3013 | I28: =+F28 -> 3013 | J28: =+(F28-G28)*H28 -> 0 | M28: 30 | O28: =+I28-M28 -> 2983 | P28: No invoice and not debited in bank but reflected in TDS
E29: 44631 | F29: 1883 | I29: =+F29 -> 1883 | J29: =+(F29-G29)*H29 -> 0 | M29: 19 | O29: =+I29-M29 -> 1864
B30: 20 | C30: T459684693 | D30: James R Grable | E30: 44632 | F30: 500 | G30: 5 | H30: 76.4359 | I30: =F30*H30 -> 38217.95 | J30: =+(F32-G30)*H30 -> 37481.108 | K30: 44276 | L30: 36794.51 | M30: =I30*1% -> 382.1795 | N30: =+J30-L30-M30 -> 304.41842
I31: =SUM(I3:I30) -> 261572.54 | L31: =SUM(L3:L30) -> 219340.63 | M31: =+SUM(M3:M30) -> 8855.7071 | N31: =SUM(N3:N30) -> 2504.3304 | O31: =+SUM(O3:O30) -> 5597.91
F32: 495.36 | L32: =I31-L31 -> 42231.91
Z33: =W33*1% -> 0

Sheet TDS
A1: NAME OF ASSESSEE : CHEMGRO BIOENERGY SOLUTIONS (OPC) PRIVATE LIMITED (10001) PAN NO : AAICC7744A ASSESSMENT YEAR : 2022-2023
A2: Name of person who deducted tax (1) | B2: Address of person who deducted tax (2) | C2: City (3) | D2: State (4) | E2: PinCode (5) | F2: Date of payment/ credit (6) | G2: Amount paid/ credited (Rs.) (7) | H2: Tax deducted inclu. surcharge and edu. cess (8) | I2: Amount out of (8) to be allowed as credit during the year (9) | J2: Tax deduction A/C No. of the deductor (10) | K2: Unique Cer. Number (Exact 6 Character) (11) | L2: Financial Year in which TDS is Deducted (e.g. For FY 2011-12 Fill 2011) (12) | M2: Amount out of (7) In hand of Spouse/Other Income (13) | N2: Amount out of (8) (Tax Deducted In hand of Spouse/Other Income) (14) | O2: Amount out of (9) (Tax Claimed In hand of Spouse/Other Income) (15) | P2: Spouse/Other PAN (16) | Q2: Section (17) | R2: Head of income (18) | S2: Aadhar No. Tenant (19) | T2: Aadhar No. Spouse/Other (20)
A3: AVIS ENERTECH PRIVATE LIMITED | F3: 01-Jun-2021 | G3: 30000 | H3: 3000 | I3: 3000 | J3: CHEA19221G | L3: 0 | M3: 0 | N3: 0 | O3: 0 | Q3: 194JB | U3: =+G3-H3 -> 27000
A4: AVIS ENERTECH PRIVATE LIMITED | F4: 23-Jun-2021 | G4: 30000 | H4: 3000 | I4: 3000 | J4: CHEA19221G | L4: 0 | M4: 0 | N4: 0 | O4: 0 | Q4: 194JB | U4: =+G4-H4 -> 27000
A5: THIRD BRIDGE INDIA PRIVATE LIMITED | F5: 01-Jun-2021 | G5: 10936 | H5: 1094 | I5: 1094 | J5: DELC13005G | L5: 0 | M5: 0 | N5: 0 | O5: 0 | Q5: 194JB | U5: =+G5-H5 -> 9842
A6: THIRD BRIDGE INDIA PRIVATE LIMITED | F6: 31-Oct-2021 | G6: 2812 | H6: 281 | I6: 281 | J6: DELC13005G | L6: 0 | M6: 0 | N6: 0 | O6: 0 | Q6: 194JB | U6: =+G6-H6 -> 2531
A7: UPWORK GLOBAL INC | F7: 27-Jul-2021 | G7: 2957 | H7: 30 | I7: 30 | J7: DELU07765C | L7: 0 | M7: 0 | N7: 0 | O7: 0 | Q7: 194O | U7: =+G7-H7 -> 2927
A8: UPWORK GLOBAL INC | F8: 31-Aug-2021 | G8: 11656 | H8: 117 | I8: 117 | J8: DELU07765C | L8: 0 | M8: 0 | N8: 0 | O8: 0 | Q8: 194O | U8: =+G8-H8 -> 11539
A9: UPWORK GLOBAL INC | F9: 31-Aug-2021 | G9: 3643 | H9: 36 | I9: 36 | J9: DELU07765C | L9: 0 | M9: 0 | N9: 0 | O9: 0 | Q9: 194O | U9: =+G9-H9 -> 3607
A10: UPWORK GLOBAL INC | F10: 26-Sep-2021 | G10: 7754 | H10: 78 | I10: 78 | J10: DELU07765C | L10: 0 | M10: 0 | N10: 0 | O10: 0 | Q10: 194O | U10: =+G10-H10 -> 7676
A11: UPWORK GLOBAL INC | F11: 25-Oct-2021 | G11: 8195 | H11: 82 | I11: 82 | J11: DELU07765C | L11: 0 | M11: 0 | N11: 0 | O11: 0 | Q11: 194O | U11: =+G11-H11 -> 8113
A12: UPWORK GLOBAL INC | F12: 16-Nov-2021 | G12: 745 | H12: 7 | I12: 7 | J12: DELU07765C | L12: 0 | M12: 0 | N12: 0 | O12: 0 | Q12: 194O | U12: =+G12-H12 -> 738
A13: UPWORK GLOBAL INC | F13: 28-Nov-2021 | G13: 745 | H13: 7 | I13: 7 | J13: DELU07765C | L13: 0 | M13: 0 | N13: 0 | O13: 0 | Q13: 194O | U13: =+G13-H13 -> 738
A14: UPWORK GLOBAL INC | F14: 30-Nov-2021 | G14: 3727 | H14: 37 | I14: 37 | J14: DELU07765C | L14: 0 | M14: 0 | N14: 0 | O14: 0 | Q14: 194O | U14: =+G14-H14 -> 3690
... A27: UPWORK GLOBAL INC | F27: 12-Mar-2022 | G27: 37660 | H27: 377 | I27: 377 | J27: DELU07765C | L27: 0 | M27: 0 | N27: 0 | O27: 0 | Q27: 194O | U27: =+G27-H27 -> 37283
G28: 221828 | H28: 8855 | I28: 8855
K30: =30+19+5 -> 54

Sheet Exp
B3: Computation of Professional Fee Paid
B5: S No | C5: Invoice No | D5: Party Name | E5: Date of Invoice | F5: Invoice Value | G5: Exchange rate | H5: Invoice Value in Rs.
B6: 1 | C6: T400821624 | D6: Upwork Global | E6: 44404 | F6: 8 | G6: 74.416 | H6: =F6*G6 -> 595.328
B7: 2 | C7: T409471440 | D7: Upwork Global | E7: 44439 | F7: 32 | G7: 73.1536 | H7: =F7*G7 -> 2340.9152
B8: 3 | C8: T409471444 | D8: Upwork Global | E8: 44439 | F8: 10 | G8: 73.1536 | H8: =F8*G8 -> 731.536
B9: 4 | C9: T415500980 | D9: Upwork Global | E9: 44465 | F9: 21 | G9: 73.6567 | H9: =F9*G9 -> 1546.7907
B10: 5 | C10: T423261759 | D10: Upwork Global | E10: 44494 | F10: 22 | G10: 75.0191 | H10: =F10*G10 -> 1650.4202
B11: 6 | C11: T429500162 | D11: Upwork Global | E11: 44516 | F11: 2 | G11: 74.4535 | H11: =F11*G11 -> 148.907
B12: 7 | C12: T432026492 | D12: Upwork Global | E12: 44528 | F12: 2 | G12: 75.091 | H12: =F12*G12 -> 150.182
B13: 8 | C13: T433046960 | D13: Upwork Global | E13: 44530 | F13: 10 | G13: 75.0885 | H13: =F13*G13 -> 750.885
B14: 9 | C14: T435022341 | D14: Upwork Global | E14: 44532 | F14: 10 | G14: 74.9989 | H14: =F14*G14 -> 749.989
B15: 10 | C15: T437690387 | D15: Upwork Global | E15: 44550 | F15: 10 | G15: 75.9865 | H15: =F15*G15 -> 759.865
B16: 11 | C16: T441863785 | D16: Upwork Global | E16: 44565 | F16: 10 | G16: 74.5717 | H16: =F16*G16 -> 745.717
B17: 12 | C17: T447608596 | D17: Upwork Global | E17: 44588 | F17: 10 | G17: 75.1724 | H17: =F17*G17 -> 751.724
... B24: 19 | C24: T459684695 | D24: Upwork Global | E24: 44632 | F24: 50 | G24: 76.6086 | H24: =F24*G24 -> 3830.43
H25: =SUM(H6:H24) -> 24183.258

Sheet Sheet1
A3: 1 | B3: Breakup for Income tax provision to be check from last year
A4: 2 | B4: Director Loan Repaid to be added under Ralated party transcation
A5: 3 | B5: What is the Trade Receivable
A6: 4 | B6: Narration to be made
A7: 5 | B7: Breakup for Other Current Asset
A8: 6 | B8: Upwards FCTR
A9: 7 | B9: Opening balance for PPE Rs.100 to be add
A10: 9 | B10: Sundry Debtor To be Adjusted for Export and Local

Sheet TB
C5: Trial Balance as at March 2026
D7: Opening Balance | F7: Current Year | H7: Closing Balance
C8: Particulars | D8: Debit | E8: Credit | F8: Debit | G8: Credit | H8: Debit | I8: Credit
C9: Shareholder's funds
C10: Share Capital | D10: 0 | E10: 100000 | I10: =E10-D10+G10-F10 -> 100000
C11: Reserves and Surplus | D11: 0 | E11: =512074.62 -> 512074.62 | I11: =E11-D11+G11-F11 -> 512074.62 | M11: =I72+I73+I75-SUM(H77:H92) -> 24618.49
C12: Current Liabilities
C13: Sundry Creditors
C14: ADOBE A/C | F14: =17561.8+D129 -> 19158.48 | G14: 19158.48 | I14: =D14+E14-F14+G14 -> 0
C15: AIRTEL A/C | F15: 9616.76 | G15: 9616.76 | I15: =D15+E15-F15+G15 -> 0
C16: ALGOPAGE A/C | F16: 6530 | G16: 6530 | I16: =D16+E16-F16+G16 -> 0
C17: CHENNAI TRAVELS A/C | F17: 3498 | G17: 3498 | I17: =D17+E17-F17+G17 -> 0
C18: DOTCOWORKS A/C | F18: 106200 | G18: 106200 | I18: =D18+E18-F18+G18 -> 0
C19: EMUDHRA A/C | F19: 2655 | G19: 2655 | I19: =D19+E19-F19+G19 -> 0
C20: FREELANCERCOM A/C | F20: 127.53 | G20: 127.53 | I20: =D20+E20-F20+G20 -> 0
C21: HP INDIA A/C | F21: 1716 | G21: 1716 | I21: =D21+E21-F21+G21 -> 0
C22: McAfee A/C | F22: 4899 | G22: 4899 | I22: =D22+E22-F22+G22 -> 0
C23: PVtools A/c | F23: 3000 | G23: 3000 | I23: =D23+E23-F23+G23 -> 0
C24: RAMANUJAM & BOOVARAHAN A/C | F24: 11800 | G24: 11800 | I24: =D24+E24-F24+G24 -> 0
C25: RBJV ASSOCIATES A/C | F25: 29687 | G25: 29687 | I25: =D25+E25-F25+G25 -> 0
C26: SAKTHI TALLY A/C | F26: 9558 | G26: 9558 | I26: =D26+E26-F26+G26 -> 0
C27: UPWORKS A/C | F27: =2840.1+D163+D198 -> 156544.45 | G27: =155461.5+E203 -> 156544.45 | I27: =D27+E27-F27+G27 -> 0
C28: Loan Payable | E28: 47640 | F28: 47640 | H28: 0 | I28: =E28-D28+G28-F28 -> 0
C29: Other Current Liabilities
C30: Audit fee payable | D30: 0 | E30: 10000 | F30: 10000 | G30: =E156 -> 10000 | I30: =E30-D30+G30-F30 -> 10000
C31: Short-Term Provisions
C32: Provision for taxation AY 23-24 | E32: 97172 | F32: =D149 -> 97172 | I32: =E32-D32+G32-F32 -> 0
C33: Provision for taxation AY 24-25 | E33: 24157 | I33: =E33-D33+G33-F33 -> 24157
C34: Provision for taxation AY 25-26 | E34: 57607 | I34: =E34-D34+G34-F34 -> 57607
C35: Provision for taxation AY 26-27 | F35: =52260-E146 -> 0 | G35: =E118 -> 5872 | I35: =E35-D35+G35-F35 -> 5872
C36: Fixed Assets
C37: Property Plant & Equipment | D37: 56641.02 | G37: =E106+E110 -> 25878 | H37: =D37-E37+F37-G37 -> 30763.02
C38: Deferred tax
C39: Deferred Tax Assets | D39: 5623.65 | E39: 0 | G39: =E114 -> 617.37 | H39: =D39-E39+F39-G39 -> 5006.28
C40: Current Assets
C41: Trade Receivables | D41: 5323.11 | G41: 5323.11 | H41: =D41-E41+F41-G41 -> 0
C42: Sundry Debtors | H42: =D42-E42+F42-G42 -> 0
C43: AIRSCIENCE TECHNOLOGIES A/C | F43: 118300 | G43: =106470+E181 -> 118300 | H43: =D43-E43+F43-G43 -> 0
C44: AKA ADVTECH A/C | F44: 39957.65 | G44: =35026.98+E164 -> 39957.65 | H44: =D44-E44+F44-G44 -> 0
C45: COURTNEY HAYEK A/C | F45: 51261.98 | G45: =44134.73+E165 -> 51261.98 | H45: =D45-E45+F45-G45 -> 0
...

Sheet BS
B2: Chemgro Bioenergy Solutions (OPC) Private Limited
B3: Plot no:1&2, Vimala Gardens , East coast road, Injambakkam.
B4: Chennai - 600115 ,Tamil Nadu, India.
B5: CIN:U11100TN2020OPC135994
B7: Balance Sheet as at 31st March 2026
B9: Particulars | G9: Note No. | H9: As at March 31, 2026 | I9: As at March 31, 2025
C10: EQUITY AND LIABILITIES
D11: Shareholder's funds
E12: Share Capital | G12: 3 | H12: =+'3-8'!C17 -> 100000 | I12: 100000
E13: Reserves and Surplus | G13: 4 | H13: =+'3-8'!C61 -> 522814.35 | I13: 512074.62
E14: Money Received against Share Warrants | I14: 0
H15: =SUM(H12:H14) -> 622814.35 | I15: =SUM(I12:I14) -> 612074.62
D16: Share Application Money Pending Allotment | H16: =0 -> 0 | I16: 0
D17: Non-Current Liabilities
E18: Long-Term Borrowings | H18: =0 -> 0 | I18: 0
E19: Deferred Tax Liabilities (Net) | G19: 5 | H19: ='3-8'!C80 -> 0 | I19: 0
E20: Other Long Term Liabilities | H20: =0 -> 0 | I20: 0
E21: Long-Term Provisions | G21: 6 | H21: ='3-8'!C102 -> 81764 | I21: ='3-8'!D102 -> 121329
H22: =SUM(H18:H21) -> 81764 | I22: =SUM(I18:I21) -> 121329
D23: Current Liabilities
E24: Short-Term Borrowings | G24: 7 | H24: ='3-8'!C108 -> 0 | I24: 47640
E25: Trade Payables
E26: (A) | F26: Total Outstanding Dues of Micro Enterprises and Small Enterprises
E27: (B) | F27: Total Outstanding Dues of Creditors other then Micro Enterprises.and Small Enterprises
E28: Other Current Liabilities | G28: 8 | H28: =+'3-8'!C117 -> 10000 | I28: 10000
E29: Short-Term Provisions | G29: 6 | H29: ='3-8'!C93 -> 5872 | I29: ='3-8'!D93 -> 57607
H30: =+SUM(H24:H29) -> 15872 | I30: =SUM(I24:I29) -> 115247
C31: TOTAL | H31: =H15+H16+H22+H30 -> 720450.35 | I31: =I15+I22+I30 -> 848650.62
C33: ASSETS
D34: Non-Current Assets
E35: Property, Plant and Equipment | G35: 9
F36: Tangible Assets | H36: ='9'!N16 -> 30763.02 | I36: 56641.02 | J36: =I36-'9'!O16 -> 0
F37: Intangible Assets | H37: =0 -> 0 | I37: 0
F38: Capital Work-in-Progress | H38: =0 -> 0 | I38: 0
F39: Intangible Assets Under Development | H39: =0 -> 0 | I39: 0
H40: =SUM(H36:H39) -> 30763.02 | I40: =I36 -> 56641.02
E41: Non-Current Investments
D42: Deferred Tax Assets (net) | G42: 5 | H42: =+'3-8'!C79 -> 5006.63 | I42: 5623.65
D43: Long-Term Loans and Advances | H43: =0 -> 0 | I43: 0
D44: Other Non Current Assets | H44: =0 -> 0 | I44: 0
...

Sheet P&L
B2: Chemgro Bioenergy Solutions (OPC) Private Limited
B3: Plot no:1&2, Vimala Gardens , East coast road .
B4: Injambakkam , Chennai - 600115 ,Tamil Nadu, India.
B5: CIN:U11100TN2020OPC135994
B7: Statement of Profit and Loss for the year ended March 31, 2026
B9: Particulars | G9: Note No. | H9: For the year ended March 31, 2026 | I9: For the year ended March 31, 2025
B10: Revenue
C11: Revenue from Operations | G11: 13 | H11: =+'14-22'!C14 -> 1176772.7 | I11: 786474.67
C12: Other Income | G12: 14 | H12: ='14-22'!C21 -> 1112.93 | I12: 19481
B14: Total Revenue | H14: =SUM(H11:H12) -> 1177885.6 | I14: =SUM(I11:I13) -> 805955.67
K15: =1176772-786474 -> 390298
B16: Expenses
C17: Employee Benefits Expense | G17: 15 | H17: =+'14-22'!C28 -> 780000 | I17: 255000
C18: Finance Cost | G18: 16 | H18: =+'14-22'!C34 -> 0 | I18: 16031.56
C19: Depreciation and Amortisation Expense | G19: 17 | H19: =TB!H79 -> 25878 | I19: 29286
C20: Other Expenses | G20: 18 | H20: =+'14-22'!C64 -> 346222.53 | I20: 288960.93
B22: Total Expense | H22: =H17+H18+H19+H20 -> 1152100.5 | I22: =SUM(I17:I21) -> 589278.49
B24: Profit Before Exceptional and Extraordinary items and Tax | H24: =H14-H22 -> 25785.1 | I24: =I14-I22 -> 216677.18
C25: Exceptional items | H25: 0 | I25: 0
B26: Profit Before Extraordinary and Prior Period Items and Tax | H26: =SUM(H24:H25) -> 25785.1 | I26: =SUM(I24:I25) -> 216677.18
C27: Extraordinary items | H27: 0 | I27: 0
C28: Prior Period Items | G28: 19 | H28: ='14-22'!C69 -> -8556 | I28: ='14-22'!D69 -> 0
B29: Profit Before Tax | H29: =SUM(H26:H28) -> 17229.1 | I29: =SUM(I26:I28) -> 216677.18
B30: Tax Expense
C31: Current Tax | G31: 20 | H31: =+'14-22'!C74 -> 5872 | I31: 57607
C32: Deferred Tax | H32: =-'Deferred Tax'!E14 -> 617.37 | I32: 778.95
C33: Excess / Short Provision Relating Earlier Year Tax | H33: 0 | I33: 0
C34: Total Tax | H34: =SUM(H31:H33) -> 6489.37 | I34: =SUM(I31:I33) -> 58385.95
B36: Profit (Loss) for the Period | H36: =H29-H34 -> 10739.73 | I36: =I29-I34 -> 158291.23 | K36: =158291-10739 -> 147552
B38: Earnings Per Equity Sshare: | G38: 21
B40: Basic
B41: Before Extraordinary Items | H41: =+'14-22'!C83 -> 1.073973 | I41: =+'14-22'!C96 -> 15.829123
B42: After Extraordinary Adjustment | H42: =+'14-22'!D83 -> 1.073973 | I42: =+'14-22'!D96 -> 15.829123
B43: Diluted
B44: Before Extraordinary Items | H44: =+'14-22'!C88 -> 1.073973 | I44: =+'14-22'!C101 -> 15.829123
B45: After Extraordinary Adjustment | H45: =+'14-22'!D88 -> 1.073973 | I45: =+'14-22'!D101 -> 15.829123
B46: Significant Accounting Policies | G46: 1 & 2
B47: See accompanying notes to the Financial Statements
B48: The accompanying notes are an integral part of the financial statements.
B51: For RAMANUJAM and BOOVARAHAN | G51: For and on behalf of the Board of Directors
...

Sheet 3-8
B2: Chemgro Bioenergy Solutions (OPC) Private Limited
B3: Plot no:1&2, Vimala Gardens , East coast road .
B4: Injambakkam , Chennai - 600115 ,Tamil Nadu, India.
B5: CIN:U11100TN2020OPC135994
B7: Notes forming part of the Financial Statements for the Year ended March 31, 2026
B8: Note No. 3 Share Capital
B9: Particulars | C9: As at March 31, 2026 | D9: As at March 31, 2025
B10: Authorised
B11: 10,000 Equity shares of Rs. 10/- each | C11: 100000 | D11: 100000
B13: Issued
B14: 10,000 Equity shares of Rs. 10/- each | C14: 100000 | D14: 100000
B16: Subscribed and Fully Paid Up
B17: 10,000 Equity shares of Rs. 10/- each | C17: =TB!I10 -> 100000 | D17: 100000
B20: Note No. 3.1 Reconciliation of the shares outstanding at the beginning and at the end of the year
B21: Particulars | C21: As at March 31, 2026 | E21: As at March 31, 2025
C22: Number | D22: Amount | E22: Number | F22: Amount
B23: Shares outstanding at the beginning of the period | C23: 10000 | D23: =C23*10 -> 100000 | E23: 10000 | F23: =E23*10 -> 100000
B24: Shares issued during the period | C24: 0 | D24: =C24*10 -> 0 | E24: 0 | F24: =E24*10 -> 0
B25: Shares bought back during the period | C25: 0 | D25: =C25*100 -> 0
B26: Shares outstanding at the end of the period | C26: =SUM(C23:C25) -> 10000 | D26: =SUM(D23:D25) -> 100000 | E26: =SUM(E23:E25) -> 10000 | F26: =SUM(F23:F25) -> 100000
B29: Note No. 3.2 Rights, Preferences and Restrictions
B31: The Company has one class of equity shares having a par value of Rs. 10 per share. The equity shares are attached with voting rights. Each shareholder is eligible for one vote per share held. The dividend, if any, proposed by the Board of Directors during a year is subject to the approval of the shareholders in the Annual General Meeting, except in case of interim dividend. In the event of liquidation, the equity shareholders are eligible to receive the remaining assets of the Company after distribution of all preferential amount, in proportion to their shareholding.
B36: Note No. 3.3 Shares held be shareholders holding more than 5%
B38: Particulars | C38: =+C21 -> As at March 31, 2026
C39: Number of Shares held | D39: Amount | E39: Percentage of Holding
B41: Vasudevan V | C41: 10000 | D41: 100000 | E41: 1
B44: Note No. 3.4 Shares held by promoters at the end of the year 31st March 2026
B46: Promoter Name | C46: Number of Shares held | D46: Percentage of Holding | E46: Percentage Change during the year
B48: Vasudevan V | C48: 10000 | D48: 1 | E48: 0
B52: Note No. 4 Reserves and Surplus
B54: Particulars | C54: As at March 31, 2026 | D54: As at March 31, 2025
B55: Profit and Loss Account (Surplus)
B56: Opening Balance | C56: =D61 -> 512074.62 | D56: 353603.64
B57: Add: Net Profit / (Loss) for the Current Period | C57: ='P&L'!H36 -> 10739.73 | D57: 158470.98 | E57: =D57-'P&L'!I36 -> 179.75
B59: Closing Balance | C59: =SUM(C56:C57) -> 522814.35 | D59: =SUM(D56:D58) -> 512074.62
B61: Balance carried to balance sheet | C61: =+C59 -> 522814.35 | D61: =+D59 -> 512074.62
B64: Note No. 5 Deferred tax
B66: Particulars | C66: As at March 31, 2026 | D66: As at March 31, 2025
B67: Deferred Tax Liability
B68: Depreciation | C68: 0 | D68: 0
...

Sheet 9
B2: Chemgro Bioenergy Solutions (OPC) Private Limited
B3: Plot no:1&2, Vimala Gardens , East coast road .
B4: Injambakkam , Chennai - 600115 ,Tamil Nadu, India.
B5: CIN:U11100TN2020OPC135994
B6: Notes forming part of the Financial Statements for the Year ended 31 March 2026
B8: Note No. 9 Property, Plant and Equipment
B9: Asset | D9: Useful Life (in years) | E9: Gross Block | J9: Accumulated Depreciation | N9: Net Block
E10: Balance as at April 01, 2025 | F10: Additions during the period | G10: Addition on account of business acquisition | H10: Deletion during the period | I10: Balance as at March 31, 2026 | J10: Balance as at April 01, 2025 | K10: Provided for the period | L10: Deletion / adjustments during the period | M10: Balance as at March 31, 2025 | N10: Balance as at March 31, 2026 | O10: Balance as at March 31, 2025
B11: A | C11: Tangible Assets
C12: Own Assets
C13: Computer | D13: 3 | E13: =SUM(I21:I24) -> 181583.49 | G13: 0 | H13: 0 | I13: =SUM(E13:G13)-H13 -> 181583.49 | J13: 135415.51 | K13: =SUM(M21:M24) -> 21157 | L13: 0 | M13: =J13+K13+L13 -> 156572.51 | N13: =I13-M13 -> 25010.98 | O13: =E13-J13 -> 46167.98
C14: Office Equipment | D14: 5 | E14: =SUM(I25:I26) -> 25989.04 | G14: 0 | H14: 0 | I14: =SUM(E14:G14)-H14 -> 25989.04 | J14: 15516 | K14: =SUM(M25:M26) -> 4721 | L14: 0 | M14: =J14+K14+L14 -> 20237 | N14: =I14-M14 -> 5752.04 | O14: =E14-J14 -> 10473.04
C16: Total | E16: =SUM(E13:E14) -> 207572.53 | F16: =SUM(F13:F15) -> 0 | G16: =SUM(G13:G15) -> 0 | H16: =SUM(H13:H15) -> 0 | I16: =SUM(I13:I15) -> 207572.53 | J16: =SUM(J13:J15) -> 150931.51 | K16: =SUM(K13:K15) -> 25878 | L16: =SUM(L13:L15) -> 0 | M16: =SUM(M13:M15) -> 176809.51 | N16: =SUM(N13:N15) -> 30763.02 | O16: =SUM(O13:O14) -> 56641.02
C19: Existing Assets | I19: 45747 | L19: 46112
B20: Category of Asset | C20: Name of Asset | D20: Date of Purchase (dd/mm/yyyy) | E20: Rate as per Companies Act 2013 | F20: Life | G20: Remaining Useful Life | H20: Assets w/o Date | I20: Purchase Amount | J20: WDV as on 31/03/2025 | K20: Date of Sale | L20: Sale amount | M20: Depreciation for FY 2025-26 | N20: WDV as on 31/03/2026 | O20: Scrap Value (5% of Original Cost) | P20: Remarks
B21: Computer | C21: Dell Inspiron 3521 laptop | D21: 44126 | E21: 0.63159685 | F21: 3 | G21: =MAX(ROUND((H21-$L$19-1)/366,3),0) -> 0 | H21: =D21+(F21*366) -> 45224 | I21: 45724.45 | J21: 1648.9437 | K21: - | L21: 0 | M21: =ROUND(IF(G21>0,IF(L21=0,(J21*E21),(L21*E21*(K21-L$19)/366)),0),0) -> 0 | N21: =J21-M21 -> 1648.9437 | O21: =ROUND(I21*0.05,0) -> 2286
B22: Computer | C22: Lenovo IdeaPad Slim | D22: 28-12-2022 | E22: 0.6316 | F22: 3 | G22: =MAX(ROUND((H22-$L$19-1)/366,3),0) -> 0 | H22: 46021 | I22: 48490 | J22: 5511 | K22: - | L22: 0 | M22: =ROUND(IF(G22>0,IF(L22=0,(J22*E22),(L22*E22*(K22-L$19)/366)),0),0) -> 0 | N22: =J22-M22 -> 5511 | O22: =ROUND(I22*0.05,0) -> 2425
B23: Computer | C23: Lenovo IdeaPad Slim | D23: 28-12-2022 | E23: 0.6316 | F23: 3 | G23: =MAX(ROUND((H23-$L$19-1)/366,3),0) -> 0 | H23: 46021 | I23: 48490 | J23: 5511 | K23: - | L23: 0 | M23: =ROUND(IF(G23>0,IF(L23=0,(J23*E23),(L23*E23*(K23-L$19)/366)),0),0) -> 0 | N23: =J23-M23 -> 5511 | O23: =ROUND(I23*0.05,0) -> 2425
B24: Computer | C24: Lenovo IdeaPad | D24: 45668 | E24: 0.63159685 | F24: 3 | G24: =MAX(ROUND((H24-$L$19-1)/366,3),0) -> 1.776 | H24: =D24+(F24*365) -> 46763 | I24: 38879.04 | J24: 33497.04 | K24: 0 | L24: 0 | M24: =ROUND(IF(G24>0,IF(L24=0,(J24*E24),(L24*E24*(K24-L$19)/366)),0),0) -> 21157 | N24: =J24-M24 -> 12340.04 | O24: =ROUND(I24*0.05,0) -> 1944
B25: Office Equipment | C25: JBL Speaker | D25: 45668 | E25: 0.45071973 | F25: 5 | G25: =MAX(ROUND((H25-$L$19-1)/366,3),0) -> 3.77 | H25: =D25+(F25*365) -> 47493 | I25: 5595.04 | J25: 5042.04 | K25: 0 | L25: 0 | M25: =ROUND(IF(G25>0,IF(L25=0,(J25*E25),(L25*E25*(K25-L$19)/366)),0),0) -> 2273 | N25: =J25-M25 -> 2769.04 | O25: =ROUND(I25*0.05,0) -> 280
B26: Office Equipment | C26: Moto - G82 | D26: 44922 | E26: 0.45071973 | F26: 5 | G26: =MAX(ROUND((H26-$L$19-1)/366,3),0) -> 1.746 | H26: =D26+(F26*366) -> 46752 | I26: 20394 | J26: 5431 | K26: 0 | L26: 0 | M26: =ROUND(IF(G26>0,IF(L26=0,(J26*E26),(L26*E26*(K26-L$19)/366)),0),0) -> 2448 | N26: =J26-M26 -> 2983 | O26: =ROUND(I26*0.05,0) -> 1020
I28: =SUM(I21:I26) -> 207572.53 | J28: =SUM(J21:J27) -> 56641.024 | K28: =SUM(K24:K27) -> 0 | L28: =SUM(L24:L27) -> 0 | M28: =SUM(M22:M27) -> 25878 | N28: =SUM(N21:N27) -> 30763.024 | O28: =SUM(O21:O27) -> 10380
K31: =J22*E22*9/12 -> 2610.5607
K32: =J23*E23*9/12 -> 2610.5607
K33: =J24*E24 -> 21156.625 | L33: =SUM(K31:K35) -> 31596.746
K34: =2771 -> 2771
K35: =2448 -> 2448

Sheet 10-13
B2: Chemgro Bioenergy Solutions (OPC) Private Limited
B3: Plot no:1&2, Vimala Gardens , East coast road .
B4: Injambakkam , Chennai - 600115 ,Tamil Nadu, India.
B5: CIN:U11100TN2020OPC135994
B7: Notes forming part of the Financial Statements for the Year ended 31 March 2026
B10: Note No 10: Trade receivables
B11: Particulars | C11: As at March 31, 2026 | D11: As at March 31, 2025
B12: Outstanding for more than six months
B13: a) Secured, considered good | C13: 0 | D13: 0
B14: b) Unsecured, considered good | C14: 0 | D14: 0
B15: c) Doubtful | C15: 0 | D15: 0
B16: Others
B17: a) Secured, considered good | C17: =TB!H41 -> 0 | D17: 5323.11
B18: b) Unsecured, considered good | C18: 0
B19: c) Doubtful | C19: 0 | D19: 0
B21: Total | C21: =ROUND(SUM(C12:C19),100) -> 0 | D21: =SUM(D12:D19) -> 5323.11
B23: Trade Receivables ageing schedule as at 31st March,2026
B25: Particulars | C25: Outstanding for following periods from due date of payment
C26: Less than 6 months | D26: 6 months -1 year | E26: 1-2 years | F26: 2-3 years | G26: More than 3 years | H26: Total
B27: (i) Undisputed Trade receivables -considered good | C27: 0 | D27: 0 | E27: 0 | F27: 0 | G27: 0 | H27: =SUM(C27:G27) -> 0
B28: (i) Undisputed Trade receivables -considered doubtful | C28: 0 | D28: 0 | E28: 0 | F28: 0 | G28: 0 | H28: =SUM(C28:G28) -> 0
B29: (iii) Disputed trade receivables considered good | C29: 0 | D29: 0 | E29: 0 | F29: 0 | G29: 0 | H29: =SUM(C29:G29) -> 0
B30: (iv) Disputed trade receivables considered doubtful | C30: 0 | D30: 0 | E30: 0 | F30: 0 | G30: 0 | H30: =SUM(C30:G30) -> 0
B32: Trade Receivables ageing schedule as at 31st March,2025
B34: Particulars | C34: Outstanding for following periods from due date of payment
C35: Less than 6 months | D35: 6 months -1 year | E35: 1-2 years | F35: 2-3 years | G35: More than 3 years | H35: Total
B36: (i) Undisputed Trade receivables -considered good | C36: =5323.11 -> 5323.11 | D36: 0 | E36: 0 | F36: 0 | G36: 0 | H36: =SUM(C36:G36) -> 5323.11
B37: (i) Undisputed Trade receivables -considered doubtful | C37: 0 | D37: 0 | E37: 0 | F37: 0 | G37: 0 | H37: =SUM(C37:G37) -> 0
B38: (iii) Disputed trade receivables considered good | C38: 0 | D38: 0 | E38: 0 | F38: 0 | G38: 0 | H38: =SUM(C38:G38) -> 0
B39: (iv) Disputed trade receivables considered doubtful | C39: 0 | D39: 0 | E39: 0 | F39: 0 | G39: 0 | H39: =SUM(C39:G39) -> 0
B41: Note No. 11 Cash And Cash Equivalents
B43: Particulars | C43: As at March 31, 2026 | D43: As at March 31, 2025
B44: Cash at Bank
B45: HDFC Bank Current A/c | C45: =TB!H68 -> 551222.58 | D45: 606079.9
B46: ICICI Bank Current A/c | C46: =TB!H69 -> 27820.41 | D46: 28790.18
B48: Total | C48: =SUM(C45+C46) -> 579042.99 | D48: =SUM(D45:D47) -> 634870.08
B50: Note No 12: Other Current Asset
B51: Particulars | C51: =C43 -> As at March 31, 2026 | D51: =D43 -> As at March 31, 2025
B53: Rental Deposit | C53: =TB!H59 -> 9213 | D53: 9213
B54: TDS
...

Sheet 14-22
B2: Chemgro Bioenergy Solutions (OPC) Private Limited
B3: Plot no:1&2, Vimala Gardens , East coast road .
B4: Injambakkam , Chennai - 600115 ,Tamil Nadu, India.
B5: CIN:U11100TN2020OPC135994
B7: Notes forming part of the Financial Statements for the Year ended 31 March 2026
B9: Note No. 13 Revenue from operation
B10: Particulars | C10: As at March 31, 2026 | D10: As at March 31, 2025
B11: Sale of Service
B12: Export | C12: =TB!I72 -> 1058472.7 | D12: 766038.34
B13: Local | C13: =TB!I73 -> 118300 | D13: 20436.33
C14: =SUM(C12:C13) -> 1176772.7 | D14: =SUM(D12:D13) -> 786474.67 | L14: .
B16: Note No. 14 Other Income
B17: Particulars | C17: As at March 31, 2026 | D17: As at March 31, 2025
B18: FD Interest | C18: 0 | D18: 19481
B19: Interest on IT refund | C19: 0 | D19: 0
B20: Gain on Exchange Fluctuation | C20: =TB!I75-TB!H90 -> 1112.93 | D20: 0
C21: =SUM(C18:C20) -> 1112.93 | D21: =SUM(D18:D20) -> 19481
B23: Note No 15: Employment benefit expenses
B24: Particulars | C24: As at March 31, 2026 | D24: As at March 31, 2025
B26: Salary to Director | C26: 180000 | D26: =15000*12 -> 180000
B27: Bonus To Director | C27: 600000 | D27: =15000*5 -> 75000
B28: Total | C28: =SUM(C26:C27) -> 780000 | D28: =SUM(D26+D27) -> 255000
B30: Note No. 16 : Finance Cost
B31: Particulars | C31: As at March 31, 2026 | D31: As at March 31, 2025
B32: Loss on Foreign Exchange Fluctuation | C32: 0 | D32: 8097.56
B33: Bank Charges | C33: 0 | D33: 7934
C34: =SUM(C32:C32) -> 0 | D34: =SUM(D32:D33) -> 16031.56
B36: Note No. 17 : Depreciation and Amortisation
B37: Particulars | C37: As at March 31, 2026 | D37: As at March 31, 2025
B38: Depreciation on Tangible Assets | C38: =TB!F79 -> 25878 | D38: 29286
B39: Ammortisation of Intangible Assets | C39: 0 | D39: 0
C40: =SUM(C38:C39) -> 25878 | D40: =SUM(D38:D39) -> 29286
B42: Note No. 18 Other Expenses
B43: Particulars | C43: As at March 31, 2026 | D43: As at March 31, 2025
B44: Other expenses
B45: Audit fee | C45: =TB!H78 -> 11800 | D45: 14300
B46: Bank Charges | C46: =TB!H89 -> 649
B47: Professional Fee | C47: =TB!H77 -> 29687 | D47: 23600
B48: Roc Filing Exp | C48: 0 | D48: 1517
B49: Rent | C49: =TB!H84 -> 106200 | D49: 102660
...

Sheet 22-26
B2: Chemgro Bioenergy Solutions (OPC) Private Limited
B3: Plot no:1&2, Vimala Gardens , East coast road .
B4: Injambakkam , Chennai - 600115 ,Tamil Nadu, India.
B5: CIN:U11100TN2020OPC135994
B7: Note No 22 : Disclosure as required by Para 20 of Accounting Standard-AS 18 ”Related Parties”
B8: of the Companies (Accounting Standard) Rules, 2006:-
B9: CIN : | C9: U11100TN2020OPC135994
B11: Note No 22.1 :Names of related parties and description of relationship : | F11: Relevant Para of the CARO 2020 - 3(xiii)
B13: S.No. | C13: Name | D13: Relation
B14: 1 | C14: Vasudevan V | D14: Director
B17: Note No 22.2 :Transactions with related parties for the year ended March 31, 2026
B19: S.No. | C19: Particulars | D19: Purchase & Labour Charges | F19: Interest Expenses | H19: Salary Expenses
D20: 2025-26 | E20: 2024-25 | F20: =D20 -> 2025-26 | G20: 2024-25 | H20: =F20 -> 2025-26 | I20: =G20 -> 2024-25
B21: 1 | C21: Salary To Director | D21: 0 | E21: 0 | F21: 0 | G21: 0 | H21: ='14-22'!C26 -> 180000 | I21: =+'14-22'!D26 -> 180000
B22: 2 | C22: Bonus To Director | D22: 0 | E22: 0 | F22: 0 | G22: 0 | H22: ='14-22'!C27 -> 600000 | I22: =+'14-22'!D27 -> 75000
C23: Total | D23: =SUM(D21:D22) -> 0 | E23: =SUM(E21:E22) -> 0 | F23: =SUM(F21:F22) -> 0 | G23: =SUM(G21:G22) -> 0 | H23: =SUM(H21:H22) -> 780000 | I23: =SUM(I21:I22) -> 255000
B25: Note No 22.3 :Balance Outstanding with related parties for the year ended March 31, 2026
B27: S.No. | C27: Particulars | D27: Loan Outstandings
D28: 2025-26 | E28: 2024-25
B29: 1 | C29: Loan From Director | D29: - | E29: 47640
C30: Total | D30: =SUM(D29:D29) -> 0 | E30: =SUM(E29:E29) -> 47640
B32: Note No. 23 Other Statutory Information
B34: 23.1 | C34: The Company do not have any Benami property, where any proceeding has been initiated or pending against the Company for holding any Benami property.
B36: 23.2 | C36: The Company do not have any transactions with companies struck off.
B37: 23.3 | C37: The Company do not have any charges or satisfaction which is yet to be registered with ROC beyond the statutory period.
B38: 23.4 | C38: The Company have not traded or invested in Crypto currency or Virtual Currency during the financial year.
B39: 23.5 | C39: The company has no transactions which are not recorded in the books of accounts, that has been surrendered or disclosed as income during the year under the Income Tax Act, 1961. (such as Search or Survey under the Income Tax Act, 1961)
B41: 23.6 | C41: The Company has complied with the number of layers prescribed under clause (87) of section 2 of the Act read with the Companies (Restriction on number of Layers) Rules, 2017.
B43: 23.7 | C43: The Company have not advanced or loaned or invested funds to any other person(s) or entity(ies), including foreign entities (Intermediaries) with the understanding that the Intermediary shall:
C45: (a) directly or indirectly lend or invest in other persons or entities identified in any manner whatsoever by or on behalf of the Company (Ultimate Beneficiaries); or
C47: (b) provide any guarantee, security or the like to or on behalf of the Ultimate Beneficiaries.
B48: 23.8 | C48: The Company have not received any fund from any person(s) or entity(ies), including foreign entities (Funding Party) with the understanding (whether recorded in writing or otherwise) that the Company shall:
C50: (a) directly or indirectly lend or invest in other persons or entities identified in any manner whatsoever by or on behalf of the Funding Party (Ultimate Beneficiaries); or
C52: (b) provide any guarantee, security or the like on behalf of the Ultimate Beneficiaries.
B53: 23.9 | C53: The company is not declared as a wilful defaulter by any bank or financial Institution or other lender.
B55: Note No. 24 Disclosures required under Section 22 of the Micro, Small and Medium Enterprises Development Act, 2006
B57: Based on and to the extent of information received by the Company from the suppliers during the year regarding their status under the Micro Small and Medium Enterprises Development Act, 2006 (MSMED Act), the relevant particulars for the period ended March 31, 2022 is furnished below:
B59: Particulars | H59: 46112
B61: Principal amount remaining unpaid to any supplier as at the end of the accounting year. | H61: NIL
B62: Interest due thereon remaining unpaid to any supplier as at the end of the accounting year. | H62: 0
...

Sheet Ratio Analysis
B2: Chemgro Bioenergy Solutions (OPC) Private Limited
B3: Plot no:1&2, Vimala Gardens , East coast road .
B4: Injambakkam , Chennai - 600115 ,Tamil Nadu, India.
B5: CIN:U11100TN2020OPC135994
B7: Note No. 27 Notes Forming Part of Statement of Profit & Loss
B9: S.No | C9: Particulars | D9: Measurement | E9: Numerator | F9: Denominator | G9: Mar 31, 2026 | H9: Mar 31, 2025 | I9: % Change | J9: Explanation for Significant Change
B10: 1 | C10: Current Ratio | D10: In Times | E10: Current Asset | F10: Current Liabilities | G10: ='Ratio Workings'!E8 -> 43.137645 | H10: ='Ratio Workings'!F8 -> 6.823483 | I10: =IFERROR((G10-H10)/H10,"NA") -> 5.3219392 | J10: ='Ratio Workings'!H8 -> Decrease in Current Liabilities
B11: 2 | C11: Debt - Equity Ratio | D11: In Times | E11: Debt = Long Term Borrowings + Short Term Borrowings | F11: Total Equity | G11: ='Ratio Workings'!E9 -> NA | H11: ='Ratio Workings'!F9 -> 0.077833647 | I11: =IFERROR((G11-H11)/H11,"NA") -> NA | J11: ='Ratio Workings'!H9 -> Since there is no Debt for Current Year, this ratio cannot be calculated.
B12: 3 | C12: Debt Service Coverage Ratio | D12: In Times | E12: Earnings for Debt Service = Net Profit after Taxes + Non Cash Operating Expenses + Finance Cost | F12: Debt Service = Interest & Lease Payments + Principal Payments | G12: ='Ratio Workings'!E17 -> NA | H12: ='Ratio Workings'!F17 -> NA | I12: =IFERROR((G12-H12)/H12,"NA") -> NA | J12: ='Ratio Workings'!H17 -> 0
B13: 4 | C13: Return on Equity Ratio | D13: In Percentage | E13: Profit after Tax | F13: Average Shareholder's Fund | G13: ='Ratio Workings'!E10 -> 0.017393839 | H13: ='Ratio Workings'!F10 -> 0.29707133 | I13: =IFERROR((G13-H13)/H13,"NA") -> -0.94144895 | J13: ='Ratio Workings'!H10 -> Decrease in Net Profit and Increase in Average Shareholders' Funds
B14: 5 | C14: Inventory Turnover Ration | D14: In Times | E14: Revenue from Operations | F14: Average Inventory | G14: ='Ratio Workings'!E11 -> NA | H14: ='Ratio Workings'!F11 -> NA | I14: =IFERROR((G14-H14)/H14,"NA") -> NA | J14: ='Ratio Workings'!H11 -> The Company is in the business of Engineering and Management Consultancy and hence does not have any Inventory
B15: 6 | C15: Trade Receivables Turnover Ratio | D15: In Times | E15: Net Credit Sales = Gross Credit Sales - Sales Return (Excluding Other Income) | F15: Average Trade Receivable | G15: ='Ratio Workings'!E12 -> 442.55543 | H15: ='Ratio Workings'!F12 -> 302.81383 | I15: =IFERROR((G15-H15)/H15,"NA") -> 0.46147694 | J15: ='Ratio Workings'!H12 -> Increase in Net Credit Sales
B16: 7 | C16: Trade Payable Turnover Ratio | D16: In Times | E16: Purchases and Other Services | F16: Average Trade Payable | G16: ='Ratio Workings'!E13 -> NA | H16: ='Ratio Workings'!F13 -> NA | I16: =IFERROR((G16-H16)/H16,"NA") -> NA | J16: ='Ratio Workings'!H13 -> The Trade Payable Turnover cannot be calculated as the Company does not have Average Trade Payables.
B17: 8 | C17: Net Capital Turnover Ratio | D17: In Times | E17: Net Sales = Total Sales - Sales Return (Including Other Income) | F17: Working Capital = Current Assets - Current Liabilities | G17: ='Ratio Workings'!E14 -> 1.7611697 | H17: ='Ratio Workings'!F14 -> 1.2008775 | I17: =IFERROR((G17-H17)/H17,"NA") -> 0.46656899 | J17: ='Ratio Workings'!H14 -> Increase in Net Sales
B18: 9 | C18: Net Profit Ratio | D18: In Percentage | E18: Profit After Tax | F18: Net Sales = Total Sales - Sales Return (Including Other Income) | G18: ='Ratio Workings'!E15 -> 0.0091178037 | H18: ='Ratio Workings'!F15 -> 0.19640191 | I18: =IFERROR((G18-H18)/H18,"NA") -> -0.95357579 | J18: ='Ratio Workings'!H15 -> Decrease in Net Profit of the Company.
B19: 10 | C19: Return on Capital Employed | D19: In Percentage | E19: Earnings Before Interest and Tax | F19: Capital Employed = Net Worth + Total Debt | G19: ='Ratio Workings'!E16 -> 0.0276633 | H19: ='Ratio Workings'!F16 -> 0.32844077 | I19: =IFERROR((G19-H19)/H19,"NA") -> -0.91577386 | J19: ='Ratio Workings'!H16 -> Decrease in EBIT during the year.
B20: 11 | C20: Return on Investment | D20: In Percentage | E20: Profit After Tax | F20: Total Assets | G20: ='Ratio Workings'!E18 -> 0.013689023 | H20: ='Ratio Workings'!F18 -> 0.18462388 | I20: =IFERROR((G20-H20)/H20,"NA") -> -0.92585454 | J20: ='Ratio Workings'!H18 -> Decrease in Profit during the year.
B22: Note: Previous Year’s Figures
B23: The amounts for the previous year have been regrouped wherever necessary
B26: In terms of our report attached.
B27: For RAMANUJAM and BOOVARAHAN | F27: For and on behalf of the Board of Directors
B28: Chartered Accountants
B29: (FRN: 02945S)
B32: N R BOOVARAHAN
B33: Partner | F33: Director
B34: Membership No.: 053073 | F34: DIN: 08773250
B36: Place: | C36: CHENNAI
B37: Date:
B39: UDIN:

Sheet Ratio Workings
B2: ='[11]29-33'!B2 -> MILANO INTERNATIONAL (INDIA) PRIVATE LIMITED
B3: ='[11]29-33'!B3 -> C-4, COMMUNITY CENTRE,NARAINA VIHAR, NEW DELHI-110028
B4: ='[11]29-33'!B4 -> CIN : U74899DL1978PTC008991
B6: Analytical Ratios
B7: Ratio | C7: Numberator | D7: Denominator | E7: Mar 31, 2026 | F7: Mar 31, 2025 | G7: % Variance | H7: Reason for variance
B8: Current Ratio | C8: Current Asset | D8: Current Liabilities | E8: =IFERROR(E25/E26,"NA") -> 43.137645 | F8: =IFERROR(F25/F26,"NA") -> 6.823483 | G8: =IFERROR((E8-F8)/F8,"NA") -> 5.3219392 | H8: Decrease in Current Liabilities
B9: Debt - Equity Ratio | C9: Debt = Long Term Borrowings + Short Term Borrowings | D9: Total Equity | E9: NA | F9: =IFERROR(F28/F29,"NA") -> 0.077833647 | G9: =IFERROR((E9-F9)/F9,"NA") -> NA | H9: Since there is no Debt for Current Year, this ratio cannot be calculated.
B10: Return on Equity Ratio | C10: Profit after Tax | D10: Average Shareholder's Fund | E10: =IFERROR(E31/E30,"NA") -> 0.017393839 | F10: =IFERROR(F31/F30,"NA") -> 0.29707133 | G10: =IFERROR((E10-F10)/F10,"NA") -> -0.94144895 | H10: Decrease in Net Profit and Increase in Average Shareholders' Funds
B11: Inventory Turnover Ration | C11: Revenue from Operations | D11: Average Inventory | E11: NA | F11: =IFERROR(F44/F46,"NA") -> NA | G11: =IFERROR((E11-F11)/F11,"NA") -> NA | H11: The Company is in the business of Engineering and Management Consultancy and hence does not have any Inventory
B12: Trade Receivables Turnover Ratio | C12: Net Credit Sales = Gross Credit Sales - Sales Return (Excluding Other Income) | D12: Average Trade Receivable | E12: =IFERROR(E44/E48,"NA") -> 442.55543 | F12: =IFERROR(F44/F48,"NA") -> 302.81383 | G12: =IFERROR((E12-F12)/F12,"NA") -> 0.46147694 | H12: Increase in Net Credit Sales
B13: Trade Payable Turnover Ratio | C13: Purchases and Other Services | D13: Average Trade Payable | E13: =IFERROR(E49/E51,"NA") -> NA | F13: =IFERROR(F49/F51,"NA") -> NA | G13: =IFERROR((E13-F13)/F13,"NA") -> NA | H13: The Trade Payable Turnover cannot be calculated as the Company does not have Average Trade Payables.
B14: Net Capital Turnover Ratio | C14: Net Sales = Total Sales - Sales Return (Including Other Income) | D14: Working Capital = Current Assets - Current Liabilities | E14: =IFERROR(E44/E27,"NA") -> 1.7611697 | F14: =IFERROR(F44/F27,"NA") -> 1.2008775 | G14: =IFERROR((E14-F14)/F14,"NA") -> 0.46656899 | H14: Increase in Net Sales
B15: Net Profit Ratio | C15: Profit After Tax | D15: Net Sales = Total Sales - Sales Return (Including Other Income) | E15: =IFERROR(E31/E44,"NA") -> 0.0091178037 | F15: =IFERROR(F31/F44,"NA") -> 0.19640191 | G15: =IFERROR((E15-F15)/F15,"NA") -> -0.95357579 | H15: Decrease in Net Profit of the Company.
B16: Return on Capital Employed | C16: Earnings Before Interest and Tax | D16: Capital Employed = Net Worth + Total Debt | E16: =IFERROR(E34/E53,"NA") -> 0.0276633 | F16: =IFERROR(F34/F53,"NA") -> 0.32844077 | G16: =IFERROR((E16-F16)/F16,"NA") -> -0.91577386 | H16: Decrease in EBIT during the year.
B17: Debt Service Coverage Ratio | C17: Earnings for Debt Service = Net Profit after Taxes + Non Cash Operating Expenses + Finance Cost | D17: Debt Service = Interest & Lease Payments + Principal Payments | E17: =IFERROR(E40/E43,"NA") -> NA | F17: =IFERROR(F40/F43,"NA") -> NA | G17: =IFERROR((E17-F17)/F17,"NA") -> NA
B18: Return on Investment | C18: Profit After Tax | D18: Average Total Assets | E18: =IFERROR(E31/E54,"NA") -> 0.013689023 | F18: =IFERROR(F31/F54,"NA") -> 0.18462388 | G18: =IFERROR((E18-F18)/F18,"NA") -> -0.92585454 | H18: Decrease in Profit during the year.
B19: Note
B20: *Working capital shall be calculated as current assets minus current liabilities(excluding current maturities of Iong term debt, lease liability and interest accrued on borrowings)
B21: #EBIT = Earning before interest and taxes
B22: ^Capital Employed = Tangible Net Worth + Total Debt
B23: Workings
B24: Particulars | D24: Source from FS | E24: Mar 31, 2026 | F24: Mar 31, 2025 | G24: Mar 31, 2024
A25: 1 | B25: Current Assets including Assets held for sale | D25: BS | E25: =BS!H53 -> 684680.7 | F25: =BS!I53 -> 786385.95 | G25: =[12]BS!$I$53 -> 818236.56
A26: 2 | B26: Current Liabilities | D26: BS | E26: =BS!H30 -> 15872 | F26: =BS!I30 -> 115247 | G26: =[12]BS!$I$30 -> 412488.46
A27: 3 | B27: Working Capital | D27: (1-2) | E27: =E25-E26 -> 668808.7 | F27: =F25-F26 -> 671138.95 | G27: =G25-G26 -> 405748.1
A28: 4 | B28: Total Debt | D28: BS | E28: =BS!H24+BS!H18 -> 0 | F28: =BS!I18+BS!I24 -> 47640 | G28: =[12]BS!$I$18+[12]BS!$I$24 -> 272640
A29: 5 | B29: Shareholder's Equity / Tangible Net Worth | D29: BS | E29: =BS!H15 -> 622814.35 | F29: =BS!I15 -> 612074.62 | G29: =[12]BS!$I$15 -> 453603.64
A30: 6 | B30: Avg. Shareholder’s Equity | D30: Avg (5) | E30: =(E29+F29)/2 -> 617444.48 | F30: =(F29+G29)/2 -> 532839.13
A31: 7 | B31: Net Profit after taxes | D31: P&L | E31: ='P&L'!H36 -> 10739.73 | F31: ='P&L'!I36 -> 158291.23 | G31: ='[12]P&L'!$I$36 -> 54538.955
A32: 8 | B32: Interest | D32: P&L | E32: 0 | F32: 0 | G32: 0
A33: 9 | B33: Tax Expenses | D33: P&L | E33: ='P&L'!H34 -> 6489.37 | F33: ='P&L'!I34 -> 58385.95 | G33: ='[12]P&L'!$I$34 -> 18342.94
A34: 10 | B34: EBIT | D34: SUM(7:9) | E34: =SUM(E31:E33) -> 17229.1 | F34: =SUM(F31:F33) -> 216677.18 | G34: =SUM(G31:G33) -> 72881.896
A35: 11 | B35: Depreciation and Impairment | D35: P&L | E35: ='P&L'!H19 -> 25878 | F35: ='P&L'!I19 -> 29286 | G35: ='[12]P&L'!$I$19 -> 62232.01
A36: 12 | B36: Impairment of financial assets | D36: CFS | E36: 0 | F36: 0 | G36: 0
A37: 13 | B37: Unrealised (gain) / loss of foreign exchange transactions (net) | D37: CFS | E37: 0 | F37: 0 | G37: 0
A38: 14 | B38: Provision no longer required written back | D38: Note 5 | E38: 0 | F38: 0 | G38: 0
A39: 15 | B39: Non-Cash Items | D39: SUM(10:13) | E39: =SUM(E35:E38) -> 25878 | F39: =SUM(F35:F38) -> 29286 | G39: =SUM(G35:G38) -> 62232.01
A40: 16 | B40: Earnings for Debt Service | D40: (10+15-9) | E40: =E34+E39-E33 -> 36617.73 | F40: =F34+F39-F33 -> 187577.23 | G40: =G34+G39-G33 -> 116770.97
A41: 17 | B41: Interest and Lease Payments | D41: CFS | E41: 0 | F41: 0
A42: 18 | B42: Debt payments | D42: CFS | E42: 0 | F42: 0
...

Sheet Deferred Tax
B2: Chemgro Bioenergy Solutions (OPC) Private Limited
B3: Plot no:1&2, Vimala Gardens , East coast road .
B4: Injambakkam , Chennai - 600115 ,Tamil Nadu, India.
B5: CIN:U11100TN2020OPC135994
B9: Calculation of Deferred Tax | C9: A Y 2025-26 | E9: Amount (In Rs.)
B10: Opening Deferred Tax Asset at March 31, 2025 | E10: 5624
B11: Fixed Assets
B12: Depreciation as per Books | C12: ='9'!K16+'9'!L16 -> 25878
B13: Depreciation as per Income Tax Act | C13: ='IT DEPRECIATION'!M13 -> 28331 | D13: =+C12-C13 -> -2453 | G13: Tax Rate @ 22% | H13: 0.22
D14: =H16 -> 0.25168 | E14: =ROUND(D13*D14,2) -> -617.37 | G14: Surcharge @ 10% | H14: =H13*0.1 -> 0.022
B15: Deferred Tax Asset at March 31, 2025 | E15: =(E14+E10) -> 5006.63 | G15: HEC @ 4% | H15: {=SUM(H13:H14*0.04)} -> 0.00968
H16: =SUM(H13:H15) -> 0.25168
B17: Deferred tax Asset on Disallowances As per Sec 43 B Disallowances
B18: Gratuity Payable | C18: 0 | D18: 0 | E18: =ROUND(C18*D18,0) -> 0
B19: Net Deferred Tax Asset | E19: =E15-E18 -> 5006.63
B21: To be provided in P&L | E21: =E19-E10 -> -617.37

Sheet IT DEPRECIATION
B2: Chemgro Bioenergy Solutions (OPC) Private Limited
B3: Plot no:1&2, Vimala Gardens , East coast road .
B4: Injambakkam , Chennai - 600115 ,Tamil Nadu, India.
B5: CIN:U11100TN2020OPC135994
B7: S. No. | C7: Name of the Asset | D7: Rate | E7: WDV as at 31 March 2025 | F7: Additions | H7: Deletions | J7: Total | K7: Depreciation | M7: Total Depreciation | N7: WDV as at 31 March 2026
F8: More than 180 Days | G8: Less than 180 Days | H8: Out of Opening and Addition (more than 180 days) | I8: Out of Addition (less than 180 days) | K8: More than 180 Days | L8: Less than 180 Days
B10: 1 | C10: Office Equipments & Motor Car | D10: 0.15 | E10: 18804.04 | F10: =ROUND(SUM(E19),0) -> 0 | H10: 0 | I10: =SUM(F25) -> 0 | J10: =SUM(E10:G10)-SUM(H10:I10) -> 18804.04 | K10: =ROUND((SUM(E10:F10)-H10)*D10,0) -> 2821 | L10: =ROUND((G10-I10)*D10/2,0) -> 0 | M10: =SUM(K10:L10) -> 2821 | N10: =J10-M10 -> 15983.04
B11: 2 | C11: Computer & Software | D11: 0.4 | E11: =63774.04 -> 63774.04 | F11: =ROUND(SUM(E18:E18),0) -> 0 | H11: =SUM(E24:E24) -> 0 | I11: =SUM(F24:F24) -> 0 | J11: =SUM(E11:G11)-SUM(H11:I11) -> 63774.04 | K11: =ROUND((SUM(E11:F11)-H11)*D11,0) -> 25510 | L11: =ROUND((G11-I11)*D11/2,0) -> 0 | M11: =SUM(K11:L11) -> 25510 | N11: =J11-M11 -> 38264.04
C13: Total | E13: =SUM(E10:E12) -> 82578.08 | F13: =SUM(F10:F12) -> 0 | G13: =SUM(G10:G12) -> 0 | H13: =SUM(H10:H12) -> 0 | I13: =SUM(I10:I12) -> 0 | J13: =SUM(J10:J12) -> 82578.08 | K13: =SUM(K10:K12) -> 28331 | L13: =SUM(L10:L12) -> 0 | ... N13: =SUM(N10:N12) -> 54247.08
C15: FY 2025-26
C16: Fixed Assets | E16: Additions | G16: Total
E17: > 180 days | F17: < 180 days
C18: Computers | F18: 0 | G18: =+E18+F18 -> 0
C19: Office Equpments | F19: 0 | G19: =+E19+F19 -> 0
C20: Total | E20: =SUM(E18:E19) -> 0 | F20: =SUM(F18:F19) -> 0 | G20: =SUM(G18:G19) -> 0
C22: Fixed Assets | E22: Deletion | G22: Total
E23: > 180 days | F23: < 180 days
C24: Computers | E24: 0 | F24: 0 | G24: =+E24+F24 -> 0
C25: Office Equpments | E25: 0 | F25: 0 | G25: =+E25+F25 -> 0
C26: Total | E26: =SUM(E24:E25) -> 0 | F26: =SUM(F24:F25) -> 0 | G26: =SUM(G24:G25) -> 0

Sheet IT computation
B2: Name: | E2: CHEMGRO BIOENERGY SOLUTIONS (OPC) PRIVATE LIMITED
B3: Registered Office Address: | E3: PLOT NO.1&2,VIMALA GARDENS,EAST COAST ROAD
E4: INJAMBAKKAM,CHENNAI,CHENNAI,TAMILNADU,600115
B5: PAN: | E5: AAICC7744A
B7: Financial Year | E7: 2024-25
B8: Assessment Year | E8: 2025-26
B9: Date of Incorporation | E9: 44008
B10: Has the Company Opted for Section 115BAA? | E10: Yes
B12: 1) | C12: Income from Business or Profession (Chapter IV D)
C14: Profit as per Profit and Loss Account from Other Business | F14: =ROUND('P&L'!H29,0) -> 17229
C16: Add: Depreciation debited in P&L | E16: ='P&L'!H19 -> 25878
C17: Less: Depreciation as per Income Tax Act, 1961 | E17: =+'IT DEPRECIATION'!M13 -> 28331 | F17: =+E16-E17 -> -2453
F19: =SUM(F14:F17) -> 14776
C20: Less: Interest Received | E20: ='14-22'!C18 -> 0
C21: Add: Prior Period Provision Written Off | E21: =-'14-22'!C68 -> 8556 | F21: =SUM(E20:E21) -> 8556
G22: =SUM(F19:F21) -> 23332
B23: 2) | C23: Income from Other Sources
C24: (a) Interest Received on FD | F24: =+'14-22'!C18 -> 0
C25: (a) Interest on IT Refund | F25: 0
C27: Income from Other Sources | G27: =SUM(F24:F26) -> 0
C29: Total Income | G29: =SUM(G12:G28) -> 23332
C30: Total Income Rounded Off U/s 288A | G30: =MROUND(G29,10) -> 23330
C33: Calculation of Tax as per IT Act | G33: =ROUND(G30*22%,0) -> 5133
G35: =+G33 -> 5133
C36: Add: Surcharge @ 10% (Since the assessee has opted for Provisions of Section 115BAA) | G36: =ROUND(G35*10%,0) -> 513
C37: Add : Health & Educational Cess | G37: =ROUND((G35+G36)*4%,1) -> 225.8
G38: =ROUND(SUM(G34:G37),0) -> 5872
C39: Less: TDS | G39: =TB!H63 -> 12912.95
C41: =IF(SUM(G41:G41)<0,"Tax Refundable","Tax Payable") -> Tax Refundable | G41: =+G38-G39 -> -7040.95
C43: Add: Interest u/s 234 B | F43: =D63 -> 0
C44: Add: Interest u/s 234 C | F44: =J73 -> 0
G45: =SUM(F43:F44) -> 0
C46: Tax Refundable | G46: =G41+G45 -> -7040.95
C48: =IF(SUM(G40:G40)<0,"Tax Refundable Rounded Off U/s 288B","Tax Refundable Rounded Off U/s 288B") -> Tax Refundable Rounded Off U/s 288B | G48: =-MAX(ROUND(G46,10)) -> 7040.95
C53: Interest u/s 234 B
C55: Tax Due | D55: =G38 -> 5872
C56: 90% of Tax due | D56: =D55*90% -> 5284.8
C57: Tax Paid (TDS, TCS and Advance Tax) | D57: =G39 -> 12912.95
C59: Difference | D59: =D55-D57 -> -7040.95
C61: =IF(D57>D56,"Since 90% of Tax Due has been paid, Section 234 B of Income Tax Act, 1956 has not been attracted.","Since 90% of Tax Due has not been paid Section ,234 B of the Income Tax Act, 1961 has been attracted.") -> Since 90% of Tax Due has been paid, Section 234 B of Income Tax Act, 1956 has not been attracted.
...

Sheet Depreciation
