Workbook
Name \a: #N/A
Name \B: #REF!
Name \B: #REF!
Name \C: #REF!
Name \C: #REF!
Name \e: #N/A
Name \m: #N/A
Name \P: #REF!
Name \P: #REF!
Name \q: #N/A
Name \x: #REF!
Name \x: #REF!
Name \y: #REF!
Name \y: #REF!
Name \z: #REF!
Name \z: #REF!
Name _: #REF!
Name _.ignore9._: #REF!
Name ___????: #REF!
Name ___?????????: #REF!
Name ___??_???: #REF!
Name ___?_??: #REF!
Name _________?: #REF!
Name ________a2: #REF!
Name _______UCE08: #REF!
Name _______UCE09: #REF!
Name _______UCE10: #REF!
Name _______UCE11: #REF!
Name _______UCE12: #REF!
Name _______UCE13: #REF!
Name _______UCE14: #REF!
Name _______UCE15: #REF!
Name _______UCE16: #REF!
Name _______UCE17: #REF!
Name _______UCE18: #REF!
Name _______UCE19: #REF!
Name _______UCE20: #REF!
Name _______UCE21: #REF!
Name _______UCE22: #REF!
Name _______UCE23: #REF!
Name _______UCE24: #REF!
Name _______UCE25: #REF!
Name _______UCE26: #REF!
Name _______UCE27: #REF!
Name _______UCE28: #REF!
Name _______UCE29: #REF!
Name _______UCE30: #REF!
Name _______UCE31: #REF!
Name _______UCE32: #REF!
Name _______UCE33: #REF!
Name _______UCE34: #REF!
Name _______UCE35: #REF!
Name _______UCE36: #REF!
Name _______UCE37: #REF!
Name _______UCE38: #REF!
Name _______UCE39: #REF!
Name _______UCE40: #REF!
Name ______UCE01: #REF!
Name ______UCE02: #REF!
Name ______UCE03: #REF!

Sheet Financial Statements
A2: MARKETSOF1 ANALYTICAL MARKETING SERVICES PRIVATE LIMITED
A3: CIN: U72501TN2019PTC129911
A5: Balance Sheet as on March 31, 2026
A6: (All amounts are in thousands Indian Rupees, unless otherwise stated)
G7: ( Amount in Rs. )
A8: Particulars | D8: Note No. | E8: As at 31st March 2026 | F8: As at 31st March 2025 | G8: As at 31st March 2023
A9: I | B9: EQUITY AND LIABILITIES
A10: 1. | B10: Shareholders' Funds
B11: a. | C11: Share Capital | D11: ='3-15'!A9 -> 3 | E11: ='3-15'!E15 -> 100000 | F11: ='3-15'!F15 -> 100000 | G11: ='3-15'!#REF! -> #REF! | J11: =E11-F11 -> 0
B12: b. | C12: Reserves and Surplus | D12: ='3-15'!A44 -> 4 | E12: =+'3-15'!E50 -> 55465687 | F12: =+'3-15'!F50 -> 44411901 | G12: =+'3-15'!#REF! -> #REF! | J12: =E12-F12 -> 11053787
B13: c. | C13: Money received against share warrants | E13: 0 | F13: 0 | G13: 0
A14: 2. | B14: Share application money pending allotment | E14: 0 | F14: 0 | G14: 0
A16: 3. | B16: Non-Current Liabilities
B17: a. | C17: Long-term borrowings | E17: 0 | F17: 0 | G17: ='3-15'!#REF! -> #REF!
B18: b. | C18: Deferred tax liabilities (Net) | D18: =D12+1 -> 5 | E18: ='3-15'!E65 -> 19661.91 | F18: ='3-15'!F65 -> 64525.59 | G18: 0 | J18: =E18-F18 -> -44863.68
B19: c. | C19: Other Long term liabilities | E19: 0 | F19: 0 | G19: ='3-15'!#REF! -> #REF!
B20: d. | C20: Long Term Provisions | D20: =D18+1 -> 6 | E20: ='3-15'!E72 -> 4470006 | F20: ='3-15'!F72 -> 79164 | G20: ='3-15'!#REF! -> #REF! | J20: =E20-F20 -> 4390842
A22: 4. | B22: Current Liabilities
B23: a. | C23: Short-term borrowings | E23: 0 | F23: 0 | G23: ='3-15'!#REF! -> #REF!
B24: b. | C24: Trade payables | D24: =D20+1 -> 7 | G24: =+'3-15'!#REF! -> #REF! | H24: =+#REF!-G24 -> #REF!
C25: -total outstanding dues of micro and small enterprises | E25: ='Ageing schedule'!G13 -> 0 | F25: ='Ageing schedule'!H13 -> 0 | G25: ='Ageing schedule'!J13 -> 0
C26: -total outstanding dues of creditors other than micro and small enterprises | E26: =+'3-15'!E78 -> 31351590 | F26: =+'3-15'!F78-2 -> 32229650 | G26: ='Ageing schedule'!J14 -> 0 | J26: =E26-F26 -> -878059.5 | K26: a
B27: c. | C27: Other current liabilities | D27: =D24+1 -> 8 | E27: ='3-15'!E88-0.5 -> 29470755 | F27: ='3-15'!F88 -> 22980524 | G27: ='3-15'!#REF! -> #REF! | H27: =+#REF!-G27+11000000 -> #REF! | J27: =E27-F27 -> 6490230.9 | K27: a
B28: d. | C28: Short - term provisions | D28: =D27+1 -> 9 | E28: ='3-15'!E95 -> 55650000 | F28: ='3-15'!F95 -> 8450000 | G28: ='3-15'!#REF! -> #REF! | J28: =E28-F28 -> 47200000
C30: Total | E30: =SUM(E11:E28)+0.5 -> 1.765277e+08 | F30: =SUM(F11:F28)+0.5 -> 1.0831576e+08 | G30: =SUM(G11:G28) -> #REF!
A32: II | B32: ASSETS
A33: 1. | B33: Non-current assets
B34: a. | C34: Property, Plant & Equipments and Intangible assets | D34: =D28+1 -> 10
C35: (i) Property, Plant and Equipment | E35: ='10'!K24 -> 5439341.5 | F35: ='10'!K25 -> 4478032.3 | G35: 1572250 | H35: =+#REF!-G35 -> #REF! | J35: =E35-F35 -> 961309.17
C36: (ii) Intangible Assets | E36: ='10'!J30 -> 0 | F36: 0 | G36: 0 | H36: =+#REF!+#REF! -> #REF!
C37: (iii) Capital Work in Progress | E37: 0 | F37: 0 | G37: 0
B38: b. | C38: Non Current Investments | E38: 0 | F38: 0 | G38: ='3-15'!#REF! -> #REF!
B39: c. | C39: Deferred tax assets (net) | D39: =D18 -> 5 | E39: 0 | F39: 0 | G39: =-'3-15'!#REF! -> #REF!
B40: d. | C40: Long term loans and advances | D40: =D34+1 -> 11 | E40: ='3-15'!E103 -> 10709306 | F40: ='3-15'!F103 -> 6408655 | G40: ='3-15'!#REF! -> #REF! | H40: =+#REF!-G40 -> #REF! | J40: =E40-F40 -> 4300651 | K40: a
B41: e. | C41: Other Non Current Assets | E41: 0 | F41: 0 | G41: ='3-15'!#REF! -> #REF!
A43: 2. | B43: Current Assets
B44: a. | C44: Current Investments | E44: 0 | F44: 0 | G44: ='3-15'!#REF! -> #REF!
B45: b. | C45: Inventories | E45: 0 | F45: 0 | G45: ='3-15'!#REF! -> #REF!
B46: c. | C46: Trade Receivables | D46: =D40+1 -> 12 | E46: ='3-15'!E110 -> 4317419.3 | F46: ='3-15'!F110 -> 1242797.4 | G46: ='3-15'!#REF! -> #REF! | H46: =+#REF!-G46 -> #REF! | J46: =E46-F46 -> 3074621.8 | K46: a
B47: d. | C47: Cash and Bank Balance | D47: =D46+1 -> 13 | E47: ='3-15'!E119 -> 66610087 | F47: ='3-15'!F119 -> 81786790 | G47: ='3-15'!#REF! -> #REF! | H47: =+#REF!-G47 -> #REF! | J47: =E47-F47 -> -15176703
...

Sheet 1-2
B2: MARKETSOF1 ANALYTICAL MARKETING SERVICES PRIVATE LIMITED
B3: CIN: U72501TN2019PTC129911
B5: Notes to Financial Statements for the year ended March 31, 2026
B6: (All amounts are in thousands Indian Rupees, unless otherwise stated)
B9: 1. General Information
B11: MARKETSOF1 ANALYTICAL MARKETING SERVICES Pvt Ltd, having its registered office at Ram Nivas apart-7, 1st floor, old No.79, New No.82, DRT Ranga Road, Mylapore, Chennai-600004. The Subscribers to the Memorandum of association of this company are:- a. M1 Marketing Services Pvt Ltd – having 50% stake b. Jayaram K Iyer – having 50% stake
B13: 2. Summary of Significant Accounting Policies
B15: 2.1 Basis of Preparation
B17: These financial statements have been prepared in accordance with the generally accepted accounting principles in India under the historical cost convention on accrual basis. Pursuant to Section 133 of the Companies Act, 2013 read with Rule 7(1) of the Companies (Accounts) Rules, 2014, till the standards of accounting or any addendum thereto are prescribed by Central Government in consultation and recommendation of the National Financial Reporting Authority, the existing Accounting Standards notified under the Companies Act, 1956 shall continue to apply. Consequently, these financial statements have been prepared to comply in all material aspects with the Accounting Standards notified under Section 211(3C) of the Companies Act, 1956 [Companies (Accounting Standards) Rules, 2006, as amended] and other relevant provisions of the Companies Act, 2013.
B18: All assets and liabilities have been classified as current or non-current as per the Company’s normal operating cycle and other criteria set out in the Schedule III (Division I) to the Companies Act, 2013. Based on the nature of products and the time between the acquisition of assets for processing and their realisation in cash and cash equivalents, the Company has ascertained its operating cycle as 12 months for the purpose of current - non-current classification of assets and liabilities.
B20: 2.2 Use of Estimates
B22: The preparation of the financial statements in conformity with the accounting principles generally accepted in India requires the Management to make estimates and assumptions that affect the reported amount of assets and liabilities as of the Balance Sheet date, reported amount of revenues and expenses for the period and disclosure of contingent liabilities as of the Balance Sheet date. The estimates and assumptions used in the financial statements are based on Management’s evaluation of the relevant facts and circumstances as of the date of the financial statements. The actual results may differ from these estimates and the difference between the actual results and the estimates are recognised in the period in which the results are known/materialise.
... B119: Based on the nature of activities of the Company and the normal time between acquisition of assets and their realisation in cash or cash equivalents, the Company has determined its operating cycle as 12 months for the purpose of classification of its assets and liabilities as current and non-current.

Sheet 3-15
A1: MARKETSOF1 ANALYTICAL MARKETING SERVICES PRIVATE LIMITED
A2: CIN: U72501TN2019PTC129911
A4: Notes to Financial Statements for the year ended March 31, 2026
A5: (All amounts are in thousands Indian Rupees, unless otherwise stated)
A7: Note No. | B7: Particulars | E7: As at 31st March, 2026 | F7: As at 31st March, 2025
A9: 3 | B9: Share Capital
A10: =A9+0.1 -> 3.1 | B10: Authorized Share Capital
B11: 10,000 (Previous Year 10,000) Equity Shares of Rs. 10/- each. | E11: =-SUMIF(Table2[FS Subgroup],"Share Capital",Table2[Adjusted balance as on 31-03-2026]) -> 100000 | F11: =E11 -> 100000
A13: =A10+0.1 -> 3.2 | B13: Issued , Subscribed & Fully Paid up Capital
B14: 10,000 (Previous Year 10,000) Equity Shares of Rs. 10/- each. | E14: =E11 -> 100000 | F14: =E14 -> 100000
E15: =SUM(E14) -> 100000 | F15: =SUM(F14) -> 100000
A17: =A13+0.1 -> 3.3 | B17: Reconciliation Of Number of Shares
B18: Number Of Equity Shares as at the beginning of the Financial year | E18: 10000 | F18: 10000
B19: Add: Number of Shares Issued during the period | E19: 0 | F19: 0
B20: Number Of Equity Shares as at the end of the financial Years | E20: =SUM(E18:E19) -> 10000 | F20: =SUM(F18:F19) -> 10000
A22: =A17+0.1 -> 3.4 | B22: List of Shareholders holding more than 5% of Equity Shares of the company
B23: Name | C23: % of Shares | E23: Number of Shares | F23: Number of Shares
C24: 46112 | D24: 45747 | E24: 46112 | F24: 45747
B25: 5000 equity shares held by M1 Marketing Services Private Limited | C25: =E25/E$18 -> 0.5 | D25: =F25/F$18 -> 0.5 | E25: 5000 | F25: 5000
B26: 5000 equity shares held by Mr. Jayaram K Iyer | C26: =E26/E$18 -> 0.5 | D26: =F26/F$18 -> 0.5 | E26: 5000 | F26: 5000
A28: =A22+0.1 -> 3.5 | B28: Details of Shares held by promoters
B29: Promoter Name | E29: 2025-26
E30: No. of Shares | F30: % of total shares
B31: 5000 equity shares held by Mr. Jayaram K Iyer | E31: =E25 -> 5000 | F31: =C26 -> 0.5
B32: 5000 equity shares held by M1 Marketing Services Private Limited | E32: =E26 -> 5000 | F32: 0.5
B34: Promoter Name | E34: 2024-25
E35: No. of Shares | F35: % of total shares
B36: 5000 equity shares held by Mr. Jayaram K Iyer | E36: =E31 -> 5000 | F36: =F31 -> 0.5
B37: 5000 equity shares held by M1 Marketing Services Private Limited | E37: =E32 -> 5000 | F37: =F32 -> 0.5
A39: =A28+0.1 -> 3.6 | B39: Terms / Rights attached to Equity Shares
B40: The company has only one class of equity share having par value of Rs.10 per share. Each holder of the equity share is entilted to one vote per share. Whenever the company declares dividend it will be paid in Indian Rupees.
B41: In the event of liquidation of the Company, the holders of Equity Shares will be entitled to receive any of the remaining assets of the Company, after distribution of all preferential amounts. However, no such preferential amounts exist curently. The distribution will be in proportion to the number of Equity Shares held by the Shareholders.
A44: =A9+1 -> 4 | B44: Reserves & Surplus
B45: Surplus (Statement of Profit & Loss )
B46: Opening balance | E46: =-SUMIF(Table2[FS Subgroup],B46,Table2[Adjusted balance as on 31-03-2026]) -> 44411901 | F46: 21028880 | H46: ='Trial Balance'!C62+'3-15'!E46 -> 8820
B47: Add : Profit During the Year | E47: ='Financial Statements'!E105 -> 11053787 | F47: ='Financial Statements'!F105 -> 23383021
B48: Less : Loss during the year / Appropriations | E48: 0 | F48: 0
B50: Total | E50: =E46+E47-E48 -> 55465687 | F50: =F46+F47-F48 -> 44411901
A52: =A44+1 -> 5 | B52: Deferred Tax Liability/ Asset (Net)
A53: =A52+0.1 -> 5.1 | B53: Deferred Tax Liability
...

Sheet Sub Schedule BS
B2: MARKETSOF1 ANALYTICAL MARKETING SERVICES PRIVATE LIMITED
B3: Notes forming part of Financial Statements as on March 31, 2025
C4: For the year ended 31.03.2025 | D4: For the year ended 31.03.2024 | E4: For the year ended 31.03.2023
B6: a) Trade Payable
B7: Trade Payables | C7: ='Ageing schedule'!J12 -> 31351590 | D7: ='Ageing schedule'!J23 -> 32229652 | E7: ='Ageing schedule'!J20 -> 32229652
C8: =+SUM(C7) -> 31351590 | D8: =+SUM(D7) -> 32229652 | E8: =+SUM(E7) -> 32229652
B10: b) Statutory dues including provident fund and tax deducted at source
B11: - TDS Payable | C11: 3111621 | D11: =#REF! -> #REF! | E11: 1367262
B12: - Professional Tax Payable | C12: 107180 | D12: =#REF! -> #REF! | E12: 69427
B13: - ESI Payable | C13: 220927 | D13: =#REF! -> #REF! | E13: 164547
B14: - GST Payable | C14: -132905 | D14: =#REF! -> #REF! | E14: 997540
B15: - PF Payable | C15: 1528726 | D15: =#REF! -> #REF! | E15: 868018
B16: - Earned leave Encashment Payable | C16: 79164 | D16: =#REF! -> #REF!
C17: =SUM(C11:C16) -> 4914713 | D17: =SUM(D11:D16) -> #REF! | E17: =SUM(E11:E15) -> 3466794
B19: c) Other Liabilities
B20: - Accounts payable | C20: =+'Groupings BS'!C10 -> 759807 | D20: =+'Groupings BS'!D10 -> #REF! | E20: 322821
B21: - Accrued expense | C21: 0 | D21: 0 | E21: 0
B22: - Salary Payable | C22: 9089952 | D22: =#REF! -> #REF! | E22: 4798580
B23: - Provision for Audit Fees | C23: 450000 | E23: 100000
B24: - HDFC Credit Card | C24: 295215.86 | D24: =#REF! -> #REF! | E24: 70760.7
B25: - Loan from director
B26: - Provision for COVID-19
B27: - Provision for Current Tax | C27: 8000000 | D27: =#REF! -> #REF! | E27: 103840
C29: =SUM(C20:C28) -> 18594975 | D29: =SUM(D20:D28) -> #REF! | E29: =SUM(E20:E28) -> 5396001.7
B32: e) Security Deposit
B33: Rent Advance - Guindy | C33: 1000000 | D33: =#REF! -> #REF! | E33: 1000000
B34: Rent Advance - VLV Complex | C34: 1102520 | D34: =#REF! -> #REF! | E34: 1102520
B35: Rental Advance - Temple Steps | C35: 1680000 | D35: =#REF! -> #REF!
B36: Rental Advance Coimbatore | C36: 2354801
C37: =SUM(C33:C36)+C40+C41 -> 6201321 | D37: =SUM(D33:D36) -> #REF! | E37: =SUM(E33:E34) -> 2102520
B39: f) Other Advance
B40: Deposit - UPS | C40: 24000 | D40: =#REF! -> #REF! | E40: 24000
B41: Deposit - Computers | C41: 40000 | D41: =#REF! -> #REF! | E41: 40000
B42: Salary Advance | C42: 207334 | D42: =#REF! -> #REF! | E42: 188250
C43: =C42 -> 207334 | D43: =SUM(D40:D42) -> #REF! | E43: =SUM(E40:E42) -> 252250
B45: g) Balances with Bank
B46: - Current account | C46: =1588011.23+37647450 -> 39235461 | D46: =#REF!+#REF! -> #REF! | E46: 3210639.6
B47: - in Fixed deposit accounts (including Interest accrued) | C47: =42420521+171762.5 -> 42592284 | D47: =#REF!+#REF! -> #REF! | E47: 27974875
C49: =SUM(C46:C48) -> 81827745 | D49: =SUM(D46:D48) -> #REF! | E49: =SUM(E46:E48) -> 31185515
B51: h)Trade receivables (unsecured considered good)
...

Sheet 10
A1: MARKETSOF1 ANALYTICAL MARKETING SERVICES PRIVATE LIMITED
A2: CIN: U72501TN2019PTC129911
A4: Notes to Financial Statements for the year ended March 31, 2026
A5: (All amounts are in thousands Indian Rupees, unless otherwise stated)
A7: Note No. 10 : Property, Plant & Equipments
A9: Particulars | C9: Gross Block | G9: Accumulated Depreciation | K9: Net Block
C10: As on 01-04-2025 | D10: Addition during the year | E10: Deduction during the year | F10: As on 31-03-2026 | G10: As on 01-04-2025 | H10: Addition during the year | I10: Deduction during the year | J10: As on 31-03-2026 | K10: As on 31-03-2026 | L10: As on 31-03-2025
A11: 10.1 | B11: Tangible Assets
A12: a. | B12: Office Building | C12: 0 | D12: =SUMIF(Table2[FS Subgroup],'10'!B12,Table2[Adjusted balance as on 31-03-2026])-'10'!C12 -> 0 | E12: 0 | F12: =+C12+D12-E12 -> 0 | G12: 0 | H12: 0 | I12: 0 | J12: =+G12+H12-I12 -> 0 | K12: =+F12-J12 -> 0 | L12: =+C12-G12 -> 0
A13: b. | B13: Factory Building | C13: 0 | D13: =SUMIF(Table2[FS Subgroup],'10'!B13,Table2[Adjusted balance as on 31-03-2026])-'10'!C13 -> 0 | E13: 0 | F13: =+C13+D13-E13 -> 0 | G13: 0 | H13: 0 | I13: 0 | J13: =+G13+H13-I13 -> 0 | K13: =+F13-J13 -> 0 | L13: =+C13-G13 -> 0
A14: c. | B14: Computers Software | C14: 50000 | D14: =SUMIF(Table2[FS Subgroup],'10'!B14,Table2[Adjusted balance as on 31-03-2026])-'10'!C14 -> 0 | E14: 0 | F14: =+C14+D14-E14 -> 50000 | G14: 39713.448 | H14: 7916.67 | I14: 0 | J14: =+G14+H14-I14 -> 47630.118 | K14: =+F14-J14 -> 2369.8819 | L14: =+C14-G14 -> 10286.552
A15: d. | B15: Furniture & Fittings | C15: 2635970.4 | D15: =SUMIF(Table2[FS Subgroup],'10'!B15,Table2[Adjusted balance as on 31-03-2026])-'10'!C15 -> 558379.01 | E15: 0 | F15: =+C15+D15-E15 -> 3194349.4 | G15: 609890.07 | H15: 281256.85 | I15: 0 | J15: =+G15+H15-I15 -> 891146.92 | K15: =+F15-J15 -> 2303202.5 | L15: =+C15-G15 -> 2026080.3 | N15: 2635971
A16: e. | B16: Leasehold Land | C16: 0 | D16: =SUMIF(Table2[FS Subgroup],'10'!B16,Table2[Adjusted balance as on 31-03-2026])-'10'!C16 -> 0 | E16: 0 | F16: =+C16+D16-E16 -> 0 | G16: 0 | H16: 0 | I16: 0 | J16: =+G16+H16-I16 -> 0 | K16: =+F16-J16 -> 0 | L16: =+C16-G16 -> 0
A17: f. | B17: Freehold Land | C17: 0 | D17: =SUMIF(Table2[FS Subgroup],'10'!B17,Table2[Adjusted balance as on 31-03-2026])-'10'!C17 -> 0 | E17: 0 | F17: =+C17+D17-E17 -> 0 | G17: 0 | H17: 0 | I17: 0 | J17: =+G17+H17-I17 -> 0 | K17: =+F17-J17 -> 0 | L17: =+C17-G17 -> 0
A18: g. | B18: Motor Vehicles | C18: 0 | D18: =SUMIF(Table2[FS Subgroup],'10'!B18,Table2[Adjusted balance as on 31-03-2026])-'10'!C18 -> 0 | E18: 0 | F18: =+C18+D18-E18 -> 0 | G18: 0 | H18: 0 | I18: 0 | J18: =+G18+H18-I18 -> 0 | K18: =+F18-J18 -> 0 | L18: =+C18-G18 -> 0
A19: h. | B19: Office Equipments | C19: 3110.16 | D19: =SUMIF(Table2[FS Subgroup],'10'!B19,Table2[Adjusted balance as on 31-03-2026])-'10'!C19 -> 0 | E19: 0 | F19: =+C19+D19-E19 -> 3110.16 | G19: 2955.78 | H19: 3630.93 | I19: 0 | J19: =+G19+H19-I19 -> 6586.71 | K19: =+F19-J19 -> -3476.55 | L19: =+C19-G19 -> 154.38002
A20: i. | B20: Computers & Accessories | C20: 4563131 | D20: =SUMIF(Table2[FS Subgroup],'10'!B20,Table2[Adjusted balance as on 31-03-2026])-'10'!C20 -> 2398648.8 | E20: 0 | F20: =+C20+D20-E20 -> 6961779.8 | G20: 2159469.2 | H20: 1736655.8 | I20: 0 | J20: =+G20+H20-I20 -> 3896125 | K20: =+F20-J20 -> 3065654.8 | L20: =+C20-G20 -> 2403661.8
A21: j. | B21: Printer | C21: 62575 | D21: =SUMIF(Table2[FS Subgroup],'10'!B21,Table2[Adjusted balance as on 31-03-2026])-'10'!C21 -> 49889.41 | E21: 0 | F21: =+C21+D21-E21 -> 112464.41 | G21: 24725.682 | H21: 16147.87 | I21: 0 | J21: =+G21+H21-I21 -> 40873.552 | K21: =+F21-J21 -> 71590.858 | L21: =+C21-G21 -> 37849.318
A22: k. | B22: Plant & Machinery | C22: 0 | D22: =SUMIF(Table2[FS Subgroup],'10'!B22,Table2[Adjusted balance as on 31-03-2026])-'10'!C22 -> 0 | E22: 0 | F22: =+C22+D22-E22 -> 0 | G22: 0 | H22: 0 | I22: 0 | J22: =+G22+H22-I22 -> 0 | K22: =+F22-J22 -> 0 | L22: =+C22-G22 -> 0
B24: Total | C24: =SUM(C12:C23) -> 7314786.6 | D24: =SUM(D12:D23) -> 3006917.3 | E24: =SUM(E12:E23) -> 0 | F24: =SUM(F12:F23) -> 10321704 | G24: =SUM(G12:G23) -> 2836754.2 | H24: =SUM(H12:H23) -> 2045608.1 | I24: =SUM(I12:I23) -> 0 | J24: =SUM(J12:J23) -> 4882362.3 | K24: =+F24-J24 -> 5439341.5 | L24: =SUM(L12:L23) -> 4478032.3
B25: (Previous Year) | C25: 5167958.6 | D25: 2146828 | E25: 0 | F25: 7314786.6 | G25: 1473367 | H25: 1363387.2 | I25: 0 | J25: 2836754.2 | K25: 4478032.3 | L25: 3694591.5
A27: =A11+0.1 -> 10.2 | B27: Intangible Asset
A28: a. | B28: Computer Software | C28: 0 | D28: 0 | E28: 0 | F28: =+C28+D28-E28 -> 0 | G28: 0 | H28: 0 | I28: 0 | J28: =+G28+H28-I28 -> 0 | K28: =+F28-J28 -> 0 | L28: =+C28-G28 -> 0 | R28: =D24+D30 -> 3006917.3
R29: =R28-D16 -> 3006917.3
B30: Total | C30: =SUM(C28:C29) -> 0 | D30: =SUM(D28:D29) -> 0 | E30: =SUM(E28:E29) -> 0 | F30: =SUM(F28:F29) -> 0 | G30: =SUM(G28:G29) -> 0 | H30: =SUM(H28:H29) -> 0 | I30: =SUM(I28:I29) -> 0 | J30: =SUM(J28:J29) -> 0 | ... L30: =SUM(L28:L29) -> 0
B31: (Previous Year) | C31: 0 | D31: 0 | E31: 0 | F31: 0 | G31: 0 | H31: 0 | I31: 0 | J31: 0 | K31: 0 | L31: 0
A33: =A27+0.1 -> 10.3 | B33: Capital Work in Progress | C33: 0 | E33: 0 | F33: =+C33+D33-E33 -> 0 | G33: 0 | H33: 0 | I33: 0 | J33: =+G33+H33-I33 -> 0 | K33: =+F33-J33 -> 0 | L33: =+C33-G33 -> 0
B35: Total | C35: =SUM(C33) -> 0 | D35: =SUM(D33) -> 0 | E35: =SUM(E33) -> 0 | F35: =SUM(F33) -> 0 | G35: =SUM(G33) -> 0 | H35: =SUM(H33) -> 0 | I35: =SUM(I33) -> 0 | J35: =SUM(J33) -> 0 | ... L35: =SUM(L33) -> 0
B36: (Previous Year) | C36: 0 | D36: 0 | E36: 0 | F36: 0 | G36: 0 | H36: 0 | I36: 0 | J36: 0 | K36: 0 | L36: 0
A38: =A33+0.1 -> 10.4 | B38: Intangible assets under development | C38: 0 | E38: 0 | F38: =+C38+D38-E38 -> 0 | G38: 0 | H38: 0 | I38: 0 | J38: =+G38+H38-I38 -> 0 | K38: =+F38-J38 -> 0 | L38: =+C38-G38 -> 0
B40: Total | C40: =SUM(C38) -> 0 | D40: =SUM(D38) -> 0 | E40: =SUM(E38) -> 0 | F40: =SUM(F38) -> 0 | G40: =SUM(G38) -> 0 | H40: =SUM(H38) -> 0 | I40: =SUM(I38) -> 0 | J40: =SUM(J38) -> 0 | ... L40: =SUM(L38) -> 0
B41: (Previous Year) | C41: 0 | D41: 0 | E41: 0 | F41: 0 | G41: 0 | H41: 0 | I41: 0 | J41: 0 | K41: 0 | L41: 0
A43: TOTAL | C43: =C40+C35+C30+C24 -> 7314786.6 | D43: =D40+D35+D30+D24 -> 3006917.3 | E43: =E40+E35+E30+E24 -> 0 | F43: =F40+F35+F30+F24 -> 10321704 | G43: =G40+G35+G30+G24 -> 2836754.2 | H43: =H40+H35+H30+H24 -> 2045608.1 | I43: =I40+I35+I30+I24 -> 0 | J43: =J40+J35+J30+J24 -> 4882362.3 | ... L43: =L40+L35+L30+L24 -> 4478032.3

Sheet Ageing schedule
A1: MARKETSOF1 ANALYTICAL MARKETING SERVICES PRIVATE LIMITED
A2: CIN: U72501TN2019PTC129911
A4: Notes to Financial Statements for the year ended March 31, 2026
A5: (All amounts are in thousands Indian Rupees, unless otherwise stated)
A7: Note No. 7 | B7: Trade payable ageing schedule
B9: Outstanding for following periods from due date of payment (2025-26)
A10: S.No. | B10: Particulars | C10: Not due | D10: Unbilled amount | E10: < 6 months | F10: 6 month -1 year | G10: 1-2 years | H10: 2-3 years | I10: > 3 years | J10: Total
A11: ='3-15'!A74+0.1 -> 7.1 | B11: MSME | C11: 0 | D11: 0 | E11: 0 | F11: 0 | G11: 0 | H11: 0 | I11: 0 | J11: =SUM(C11:I11) -> 0
A12: =A11+0.1 -> 7.2 | B12: Others | C12: 0 | D12: 0 | E12: ='3-15'!E76 -> 31351590 | F12: 0 | G12: 0 | H12: 0 | I12: 0 | J12: =SUM(C12:I12) -> 31351590
A13: =A12+0.1 -> 7.3 | B13: Disputed dues-MSME | E13: 0 | F13: 0 | G13: 0 | H13: 0 | I13: 0 | J13: =SUM(D13:I13) -> 0
A14: =A13+0.1 -> 7.4 | B14: Disputed dues-Other | E14: 0 | F14: 0 | G14: 0 | H14: 0 | I14: 0 | J14: =SUM(D14:I14) -> 0
B15: Total | C15: =SUM(C11:C14) -> 0 | D15: =SUM(D11:D14) -> 0 | E15: =SUM(E11:E14) -> 31351590 | F15: =SUM(F11:F14) -> 0 | G15: =SUM(G11:G14) -> 0 | H15: =SUM(H11:H14) -> 0 | I15: =SUM(I11:I14) -> 0 | J15: =SUM(J11:J14) -> 31351590
B17: Outstanding for following periods from due date of payment (2024-25)
A18: S.No. | B18: Particulars | C18: Not due | D18: Unbilled amount | E18: < 6 months | F18: 6 month -1 year | G18: 1-2 years | H18: 2-3 years | I18: > 3 years | J18: Total
A19: ='3-15'!A74+0.1 -> 7.1 | B19: MSME | C19: 0 | D19: 0 | E19: 0 | F19: 0 | G19: 0 | H19: 0 | I19: 0 | J19: 0
A20: =A19+0.1 -> 7.2 | B20: Others | C20: 0 | D20: 0 | E20: =31998228.36+231423.21 -> 32229652 | G20: 0 | H20: 0 | I20: 0 | J20: =SUM(D20:I20) -> 32229652
A21: =A20+0.1 -> 7.3 | B21: Disputed dues-MSME | E21: 0 | I21: 0 | J21: 0
A22: =A21+0.1 -> 7.4 | B22: Disputed dues-Other | E22: 0 | I22: 0 | J22: 0
B23: Total | C23: =SUM(C19:C22) -> 0 | D23: =SUM(D19:D22) -> 0 | E23: =SUM(E19:E22) -> 32229652 | F23: =SUM(F19:F22) -> 0 | G23: =SUM(G19:G22) -> 0 | H23: =SUM(H19:H22) -> 0 | I23: =SUM(I19:I22) -> 0 | J23: =SUM(J19:J22) -> 32229652
A26: Note No. 12 | B26: Trade receivable ageing schedule
B28: Outstanding for following periods from due date of payment (2025-26)
A29: S.No. | B29: Particulars | C29: Not due | D29: Unbilled amount | E29: < 6 months | F29: 6 month -1 year | G29: 1-2 years | H29: 2-3 years | I29: > 3 years | J29: Total
A30: 12.1 | B30: Undisputed Trade Receivables – considered good | C30: 0 | D30: ='3-15'!E130 -> 26920883 | E30: ='3-15'!E110 -> 4317419.3 | F30: 0 | G30: 0 | H30: 0 | I30: 0 | J30: =SUM(C30:I30) -> 31238302
A31: =A30+0.1 -> 12.2 | B31: Undisputed Trade Receivables – considered doubtful | C31: 0 | D31: 0 | E31: 0 | F31: 0 | G31: 0 | H31: 0 | I31: 0 | J31: =SUM(C31:I31) -> 0
A32: =A31+0.1 -> 12.3 | B32: Disputed Trade Receivables – considered good | C32: 0 | D32: 0 | E32: 0 | F32: 0 | G32: 0 | H32: 0 | I32: 0 | J32: =SUM(C32:I32) -> 0
A33: =A32+0.1 -> 12.4 | B33: Disputed Trade Receivables – considered doubtful | C33: 0 | D33: 0 | E33: 0 | F33: 0 | G33: 0 | H33: 0 | I33: 0 | J33: =SUM(C33:I33) -> 0
B34: Total | C34: =SUM(C30:C33) -> 0 | D34: =SUM(D30:D33) -> 26920883 | E34: =SUM(E30:E33) -> 4317419.3 | F34: =SUM(F30:F33) -> 0 | G34: =SUM(G30:G33) -> 0 | H34: =SUM(H30:H33) -> 0 | I34: =SUM(I30:I33) -> 0 | J34: =SUM(J30:J33) -> 31238302
B36: Outstanding for following periods from due date of payment (2024-25)
A37: S.No. | B37: Particulars | C37: Not due | D37: Unbilled amount | E37: < 6 months | F37: 6 month -1 year | G37: 1-2 years | H37: 2-3 years | I37: > 3 years | J37: Total
A38: 12.1 | B38: Undisputed Trade Receivables – considered good | C38: 0 | D38: 5000000 | E38: ='Financial Statements'!F46 -> 1242797.4 | F38: 0 | G38: 0 | H38: 0 | I38: 0 | J38: =SUM(C38:I38) -> 6242797.4
A39: =A38+0.1 -> 12.2 | B39: Undisputed Trade Receivables – considered doubtful | C39: 0 | D39: 0 | E39: 0 | F39: 0 | G39: 0 | H39: 0 | I39: 0 | J39: =SUM(C39:I39) -> 0
A40: =A39+0.1 -> 12.3 | B40: Disputed Trade Receivables – considered good | C40: 0 | D40: 0 | E40: 0 | F40: 0 | G40: 0 | H40: 0 | I40: 0 | J40: =SUM(C40:I40) -> 0
A41: =A40+0.1 -> 12.4 | B41: Disputed Trade Receivables – considered doubtful | C41: 0 | D41: 0 | E41: 0 | F41: 0 | G41: 0 | H41: 0 | I41: 0 | J41: =SUM(C41:I41) -> 0
B42: Total | C42: =SUM(C38:C41) -> 0 | D42: =SUM(D38:D41) -> 5000000 | E42: =SUM(E38:E41) -> 1242797.4 | F42: =SUM(F38:F41) -> 0 | G42: =SUM(G38:G41) -> 0 | H42: =SUM(H38:H41) -> 0 | I42: =SUM(I38:I41) -> 0 | J42: =SUM(J38:J41) -> 6242797.4

Sheet 16-23
A1: MARKETSOF1 ANALYTICAL MARKETING SERVICES PRIVATE LIMITED
A2: CIN: U72501TN2019PTC129911
A4: Notes to Financial Statements for the year ended March 31, 2026
A5: (All amounts are in thousands Indian Rupees, unless otherwise stated)
A7: Note No. | B7: Particulars | C7: For the year ended 31st March, 2026 | D7: For the year ended 31st March, 2025
A9: ='3-15'!A127+1 -> 16 | B9: Revenue from Operations
A10: =A9+0.1 -> 16.1 | B10: Sale of Products | C10: {=-SUMIF(Table2[FS Subgroup],'16-23'!B10:B10,Table2[Adjusted balance as on 31-03-2026])} -> 0 | D10: =D19 -> 0
A11: =A10+0.1 -> 16.2 | B11: Sale of Services | C11: {=-SUMIF(Table2[FS Subgroup],'16-23'!B11:B11,Table2[Adjusted balance as on 31-03-2026])} -> 6.0174095e+08 | D11: =449121097+4500000 -> 453621097
A12: =A11+0.1 -> 16.3 | B12: Other Operating Revenue | C12: 0 | D12: 0
B14: Total | C14: =SUM(C10:C12) -> 6.0174095e+08 | D14: =SUM(D10:D12) -> 453621097
A15: Note : | B15: Sale of Products Comprise of
B17: i.) | D17: 0
B18: ii.) | D18: 0
B19: Total | D19: =SUM(D17:D18) -> 0
A21: Note : | B21: Sale of Services Comprise of
B22: Revenue from Services | C22: =C11 -> 6.0174095e+08 | D22: =D11 -> 453621097
B23: Total | C23: =SUM(C22:C22) -> 6.0174095e+08 | D23: =SUM(D22:D22) -> 453621097
A25: =A9+1 -> 17 | B25: Other Income
A26: =A25+0.1 -> 17.1 | B26: Interest Income
B27: Interest on FD | C27: {=-SUMIF(Table2[FS Subgroup],'16-23'!B27:B27,Table2[Adjusted balance as on 31-03-2026])} -> 3782232.6 | D27: 3500599.8
B28: Interest on Staff Loans | C28: {=-SUMIF(Table2[FS Subgroup],'16-23'!B28:B28,Table2[Adjusted balance as on 31-03-2026])} -> 31353 | D28: 0
B29: Interest from Income Tax Refund | C29: {=-SUMIF(Table2[FS Subgroup],'16-23'!B29:B29,Table2[Adjusted balance as on 31-03-2026])} -> 0 | D29: 111865
A30: =A26+0.1 -> 17.2 | B30: Bad debts recovered | C30: {=-SUMIF(Table2[FS Subgroup],'16-23'!B30:B30,Table2[Adjusted balance as on 31-03-2026])} -> 5000 | D30: 0
A31: =A30+0.1 -> 17.3 | B31: Excess provision reversed | C31: {=-SUMIF(Table2[FS Subgroup],'16-23'!B31:B31,Table2[Adjusted balance as on 31-03-2026])} -> 8000000 | D31: 0
A32: =A31+0.1 -> 17.4 | B32: Miscellaneous Income | C32: {=-SUMIF(Table2[FS Subgroup],'16-23'!B32:B32,Table2[Adjusted balance as on 31-03-2026])} -> 4.14 | D32: 7.17
B34: Total | C34: =SUM(C26:C32) -> 11818590 | D34: =SUM(D26:D32) -> 3612471.9
A36: =A25+1 -> 18 | B36: Operating Expenses
A37: =A36+0.1 -> 18.1 | B37: Campaign Expenses | C37: {=SUMIF(Table2[FS Subgroup],'16-23'!B37:B37,Table2[Adjusted balance as on 31-03-2026])} -> 70563000 | D37: 41381396
A38: =A37+0.1 -> 18.2 | B38: Direct Costs-User licences for algorithms | C38: {=SUMIF(Table2[FS Subgroup],'16-23'!B38:B38,Table2[Adjusted balance as on 31-03-2026])} -> 81620248 | D38: 92575051
A39: =A38+0.1 -> 18.3 | B39: Direct Costs:Professional Fees for Analytics and UI/UX | C39: {=SUMIF(Table2[FS Subgroup],'16-23'!B39:B39,Table2[Adjusted balance as on 31-03-2026])} -> 73739161 | D39: 97545428
A40: =A39+0.1 -> 18.4 | B40: Direct Costs: Predictive modeling and updates | C40: {=SUMIF(Table2[FS Subgroup],'16-23'!B40:B40,Table2[Adjusted balance as on 31-03-2026])} -> 0 | D40: 5000000
B42: Total | C42: =SUM(C37:C40) -> 2.2592241e+08 | D42: =SUM(D37:D40) -> 2.3650187e+08
A44: =A36+1 -> 19 | B44: Employee Benefit Expenses
A45: =A44+0.1 -> 19.1 | B45: Salary & Wages (Inculding bonus) | C45: {=SUMIF(Table2[FS Subgroup],'16-23'!B45:B45,Table2[Adjusted balance as on 31-03-2026])} -> 163491002 | D45: =+'Sub Schedule P & L'!C34 -> 1.1168932e+08
A46: =A45+0.1 -> 19.2 | B46: Director's Salary | C46: {=SUMIF(Table2[FS Subgroup],'16-23'!B46:B46,Table2[Adjusted balance as on 31-03-2026])} -> 38000000 | D46: =+'Sub Schedule P & L'!C50 -> 0
A47: =A46+0.1 -> 19.3 | B47: Staff welfare Expenses | C47: {=SUMIF(Table2[FS Subgroup],'16-23'!B47:B47,Table2[Adjusted balance as on 31-03-2026])} -> 16980923 | D47: =+'Sub Schedule P & L'!C44-D53 -> 13935381
A48: =A47+0.1 -> 19.4 | B48: Contribution to Various Funds | C48: {=SUMIF(Table2[FS Subgroup],'16-23'!B48:B48,Table2[Adjusted balance as on 31-03-2026])} -> 12131036 | D48: =D56 -> 9623827.4
A49: =A48+0.1 -> 19.5 | B49: Gratuity and Leave Encashment | C49: {=SUMIF(Table2[FS Subgroup],'16-23'!B49:B49,Table2[Adjusted balance as on 31-03-2026])} -> 4724292 | D49: 56811
B51: Total | C51: =SUM(C45:C50) -> 2.3532725e+08 | D51: =SUM(D45:D50) -> 1.3530534e+08
A52: Note : | B52: Details of Contribution to various Funds
...

Sheet 24-41
B2: MARKETSOF1 ANALYTICAL MARKETING SERVICES PRIVATE LIMITED
B3: CIN: U72501TN2019PTC129911
B5: Notes to Financial Statements for the year ended March 31, 2026
B6: (All amounts are in thousands Indian Rupees, unless otherwise stated)
B8: ='16-23'!A97+1 -> 24 | C8: Contingent liabilities
C9: Based on the assessment made by the management, adequate provision have been provided for the contingent liabilities.
B12: =OLE_LINK7+1 -> 25 | C12: Exceptional Items
C13: Particulars | F13: =+$F$166 -> Year Ended March 31, 2026 | G13: =+$G$166 -> Year Ended March 31, 2025
C14: Provision for Litigation and Court claim (refer note no. 39) | F14: 0 | G14: 0
C16: Total | F16: =SUM(F10:F15) -> 0 | G16: =SUM(G10:G15) -> 0
B18: =B12+1 -> 26 | C18: Capital commitment (net of advances)
C19: As at 31st March, 2026 Rs. Nil. (31-Mar-2025: Rs. Nil).
B21: =+B18+1 -> 27 | C21: Segment Reporting
C22: In the opinion of the management, there is only one reportable segment. i.e. Marketing Consultancy Services and Company operates in only one geographic country i.e. India. Accordingly, no separate disclosure is required to be made under Accounting Standard 17, Segment Reporting.
B26: =+B21+1 -> 28 | C26: Related Party Disclosures
C28: A. List of Related Parties
C29: Nature of Relationship | E29: Party
C30: Key Managerial Personnel | E30: Jayaram Krishnamoorthy
E31: Deepa Mahadevan
E32: Mahul H Shah
E33: Mahadevan Jayaraman
C34: Entities in which key management personnel are interested | E34: Ganitscience Artificial Intelligence and analytics P Ltd (OPC)
E35: ILIVE Daily Creations P Ltd(OPC)
E36: M1 Marketing Services Pvt Ltd
E37: DQAI Telesales Pvt Ltd
E38: DeepQuanty Artificial Intelligence Labs Pvt Ltd
C40: B. Transactions with Related Parties during the year (excluding directors remuneration*)
C41: Transaction | D41: Related Party | F41: Year Ended March 31, 2026 | G41: Year Ended March 31, 2025
D42: Ganitscience Artificial Intelligence and analytics P Ltd (OPC)
D43: ILIVE Daily Creations P Ltd(OPC)
D44: M1 Marketing Services Pvt Ltd
D45: DQAI Telesales Pvt Ltd
D46: DeepQuanty Artificial Intelligence Labs Pvt Ltd
C48: *- Refer C for Directors remuneration.
C50: C. Directors’ Remuneration
C52: Particulars | F52: =+$F$166 -> Year Ended March 31, 2026 | G52: =+$G$166 -> Year Ended March 31, 2025
C53: Executive Directors
C54: Jayaram Krishnamoorthy | F54: 0 | G54: 0
C55: Deepa Mahadevan | F55: ='Trial Balance'!C88 -> 15000000 | G55: 0
C56: Mahul H Shah | F56: 0 | G56: 0
...

Sheet Trial Balance
C2: =SUM(Table2[Adjusted balance as on 31-03-2026]) -> -2.30968e-07 | D2: =SUM(Table2[Adjusted balance as on 31-03-2026]) -> -2.30968e-07 | E2: =SUM(Table2[Adjusted balance as on 31-03-2026]) -> -2.30968e-07
A3: Zoho Group | B3: Zoho Ledger | C3: Balance as on 31-03-2026 | D3: Adjustments | E3: Adjusted balance as on 31-03-2026 | F3: FS Subgroup | G3: FS Group | H3: FS Head
A4: Assets | B4: Accounts Receivable | C4: =IFERROR(VLOOKUP(B4,'TB 2026'!$A$4:$E$155,5,),0) -> 4317419.3 | E4: =Table2[[#This Row],[Balance as on 31-03-2026]]+Table2[[#This Row],[Adjustments]] -> 4317419.3 | F4: -with others | G4: Trade Receivables | H4: Current Asset
A5: Assets | B5: Accounts Receivable (Debtors) | C5: =IFERROR(VLOOKUP(B5,'TB 2026'!$A$4:$E$155,5,),0) -> 23125223 | D5: =J5-Table2[[#This Row],[Balance as on 31-03-2026]] -> 3795659.6 | E5: =Table2[[#This Row],[Balance as on 31-03-2026]]+Table2[[#This Row],[Adjustments]] -> 26920883 | F5: Accrued Revenue | G5: Other Current Assets | H5: Current Asset | J5: 26920883
A6: Assets | B6: Accumulated Depreciation | C6: =IFERROR(VLOOKUP(B6,'TB 2026'!$A$4:$E$155,5,),0) -> -2836754 | D6: =-D99 -> -2045608.1 | E6: =Table2[[#This Row],[Balance as on 31-03-2026]]+Table2[[#This Row],[Adjustments]] -> -4882362.1 | F6: Fixed Assets | G6: Fixed Assets | H6: Non-Current Assets
A7: Assets | B7: Accured Interest On FD | C7: =IFERROR(VLOOKUP(B7,'TB 2026'!$A$4:$E$155,5,),0) -> 149543.83 | E7: =Table2[[#This Row],[Balance as on 31-03-2026]]+Table2[[#This Row],[Adjustments]] -> 149543.83 | F7: Accrued Interest on FD | G7: Other Current Assets | H7: Current Asset
A8: Assets | B8: Advance to Suppliers | C8: =IFERROR(VLOOKUP(B8,'TB 2026'!$A$4:$E$155,5,),0) -> 80942.1 | E8: =Table2[[#This Row],[Balance as on 31-03-2026]]+Table2[[#This Row],[Adjustments]] -> 80942.1 | F8: Advances to Supplier | G8: Short term Loan & Advances | H8: Current Asset
A9: Assets | B9: computer software | C9: =IFERROR(VLOOKUP(B9,'TB 2026'!$A$4:$E$155,5,),0) -> 50000 | E9: =Table2[[#This Row],[Balance as on 31-03-2026]]+Table2[[#This Row],[Adjustments]] -> 50000 | F9: Computers Software | G9: Fixed Assets | H9: Non-Current Assets
A10: Assets | B10: Computers | C10: =IFERROR(VLOOKUP(B10,'TB 2026'!$A$4:$E$155,5,),0) -> 6961779.8 | E10: =Table2[[#This Row],[Balance as on 31-03-2026]]+Table2[[#This Row],[Adjustments]] -> 6961779.8 | F10: Computers & Accessories | G10: Fixed Assets | H10: Non-Current Assets
A11: Assets | B11: Current Account-LITTLE MOUNT ANNASALAI-xxxxxxxxxx7205 | C11: =IFERROR(VLOOKUP(B11,'TB 2026'!$A$4:$E$155,5,),0) -> 25939002 | E11: =Table2[[#This Row],[Balance as on 31-03-2026]]+Table2[[#This Row],[Adjustments]] -> 25939002 | F11: - in current account | G11: Cash and cash equivalents | H11: Current Asset
A12: Assets | B12: Deposits - Rental Advance Coimbatore | C12: =IFERROR(VLOOKUP(B12,'TB 2026'!$A$4:$E$155,5,),0) -> 2354801 | E12: =Table2[[#This Row],[Balance as on 31-03-2026]]+Table2[[#This Row],[Adjustments]] -> 2354801 | F12: Security Deposit | G12: Long Term Loans & Advances | H12: Non-Current Assets
A13: Assets | B13: Deposits - Rental Advance Kochi | C13: =IFERROR(VLOOKUP(B13,'TB 2026'!$A$4:$E$155,5,),0) -> 1537200 | E13: =Table2[[#This Row],[Balance as on 31-03-2026]]+Table2[[#This Row],[Adjustments]] -> 1537200 | F13: Security Deposit | G13: Long Term Loans & Advances | H13: Non-Current Assets
A14: Assets | B14: Deposits - Rental Advance Temple Steps | C14: =IFERROR(VLOOKUP(B14,'TB 2026'!$A$4:$E$155,5,),0) -> 1680000 | E14: =Table2[[#This Row],[Balance as on 31-03-2026]]+Table2[[#This Row],[Adjustments]] -> 1680000 | F14: Security Deposit | G14: Long Term Loans & Advances | H14: Non-Current Assets
A15: Assets | B15: Deposits - Rental Advance VLV Complex | C15: =IFERROR(VLOOKUP(B15,'TB 2026'!$A$4:$E$155,5,),0) -> 1102520 | E15: =Table2[[#This Row],[Balance as on 31-03-2026]]+Table2[[#This Row],[Adjustments]] -> 1102520 | F15: Security Deposit | G15: Long Term Loans & Advances | H15: Non-Current Assets
A16: Assets | B16: Deposits - Rental Advance:Rent Advance - Guindy | C16: =IFERROR(VLOOKUP(B16,'TB 2026'!$A$4:$E$155,5,),0) -> 2000000 | E16: =Table2[[#This Row],[Balance as on 31-03-2026]]+Table2[[#This Row],[Adjustments]] -> 2000000 | F16: Security Deposit | G16: Long Term Loans & Advances | H16: Non-Current Assets
A17: Assets | B17: Deposits - Rental Advance:Rental Deposit Computers | C17: =IFERROR(VLOOKUP(B17,'TB 2026'!$A$4:$E$155,5,),0) -> 40000 | E17: =Table2[[#This Row],[Balance as on 31-03-2026]]+Table2[[#This Row],[Adjustments]] -> 40000 | F17: Security Deposit | G17: Long Term Loans & Advances | H17: Non-Current Assets
A18: Assets | B18: Deposits - Rental Advance:Rental Deposit UPS | C18: =IFERROR(VLOOKUP(B18,'TB 2026'!$A$4:$E$155,5,),0) -> 24000 | E18: =Table2[[#This Row],[Balance as on 31-03-2026]]+Table2[[#This Row],[Adjustments]] -> 24000 | F18: Security Deposit | G18: Long Term Loans & Advances | H18: Non-Current Assets
... A21: Assets | B21: IDFC First Bank | C21: =IFERROR(VLOOKUP(B21,'TB 2026'!$A$4:$E$155,5,),0) -> 134628 | E21: =Table2[[#This Row],[Balance as on 31-03-2026]]+Table2[[#This Row],[Adjustments]] -> 134628 | F21: - in current account | G21: Cash and cash equivalents | H21: Current Asset
A22: Assets | B22: Input Tax Credits | C22: =IFERROR(VLOOKUP(B22,'TB 2026'!$A$4:$E$155,5,),0) -> 0 | E22: =Table2[[#This Row],[Balance as on 31-03-2026]]+Table2[[#This Row],[Adjustments]] -> 0
A23: Assets | B23: Input CGST | C23: =IFERROR(VLOOKUP(B23,'TB 2026'!$A$4:$E$155,5,),0) -> 129394.01 | E23: =Table2[[#This Row],[Balance as on 31-03-2026]]+Table2[[#This Row],[Adjustments]] -> 129394.01 | F23: Balance with Government Authorities | G23: Other Current Assets | H23: Current Asset
A24: Assets | B24: Input IGST | C24: =IFERROR(VLOOKUP(B24,'TB 2026'!$A$4:$E$155,5,),0) -> 128160.6 | E24: =Table2[[#This Row],[Balance as on 31-03-2026]]+Table2[[#This Row],[Adjustments]] -> 128160.6 | F24: Balance with Government Authorities | G24: Other Current Assets | H24: Current Asset
A25: Assets | B25: Input SGST | C25: =IFERROR(VLOOKUP(B25,'TB 2026'!$A$4:$E$155,5,),0) -> 129394 | E25: =Table2[[#This Row],[Balance as on 31-03-2026]]+Table2[[#This Row],[Adjustments]] -> 129394 | F25: Balance with Government Authorities | G25: Other Current Assets | H25: Current Asset
A26: Assets | B26: Petty Cash | C26: =IFERROR(VLOOKUP(B26,'TB 2026'!$A$4:$E$155,5,),0) -> 162254 | E26: =Table2[[#This Row],[Balance as on 31-03-2026]]+Table2[[#This Row],[Adjustments]] -> 162254 | F26: Cash on hand | G26: Cash and cash equivalents | H26: Current Asset
A27: Assets | B27: Prepaid Expenses | C27: =IFERROR(VLOOKUP(B27,'TB 2026'!$A$4:$E$155,5,),0) -> 87762.95 | D27: -87762.95 | E27: =Table2[[#This Row],[Balance as on 31-03-2026]]+Table2[[#This Row],[Adjustments]] -> 0 | F27: Prepaid Expenses | G27: Other Current Assets | H27: Current Asset
A28: Assets | B28: Prepaid Insurance | C28: =IFERROR(VLOOKUP(B28,'TB 2026'!$A$4:$E$155,5,),0) -> 0 | E28: =Table2[[#This Row],[Balance as on 31-03-2026]]+Table2[[#This Row],[Adjustments]] -> 0
A29: Assets | B29: Printers | C29: =IFERROR(VLOOKUP(B29,'TB 2026'!$A$4:$E$155,5,),0) -> 112464.41 | E29: =Table2[[#This Row],[Balance as on 31-03-2026]]+Table2[[#This Row],[Adjustments]] -> 112464.41 | F29: Printer | G29: Fixed Assets | H29: Non-Current Assets
A30: Assets | B30: Refund Due FY25 | C30: =IFERROR(VLOOKUP(B30,'TB 2026'!$A$4:$E$155,5,),0) -> 0 | E30: =Table2[[#This Row],[Balance as on 31-03-2026]]+Table2[[#This Row],[Adjustments]] -> 0
A31: Assets | B31: Reverse Charge Tax Input but not due | C31: =IFERROR(VLOOKUP(B31,'TB 2026'!$A$4:$E$155,5,),0) -> 612.38 | E31: =Table2[[#This Row],[Balance as on 31-03-2026]]+Table2[[#This Row],[Adjustments]] -> 612.38 | F31: Balance with Government Authorities | G31: Other Current Assets | H31: Current Asset
A32: Assets | B32: Salary Advance | C32: =IFERROR(VLOOKUP(B32,'TB 2026'!$A$4:$E$155,5,),0) -> 1970785 | E32: =Table2[[#This Row],[Balance as on 31-03-2026]]+Table2[[#This Row],[Adjustments]] -> 1970785 | F32: Employee Advances | G32: Long Term Loans & Advances | H32: Non-Current Assets
A33: Assets | B33: TDS Receivable AY 25-26 | C33: =IFERROR(VLOOKUP(B33,'TB 2026'!$A$4:$E$155,5,),0) -> 0 | E33: =Table2[[#This Row],[Balance as on 31-03-2026]]+Table2[[#This Row],[Adjustments]] -> 0
A34: Assets | B34: TDS Receivable AY 26-27 | C34: =IFERROR(VLOOKUP(B34,'TB 2026'!$A$4:$E$155,5,),0) -> 11912617 | E34: =Table2[[#This Row],[Balance as on 31-03-2026]]+Table2[[#This Row],[Adjustments]] -> 11912617 | F34: Balance with Government Authorities | G34: Other Current Assets | H34: Current Asset
A35: Assets | B35: Telephone | C35: =IFERROR(VLOOKUP(B35,'TB 2026'!$A$4:$E$155,5,),0) -> 3110.16 | E35: =Table2[[#This Row],[Balance as on 31-03-2026]]+Table2[[#This Row],[Adjustments]] -> 3110.16 | F35: Office Equipments | G35: Fixed Assets | H35: Non-Current Assets
A36: Assets | B36: Undeposited Funds | C36: =IFERROR(VLOOKUP(B36,'TB 2026'!$A$4:$E$155,5,),0) -> 0 | E36: =Table2[[#This Row],[Balance as on 31-03-2026]]+Table2[[#This Row],[Adjustments]] -> 0
A37: Liabilities | B37: Accounts Payable | C37: =IFERROR(VLOOKUP(B37,'TB 2026'!$A$4:$E$155,5,),0) -> -15989116 | D37: =-'TB 2026'!H41 -> 8820 | E37: =Table2[[#This Row],[Balance as on 31-03-2026]]+Table2[[#This Row],[Adjustments]] -> -15980296 | F37: -total outstanding dues of creditors other than micro and small enterprises | G37: Trade Payables | H37: Current Liabilities
A38: Liabilities | B38: Accounts payable (Creditors) | C38: =IFERROR(VLOOKUP(B38,'TB 2026'!$A$4:$E$155,5,),0) -> -54850294 | D38: =-D86 -> 39479000 | E38: =Table2[[#This Row],[Balance as on 31-03-2026]]+Table2[[#This Row],[Adjustments]] -> -15371294 | F38: -total outstanding dues of creditors other than micro and small enterprises | G38: Trade Payables | H38: Current Liabilities
A39: Liabilities | B39: Deferred Income Tax | C39: =IFERROR(VLOOKUP(B39,'TB 2026'!$A$4:$E$155,5,),0) -> -64525.91 | D39: =-D98 -> 44864 | E39: =Table2[[#This Row],[Balance as on 31-03-2026]]+Table2[[#This Row],[Adjustments]] -> -19661.91 | F39: Impact of WDV difference on Property, plant and equipment | G39: Deferred tax liabilities (Net) | H39: Non-Current Liabilities
A40: Liabilities | B40: Directors Remuneration Payable | C40: =IFERROR(VLOOKUP(B40,'TB 2026'!$A$4:$E$155,5,),0) -> -4967905 | E40: =Table2[[#This Row],[Balance as on 31-03-2026]]+Table2[[#This Row],[Adjustments]] -> -4967905 | F40: Director Remuneration Payable | G40: Other Current Liabilities | H40: Current Liabilities
A41: Liabilities | B41: Earned leave Encashment Payable | C41: =IFERROR(VLOOKUP(B41,'TB 2026'!$A$4:$E$155,5,),0) -> -3000095 | E41: =Table2[[#This Row],[Balance as on 31-03-2026]]+Table2[[#This Row],[Adjustments]] -> -3000095 | F41: Provision for leave benefits | G41: Long Term Provisions | H41: Non-Current Liabilities
A42: Liabilities | B42: Employee Reimbursements | C42: =IFERROR(VLOOKUP(B42,'TB 2026'!$A$4:$E$155,5,),0) -> -104665.23 | E42: =Table2[[#This Row],[Balance as on 31-03-2026]]+Table2[[#This Row],[Adjustments]] -> -104665.23 | F42: Other Employee Payable | G42: Other Current Liabilities | H42: Current Liabilities
A43: Liabilities | B43: ESIC Payable | C43: =IFERROR(VLOOKUP(B43,'TB 2026'!$A$4:$E$155,5,),0) -> -186955 | E43: =Table2[[#This Row],[Balance as on 31-03-2026]]+Table2[[#This Row],[Adjustments]] -> -186955 | F43: Statutory dues including provident fund and tax deducted at source | G43: Other Current Liabilities | H43: Current Liabilities
...

Sheet TB 2026
A1: Marketsof1 Analytical Marketing Services Private Limited Trial Balance Basis: Accrual From 01/04/2025 To 31/03/2026
A2: Account | B2: Opening Balance | C2: Debit | D2: Credit | E2: Closing Balance
A4: Assets
A5: Accounts Receivable | B5: 1242797.4 | C5: 6.8418768e+08 | D5: 6.8111306e+08 | E5: 4317419.3 | G5: 4317419.3 | H5: =E5-G5 -> 0
A6: Accounts Receivable (Debtors) | B6: 5000000 | C6: 23125223 | D6: 5000000 | E6: 23125223 | G6: 23125223 | H6: =E6-G6 -> 0
A7: Accumulated Depreciation | B7: -2836754 | C7: 0 | D7: 0 | E7: -2836754 | G7: -4882362.1 | H7: =E7-G7 -> 2045608.1
A8: Accured Interest On FD | B8: 171762.8 | C8: 149543.83 | D8: 171762.8 | E8: 149543.83 | G8: 149543.83 | H8: =E8-G8 -> 0
A9: Advance to Suppliers | B9: 174506.18 | C9: 4097931.8 | D9: 4191495.9 | E9: 80942.1 | G9: 80942.1 | H9: =E9-G9 -> 0
A10: computer software | B10: 50000 | C10: 0 | D10: 0 | E10: 50000 | G10: 50000 | H10: =E10-G10 -> 0
A11: Computers | B11: 4563131.4 | C11: 2398648.4 | D11: 0 | E11: 6961779.8 | G11: 6961779.8 | H11: =E11-G11 -> 0
A12: Current Account-LITTLE MOUNT ANNASALAI-xxxxxxxxxx7205 | B12: 1588011.2 | C12: 1.4059439e+09 | D12: 1.3815929e+09 | E12: 25939002 | G12: 25939002 | H12: =E12-G12 -> 0
A13: Deposits - Rental Advance Coimbatore | B13: 2354801 | C13: 0 | D13: 0 | E13: 2354801 | G13: 2354801 | H13: =E13-G13 -> 0
A14: Deposits - Rental Advance Kochi | B14: 0 | C14: 1537200 | D14: 0 | E14: 1537200 | G14: 1537200 | H14: =E14-G14 -> 0
A15: Deposits - Rental Advance Temple Steps | B15: 1680000 | C15: 0 | D15: 0 | E15: 1680000 | G15: 1680000 | H15: =E15-G15 -> 0
A16: Deposits - Rental Advance VLV Complex | B16: 1102520 | C16: 0 | D16: 0 | E16: 1102520 | G16: 1102520 | H16: =E16-G16 -> 0
... A27: Total for Input Tax Credits | B27: 101951.91 | C27: 52991568 | D27: 52706571 | E27: 386948.61 | G27: 386948.61 | H27: =E27-G27 -> 0
H28: =E28-G28 -> 0
A29: Petty Cash | B29: 130808 | C29: 1205000 | D29: 1173554 | E29: 162254 | G29: 162254 | H29: =E29-G29 -> 0
A30: Prepaid Expenses | B30: 24422.41 | C30: 4650581.2 | D30: 4587240.6 | E30: 87762.95 | G30: 87762.95 | H30: =E30-G30 -> 0
A31: Prepaid Insurance | B31: 372301.37 | C31: 0 | D31: 372301.37 | E31: 0 | G31: 0 | H31: =E31-G31 -> 0
A32: Printers | B32: 62574.58 | C32: 73949.15 | D32: 24059.32 | E32: 112464.41 | G32: 112464.41 | H32: =E32-G32 -> 0
A33: Refund Due FY25 | B33: 0 | C33: 649430 | D33: 649430 | E33: 0 | G33: 0 | H33: =E33-G33 -> 0
A34: Reverse Charge Tax Input but not due | B34: 0 | C34: 2524116.5 | D34: 2523504.1 | E34: 612.38 | G34: 612.38 | H34: =E34-G34 -> 0
A35: Salary Advance | B35: 207334 | C35: 3047500 | D35: 1284049 | E35: 1970785 | G35: 1970785 | H35: =E35-G35 -> 0
A36: TDS Receivable AY 25-26 | B36: 8554545.4 | C36: 0 | D36: 8554545.4 | E36: 0 | G36: 0 | H36: =E36-G36 -> 0
A37: TDS Receivable AY 26-27 | B37: 0 | C37: 11912617 | D37: 0 | E37: 11912617 | G37: 11912617 | H37: =E37-G37 -> 0
A38: Telephone | B38: 3110.16 | C38: 0 | D38: 0 | E38: 3110.16 | G38: 3110.16 | H38: =E38-G38 -> 0
A39: Undeposited Funds | B39: 0 | C39: 4226.43 | D39: 4226.43 | E39: 0 | G39: 0 | H39: =E39-G39 -> 0
A40: Liabilities | H40: =E40-G40 -> #VALUE!
A41: Accounts Payable | B41: -32007048 | C41: 3.7163775e+08 | D41: 3.5561982e+08 | E41: -15989116 | G41: -15980296 | H41: =E41-G41 -> -8820
A42: Accounts payable (Creditors) | B42: -231423.21 | C42: 231423.21 | D42: 54850294 | E42: -54850294 | G42: -54850294 | H42: =E42-G42 -> 0
A43: Deferred Income Tax | B43: -64525.91 | C43: 0 | D43: 0 | E43: -64525.91 | G43: -19661.91 | H43: =E43-G43 -> -44864
A44: Directors Remuneration Payable | B44: 0 | C44: 19784575 | D44: 24752480 | E44: -4967905 | G44: -4967905 | H44: =E44-G44 -> 0
A45: Earned leave Encashment Payable | B45: -79164 | C45: 370412 | D45: 3291343 | E45: -3000095 | G45: -3000095 | H45: =E45-G45 -> 0
A46: Employee Reimbursements | B46: 0 | C46: 1052080.4 | D46: 1156745.6 | E46: -104665.23 | G46: -104665.23 | H46: =E46-G46 -> 0
A47: ESIC Payable | B47: -220927 | C47: 2189756.5 | D47: 2155784.5 | E47: -186955 | G47: -186955 | H47: =E47-G47 -> 0
A48: Gratuity Payable | B48: 0 | C48: 0 | D48: 1469911 | E48: -1469911 | G48: -1469911 | H48: =E48-G48 -> 0
A49: GST Payable | B49: 283435 | C49: 53241012 | D49: 56290006 | E49: -2765559 | G49: -2765559 | H49: =E49-G49 -> 0
A50: Output CGST | B50: -61332.78 | C50: 1292351.3 | D50: 1231018.5 | E50: 0 | G50: 0 | H50: =E50-G50 -> 0
A51: Output IGST | B51: -27864.52 | C51: 1.0445694e+08 | D51: 1.0442969e+08 | E51: -612.34 | G51: -612.34 | H51: =E51-G51 -> 0
...

Sheet TB 2025
A1: Marketsof1 Analytical Marketing Services Private Limited Trial Balance Basis: Accrual From 01/03/2024 To 31/03/2025
A2: Account | B2: Opening Balance | C2: Debit | D2: Credit | E2: Closing Balance
A4: Assets
A5: Accounts Receivable | B5: 0 | C5: 5.8980937e+08 | D5: 5.8856657e+08 | E5: 1242797.4
A6: Accounts Receivable (Debtors) | B6: 0 | C6: 5500000 | D6: 500000 | E6: 5000000
A7: Accumulated Depreciation | B7: -1283683.2 | C7: 0 | D7: 1553070.8 | E7: -2836754
A8: Accured Interest On FD | B8: 211719.75 | C8: 255725 | D8: 295681.95 | E8: 171762.8
A9: Advance to Suppliers | B9: 71131.91 | C9: 2110505.9 | D9: 2007131.6 | E9: 174506.18
A10: Amazon Pay | B10: 0 | C10: 720.1 | D10: 720.1 | E10: 0
A11: computer software | B11: 50000 | C11: 0 | D11: 0 | E11: 50000
A12: Computers | B12: 2548918.1 | C12: 2014213.3 | D12: 0 | E12: 4563131.4
A13: Current Account-LITTLE MOUNT ANNASALAI-xxxxxxxxxx7205 | B13: 2435995.1 | C13: 1.097068e+09 | D13: 1.0979159e+09 | E13: 1588011.2
A14: Deposits - Rental Advance Coimbatore | B14: 0 | C14: 2354801 | D14: 0 | E14: 2354801
A15: Deposits - Rental Advance Temple Steps | B15: 1680000 | C15: 0 | D15: 0 | E15: 1680000
A16: Deposits - Rental Advance VLV Complex | B16: 1102520 | C16: 0 | D16: 0 | E16: 1102520
... A20: Fixed Deposit | B20: 41338890 | C20: 612515000 | D20: 611433369 | E20: 42420521
A21: Furniture and Equipment | B21: 2457557.2 | C21: 178413.96 | D21: 0 | E21: 2635971.2 | F21: 2640971.2 | G21: =E21-F21 -> -5000
A22: IDFC First Bank | B22: 1500191.1 | C22: 3.4709906e+08 | D22: 310951798 | E22: 37647450
A23: Input Tax Credits | B23: 0 | C23: 0 | D23: 0 | E23: 0
A24: Input CGST | B24: 67045.41 | C24: 22654609 | D24: 22670719 | E24: 50935.6
A25: Input IGST | B25: 11422.71 | C25: 9704469.6 | D25: 9715811.6 | E25: 80.71
A26: Input SGST | B26: 67045.41 | C26: 22654609 | D26: 22670719 | E26: 50935.6
A27: Total for Input Tax Credits | B27: 145513.53 | C27: 55013687 | D27: 55057249 | E27: 101951.91
A29: Petty Cash | B29: 149668 | C29: 1471111 | D29: 1489971 | E29: 130808
A30: Prepaid Expenses | B30: 0 | C30: 3082301.1 | D30: 3057878.7 | E30: 24422.41
A31: Prepaid Insurance | B31: 0 | C31: 722707.11 | D31: 350405.74 | E31: 372301.37
A32: Printers | B32: 42372.04 | C32: 42849.59 | D32: 22647.05 | E32: 62574.58
A33: Refund Due FY24 | B33: 0 | C33: 2485995 | D33: 2485995 | E33: 0
A34: Reverse Charge Tax Input but not due | B34: 20468.77 | C34: 509940.11 | D34: 530408.88 | E34: 0
... A39: Undeposited Funds | B39: 0 | C39: 12900.1 | D39: 12900.1 | E39: 0
A40: Liabilities
A41: Accounts Payable | B41: -28896199 | C41: 3.6011723e+08 | D41: 3.6321926e+08 | E41: -31998228
A42: Accounts payable (Creditors) | B42: 0 | C42: 1018636 | D42: 1250059.2 | E42: -231423.21
A43: Deferred Income Tax | B43: 12118.09 | C43: 0 | D43: 109992.7 | E43: -97874.61 | F43: 64526 | G43: =-E43-F43 -> 33348.61
A44: Earned leave Encashment Payable | B44: -27622 | C44: 311603 | D44: 363145 | E44: -79164
A45: Employee Reimbursements | B45: 0 | C45: 510463.02 | D45: 510463.02 | E45: 0
A46: ESIC Payable | B46: -189951 | C46: 2530742 | D46: 2561718 | E46: -220927
A47: GST Payable | B47: -640096.3 | C47: 36701715 | D47: 35778184 | E47: 283435
A48: Output CGST | B48: 0 | C48: 172433.72 | D48: 233766.5 | E48: -61332.78
A49: Output IGST | B49: 0.72 | C49: 89986675 | D49: 90014540 | E49: -27864.52
...

Sheet Sub Schedule P & L
B2: =+'Sub Schedule BS'!B2:E2 -> MARKETSOF1 ANALYTICAL MARKETING SERVICES PRIVATE LIMITED
B3: Notes forming part of Financial Statements as on March 31, 2025
C4: For the year ended 31.03.2025 | D4: For the year ended 31.03.2024 | E4: For the year ended 31.03.2023
B6: (i) Revenue From Services
B7: - Digital Design
B8: - Digital Profile | E8: 76544665
B9: - FTE & Sales Process | E9: 47773061
B10: - MLMS | E10: 12882556
B11: - Offline Profile-Affiliate | E11: 32790159
B12: - Project operation | E12: 23810000
B13: - Services | E13: 0
B14: - Sales reimbursements | C14: 141090
C15: =448980007+C14 -> 449121097 | D15: =#REF! -> #REF! | E15: =SUM(E7:E13) -> 1.9380044e+08
B17: (ii) Operating Expenses
E18: 0
B19: Campaign Expenses | C19: ='Groupings P &L'!C39 -> 41381396 | D19: ='Groupings P &L'!D39 -> #REF! | E19: 31685424
B20: Brokerage Expenses | D20: 0 | E20: 0
B21: ICT-Service | D21: =#REF! -> #REF! | E21: 10436080
B22: Provision for Expenses | D22: =+'Groupings P &L'!D24 -> 0 | E22: 0
B23: All Other Direct Costs-User licences for algorithms | C23: =92575050.64 -> 92575051 | D23: =#REF!+#REF! -> #REF! | E23: 46366000
B24: All Other Direct Costs:Professional Fees for Analytics and UI/UX | C24: 97545428 | D24: =#REF! -> #REF! | E24: 45750000
B25: All Other Direct Costs: Predictive modeling and updates | C25: 5000000
C26: =SUM(C18:C25) -> 2.3650187e+08 | D26: =SUM(D18:D25) -> #REF! | E26: =SUM(E18:E25) -> 1.342375e+08
B28: (iii) Salaries, wages and bonus
B29: Salaries & Wages | C29: 104050187 | D29: =#REF!+#REF! -> #REF! | E29: 30837186
B30: Bonus | C30: 0 | D30: 0 | E30: 0
B31: Performance Payouts | C31: =+'Groupings P &L'!C12 -> 6965842 | D31: =+'Groupings P &L'!D12 -> #REF! | E31: 2605633 | G31: =78438+894965+55361+148512.5+132000 -> 1309276.5
B32: Staff Recriitment expenses | C32: 310142.98 | D32: =#REF! -> #REF! | E32: 199000
B33: Earned leave encashment | C33: 363145 | D33: =#REF! -> #REF! | E33: 30225
C34: =SUM(C29:C33) -> 1.1168932e+08 | D34: =SUM(D29:D33) -> #REF! | E34: =SUM(E29:E33) -> 33672044
B36: (iv) Contribution to provident fund & NPS
B37: Contribution to EPF | C37: 7684444 | D37: =#REF! -> #REF! | E37: 2435672
C38: =SUM(C37:C37) -> 7684444 | D38: =SUM(D37:D37) -> #REF! | E38: =SUM(E37:E37) -> 2435672
B40: (v) Staff welfare expenses
B41: Staff Welfare Expenses | C41: =42650+9436453+8011+911763+313772+149000+2396807 -> 13258456 | D41: =#REF!+#REF!+#REF!+#REF!+#REF! -> #REF! | E41: 5675282.1
B42: Staff Entertainment | C42: 676925 | D42: =#REF! -> #REF! | E42: 395330.62
B43: Contribution to ESIC | C43: 1914430 | D43: =#REF! -> #REF! | E43: 786030
C44: =SUM(C41:C43) -> 15849811 | D44: =SUM(D41:D43) -> #REF! | E44: =SUM(E41:E43) -> 6856642.7
B46: (vi) Directors Remuneration
B47: Jayaram Iyer krishnamoorthy | D47: 0 | E47: 0
...

Sheet Groupings P &L
B2: MARKETSOF1 ANALYTICAL MARKETING SERVICES PRIVATE LIMITED
B3: Notes forming part of Financial Statements
C4: For the year ended 31.03.2025 | D4: For the year ended 31.03.2024 | E4: For the year ended 31.03.2023
B6: (i) Performance payout
B7: Attendance Bonus | E7: 0
B8: Holiday pay | E8: 0
B9: Incentive | C9: 5927627 | D9: =#REF! -> #REF! | E9: 2154508
B10: Spot Incentive | C10: 349215 | D10: =#REF! -> #REF! | E10: 224125
B11: Referral Bonus | C11: 689000 | D11: =#REF! -> #REF! | E11: 227000
C12: =SUM(C7:C11) -> 6965842 | D12: =SUM(D7:D11) -> #REF! | E12: =SUM(E7:E11) -> 2605633
B13: (ii) Rent
B14: System Rent | C14: 2540591.2 | D14: =#REF! -> #REF! | E14: 1449707.2
B15: UPS Rent | C15: 738000 | D15: =#REF! -> #REF! | E15: 284000
B16: Rent - VLV Complex | C16: 2708838 | D16: =#REF! -> #REF! | E16: 2297109
B17: Rent - Guindy | C17: 1777277 | D17: =#REF! -> #REF! | E17: 529250
B18: Rent for Temple Steps | C18: 3486000 | D18: =#REF! -> #REF!
B19: Rent for Coimbatore | C19: 549453
C20: =SUM(C14:C19) -> 11800159 | D20: =SUM(D14:D18) -> #REF! | E20: =SUM(E14:E17) -> 4560066.2
B21: (iii)Provision for Expenses
B22: Provision for Expenses
B23: Provision for COVID | D23: 0 | E23: 0
D24: =SUM(D22:D23) -> 0 | E24: =SUM(E22:E23) -> 0
B26: (iv) Office Expenses
B27: Pooja Expenses | C27: 111705.64 | D27: =#REF! -> #REF! | E27: 44250
B28: Office Expenses | C28: 110292.21 | D28: =#REF! -> #REF! | E28: 34902.39
B29: Office Maintenance Charges | C29: =28419+193706+840000+1354416 -> 2416541 | D29: =#REF!+#REF!+#REF! -> #REF! | E29: 269315
B30: Electrical & Electronic Consumables | C30: 729689 | D30: =#REF! -> #REF! | E30: 469862.08
C31: =SUM(C27:C30) -> 3368227.9 | D31: =SUM(D27:D30) -> #REF! | E31: =SUM(E27:E30) -> 818329.47
B33: (v) Campaigns Expenses
B35: Campaigns-Affiliate | C35: 9856490.7 | D35: =#REF! -> #REF! | E35: 7431935.4
B36: Campaigns-Facebook | C36: 1402539 | D36: =#REF! -> #REF! | E36: 3042747.1
B37: Campaigns-Google | C37: 30122366 | D37: =#REF! -> #REF! | E37: 21210742
B38: Campaigns-Others
C39: =SUM(C35:C38) -> 41381396 | D39: =SUM(D35:D38) -> #REF! | E39: =SUM(E35:E38) -> 31685424
B41: (vi) Other Expenses
B43: Water Tax | C43: 15852 | D43: =#REF! -> #REF! | E43: 45299
B44: Asset Written Off | C44: -500000 | D44: =#REF! -> #REF! | E44: -113280
B45: Professional charges | C45: 254958 | D45: =#REF! -> #REF! | E45: 230424
B46: Diesel Charges | C46: 300094 | D46: =#REF! -> #REF! | E46: 398595
B47: Interest on TDS payment | D47: 513
...

Sheet Groupings BS
B3: Notes forming part of Financial Statements as on March 31, 2025
C4: For the year ended 31.03.2025 | D4: For the year ended 31.03.2024 | E4: For the year ended 31.03.2023
B6: (i) Accounts payable
B7: Referral Bonus payable | C7: 33500 | D7: =#REF! -> #REF! | E7: 65000
B8: Incentive Payable | C8: 726307 | D8: =#REF! -> #REF! | E8: 257821
B9: Government charges payable | D9: 0 | E9: 0
C10: =SUM(C7:C9) -> 759807 | D10: =SUM(D7:D9) -> #REF! | E10: =SUM(E7:E9) -> 322821
B12: (ii) Input GST
B13: Input CGST | C13: 50935.6 | D13: =#REF! -> #REF! | E13: 38490.38
B14: Input SGST | C14: 50935.6 | D14: =#REF! -> #REF! | E14: 38490.38 | F14: 9750857 | G14: =+D14-F14 -> #REF!
B15: Input IGST | C15: 80.71 | D15: =#REF! -> #REF! | E15: 14607.76 | G15: 26330
C16: =SUM(C13:C15) -> 101951.91 | D16: =SUM(D13:D15) -> #REF! | E16: =SUM(E13:E15) -> 91588.52 | G16: =+G14-G15 -> #REF!
B29: (i) Trade payable
B30: Aachi Masala Foods Pvt.Ltd.
B31: ACR INFOSYSTEMS
B32: Akshaya Security Services
B33: Airtel
B34: Bharani Kumar
B35: DeepQuanty Artificial Intelligence Labs Pvt Ltd
B36: DIGITAL CREST
B37: DQAI Telesales Pvt Ltd
B38: Facebook India Online services Pvt.Ltd.
B39: Freedom solution
B40: GALAXY POWER SOLUTION
... B64: Vodafone Idea Limited
E65: =SUM(E30:E64) -> 0

Sheet Deferred Tax
B2: Computation of Deffered Tax
B3: Particulars | C3: Amount
B4: WDV as per IT act | C4: 4229857 | J4: 5363721
B5: WDV as per Books of Accounts | C5: ='10'!L43 -> 4478032.3 | J5: ='Financial Statements'!E35 -> 5439341.5
B6: Difference | C6: =C5-C4 -> 248175.35 | E6: Deferred tax exp | G6: =C11 -> -10930.32 | H6: (P&L item) | J6: =J5-J4 -> 75620.518
B7: Tax @22% | C7: =+C6*25% -> 62043.837 | F7: to def liab | H7: =G6 -> -10930.32 | J7: =J6*0.25*1.04 -> 19661.335
B8: Cess @4% | C8: =+C7*4% -> 2481.7535
B9: Closing Deferred Tax Liability (DTL) | C9: =+C7+C8 -> 64525.59
B10: Opening Balance | C10: 75455.91
B11: Current year DTL | C11: =+C9-C10 -> -10930.32

Sheet Current Tax
