Workbook
Name Deno: 'Master data'!$B$2

Sheet Master data
A2: Lakhs | B2: =+SUMIF(A4:A10,A2,B4:B10) -> 100000 | C2: =+Deno -> 100000
A4: Millions | B4: 1000000
A5: Lakhs | B5: 100000
A6: Ten Thousands | B6: 10000
A7: Thousands | B7: 1000
A8: Hundreds | B8: 100
A9: Tens | B9: 10
A10: Ones | B10: 1

Sheet Sheet1
A2: As per RBI Prevailing Rates
A3: Date | B3: Currency | C3: Rate/ INR
A4: 45747 | B4: USD | C4: 85.424
A5: 45747 | B5: EUR | C5: 92.415
A6: 45747 | B6: GBP | C6: 110.53

Sheet Audit entry
B2: Audit Entry for FY 2024-25 | E2: =+D3-E3 -> -1.94
D3: =+SUM(D5:D1048576) -> 29995065 | E3: =+SUM(E5:E1048576) -> 29995067
B4: SI no | C4: Particulars | D4: Debit | E4: Credit | F4: Remarks | M4: Check
H5: Assest break ups | M5: Income Tax payable | N5: ='Statement of Income'!E44 -> 654762.49 | O5: =E149 -> 654762.49 | P5: =N5-O5 -> 1.4202669e-08
B6: 1 | C6: INSURANCE. | D6: 122066.25 | F6: Given | H6: 44109 | I6: NETWORK CHSING PURCHSED FOR MAA NEW OFFICE | J6: 2928 | M6: TDS Receivables | N6: ='Statement of Income'!E47 -> 3660953 | O6: ='TB 24-25'!I61 -> 3255908.4 | P6: =N6-O6 -> 405044.67
C7: To PREPAID INSURANCES | E7: =+D6 -> 122066.25 | F7: Given | H7: 44119 | I7: AC INSTALATION CHARGES | J7: 1500
C8: (Prepaid of FY 23-24 Transferred to Exp)
H9: 44119 | I9: PLUG - INR 60 1/2" NUTS - INR 150 ANGLR FLANZ - INR 90 | J9: 400
B10: 2 | C10: PREPAID INSURANCES | D10: =392364.68/12*4 -> 130788.23 | F10: Given | H10: 44119 | I10: NETWORKING ACCESSORIES | J10: 1684
C11: To INSURANCE. | E11: =+D10 -> 130788.23 | F11: Given | H11: 44141 | J11: 2142
C12: (Prepaid of FY 24-25 Transferred to Exp) | H12: 44989 | I12: Stablizer FOR AC | J12: 1550
B14: 3 | C14: AUDIT FEES PAYABLE | D14: 225000 | F14: Given | H14: 44013 | J14: 638.98
C15: To Accurals | E15: =+D14 -> 225000 | F15: Given | H15: 44032 | J15: 4287.05
C16: (Transfer entry - reversal of audit fee payable for the Previous FY & GST audit fee payable for the FY 2022-23) | H16: 44119 | I16: STABLIZER | J16: 1100
H17: 44124 | I17: Stabiliser | J17: 2400
B18: 4 | C18: STATUTORY EXPENSES | D18: 10000 | F18: Given | H18: 44965 | I18: AIRTEL DONGLE | J18: 2200
C19: ACCRUALS | E19: 10000 | F19: Given | H19: 44983 | I19: Window Curtain | J19: 2500
C20: (IT filing transferred) | H20: 44162 | J20: 960
B22: 5 | C22: ACCRUALS | D22: 1315 | F22: Given
C23: INTEREST ON DEPOSIT | E23: =+D22 -> 1315 | F23: Given
C24: Interest trf entry)
B26: 6 | C26: Stat Audit | D26: 125000 | F26: Given
C27: Tax audit | D27: 100000 | F27: Given
C28: AUDIT FEES PAYABLE | E28: =SUM(D26:D27) -> 225000 | F28: Given
C29: (FY 24-25 audit fee)
B31: 7 | C31: Profit and loss ac | D31: =-'Deffered Tax'!H23 -> 0.37521685 | F31: Given
C32: Deffered Tax | E32: =+D31 -> 0.37521685 | F32: Given
B34: 8 | C34: LOCAL CREDITORS - FREIGHT FORWARDING | D34: 12250 | F34: Given
C35: REPAIRS & MAINTENANCE FOR COMPUTERS HARDWARE | E35: =+D34 -> 12250 | F35: Given
B37: 9 | C37: INTERNET | D37: 8846.46 | F37: Given
C38: LOCAL CREDITORS - FREIGHT FORWARDING | E38: =+D37 -> 8846.46 | F38: Given
B40: 10 | C40: BLUE DART | D40: 177 | F40: Given
C41: I2 IMPEX | D41: 298.62
C42: STAR HEALTH AND ALLIED INSURANCE COMPANY LIMITED | D42: 38558.96
C43: THE PROFESSIONAL COURIERS CHENNAI LLP | D43: 197.97
C44: UNIQUE PEST MANAGEMENT | D44: 1000
C45: BABU RAO | D45: 2144
C46: BANGALORE ELECTRICITY (BESCOM) | D46: 2022.48
C47: GURUASHISH LOGISTICS PVT LTD | D47: 885
C48: MOKSHITA TRANSPORT | D48: 3120
...

Sheet TB 24-25
D1: =Deno -> 100000 | F1: =+F2-E2 -> -3.685464e-06 | H1: =+H2-G2 -> 408.63145 | J1: =+J2-I2 -> -408.63 | L1: =+L2-K2 -> 0.0014525056 | N1: =+N2-M2 -> -0.059999999 | P1: =(O2-P2)*Deno -> 0.05854763 | V1: -99152768
E2: =SUBTOTAL(9,E6:E342) -> 3279.2606 | F2: =SUBTOTAL(9,F6:F342) -> 3279.2606 | G2: =SUBTOTAL(9,G6:G342) -> 1.6962661e+08 | H2: =SUBTOTAL(9,H6:H342) -> 1.6962702e+08 | I2: =SUBTOTAL(9,I6:I342) -> 3.2757994e+08 | J2: =SUBTOTAL(9,J6:J342) -> 3.2757953e+08 | K2: =SUBTOTAL(9,K6:K342) -> 4.6262336e+08 | L2: =SUBTOTAL(9,L6:L342) -> 4.6262336e+08 | ... P2: =SUBTOTAL(9,P6:P342) -> 4665.1232 | R2: =+E2-F2 -> 3.685464e-06 | S2: 1930545.7 | T2: =+R2-S2 -> -1930545.7 | V2: 1.0118639e+08 | W2: =+SUM(V1:V2) -> 2033619.2
E3: Closing Balance after AR | G3: Opening Balance | I3: During the Year Transaction | K3: Closing Balance | M3: Audit entries | O3: Closing Balance after AR
D4: Particulars | E4: FY 23-24 | G4: FY 24-25 | I4: FY 24-25 | K4: FY 24-25 | M4: FY 24-25 | O4: FY 24-25
E5: Debit | F5: Credit | G5: Debit | H5: Credit | I5: Debit | J5: Credit | K5: Debit | L5: Credit | M5: Debit | N5: Credit | O5: Debit | P5: Credit | Q5: Sumif | R5: Note no | S5: CY Grouping | T5: Sub sch Ref
A6: ASSETS
B7: FIXED ASSETS
C8: FIXED ASSETS AT COST
D9: COMPUTER | E9: =139899.35933321/(Deno) -> 1.3989936 | F9: =0/(Deno) -> 0 | G9: 139899.36 | H9: 0 | I9: 32966.11 | J9: 0 | K9: =+IF((G9+I9-H9-J9>0),G9+I9-H9-J9,0) -> 172865.47 | L9: =+IF((H9+J9-G9-I9)>0,H9+J9-G9-I9,0) -> 0 | O9: =+IF((K9+M9-L9-N9>0),K9+M9-L9-N9,0)/Deno -> 1.7286547 | P9: =+IF((L9+N9-K9-M9)>0,L9+N9-K9-M9,0)/Deno -> 0 | R9: 8 | S9: Fixed Assets
D10: OFFICE EQUIPMENTS | E10: =517825.649127016/(Deno) -> 5.1782565 | F10: =0/(Deno) -> 0 | G10: 517825.65 | H10: 0 | I10: 0 | J10: 0 | K10: =+IF((G10+I10-H10-J10>0),G10+I10-H10-J10,0) -> 517825.65 | L10: =+IF((H10+J10-G10-I10)>0,H10+J10-G10-I10,0) -> 0 | O10: =+IF((K10+M10-L10-N10>0),K10+M10-L10-N10,0)/Deno -> 5.1782565 | P10: =+IF((L10+N10-K10-M10)>0,L10+N10-K10-M10,0)/Deno -> 0 | R10: 8 | S10: Fixed Assets
D11: FURNITURE & FIXTURES | E11: =125082.421142074/(Deno) -> 1.2508242 | F11: =0/(Deno) -> 0 | G11: 125082.42 | H11: 0 | I11: 0 | J11: 0 | K11: =+IF((G11+I11-H11-J11>0),G11+I11-H11-J11,0) -> 125082.42 | L11: =+IF((H11+J11-G11-I11)>0,H11+J11-G11-I11,0) -> 0 | O11: =+IF((K11+M11-L11-N11>0),K11+M11-L11-N11,0)/Deno -> 1.2508242 | P11: =+IF((L11+N11-K11-M11)>0,L11+N11-K11-M11,0)/Deno -> 0 | R11: 8 | S11: Fixed Assets
D12: MOTOR VEHICLES - CAR | E12: =0.00022921827621758/(Deno) -> 2.2921828e-09 | F12: =0/(Deno) -> 0 | G12: 0.00022921828 | H12: 0 | I12: 0 | J12: 0 | K12: =+IF((G12+I12-H12-J12>0),G12+I12-H12-J12,0) -> 0.00022921828 | L12: =+IF((H12+J12-G12-I12)>0,H12+J12-G12-I12,0) -> 0 | O12: =+IF((K12+M12-L12-N12>0),K12+M12-L12-N12,0)/Deno -> 2.2921828e-09 | P12: =+IF((L12+N12-K12-M12)>0,L12+N12-K12-M12,0)/Deno -> 0 | R12: 8 | S12: Fixed Assets
D13: ELECTRICAL INSTALLATIONS | E13: =37190.2148490844/(Deno) -> 0.37190215 | F13: =0/(Deno) -> 0 | G13: 37190.215 | H13: 0 | I13: 56000 | J13: 0 | K13: =+IF((G13+I13-H13-J13>0),G13+I13-H13-J13,0) -> 93190.215 | L13: =+IF((H13+J13-G13-I13)>0,H13+J13-G13-I13,0) -> 0 | O13: =+IF((K13+M13-L13-N13>0),K13+M13-L13-N13,0)/Deno -> 0.93190215 | P13: =+IF((L13+N13-K13-M13)>0,L13+N13-K13-M13,0)/Deno -> 0 | R13: 8 | S13: Fixed Assets
D14: MOBILE PURCHASE | E14: =19061/(Deno) -> 0.19061 | F14: =0/(Deno) -> 0 | G14: 19061 | H14: 0 | I14: 0 | J14: 0 | K14: =+IF((G14+I14-H14-J14>0),G14+I14-H14-J14,0) -> 19061 | L14: =+IF((H14+J14-G14-I14)>0,H14+J14-G14-I14,0) -> 0 | O14: =+IF((K14+M14-L14-N14>0),K14+M14-L14-N14,0)/Deno -> 0.19061 | P14: =+IF((L14+N14-K14-M14)>0,L14+N14-K14-M14,0)/Deno -> 0 | R14: 8 | S14: Fixed Assets
D15: OFFICE EQUIPMENTS | E15: =39297.176257463/(Deno) -> 0.39297176 | F15: =0/(Deno) -> 0 | G15: 39297.176 | H15: 0 | I15: 0 | J15: 0 | K15: =+IF((G15+I15-H15-J15>0),G15+I15-H15-J15,0) -> 39297.176 | L15: =+IF((H15+J15-G15-I15)>0,H15+J15-G15-I15,0) -> 0 | O15: =+IF((K15+M15-L15-N15>0),K15+M15-L15-N15,0)/Deno -> 0.39297176 | P15: =+IF((L15+N15-K15-M15)>0,L15+N15-K15-M15,0)/Deno -> 0 | R15: 8 | S15: Fixed Assets
D16: OFFICE EQUIP | E16: =35787.5/(Deno) -> 0.357875 | F16: =0/(Deno) -> 0 | G16: 35787.5 | H16: 0 | I16: 0 | J16: 0 | K16: =+IF((G16+I16-H16-J16>0),G16+I16-H16-J16,0) -> 35787.5 | L16: =+IF((H16+J16-G16-I16)>0,H16+J16-G16-I16,0) -> 0 | O16: =+IF((K16+M16-L16-N16>0),K16+M16-L16-N16,0)/Deno -> 0.357875 | P16: =+IF((L16+N16-K16-M16)>0,L16+N16-K16-M16,0)/Deno -> 0 | R16: 8 | S16: Fixed Assets
D17: MACHINERY & ELECTRICAL | E17: =0/(Deno) -> 0 | F17: =0.30000000000291/(Deno) -> 3e-06 | G17: 0 | H17: 0.3 | I17: 0 | J17: 0 | K17: =+IF((G17+I17-H17-J17>0),G17+I17-H17-J17,0) -> 0 | L17: =+IF((H17+J17-G17-I17)>0,H17+J17-G17-I17,0) -> 0.3 | O17: =+IF((K17+M17-L17-N17>0),K17+M17-L17-N17,0)/Deno -> 0 | P17: =+IF((L17+N17-K17-M17)>0,L17+N17-K17-M17,0)/Deno -> 3e-06 | R17: 8 | S17: Fixed Assets
B18: CURRENT ASSETS | E18: =0/(Deno) -> 0 | F18: =0/(Deno) -> 0 | K18: =+IF((G18+I18-H18-J18>0),G18+I18-H18-J18,0) -> 0 | L18: =+IF((H18+J18-G18-I18)>0,H18+J18-G18-I18,0) -> 0 | O18: =+IF((K18+M18-L18-N18>0),K18+M18-L18-N18,0)/Deno -> 0 | P18: =+IF((L18+N18-K18-M18)>0,L18+N18-K18-M18,0)/Deno -> 0
C19: SUNDRY DEBTORS | F19: =0/(Deno) -> 0 | K19: =+IF((G19+I19-H19-J19>0),G19+I19-H19-J19,0) -> 0 | L19: =+IF((H19+J19-G19-I19)>0,H19+J19-G19-I19,0) -> 0 | O19: =+IF((K19+M19-L19-N19>0),K19+M19-L19-N19,0)/Deno -> 0 | P19: =+IF((L19+N19-K19-M19)>0,L19+N19-K19-M19,0)/Deno -> 0
D20: OVERSEAS DEBTORS - FREIGHT FORWARDING | E20: =129065551.851325/(Deno) -> 1290.6555 | F20: =0/(Deno) -> 0 | G20: 1.2906555e+08 | H20: 0 | I20: 0 | J20: 855729.83 | K20: =+IF((G20+I20-H20-J20>0),G20+I20-H20-J20,0) -> 1.2820982e+08 | L20: =+IF((H20+J20-G20-I20)>0,H20+J20-G20-I20,0) -> 0 | M20: =+'Audit entry'!D122 -> 4081269.3 | O20: =+IF((K20+M20-L20-N20>0),K20+M20-L20-N20,0)/Deno -> 1322.9109 | P20: =+IF((L20+N20-K20-M20)>0,L20+N20-K20-M20,0)/Deno -> 0 | R20: 11 | S20: Trade Receivable
D21: LOCAL DEBTORS - FREIGHT FORWARDING | E21: =0/(Deno) -> 0 | F21: =65357815.8800001/(Deno) -> 653.57816 | G21: 0 | H21: 65357816 | I21: 36471481 | J21: 0 | K21: =+IF((G21+I21-H21-J21>0),G21+I21-H21-J21,0) -> 0 | L21: =+IF((H21+J21-G21-I21)>0,H21+J21-G21-I21,0) -> 28886335 | N21: =SUM('Audit entry'!E64:E83)-SUM('Audit entry'!D60:D83)+SUM('Audit entry'!E89:E97)-SUM('Audit entry'!D86:D87) -> 3171028.9 | O21: =+IF((K21+M21-L21-N21>0),K21+M21-L21-N21,0)/Deno -> 0 | P21: =+IF((L21+N21-K21-M21)>0,L21+N21-K21-M21,0)/Deno -> 320.57364 | R21: 11 | S21: Trade Receivable
C22: CASH AND BANK BALANCE | E22: =0/(Deno) -> 0 | F22: =0/(Deno) -> 0 | K22: =+IF((G22+I22-H22-J22>0),G22+I22-H22-J22,0) -> 0 | L22: =+IF((H22+J22-G22-I22)>0,H22+J22-G22-I22,0) -> 0 | O22: =+IF((K22+M22-L22-N22>0),K22+M22-L22-N22,0)/Deno -> 0 | P22: =+IF((L22+N22-K22-M22)>0,L22+N22-K22-M22,0)/Deno -> 0
D23: CASH IN HAND | E23: =371979.04/(Deno) -> 3.7197904 | F23: =0/(Deno) -> 0 | G23: 371979.04 | H23: 0 | I23: 0 | J23: 0 | K23: =+IF((G23+I23-H23-J23>0),G23+I23-H23-J23,0) -> 371979.04 | L23: =+IF((H23+J23-G23-I23)>0,H23+J23-G23-I23,0) -> 0 | N23: ='Audit entry'!E138+'Audit entry'!E142 -> 371979.04 | O23: =+IF((K23+M23-L23-N23>0),K23+M23-L23-N23,0)/Deno -> 0 | P23: =+IF((L23+N23-K23-M23)>0,L23+N23-K23-M23,0)/Deno -> 0 | Q23: Cash in hand | R23: 12 | S23: Cash and cash equivalents
D24: BANK BALANCE LOCAL CURRENCY | E24: =3691589.10000008/(Deno) -> 36.915891 | F24: =0/(Deno) -> 0 | G24: 3691589.1 | H24: 0 | I24: 17744544 | J24: 0 | K24: =+IF((G24+I24-H24-J24>0),G24+I24-H24-J24,0) -> 21436133 | L24: =+IF((H24+J24-G24-I24)>0,H24+J24-G24-I24,0) -> 0 | O24: =+IF((K24+M24-L24-N24>0),K24+M24-L24-N24,0)/Deno -> 214.36133 | P24: =+IF((L24+N24-K24-M24)>0,L24+N24-K24-M24,0)/Deno -> 0 | Q24: Cash at Bank - Local Currency | R24: 12 | S24: Cash and cash equivalents
D25: FIXED DEPOSIT IN BANK | E25: =500000/(Deno) -> 5 | F25: =0/(Deno) -> 0 | G25: 500000 | H25: 0 | I25: 0 | J25: 500000 | K25: =+IF((G25+I25-H25-J25>0),G25+I25-H25-J25,0) -> 0 | L25: =+IF((H25+J25-G25-I25)>0,H25+J25-G25-I25,0) -> 0 | O25: =+IF((K25+M25-L25-N25>0),K25+M25-L25-N25,0)/Deno -> 0 | P25: =+IF((L25+N25-K25-M25)>0,L25+N25-K25-M25,0)/Deno -> 0 | Q25: Cash at Bank - Local Currency | R25: 12 | S25: Cash and cash equivalents
D26: MAA PETTY CASH | E26: =7465/(Deno) -> 0.07465 | F26: =0/(Deno) -> 0 | G26: 7465 | H26: 0 | I26: 0 | J26: 7452 | K26: =+IF((G26+I26-H26-J26>0),G26+I26-H26-J26,0) -> 13 | L26: =+IF((H26+J26-G26-I26)>0,H26+J26-G26-I26,0) -> 0 | M26: ='Audit entry'!D137 -> 5148 | O26: =+IF((K26+M26-L26-N26>0),K26+M26-L26-N26,0)/Deno -> 0.05161 | P26: =+IF((L26+N26-K26-M26)>0,L26+N26-K26-M26,0)/Deno -> 0 | Q26: Petty Cash | R26: 12 | S26: Cash and cash equivalents
D27: AIRPORT PETTY CASH | E27: =0/(Deno) -> 0 | F27: =0/(Deno) -> 0 | G27: 0 | H27: 0 | I27: 0 | J27: 0 | K27: =+IF((G27+I27-H27-J27>0),G27+I27-H27-J27,0) -> 0 | L27: =+IF((H27+J27-G27-I27)>0,H27+J27-G27-I27,0) -> 0 | O27: =+IF((K27+M27-L27-N27>0),K27+M27-L27-N27,0)/Deno -> 0 | P27: =+IF((L27+N27-K27-M27)>0,L27+N27-K27-M27,0)/Deno -> 0 | Q27: Petty Cash | R27: 12 | S27: Cash and cash equivalents
D28: BANK BALANCE OVERSEAS CURRENCY | E28: =1494951.55499099/(Deno) -> 14.949516 | F28: =0/(Deno) -> 0 | G28: 1494951.6 | H28: 0 | I28: 0 | J28: 1253840.1 | K28: =+IF((G28+I28-H28-J28>0),G28+I28-H28-J28,0) -> 241111.49 | L28: =+IF((H28+J28-G28-I28)>0,H28+J28-G28-I28,0) -> 0 | O28: =+IF((K28+M28-L28-N28>0),K28+M28-L28-N28,0)/Deno -> 2.4111149 | P28: =+IF((L28+N28-K28-M28)>0,L28+N28-K28-M28,0)/Deno -> 0 | Q28: Cash at Bank - Foreign Currency | R28: 12 | S28: Cash and cash equivalents
D29: ATM CASH W/D | E29: =0/(Deno) -> 0 | F29: =0/(Deno) -> 0 | G29: 0 | H29: 0 | I29: 0 | J29: 0 | K29: =+IF((G29+I29-H29-J29>0),G29+I29-H29-J29,0) -> 0 | L29: =+IF((H29+J29-G29-I29)>0,H29+J29-G29-I29,0) -> 0 | O29: =+IF((K29+M29-L29-N29>0),K29+M29-L29-N29,0)/Deno -> 0 | P29: =+IF((L29+N29-K29-M29)>0,L29+N29-K29-M29,0)/Deno -> 0 | Q29: Cash in hand | R29: 12 | S29: Cash and cash equivalents
D30: INTER BANK ACCOUNT TRANSFER | E30: =0/(Deno) -> 0 | F30: =0/(Deno) -> 0 | G30: 0 | H30: 0 | I30: 0 | J30: 0 | K30: =+IF((G30+I30-H30-J30>0),G30+I30-H30-J30,0) -> 0 | L30: =+IF((H30+J30-G30-I30)>0,H30+J30-G30-I30,0) -> 0 | O30: =+IF((K30+M30-L30-N30>0),K30+M30-L30-N30,0)/Deno -> 0 | P30: =+IF((L30+N30-K30-M30)>0,L30+N30-K30-M30,0)/Deno -> 0 | Q30: Cash at Bank - Local Currency | R30: 12 | S30: Cash and cash equivalents
D31: SECURITY DEPOSIT | E31: =0/(Deno) -> 0 | F31: =0/(Deno) -> 0 | G31: 0 | H31: 0 | I31: 0 | J31: 0 | K31: =+IF((G31+I31-H31-J31>0),G31+I31-H31-J31,0) -> 0 | L31: =+IF((H31+J31-G31-I31)>0,H31+J31-G31-I31,0) -> 0 | O31: =+IF((K31+M31-L31-N31>0),K31+M31-L31-N31,0)/Deno -> 0 | P31: =+IF((L31+N31-K31-M31)>0,L31+N31-K31-M31,0)/Deno -> 0 | Q31: Security Deposit | R31: 12 | S31: Cash and cash equivalents
D32: TUT PETTY CASH | E32: =1988/(Deno) -> 0.01988 | F32: =0/(Deno) -> 0 | G32: 1988 | H32: 0 | I32: 0 | J32: 0 | K32: =+IF((G32+I32-H32-J32>0),G32+I32-H32-J32,0) -> 1988 | L32: =+IF((H32+J32-G32-I32)>0,H32+J32-G32-I32,0) -> 0 | O32: =+IF((K32+M32-L32-N32>0),K32+M32-L32-N32,0)/Deno -> 0.01988 | P32: =+IF((L32+N32-K32-M32)>0,L32+N32-K32-M32,0)/Deno -> 0 | Q32: Petty Cash | R32: 12 | S32: Cash and cash equivalents
D33: HYD PETTY CASH | E33: =0/(Deno) -> 0 | F33: =2993.62/(Deno) -> 0.0299362 | G33: 0 | H33: 2993.62 | I33: 11684.77 | J33: 0 | K33: =+IF((G33+I33-H33-J33>0),G33+I33-H33-J33,0) -> 8691.15 | L33: =+IF((H33+J33-G33-I33)>0,H33+J33-G33-I33,0) -> 0 | O33: =+IF((K33+M33-L33-N33>0),K33+M33-L33-N33,0)/Deno -> 0.0869115 | P33: =+IF((L33+N33-K33-M33)>0,L33+N33-K33-M33,0)/Deno -> 0 | Q33: Petty Cash | R33: 12 | S33: Cash and cash equivalents
D34: BLR PETTY CASH | E34: =0/(Deno) -> 0 | F34: =0/(Deno) -> 0 | G34: 0 | H34: 0 | I34: 0 | J34: 0 | K34: =+IF((G34+I34-H34-J34>0),G34+I34-H34-J34,0) -> 0 | L34: =+IF((H34+J34-G34-I34)>0,H34+J34-G34-I34,0) -> 0 | O34: =+IF((K34+M34-L34-N34>0),K34+M34-L34-N34,0)/Deno -> 0 | P34: =+IF((L34+N34-K34-M34)>0,L34+N34-K34-M34,0)/Deno -> 0 | Q34: Petty Cash | R34: 12 | S34: Cash and cash equivalents
D35: CBE PETTY CASH | E35: =2590.5/(Deno) -> 0.025905 | F35: =0/(Deno) -> 0 | G35: 2590.5 | H35: 0 | I35: 0 | J35: 2131 | K35: =+IF((G35+I35-H35-J35>0),G35+I35-H35-J35,0) -> 459.5 | L35: =+IF((H35+J35-G35-I35)>0,H35+J35-G35-I35,0) -> 0 | O35: =+IF((K35+M35-L35-N35>0),K35+M35-L35-N35,0)/Deno -> 0.004595 | P35: =+IF((L35+N35-K35-M35)>0,L35+N35-K35-M35,0)/Deno -> 0 | Q35: Petty Cash | R35: 12 | S35: Cash and cash equivalents
C36: WORK IN PROGRESS JOBS | E36: =0/(Deno) -> 0 | F36: =0/(Deno) -> 0 | K36: =+IF((G36+I36-H36-J36>0),G36+I36-H36-J36,0) -> 0 | L36: =+IF((H36+J36-G36-I36)>0,H36+J36-G36-I36,0) -> 0 | O36: =+IF((K36+M36-L36-N36>0),K36+M36-L36-N36,0)/Deno -> 0 | P36: =+IF((L36+N36-K36-M36)>0,L36+N36-K36-M36,0)/Deno -> 0
D37: WORK IN PROGRESS JOBS | E37: =0/(Deno) -> 0 | F37: =0/(Deno) -> 0 | G37: 0 | H37: 0 | I37: 0 | J37: 0 | K37: =+IF((G37+I37-H37-J37>0),G37+I37-H37-J37,0) -> 0 | L37: =+IF((H37+J37-G37-I37)>0,H37+J37-G37-I37,0) -> 0 | O37: =+IF((K37+M37-L37-N37>0),K37+M37-L37-N37,0)/Deno -> 0 | P37: =+IF((L37+N37-K37-M37)>0,L37+N37-K37-M37,0)/Deno -> 0 | Q37: Unbilled Income | R37: 13 | S37: Short-term loans and advances
D38: WORK IN PROGRESS JOBS REV | E38: =0/(Deno) -> 0 | F38: =0/(Deno) -> 0 | G38: 0 | H38: 0 | I38: 0 | J38: 0 | K38: =+IF((G38+I38-H38-J38>0),G38+I38-H38-J38,0) -> 0 | L38: =+IF((H38+J38-G38-I38)>0,H38+J38-G38-I38,0) -> 0 | O38: =+IF((K38+M38-L38-N38>0),K38+M38-L38-N38,0)/Deno -> 0 | P38: =+IF((L38+N38-K38-M38)>0,L38+N38-K38-M38,0)/Deno -> 0 | Q38: Unbilled Income | R38: 13 | S38: Short-term loans and advances
C39: ACCRUALS | E39: =0/(Deno) -> 0 | F39: =0/(Deno) -> 0 | K39: =+IF((G39+I39-H39-J39>0),G39+I39-H39-J39,0) -> 0 | L39: =+IF((H39+J39-G39-I39)>0,H39+J39-G39-I39,0) -> 0 | O39: =+IF((K39+M39-L39-N39>0),K39+M39-L39-N39,0)/Deno -> 0 | P39: =+IF((L39+N39-K39-M39)>0,L39+N39-K39-M39,0)/Deno -> 0
D40: PREPAID INTERNET EXPESES | E40: =0/(Deno) -> 0 | F40: =0/(Deno) -> 0 | G40: 0 | H40: 0 | I40: 0 | J40: 0 | K40: =+IF((G40+I40-H40-J40>0),G40+I40-H40-J40,0) -> 0 | L40: =+IF((H40+J40-G40-I40)>0,H40+J40-G40-I40,0) -> 0 | O40: =+IF((K40+M40-L40-N40>0),K40+M40-L40-N40,0)/Deno -> 0 | P40: =+IF((L40+N40-K40-M40)>0,L40+N40-K40-M40,0)/Deno -> 0 | Q40: Prepaid Expenses | R40: 13 | S40: Short-term loans and advances
...

Sheet BS
A1: CARGO INTERNATIONAL (INDIA) PRIVATE LIMITED
A2: BALANCE SHEET AS AT 31ST MARCH, 2025
A3: CIN : U63000TN2010PTC077296
A4: Old No.7 / New No.13, First Floor, First Cross Street, Trustpuram, Kodambakkam, Chennai - 600024, India
A5: =+"(Unless otherwise specified, all amounts are "&IF('Master data'!A2="Ones","Indian Rupees","in "&'Master data'!A2&" of INR)") -> (Unless otherwise specified, all amounts are in Lakhs of INR)
A6: Particulars | B6: Note No. | C6: As on | D6: As on
C7: 31st March, 2025 | D7: 31st March, 2024
A9: I.EQUITY AND LIABILITIES | F9: +RC[-2]*100000 | G9: +RC[-2]*100000
A10: SHARE HOLDERS FUNDS | F10: +RC[-2]*100000 | G10: +RC[-2]*100000
A11: a. Share capital | B11: 3 | C11: =+'NOTE 3'!D15 -> 2 | D11: =+'NOTE 3'!E15 -> 2 | F11: +RC[-2]*100000
A12: b. Reserve and surplus | B12: 4 | C12: =+'NOTE 4-8'!B15 -> 197.74662 | D12: =+'NOTE 4-8'!C15 -> 37.069193 | E12: =+C12*100000 -> 19774662 | F12: +RC[-2]*100000 | G12: +RC[-2]*100000
C13: =SUM(C11:C12) -> 199.74662 | D13: =SUM(D11:D12) -> 39.069193 | E13: =+C13*100000 -> 19974662 | F13: +RC[-2]*100000 | G13: +RC[-2]*100000
A14: NON CURRENT LIABILITIES | E14: =+C14*100000 -> 0 | F14: +RC[-2]*100000 | G14: +RC[-2]*100000
A15: a. Other Long term Liabilities | B15: 5 | C15: =+'NOTE 4-8'!B20 -> 148.44185 | D15: =+'NOTE 4-8'!C20 -> 148.44185 | E15: =+C15*100000 -> 14844185 | F15: +RC[-2]*100000 | G15: +RC[-2]*100000
C16: =+C15 -> 148.44185 | D16: =+D15 -> 148.44185 | E16: =+C16*100000 -> 14844185 | F16: +RC[-2]*100000 | G16: +RC[-2]*100000
A17: CURRENT LIABILITIES | E17: =+C17*100000 -> 0 | F17: +RC[-2]*100000 | G17: +RC[-2]*100000
A18: a. Trade payables | B18: 6 | E18: =+C18*100000 -> 0 | F18: +RC[-2]*100000 | G18: +RC[-2]*100000
A19: i. Outstanding due against MSME | C19: =+'NOTE 6'!G12 -> 0 | D19: =+'NOTE 6'!G24 -> 0 | E19: =+C19*100000 -> 0 | F19: +RC[-2]*100000 | G19: +RC[-2]*100000
A20: ii.Outstanding due against Other than MSME | C20: =+'NOTE 6'!G17 -> 904.28354 | D20: =+SUM('NOTE 6'!G25:G27) -> 464.57415 | E20: =+C20*100000 -> 90428354 | F20: +RC[-2]*100000 | G20: +RC[-2]*100000
A21: b. Other current liabilities | B21: 7 | C21: =+'NOTE 4-8'!B28 -> 89.501951 | D21: =+'NOTE 4-8'!C28 -> 32.999611 | E21: =+C21*100000 -> 8950195.1 | F21: +RC[-2]*100000 | G21: +RC[-2]*100000 | K21: Regroupping Reconciliation
A22: c. Short term provisions | B22: 8 | C22: =+'NOTE 4-8'!B36 -> 67.553088 | D22: =+'NOTE 4-8'!C36 -> 204.8198 | E22: =+C22*100000 -> 6755308.8 | F22: +RC[-2]*100000 | G22: +RC[-2]*100000 | K22: Particulars | L22: Debit | M22: Credit | N22: Variance
C23: =SUM(C18:C22) -> 1061.3386 | D23: =SUM(D18:D22) -> 702.39356 | E23: =+C23*100000 -> 1.0613386e+08 | F23: +RC[-2]*100000 | G23: +RC[-2]*100000 | K23: As per Financials
E24: =+C24*100000 -> 0 | F24: +RC[-2]*100000 | G24: +RC[-2]*100000 | K24: TR | L24: 88995355 | M24: 0 | P24: 53379604 | Q24: 35615751 | R24: =+P24+Q24 -> 88995355 | S24: =+L24-R24 -> -0.001905784
A25: TOTAL | C25: =C13+C16+C23 -> 1409.527 | D25: =D13+D16+D23 -> 889.9046 | E25: =+C25*100000 -> 1.409527e+08 | F25: +RC[-2]*100000 | G25: +RC[-2]*100000 | K25: TP | L25: 0 | M25: 84505304 | P25: 46457415 | Q25: 38055623 | R25: =+P25+Q25 -> 84513038 | S25: =+M25-R25 -> -7734.002
E26: =+C26*100000 -> 0 | F26: +RC[-2]*100000 | G26: +RC[-2]*100000 | K26: AP/AR | L26: 0 | M26: =+'NOTE 4-8'!B34 -> 0.032858 | P26: 14467305 | Q26: 380165.39 | R26: =+P26+Q26 -> 14847471 | S26: =+M26-R26 -> -14847471
A27: II.ASSETS | E27: =+C27*100000 -> 0 | F27: +RC[-2]*100000 | G27: +RC[-2]*100000 | K27: Provision for Operation | L27: 0 | M27: =+'NOTE 4-8'!B33 -> 0
A28: NON-CURRENT ASSETS | E28: =+C28*100000 -> 0 | F28: +RC[-2]*100000 | G28: +RC[-2]*100000 | K28: Total | L28: =SUM(L24:L27) -> 88995355 | M28: =SUM(M24:M27) -> 84505304 | N28: =+L28-M28 -> 4490051
A29: a. Property, Plant & Equipment | B29: 9 | E29: =+C29*100000 -> 0 | F29: +RC[-2]*100000 | G29: +RC[-2]*100000 | K29: As per TB
A30: (i) Tangible assets | C30: =+'Note 9'!J20 -> 7.3320925 | D30: =+'Note 9'!K20 -> 9.1414207 | E30: =+C30*100000 -> 733209.25 | F30: +RC[-2]*100000 | G30: +RC[-2]*100000 | K30: TR | L30: =+'TB 24-25'!O20-'TB 24-25'!P21 -> 1002.3373 | M30: 0 | P30: 63707736 | Q30: 35615751 | R30: =+P30+Q30 -> 99323487 | S30: =+L30-R30 -> -99322485
C31: =SUM(C30:C30) -> 7.3320925 | D31: =SUM(D30:D30) -> 9.1414207 | E31: =+C31*100000 -> 733209.25 | F31: +RC[-2]*100000 | G31: +RC[-2]*100000 | K31: TP | L31: 0 | M31: =+SUM('TB 24-25'!P87:P90)-'TB 24-25'!O89 -> 1013.2276 | P31: 57351825 | Q31: 38055623 | R31: =+P31+Q31 -> 95407447 | S31: =+M31-R31 -> -95406434
E32: =+C32*100000 -> 0 | F32: +RC[-2]*100000 | G32: +RC[-2]*100000 | K32: AP/AR | L32: 0 | M32: =+'TB 24-25'!P58-'TB 24-25'!O65 -> 142.81192 | P32: 13901027 | Q32: 380165.39 | R32: =+P32+Q32 -> 14281192 | S32: =+M32-R32 -> -14281049
A33: b. Long-term loans and advances | B33: 10 | C33: =+'NOTE 10-14'!B12 -> 227.83878 | D33: =+'NOTE 10-14'!C12 -> 204.82732 | E33: =+C33*100000 -> 22783878 | F33: +RC[-2]*100000 | G33: +RC[-2]*100000 | K33: Provision for Operation | L33: 0 | M33: =+'TB 24-25'!P142 -> 0
A34: c. Deffered Tax Assets | B34: 11 | C34: =+'NOTE 10-14'!B18 -> 5.9743601 | D34: =+'NOTE 10-14'!C18 -> 6.349577 | E34: =+C34*100000 -> 597436.01 | F34: +RC[-2]*100000 | G34: +RC[-2]*100000 | K34: Total | L34: =SUM(L30:L33) -> 1002.3373 | M34: =SUM(M30:M33) -> 1156.0396 | N34: =+L34-M34 -> -153.70228
B35: 0 | C35: =+C33+C34 -> 233.81314 | D35: =D33+D34 -> 211.1769 | E35: =+C35*100000 -> 23381314 | F35: =+D35*100000 -> 21117690 | N35: =+N28-N34 -> 4490204.7
A36: CURRENT ASSETS | E36: =+C36*100000 -> 0 | F36: =+D36*100000 -> 0 | N36: =+N35*Deno -> 4.4902047e+11
A37: a. Trade receivables | B37: 12 | C37: =+'NOTE 12'!G18 -> 899.05595 | D37: =+'NOTE 12'!G30 -> 533.79604 | E37: =+C37*100000 -> 89905595 | F37: =+D37*100000 -> 53379604
A38: b. cash and cash equivalents | B38: 13 | C38: =+'NOTE 10-14'!B24+(1.99/Deno) -> 216.93546 | D38: =+'NOTE 10-14'!C24+(1.99/Deno) -> 61.175716 | E38: =+C38*100000 -> 21693546 | F38: =+D38*100000 -> 6117571.6
A39: c. Short-term loans and advances | B39: 14 | C39: =+'NOTE 10-14'!B31 -> 52.3904 | D39: =+'NOTE 10-14'!C31 -> 74.614539 | E39: =+C39*100000 -> 5239040 | F39: =+D39*100000 -> 7461453.9
C40: =SUM(C37:C39) -> 1168.3818 | D40: =SUM(D37:D39) -> 669.58629 | E40: =+C40*100000 -> 1.1683818e+08 | F40: =+D40*100000 -> 66958629
E41: =+C41*100000 -> 0 | F41: =+D41*100000 -> 0
...

Sheet PL
A1: CARGO INTERNATIONAL (INDIA) PRIVATE LIMITED
A2: STATEMENT OF PROFIT AND LOSS FOR YEAR ENDED 31ST MARCH, 2025
A3: CIN: U63000TN2010PTC077296
A4: =+BS!A4 -> Old No.7 / New No.13, First Floor, First Cross Street, Trustpuram, Kodambakkam, Chennai - 600024, India
A5: =+"(Unless otherwise specified, all amounts are "&IF('Master data'!A2="Ones","Indian Rupees","in "&'Master data'!A2&" of INR)") -> (Unless otherwise specified, all amounts are in Lakhs of INR)
A6: Particulars | C6: Note | D6: For Year Ended | E6: For Year Ended
D7: 45747 | E7: 45382
A9: I | B9: Revenue from Operation | C9: 15 | D9: ='NOTE 15-20'!B14 -> 2510.5688 | E9: ='NOTE 15-20'!C14 -> 1484.7668 | F9: =+D9*100000 -> 2.5105688e+08 | G9: =+E9*100000 -> 1.4847668e+08
A10: II | B10: Other Income | C10: 16 | D10: ='NOTE 15-20'!B20 -> 62.750698 | E10: ='NOTE 15-20'!C20 -> 46.56197 | F10: =+D10*100000 -> 6275069.8 | G10: =+E10*100000 -> 4656197
F11: =+D11*100000 -> 0
A12: III | B12: TOTAL | D12: =SUM(D9:D11) -> 2573.3195 | E12: =SUM(E9:E11) -> 1531.3288 | F12: =+D12*100000 -> 2.5733195e+08 | G12: =+E12*100000 -> 1.5313288e+08
F13: =+D13*100000 -> 0 | G13: =+E13*100000 -> 0
A14: IV | B14: EXPENSES | F14: =+D14*100000 -> 0 | G14: =+E14*100000 -> 0
B15: Operating expenses | C15: 17 | D15: ='NOTE 15-20'!B28 -> 2153.6675 | E15: ='NOTE 15-20'!C28 -> 1216.7373 | F15: =+D15*100000 -> 2.1536675e+08 | G15: =+E15*100000 -> 1.2167373e+08
B16: Employee Benefit Expenses | C16: 18 | D16: ='NOTE 15-20'!B34 -> 230.47531 | E16: ='NOTE 15-20'!C34 -> 220.628 | F16: =+D16*100000 -> 23047531 | G16: =+E16*100000 -> 22062800
B17: Finance cost | C17: 19 | D17: =+'NOTE 15-20'!B41 -> 2.664397 | E17: =+'NOTE 15-20'!C41 -> 1.879493 | F17: =+D17*100000 -> 266439.7 | G17: =+E17*100000 -> 187949.3
B18: Administrative expenses | C18: 20 | D18: ='NOTE 15-20'!B57 -> 157.28139 | E18: ='NOTE 15-20'!C57 -> 138.65936 | F18: =+D18*100000 -> 15728139 | G18: =+E18*100000 -> 13865936
B19: Depreciation | C19: 9 | D19: =+'Note 9'!G20 -> 2.6989893 | E19: =+'Note 9'!G22 -> 3.3532017 | F19: =+D19*100000 -> 269898.93 | G19: =+E19*100000 -> 335320.17
F20: =+D20*100000 -> 0 | G20: =+E20*100000 -> 0
A21: V | B21: TOTAL | D21: =SUM(D15:D20) -> 2546.7876 | E21: =SUM(E15:E20) -> 1581.2573 | F21: =+D21*100000 -> 2.5467876e+08 | G21: =+E21*100000 -> 1.5812573e+08
F22: =+D22*100000 -> 0 | G22: =+E22*100000 -> 0
A23: VI | B23: Profit before exceptional and extraordinary item and tax (III - V) | D23: =D12-D21 -> 26.531903 | E23: =E12-E21 -> -49.928502 | F23: =+D23*100000 -> 2653190.3 | G23: =+E23*100000 -> -4992850.2
F24: =+D24*100000 -> 0 | G24: =+E24*100000 -> 0
A25: VII | B25: Exceptional items/extra-ordinary items | D25: 0 | E25: 0 | F25: =+D25*100000 -> 0 | G25: =+E25*100000 -> 0
F26: =+D26*100000 -> 0 | G26: =+E26*100000 -> 0
A27: VIII | B27: Profit before extra-ordinary item and tax (VI - VII) | D27: =D23-D25 -> 26.531903 | E27: =E23-E25 -> -49.928502 | F27: =+D27*100000 -> 2653190.3 | G27: =+E27*100000 -> -4992850.2
F28: =+D28*100000 -> 0 | G28: =+E28*100000 -> 0
A29: IX | B29: Profit before tax (VIII) | D29: =D27 -> 26.531903 | E29: =E27 -> -49.928502 | F29: =+D29*100000 -> 2653190.3 | G29: =+E29*100000 -> -4992850.2
A30: X | B30: Tax expenses | F30: =+D30*100000 -> 0 | G30: =+E30*100000 -> 0
B31: (1) Current Tax | D31: =+'Audit entry'!D148/Deno -> 6.5476249 | E31: 0 | F31: =+D31*100000 -> 654762.49 | G31: =+E31*100000 -> 0
B32: (2) Deferred Tax | D32: =-'Audit entry'!D31 -> -0.37521685 | E32: =-28240.312/Deno -> -0.28240312 | F32: =+D32*100000 -> -37521.685 | G32: =+E32*100000 -> -28240.312
B33: Prior period items | F33: =+D33*100000 -> 0 | G33: =+E33*100000 -> 0
A34: XI | B34: Profit/(Loss) for the period from continuing operation (IX-X) | D34: =D29-D31+D32+D33 -> 19.609062 | E34: =E29-E31+E32+E33 -> -50.210905 | F34: =+D34*100000 -> 1960906.2 | G34: =+E34*100000 -> -5021090.5
A36: XII | B36: EPS
B37: Basic | D37: =+(D34/'NOTE 3'!D40)*Deno -> 98.045308 | E37: =+(E34/'NOTE 3'!D30)*Deno -> -251.07963
B38: Diluted | D38: =+D37 -> 98.045308 | E38: =+E37 -> -251.07963
A40: =BS!A44 -> Significant Accounting Policies in Note 1 & 2
A41: The accompanying notes are integral part of the financial statements
A43: As per our report of even date | C43: For and on behalf of
A44: For Kalyanasundaram & Associates | C44: =+BS!B48 -> CARGO INTERNATIONAL (INDIA) PVT. LTD
...

Sheet CFS
A1: =+PL!A1 -> CARGO INTERNATIONAL (INDIA) PRIVATE LIMITED
A2: CASH FLOW STATEMENT FOR THE YEAR ENDED ON 31ST MARCH 2025
A3: CIN: U63000TN2010PTC077296
A4: =+PL!A4 -> Old No.7 / New No.13, First Floor, First Cross Street, Trustpuram, Kodambakkam, Chennai - 600024, India
A5: =+"(Unless otherwise specified, all amounts are "&IF('Master data'!A2="Ones","Indian Rupees","in "&'Master data'!A2&" of INR)") -> (Unless otherwise specified, all amounts are in Lakhs of INR)
A6: Particulars | C6: For Year Ended | D6: For Year Ended
C7: 45747 | D7: 45382
A9: [A] Cash Flow from Operating Activities:
A11: Profit before Tax | C11: =+PL!D27 -> 26.531903 | D11: =+PL!E27 -> -49.928502 | E11: =+C11*100000 -> 2653190.3 | F11: =+D11*100000 -> -4992850.2
A12: Adjustments for non cash items & Non operating activity: | E12: =+C12*100000 -> 0 | F12: =+D12*100000 -> 0
A13: Depreciation | C13: =+PL!D19 -> 2.6989893 | D13: =+PL!E19 -> 3.3532017 | E13: =+C13*100000 -> 269898.93 | F13: =+D13*100000 -> 335320.17
A14: GST Input reversal | C14: =+'NOTE 4-8'!B12 -> 0 | D14: =-14902244.9/Deno -> -149.02245 | E14: =+C14*100000 -> 0 | F14: =+D14*100000 -> -14902245
A15: Provision Operation reversal | C15: =+'NOTE 4-8'!B13 -> 141.06836 | E15: =+C15*100000 -> 14106836 | F15: =+D15*100000 -> 0
A16: Interest & Finance Charges | C16: =+PL!D17 -> 2.664397 | D16: =+PL!E17 -> 1.879493 | E16: =+C16*100000 -> 266439.7 | F16: =+D16*100000 -> 187949.3
A17: Operating Profit before Working Capital changes | C17: =SUM(C11:C16) -> 172.96365 | D17: =SUM(D11:D16) -> -193.71826 | E17: =+C17*100000 -> 17296365 | F17: =+D17*100000 -> -19371826
E18: =+C18*100000 -> 0 | F18: =+D18*100000 -> 0
A19: Adjusted for : | E19: =+C19*100000 -> 0 | F19: =+D19*100000 -> 0
A20: (Increase)/Decrease in Loans & Advances | C20: =-BS!C39+BS!D39 -> 22.224139 | D20: =11919207.85/Deno -> 119.19208 | E20: =+C20*100000 -> 2222413.9 | F20: =+D20*100000 -> 11919208
A21: (Increase)/Decrease in Sundry Debtors | C21: =-BS!C37+BS!D37 -> -365.25991 | D21: =-2879939.29/Deno -> -28.799393 | E21: =+C21*100000 -> -36525991 | F21: =+D21*100000 -> -2879939.3
A22: Increase/(Decrease) in Current liabilities | C22: =+BS!C23-BS!D23 -> 358.94501 | D22: =12411981.16/Deno -> 124.11981 | E22: =+C22*100000 -> 35894501 | F22: =+D22*100000 -> 12411981
E23: =+C23*100000 -> 0 | F23: =+D23*100000 -> 0
A24: Current year Tax: | C24: =-PL!D31 -> -6.5476249 | D24: =-PL!E31 -> 0 | E24: =+C24*100000 -> -654762.49 | F24: =+D24*100000 -> 0
E25: =+C25*100000 -> 0 | F25: =+D25*100000 -> 0
A26: Net Cash from Operating Activities | C26: =SUM(C17:C24) -> 182.32527 | D26: =SUM(D17:D24) -> 20.794241 | E26: =+C26*100000 -> 18232527 | F26: =+D26*100000 -> 2079424.1
E27: =+C27*100000 -> 0 | F27: =+D27*100000 -> 0
A28: [B] Cash flow from Investing Activities | E28: =+C28*100000 -> 0 | F28: =+D28*100000 -> 0
A29: Additions to fixed assets | C29: =-'Note 9'!C20+'Note 9'!D20 -> -0.8896611 | D29: =-56567.79/Deno -> -0.5656779 | E29: =+C29*100000 -> -88966.11 | F29: =+D29*100000 -> -56567.79
A30: Increase in Long term loans and advances | C30: =-BS!C33+BS!D33 -> -23.011459 | D30: =-2434939.76/Deno -> -24.349398 | E30: =+C30*100000 -> -2301145.9 | F30: =+D30*100000 -> -2434939.8
A31: Net cash from/(used in) investing activities | C31: =SUM(C29:C30) -> -23.90112 | D31: =SUM(D29:D30) -> -24.915075 | E31: =+C31*100000 -> -2390112 | F31: =+D31*100000 -> -2491507.5
E32: =+C32*100000 -> 0 | F32: =+D32*100000 -> 0
A33: [C] Cash flow from Financing Activities | E33: =+C33*100000 -> 0 | F33: =+D33*100000 -> 0
A34: Interest & Finance Charges | C34: =-C16 -> -2.664397 | D34: =-D16 -> -1.879493 | E34: =+C34*100000 -> -266439.7 | F34: =+D34*100000 -> -187949.3
E35: =+C35*100000 -> 0 | F35: =+D35*100000 -> 0
A36: Net cash from/(used in) Financing activities | C36: =SUM(C34:C35) -> -2.664397 | D36: =SUM(D34:D35) -> -1.879493 | E36: =+C36*100000 -> -266439.7 | F36: =+D36*100000 -> -187949.3
E37: =+C37*100000 -> 0 | F37: =+D37*100000 -> 0
A38: Net Cash flow during the year [A + B + C] | C38: =C26+C31+C36 -> 155.75975 | D38: =D26+D31+D36 -> -6.0003275 | E38: =+C38*100000 -> 15575975 | F38: =+D38*100000 -> -600032.75
E39: =+C39*100000 -> 0 | F39: =+D39*100000 -> 0
A40: Cash & Cash equivalents (Opening Balance) | C40: =+D41 -> 61.175716 | D40: =6717604.32/Deno -> 67.176043 | E40: =+C40*100000 -> 6117571.6 | F40: =+D40*100000 -> 6717604.3
A41: Cash & Cash equivalents (Closing Balance) | C41: =+BS!C38 -> 216.93546 | D41: =+BS!D38 -> 61.175716 | E41: =+C41*100000 -> 21693546 | F41: =+D41*100000 -> 6117571.6
E42: =+C42*100000 -> 0 | F42: =+D42*100000 -> 0
...

Sheet Note 1-2
A1: CARGO INTERNATIONAL (INDIA) PRIVATE LIMITED
A2: NOTES TO THE FINANCIAL STATEMENTS FOR THE YEAR ENDED 31st MARCH, 2025
A3: CAPITAL TOWERS, NO.G-3/1, G-3/2 & G-2 DOOR NO.180 KODAMBAKKAM HIGH ROAD, NUNGAMBAKKAM CHENNAI 600034
A5: NOTE 1: GENERAL INFORMATION
A6: CARGO INTERNATIONAL (INDIA) PVT LTD is a Private Limited Company incorporated under the provisions of Companies Act 2013. The company is providing clearing and Forwarding services. The company is providing clearing & forwarding Transport Services to their clients through Air, Road and Sea Transport
A8: NOTE 2: SIGNIFICANT ACCOUNTING POLICIES
A9: 2.1) Basis of preparation of Financial statements:
A10: All financial transactions have been recognized on accrual basis in accordance of companies Act 2013 and Accounting Standards as adopted consistently by the company. The preparation of financial statements in conformity with the GAAP requires that the management makes estimates and assumptions that affect the reported amounts of assets and liabilities, disclosure of contingent liabilities as at the date of the financial statements and the reported amounts of revenue and expenses during the period.
A12: 2.2) Use of Estimates
A13: The preparation of financial statements requires management to make estimates and assumptions that affect the reported amount of asset and liabilities, the disclosure of contingent assets and liabilities on the date of financial statements and the reported amount of revenue and expenses during the period reported. Actual result could differ from those estimates.
A15: 2.3) Property, Plant and Equipment
A16: Property, Plant and Equipment has been accounted at their cost including all expenses such as transportation charges, installation expenses etc., incurred wholly and exclusively for the purpose of putting the assets into the use.
... A40: Contingent Assets are neither disclosed nor provided for in the financial statements.

Sheet NOTE 3
A1: CARGO INTERNATIONAL (INDIA) PRIVATE LIMITED
A2: NOTES TO THE FINANCIAL STATEMENTS FOR THE YEAR ENDED 31st MARCH, 2025
A3: =+CFS!A4 -> Old No.7 / New No.13, First Floor, First Cross Street, Trustpuram, Kodambakkam, Chennai - 600024, India
E4: =+"(Unless otherwise specified, all amounts are "&IF('Master data'!A2="Ones","Indian Rupees","in "&'Master data'!A2&" of INR)") -> (Unless otherwise specified, all amounts are in Lakhs of INR)
A5: =+'NOTE 4-8'!A5 -> Particulars | D5: As on | E5: As on
D6: 31st March, 2025 | E6: 31st March, 2024
A7: NOTE 3 : SHARE CAPITAL
A8: Authorised share capital
A9: Equity Share Capital | D9: =5000000/Deno -> 50 | E9: =5000000/Deno -> 50 | F9: =+D9*100000 -> 5000000 | G9: =+E9*100000 -> 5000000
A10: (500,000 equity shares of Rs.10 each) | F10: =+D10*100000 -> 0 | G10: =+E10*100000 -> 0
D11: =D9 -> 50 | E11: =E9 -> 50 | F11: =+D11*100000 -> 5000000 | G11: =+E11*100000 -> 5000000
A12: Issued, subscribed and paid up capital | F12: =+D12*100000 -> 0 | G12: =+E12*100000 -> 0
A13: Equity Share Capital | D13: =200000/Deno -> 2 | E13: =200000/Deno -> 2 | F13: =+D13*100000 -> 200000 | G13: =+E13*100000 -> 200000
A14: (20,000 equity shares of Rs.10 each) | F14: =+D14*100000 -> 0 | G14: =+E14*100000 -> 0
D15: =SUM(D12:D13) -> 2 | E15: =SUM(E12:E13) -> 2 | F15: =+D15*100000 -> 200000 | G15: =+E15*100000 -> 200000
A17: A. Terms and Rights attached to equity shares
A18: The company has only one class of equity shares having a par value of Rs. 10 per share. Each holder of equity share entitled to one vote per share. The company declares and pays dividend in Indian Rupees The dividend proposed by the Board of directors is subject o the approval of the shareholders in the ensuring Annual General Meeting.
A20: During the year ended 31st March 2025, the amount per share dividend recognised as distrubition to shareholders was Rs. NIL (31st march 2024 - NIL)
A23: B. Shareholders holding more than 5 percent of equity shares
A24: Name of the Shareholder | B24: =+D6 -> 31st March, 2025 | D24: =+E6 -> 31st March, 2024
B25: No. Of Shares | C25: % holding | D25: No. Of Shares | E25: % holding
A26: Suresh Padmanabhan | B26: 15998 | C26: =+B26/$B$30 -> 0.79998 | D26: 15998 | E26: =+D26/$B$30 -> 0.79998 | G26: =+D26/20000 -> 0.7999
A27: Ramkumar | B27: 2000 | C27: =+B27/$B$30 -> 0.10001 | D27: 2000 | E27: =+D27/$B$30 -> 0.10001
A28: Prasath | B28: 2000 | C28: =+B28/$B$30 -> 0.10001 | D28: 2000 | E28: =+D28/$B$30 -> 0.10001
A30: Total | B30: =SUM(B26:B29) -> 19998 | C30: =SUM(C26:C29) -> 1 | D30: =SUM(D26:D29) -> 19998 | E30: =SUM(E26:E29) -> 1
A33: C. Reconciliation of shares outstanding at the beginning and at the end of the reporting period.
A35: Particulars | B35: =+B24 -> 31st March, 2025 | D35: =+D24 -> 31st March, 2024
B36: No. Of Shares | C36: Amount | D36: No. Of Shares | E36: Amount
A37: Shares outstanding at the beginning of the year | B37: 20000 | C37: =+B37*10 -> 200000 | D37: 20000 | E37: =+D37*10 -> 200000
A38: Shares issued during the year | B38: 0 | C38: 0 | D38: 0 | E38: =+D38*10 -> 0
A39: Shares bought back during the year | B39: 0 | C39: =+B39*10 -> 0 | D39: 0 | E39: =+D39*10 -> 0
A40: Shares outstanding at the end of the year | B40: =SUM(B37:B39) -> 20000 | C40: =SUM(C37:C39) -> 200000 | D40: =SUM(D37:D39) -> 20000 | E40: =SUM(E37:E39) -> 200000
A43: D. Shares held by promoters at the end of the year
A44: Shares held by promoters at the end of the year 31st March 2025
A45: Name of the Promoter | B45: No. Of Shares | C45: Amount (Rs.) | D45: % of Total shares | E45: % Change during the year 2024
A46: Suresh Padmanabhan | B46: 15998 | C46: =+B46*10 -> 159980 | D46: =+B46/$B$50 -> 0.79998 | E46: =+(C55-C46)/C46 -> 0
A47: Ramkumar | B47: 2000 | C47: =+B47*10 -> 20000 | D47: =+B47/$B$50 -> 0.10001 | E47: =+(C56-C47)/C47 -> 0
A48: Prasath | B48: 2000 | C48: =+B48*10 -> 20000 | D48: =+B48/$B$50 -> 0.10001 | E48: =+(C57-C48)/C48 -> 0
A50: Total | B50: =SUM(B46:B48) -> 19998 | C50: =SUM(C46:C48) -> 199980 | D50: =SUM(D46:D48) -> 1
A53: Shares held by promoters at the end of the year 31st March 2024
...

Sheet NOTE 4-8
A1: =BS!A1 -> CARGO INTERNATIONAL (INDIA) PRIVATE LIMITED
A2: NOTES TO THE FINANCIAL STATEMENTS FOR THE YEAR ENDED 31st MARCH, 2025
A3: CAPITAL TOWERS, NO.G-3/1, G-3/2 & G-2 ,DOOR NO.180 KODAMBAKKAM HIGH ROAD, NUNGAMBAKKAM, CHENNAI - 600034
C4: =+"(Unless otherwise specified, all amounts are "&IF('Master data'!A2="Ones","Indian Rupees","in "&'Master data'!A2&" of INR)") -> (Unless otherwise specified, all amounts are in Lakhs of INR)
A5: Particulars | B5: As on | C5: As on
B6: 31st March, 2025 | C6: 31st March, 2024
A8: NOTE 4 : RESERVES AND SURPLUS
A9: General Reserve
A10: Opening balance | B10: =+C15 -> 37.069193 | C10: =23630254.6984153/Deno -> 236.30255 | E10: =+B10*100000 -> 3706919.3 | F10: =+C10*100000 -> 23630255
A11: Add:Net Profit/(Loss) for the current year | B11: =PL!D34 -> 19.609062 | C11: =PL!E34 -> -50.210905 | E11: =+B11*100000 -> 1960906.2 | F11: =+C11*100000 -> -5021090.5
A12: Less: GST Input reversal | B12: 0 | C12: =-14902244.9/Deno -> -149.02245 | E12: =+B12*100000 -> 0 | F12: =+C12*100000 -> -14902245
A13: Add: Provision operation reversal | B13: =+'Audit entry'!E127/Deno -> 141.06836 | E13: =+B13*100000 -> 14106836 | F13: =+C13*100000 -> 0
A14: (Refer Note. 21(9)) | E14: =+B14*100000 -> 0 | F14: =+C14*100000 -> 0
B15: =SUM(B10:B14) -> 197.74662 | C15: =SUM(C10:C14) -> 37.069193 | E15: =+B15*100000 -> 19774662 | F15: =+C15*100000 -> 3706919.3
E16: =+B16*100000 -> 0 | F16: =+C16*100000 -> 0
A17: NOTE 5 : NON CURRENT LIABILITIES | E17: =+B17*100000 -> 0 | F17: =+C17*100000 -> 0
A18: Other Long term Liabilities | B18: =(SUMIF('Sub-Schedule'!F4:F32,"RPT",'Sub-Schedule'!C4:C32)-SUMIF('Sub-Schedule'!F4:F32,"RPT",'Sub-Schedule'!B4:B32))/(+Deno) -> 148.44185 | C18: =(SUMIF('Sub-Schedule'!F4:F32,"RPT",'Sub-Schedule'!E4:E32)-SUMIF('Sub-Schedule'!F4:F32,"RPT",'Sub-Schedule'!D4:D32))/(+Deno) -> 148.44185 | E18: =+B18*100000 -> 14844185 | F18: =+C18*100000 -> 14844185
E19: =+B19*100000 -> 0 | F19: =+C19*100000 -> 0
B20: =SUM(B18:B19) -> 148.44185 | C20: =SUM(C18:C19) -> 148.44185 | E20: =+B20*100000 -> 14844185 | F20: =+C20*100000 -> 14844185
E21: =+B21*100000 -> 0 | F21: =+C21*100000 -> 0
E22: =+B22*100000 -> 0 | F22: =+C22*100000 -> 0
A23: NOTE 7 : OTHER CURRENT LIABILITIES | E23: =+B23*100000 -> 0 | F23: =+C23*100000 -> 0
A24: Expense payable | B24: =(+'Sub Sch - BS'!B12) -> 37.309243 | C24: =(+'Sub Sch - BS'!C12) -> 13.188326 | E24: =+B24*100000 -> 3730924.3 | F24: =+C24*100000 -> 1318832.6
A25: Other Liabilities | B25: =(SUMIF('TB 24-25'!$Q:$Q,$A25,'TB 24-25'!$P:$P)-SUMIF('TB 24-25'!$Q:$Q,$A25,'TB 24-25'!$O:$O)) -> 7.9754498 | C25: =(SUMIF('TB 24-25'!$Q:$Q,$A25,'TB 24-25'!$F:$F)-SUMIF('TB 24-25'!$Q:$Q,$A25,'TB 24-25'!$E:$E)) -> 0 | E25: =+B25*100000 -> 797544.98 | F25: =+C25*100000 -> 0
A26: Statutory Dues payables | B26: =(+'Sub Sch - BS'!B25) -> 44.217258 | C26: =(+'Sub Sch - BS'!C25) -> 19.811285 | E26: =+B26*100000 -> 4421725.8 | F26: =+C26*100000 -> 1981128.5
E27: =+B27*100000 -> 0 | F27: =+C27*100000 -> 0
B28: =SUM(B24:B27) -> 89.501951 | C28: =SUM(C24:C27) -> 32.999611 | E28: =+B28*100000 -> 8950195.1 | F28: =+C28*100000 -> 3299961.1
E29: =+B29*100000 -> 0 | F29: =+C29*100000 -> 0
A30: NOTE 8 : SHORT TERM PROVISIONS | E30: =+B30*100000 -> 0 | F30: =+C30*100000 -> 0
A31: Provision for income tax | B31: =(SUMIF('TB 24-25'!$Q:$Q,$A31,'TB 24-25'!$P:$P)-SUMIF('TB 24-25'!$Q:$Q,$A31,'TB 24-25'!$O:$O)) -> 67.52023 | C31: =(SUMIF('TB 24-25'!$Q:$Q,$A31,'TB 24-25'!$F:$F)-SUMIF('TB 24-25'!$Q:$Q,$A31,'TB 24-25'!$E:$E)) -> 67.52023 | E31: =+B31*100000 -> 6752023 | F31: =+C31*100000 -> 6752023
A32: Provisions non business | B32: =(SUMIF('TB 24-25'!$Q:$Q,$A32,'TB 24-25'!$P:$P)-SUMIF('TB 24-25'!$Q:$Q,$A32,'TB 24-25'!$O:$O)) -> 0 | C32: =(SUMIF('TB 24-25'!$Q:$Q,$A32,'TB 24-25'!$F:$F)-SUMIF('TB 24-25'!$Q:$Q,$A32,'TB 24-25'!$E:$E)) -> 0 | E32: =+B32*100000 -> 0 | F32: =+C32*100000 -> 0
A33: Provisions operations | B33: =(SUMIF('TB 24-25'!$Q:$Q,$A33,'TB 24-25'!$P:$P)-SUMIF('TB 24-25'!$Q:$Q,$A33,'TB 24-25'!$O:$O)) -> 0 | C33: =(SUMIF('TB 24-25'!$Q:$Q,$A33,'TB 24-25'!$F:$F)-SUMIF('TB 24-25'!$Q:$Q,$A33,'TB 24-25'!$E:$E)) -> 141.06836 | D33: CY tax included | E33: =+B33*100000 -> 0 | F33: =+C33*100000 -> 14106836
A34: Advance paid \ received | B34: =(SUMIF('Sub-Schedule'!F4:F32,"others",'Sub-Schedule'!C4:C32)-SUMIF('Sub-Schedule'!F4:F32,"others",'Sub-Schedule'!B4:B32))/(+Deno) -> 0.032858 | C34: =(SUMIF('Sub-Schedule'!F4:F32,"Others",'Sub-Schedule'!E4:E32)-SUMIF('Sub-Schedule'!F4:F32,"Others",'Sub-Schedule'!D4:D32))/(+Deno) -> -3.7687959 | E34: =+B34*100000 -> 3285.8 | F34: =+C34*100000 -> -376879.59
E35: =+B35*100000 -> 0 | F35: =+C35*100000 -> 0
B36: =SUM(B31:B35) -> 67.553088 | C36: =SUM(C31:C35) -> 204.8198 | E36: =+B36*100000 -> 6755308.8 | F36: =+C36*100000 -> 20481980

Sheet NOTE 6
A1: =BS!A1 -> CARGO INTERNATIONAL (INDIA) PRIVATE LIMITED
A2: NOTES TO THE FINANCIAL STATEMENTS FOR THE YEAR ENDED 31st MARCH, 2025
A3: CAPITAL TOWERS, NO.G-3/1, G-3/2 & G-2 ,DOOR NO.180 KODAMBAKKAM HIGH ROAD, NUNGAMBAKKAM, CHENNAI - 600034
A5: NOTE 6 : TRADE PAYABLES
A6: Sundry creditors
G7: =+"(Unless otherwise specified, all amounts are "&IF('Master data'!A2="Ones","Indian Rupees","in "&'Master data'!A2&" of INR)") -> (Unless otherwise specified, all amounts are in Lakhs of INR)
A8: Particulars | B8: As on Mar 31,2025
B9: Outstanding for following periods from due date of payment
B10: Less than 6 months | C10: 6 months to 1 year | D10: 1 - 2 years | E10: 2 - 3 years | F10: more than 3 years | G10: TOTAL
A12: MSME | B12: =0/(+Deno) -> 0 | C12: =0/(+Deno) -> 0 | D12: =0/(+Deno) -> 0 | E12: =0/(+Deno) -> 0 | F12: =0/(+Deno) -> 0 | G12: 0
A13: Others | B13: =0/(+Deno) -> 0 | C13: =87765031.46/Deno -> 877.65031 | D13: =1246926.2/(+Deno) -> 12.469262 | E13: =431714.91/(+Deno) -> 4.3171491 | F13: =984680.99/(+Deno) -> 9.8468099 | G13: =+SUM(B13:F13) -> 904.28354
A14: Disputed Dues (MSME) | B14: =0/(+Deno) -> 0 | C14: =0/(+Deno) -> 0 | D14: =0/(+Deno) -> 0 | E14: =0/(+Deno) -> 0 | F14: =0/(+Deno) -> 0 | G14: 0
A15: Disputed Dues (Others) | B15: =0/(+Deno) -> 0 | C15: =0/(+Deno) -> 0 | D15: =0/(+Deno) -> 0 | E15: =0/(+Deno) -> 0 | F15: =0/(+Deno) -> 0 | G15: 0
A17: TOTAL | B17: =SUM(B12:B16) -> 0 | C17: =SUM(C12:C16) -> 877.65031 | D17: =SUM(D12:D16) -> 12.469262 | E17: =SUM(E12:E16) -> 4.3171491 | F17: =SUM(F12:F16) -> 9.8468099 | G17: =SUM(G12:G16) -> 904.28354 | H17: =+C17*100000 -> 87765031 | I17: =+D17*100000 -> 1246926.2 | J17: =+E17*100000 -> 431714.91 | K17: =+F17*100000 -> 984680.99 | L17: =+G17*100000 -> 90428354
A20: Particulars | B20: As on Mar 31, 2024
B21: Outstanding for following periods from due date of payment
B22: Less than 6 months | C22: 6 months to 1 year | D22: 1 - 2 years | E22: 2 - 3 years | F22: more than 3 years | G22: TOTAL
A24: MSME | B24: =0/(+Deno) -> 0 | C24: =0/(+Deno) -> 0 | D24: =0/(+Deno) -> 0 | E24: =0/(+Deno) -> 0 | F24: =0/(+Deno) -> 0 | G24: =+SUM(B24:F24) -> 0
A25: Others | B25: 0 | C25: =26149952.35/Deno -> 261.49952 | D25: =5125281.95/Deno -> 51.25282 | E25: =5986824.57/Deno -> 59.868246 | F25: =9195356.38/Deno -> 91.953564 | G25: =+SUM(B25:F25) -> 464.57415
A26: Disputed Dues (MSME) | B26: =0/(+Deno) -> 0 | C26: =0/(+Deno) -> 0 | D26: =0/(+Deno) -> 0 | E26: =0/(+Deno) -> 0 | F26: =0/(+Deno) -> 0 | G26: =+SUM(B26:F26) -> 0
A27: Disputed Dues (Others) | B27: =0/(+Deno) -> 0 | C27: =0/(+Deno) -> 0 | D27: =0/(+Deno) -> 0 | E27: =0/(+Deno) -> 0 | F27: =0/(+Deno) -> 0 | G27: =+SUM(B27:F27) -> 0
A29: TOTAL | B29: =SUM(B24:B28) -> 0 | C29: =SUM(C24:C28) -> 261.49952 | D29: =SUM(D24:D28) -> 51.25282 | E29: =SUM(E24:E28) -> 59.868246 | F29: =SUM(F24:F28) -> 91.953564 | G29: =SUM(G24:G28) -> 464.57415 | H29: =+C29*100000 -> 26149952 | I29: =+D29*100000 -> 5125282 | J29: =+E29*100000 -> 5986824.6 | K29: =+F29*100000 -> 9195356.4 | L29: =+G29*100000 -> 46457415
B33: Note : Amount is derived from TP reconcilation from Ageing folder
C35: =+Deno -> 100000

Sheet Note 9
A1: CARGO INTERNATIONAL (INDIA) PRIVATE LIMITED
A2: =+'NOTE 4-8'!A2:C2 -> NOTES TO THE FINANCIAL STATEMENTS FOR THE YEAR ENDED 31st MARCH, 2025
A3: =+'NOTE 4-8'!A3:C3 -> CAPITAL TOWERS, NO.G-3/1, G-3/2 & G-2 ,DOOR NO.180 KODAMBAKKAM HIGH ROAD, NUNGAMBAKKAM, CHENNAI - 600034
A5: Note 9 - Property, Plant & Equipment
K6: =+"(Unless otherwise specified, all amounts are "&IF('Master data'!A2="Ones","Indian Rupees","in "&'Master data'!A2&" of INR)") -> (Unless otherwise specified, all amounts are in Lakhs of INR)
A7: Asset Category | B7: Gross Block | F7: Depreciation | J7: Net Block
B8: As on 01.04.2024 | C8: Additions | D8: Deletion | E8: As on 31.03.2025 | F8: =+B8 -> As on 01.04.2024 | G8: For the Year | H8: Deletion | I8: =+E8 -> As on 31.03.2025 | J8: =+I8 -> As on 31.03.2025 | K8: =+B8 -> As on 01.04.2024
A11: Tangible Assets
A12: Motor Car | B12: =0/(Deno) -> 0 | C12: 0 | D12: =(0/(+Deno))/(Deno) -> 0 | E12: =B12+C12-D12 -> 0 | F12: =0/(Deno) -> 0 | G12: 0 | H12: =(0/(+Deno))/(Deno) -> 0 | I12: =F12+G12-H12 -> 0 | J12: =+E12-I12 -> 0 | K12: =+B12-F12 -> 0
A13: Interior Decoration | B13: =4191829.7/(Deno) -> 41.918297 | C13: 0 | D13: =(0/(+Deno))/(Deno) -> 0 | E13: =B13+C13-D13 -> 41.918297 | F13: =3674004.05087299/(Deno) -> 36.740041 | G13: =136364.39/Deno -> 1.3636439 | H13: =(0/(+Deno))/(Deno) -> 0 | I13: =F13+G13-H13 -> 38.103684 | J13: =+E13-I13 -> 3.8146126 | K13: =+B13-F13 -> 5.1782565
A14: Computers | B14: =1847560.05/(Deno) -> 18.4756 | C14: =32966.11/Deno -> 0.3296611 | D14: =(0/(+Deno))/(Deno) -> 0 | E14: =B14+C14-D14 -> 18.805262 | F14: =1707661.14066679/(Deno) -> 17.076611 | G14: =49176.93/Deno -> 0.4917693 | H14: =(0/(+Deno))/(Deno) -> 0 | I14: =F14+G14-H14 -> 17.568381 | J14: =+E14-I14 -> 1.2368809 | K14: =+B14-F14 -> 1.3989891
A15: Communication Equiptments | B15: =381194/(Deno) -> 3.81194 | C15: 0 | D15: =(0/(+Deno))/(Deno) -> 0 | E15: =B15+C15-D15 -> 3.81194 | F15: =362133/(Deno) -> 3.62133 | G15: =0/Deno -> 0 | H15: =(0/(+Deno))/(Deno) -> 0 | I15: =F15+G15-H15 -> 3.62133 | J15: =+E15-I15 -> 0.19061 | K15: =+B15-F15 -> 0.19061
A16: Furniture and fixtures | B16: =1288569.39/(Deno) -> 12.885694 | C16: 0 | D16: =(0/(+Deno))/(Deno) -> 0 | E16: =B16+C16-D16 -> 12.885694 | F16: =1163486.96885793/(Deno) -> 11.63487 | G16: =31560.56/Deno -> 0.3156056 | H16: =(0/(+Deno))/(Deno) -> 0 | I16: =F16+G16-H16 -> 11.950475 | J16: =+E16-I16 -> 0.93521861 | K16: =+B16-F16 -> 1.2508242
A17: Electrical equipments | B17: =664330.5/(Deno) -> 6.643305 | C17: =56000/Deno -> 0.56 | D17: =(0/(+Deno))/(Deno) -> 0 | E17: =B17+C17-D17 -> 7.203305 | F17: =627140.285150916/(Deno) -> 6.2714029 | G17: =22733.66/Deno -> 0.2273366 | H17: =(0/(+Deno))/(Deno) -> 0 | I17: =F17+G17-H17 -> 6.4987395 | J17: =+E17-I17 -> 0.70456555 | K17: =+B17-F17 -> 0.37190215
A18: Office Equipments | B18: =571389.5/(Deno) -> 5.713895 | C18: 0 | D18: =(0/(+Deno))/(Deno) -> 0 | E18: =B18+C18-D18 -> 5.713895 | F18: =496305.623742537/(Deno) -> 4.9630562 | G18: =30063.39/Deno -> 0.3006339 | H18: =(0/(+Deno))/(Deno) -> 0 | I18: =F18+G18-H18 -> 5.2636901 | J18: =+E18-I18 -> 0.45020486 | K18: =+B18-F18 -> 0.75083876
A20: Total | B20: =SUM(B12:B18) -> 89.448731 | C20: =SUM(C12:C18) -> 0.8896611 | D20: =SUM(D12:D18) -> 0 | E20: =SUM(E12:E18) -> 90.338393 | F20: =SUM(F12:F18) -> 80.307311 | G20: =SUM(G12:G18) -> 2.6989893 | H20: =SUM(H12:H18) -> 0 | I20: =SUM(I12:I18) -> 83.0063 | ... K20: =SUM(K12:K18) -> 9.1414207
A22: Previous Year figure | B22: =8888305.35/(Deno) -> 88.883054 | C22: =56567.79/(Deno) -> 0.5656779 | D22: =0/(Deno) -> 0 | E22: =8944873.14/(Deno) -> 89.448731 | F22: =7695410.89794036/(Deno) -> 76.954109 | G22: =335320.171350791/(Deno) -> 3.3532017 | H22: =0/(Deno) -> 0 | I22: =8030731.06929115/(Deno) -> 80.307311 | J22: =914142.07070885/(Deno) -> 9.1414207 | K22: =1192894.45205964/(Deno) -> 11.928945
B26: =+B20*100000 -> 8944873.1 | C26: =+C20*100000 -> 88966.11 | D26: =+D20*100000 -> 0 | E26: =+E20*100000 -> 9033839.3 | F26: =+F20*100000 -> 8030731.1 | G26: =+G20*100000 -> 269898.93 | H26: =+H20*100000 -> 0 | I26: =+I20*100000 -> 8300630 | ... K26: =+K20*100000 -> 914142.07

Sheet NOTE 12
A1: =BS!A1 -> CARGO INTERNATIONAL (INDIA) PRIVATE LIMITED
A2: NOTES TO THE FINANCIAL STATEMENTS FOR THE YEAR ENDED 31st MARCH, 2025
A3: CAPITAL TOWERS, NO.G-3/1, G-3/2 & G-2 ,DOOR NO.180 KODAMBAKKAM HIGH ROAD, NUNGAMBAKKAM, CHENNAI - 600034
A5: NOTE 12 : TRADE RECEIVABLES
A6: Sundry Debtors
G8: =+"(Unless otherwise specified, all amounts are "&IF('Master data'!A2="Ones","Indian Rupees","in "&'Master data'!A2&" of INR)") -> (Unless otherwise specified, all amounts are in Lakhs of INR)
A9: Particulars | B9: As on Mar 31,2025
B10: Outstanding for following periods from due date of payment
B11: Less than 6 months | C11: 6 months to 1 year | D11: 1 - 2 years | E11: 2 - 3 years | F11: more than 3 years | G11: TOTAL
A13: Undisputed Trade receivables considered Good | B13: 0 | C13: =61414470.29/(+Deno) -> 614.1447 | D13: =149040.24/(+Deno) -> 1.4904024 | E13: =19056.25/(+Deno) -> 0.1905625 | F13: =28323028.71/Deno -> 283.23029 | G13: =SUM(B13:F13) -> 899.05595
A14: Undisputed Trade receivables considered doubtful | B14: 0 | C14: 0 | D14: 0 | E14: 0 | F14: 0 | G14: =SUM(B14:F14) -> 0
A15: Disputed Trade receivable considered Good | B15: 0 | C15: 0 | D15: 0 | E15: 0 | F15: 0 | G15: =SUM(B15:F15) -> 0
A16: Disputed Trade receivable considered doubtful | B16: 0 | C16: 0 | D16: 0 | E16: 0 | F16: 0 | G16: =SUM(B16:F16) -> 0
A18: TOTAL | B18: =SUM(B13:B17) -> 0 | C18: =SUM(C13:C17) -> 614.1447 | D18: =SUM(D13:D17) -> 1.4904024 | E18: =SUM(E13:E17) -> 0.1905625 | F18: =SUM(F13:F17) -> 283.23029 | G18: =SUM(G13:G17) -> 899.05595 | H18: =+C18*100000 -> 61414470 | I18: =+D18*100000 -> 149040.24 | J18: =+E18*100000 -> 19056.25 | K18: =+F18*100000 -> 28323029 | L18: =+G18*100000 -> 89905595
A21: Particulars | B21: As on Mar 31, 2024
B22: Outstanding for following periods from due date of payment
B23: Less than 6 months | C23: 6 months to 1 year | D23: 1 - 2 years | E23: 2 - 3 years | F23: more than 3 years | G23: TOTAL
A25: Undisputed Trade receivables considered Good | B25: 0 | C25: =26658528.09/Deno -> 266.58528 | D25: =729673.35/Deno -> 7.2967335 | E25: =92044.95/Deno -> 0.9204495 | F25: =25087064.29/Deno -> 250.87064 | G25: =SUM(B25:F25) -> 525.67311
A26: Undisputed Trade receivables considered doubtful | B26: =0/(+Deno) -> 0 | C26: =0/(+Deno) -> 0 | D26: =0/(+Deno) -> 0 | E26: =0/(+Deno) -> 0 | F26: =0/(+Deno) -> 0 | G26: =SUM(B26:F26) -> 0
A27: Disputed Trade receivable considered Good | B27: =0/(+Deno) -> 0 | C27: =0/(+Deno) -> 0 | D27: =0/(+Deno) -> 0 | E27: =812293.32/Deno -> 8.1229332 | F27: =0/(+Deno) -> 0 | G27: =SUM(B27:F27) -> 8.1229332
A28: Disputed Trade receivable considered doubtful | B28: =0/(+Deno) -> 0 | C28: =0/(+Deno) -> 0 | D28: =0/(+Deno) -> 0 | E28: =0/(+Deno) -> 0 | F28: =0/(+Deno) -> 0 | G28: =SUM(B28:F28) -> 0
A30: TOTAL | B30: =SUM(B25:B29) -> 0 | C30: =SUM(C25:C29) -> 266.58528 | D30: =SUM(D25:D29) -> 7.2967335 | E30: =SUM(E25:E29) -> 9.0433827 | F30: =SUM(F25:F29) -> 250.87064 | G30: =SUM(G25:G29) -> 533.79604 | H30: =+C30*100000 -> 26658528 | I30: =+D30*100000 -> 729673.35 | J30: =+E30*100000 -> 904338.27 | K30: =+F30*100000 -> 25087064 | L30: =+G30*100000 -> 53379604

Sheet NOTE 10-14
A1: =BS!A1 -> CARGO INTERNATIONAL (INDIA) PRIVATE LIMITED
A2: NOTES TO THE FINANCIAL STATEMENTS FOR THE YEAR ENDED 31st MARCH, 2025
A3: CAPITAL TOWERS, NO.G-3/1, G-3/2 & G-2 ,DOOR NO.180 KODAMBAKKAM HIGH ROAD, NUNGAMBAKKAM, CHENNAI - 600034
C4: =+"(Unless otherwise specified, all amounts are "&IF('Master data'!A2="Ones","Indian Rupees","in "&'Master data'!A2&" of INR)") -> (Unless otherwise specified, all amounts are in Lakhs of INR)
A5: Particulars | B5: As on | C5: As on
B6: 31st March, 2025 | C6: 31st March, 2024
A8: NOTE 10 : LONG TERM LOANS AND ADVANCES
A9: Rental Deposit | B9: =(SUMIF('TB 24-25'!$Q:$Q,$A9,'TB 24-25'!$O:$O)-SUMIF('TB 24-25'!$Q:$Q,$A9,'TB 24-25'!$P:$P)) -> 16.69658 | C9: =(SUMIF('TB 24-25'!$Q:$Q,$A9,'TB 24-25'!$E:$E)-SUMIF('TB 24-25'!$Q:$Q,$A9,'TB 24-25'!$F:$F)) -> 19.69658 | D9: =+B9*100000 -> 1669658 | E9: =+C9*100000 -> 1969658
A10: TDS Receivable | B10: =(SUMIF('TB 24-25'!$Q:$Q,$A10,'TB 24-25'!$O:$O)-SUMIF('TB 24-25'!$Q:$Q,$A10,'TB 24-25'!$P:$P)) -> 211.1422 | C10: =(SUMIF('TB 24-25'!$Q:$Q,$A10,'TB 24-25'!$E:$E)-SUMIF('TB 24-25'!$Q:$Q,$A10,'TB 24-25'!$F:$F)) -> 185.13074 | D10: =+B10*100000 -> 21114220 | E10: =+C10*100000 -> 18513074
D11: =+B11*100000 -> 0 | E11: =+C11*100000 -> 0
B12: =SUM(B9:B11) -> 227.83878 | C12: =SUM(C9:C11) -> 204.82732 | D12: =+B12*100000 -> 22783878 | E12: =+C12*100000 -> 20482732
D13: =+B13*100000 -> 0 | E13: =+C13*100000 -> 0
A14: NOTE 11 : DEFERRED TAX ASSETS | D14: =+B14*100000 -> 0 | E14: =+C14*100000 -> 0
A15: Opening Balance | B15: =+C18 -> 6.349577 | C15: =663198.01/Deno -> 6.6319801 | D15: =+B15*100000 -> 634957.7 | E15: =+C15*100000 -> 663198.01
A16: Add: Current year | B16: =PL!D32 -> -0.37521685 | C16: =PL!E32 -> -0.28240312 | D16: =+B16*100000 -> -37521.685 | E16: =+C16*100000 -> -28240.312
D17: =+B17*100000 -> 0 | E17: =+C17*100000 -> 0
A18: Deferred Tax Assets/(Liabilty) | B18: =SUM(B15:B17) -> 5.9743601 | C18: =SUM(C15:C17) -> 6.349577 | D18: =+B18*100000 -> 597436.01 | E18: =+C18*100000 -> 634957.7
D19: =+B19*100000 -> 0 | E19: =+C19*100000 -> 0
A20: NOTE 13 : CASH AND CASH EQUIVALENTS | D20: =+B20*100000 -> 0 | E20: =+C20*100000 -> 0
A21: Balance with banks | B21: =(+'Sub Sch - BS'!B38) -> 216.77245 | C21: =(+'Sub Sch - BS'!C38) -> 56.865407 | D21: =+B21*100000 -> 21677245 | E21: =+C21*100000 -> 5686540.7
A22: Cash on hand | B22: =(+'Sub Sch - BS'!B32) -> 0.1629965 | C22: =(+'Sub Sch - BS'!C32) -> 4.3102892 | D22: =+B22*100000 -> 16299.65 | E22: =+C22*100000 -> 431028.92
D23: =+B23*100000 -> 0 | E23: =+C23*100000 -> 0
B24: =SUM(B21:B23) -> 216.93544 | C24: =SUM(C21:C23) -> 61.175696 | D24: =+B24*100000 -> 21693544 | E24: =+C24*100000 -> 6117569.6
D25: =+B25*100000 -> 0 | E25: =+C25*100000 -> 0
A26: NOTE 14 : SHORT TERM LOANS AND ADVANCES | D26: =+B26*100000 -> 0 | E26: =+C26*100000 -> 0
A27: GST Input tax credit | B27: =(+'Sub Sch - BS'!B44) -> 50.6507 | C27: =(+'Sub Sch - BS'!C44) -> 72.83783 | D27: =+B27*100000 -> 5065070 | E27: =+C27*100000 -> 7283783
A28: Prepaid Expenses | B28: =(SUMIF('TB 24-25'!$Q:$Q,$A28,'TB 24-25'!$O:$O)-SUMIF('TB 24-25'!$Q:$Q,$A28,'TB 24-25'!$P:$P)) -> 1.3078823 | C28: =(SUMIF('TB 24-25'!$Q:$Q,$A28,'TB 24-25'!$E:$E)-SUMIF('TB 24-25'!$Q:$Q,$A28,'TB 24-25'!$F:$F)) -> 1.2206625 | D28: =+B28*100000 -> 130788.23 | E28: =+C28*100000 -> 122066.25
A29: Staff Advance | B29: =(SUMIF('TB 24-25'!$Q:$Q,$A29,'TB 24-25'!$O:$O)-SUMIF('TB 24-25'!$Q:$Q,$A29,'TB 24-25'!$P:$P)) -> 0.4318174 | C29: =(SUMIF('TB 24-25'!$Q:$Q,$A29,'TB 24-25'!$E:$E)-SUMIF('TB 24-25'!$Q:$Q,$A29,'TB 24-25'!$F:$F)) -> 0.5560464 | D29: =+B29*100000 -> 43181.74 | E29: =+C29*100000 -> 55604.64
D30: =+B30*100000 -> 0 | E30: =+C30*100000 -> 0
B31: =SUM(B27:B30) -> 52.3904 | C31: =SUM(C27:C30) -> 74.614539 | D31: =+B31*100000 -> 5239040 | E31: =+C31*100000 -> 7461453.9

Sheet NOTE 15-20
A1: CARGO INTERNATIONAL (INDIA) PRIVATE LIMITED
A2: =+'NOTE 3'!A2:E2 -> NOTES TO THE FINANCIAL STATEMENTS FOR THE YEAR ENDED 31st MARCH, 2025
C4: =+"(Unless otherwise specified, all amounts are "&IF('Master data'!A2="Ones","Indian Rupees","in "&'Master data'!A2&" of INR)") -> (Unless otherwise specified, all amounts are in Lakhs of INR)
A5: Particulars | B5: For Year Ended | C5: For Year Ended
B6: 45747 | C6: 45382 | F6: =10^5 -> 100000
A8: NOTE 15 : REVENUE FROM OPERATIONS
A9: Export Operating Income | B9: =(SUMIF('TB 24-25'!$Q:$Q,'NOTE 15-20'!$A9,'TB 24-25'!$P:$P)-SUMIF('TB 24-25'!$Q:$Q,'NOTE 15-20'!$A9,'TB 24-25'!$O:$O)) -> 1414.428 | C9: =(SUMIF('TB 24-25'!$Q:$Q,'NOTE 15-20'!$A9,'TB 24-25'!$F:$F)-SUMIF('TB 24-25'!$Q:$Q,'NOTE 15-20'!$A9,'TB 24-25'!$E:$E)) -> 552.11691 | D9: =+B9*100000 -> 1.414428e+08 | E9: =+C9*100000 -> 55211691
A10: Import Operating Income | B10: =(SUMIF('TB 24-25'!$Q:$Q,'NOTE 15-20'!$A10,'TB 24-25'!$P:$P)-SUMIF('TB 24-25'!$Q:$Q,'NOTE 15-20'!$A10,'TB 24-25'!$O:$O)) -> 273.74244 | C10: =(SUMIF('TB 24-25'!$Q:$Q,'NOTE 15-20'!$A10,'TB 24-25'!$F:$F)-SUMIF('TB 24-25'!$Q:$Q,'NOTE 15-20'!$A10,'TB 24-25'!$E:$E)) -> 120.00801 | D10: =+B10*100000 -> 27374244 | E10: =+C10*100000 -> 12000801
A11: Air Export Revenue Account | B11: =(SUMIF('TB 24-25'!$Q:$Q,'NOTE 15-20'!$A11,'TB 24-25'!$P:$P)-SUMIF('TB 24-25'!$Q:$Q,'NOTE 15-20'!$A11,'TB 24-25'!$O:$O)) -> 722.99417 | C11: =(SUMIF('TB 24-25'!$Q:$Q,'NOTE 15-20'!$A11,'TB 24-25'!$F:$F)-SUMIF('TB 24-25'!$Q:$Q,'NOTE 15-20'!$A11,'TB 24-25'!$E:$E)) -> 711.08395 | D11: =+B11*100000 -> 72299417 | E11: =+C11*100000 -> 71108395
