Workbook
Name Deno: 'Master data'!$B$2

Sheet Master data
A2: Ones | B2: =+SUMIF(A4:A10,A2,B4:B10) -> 1 | C2: =+Deno -> 1
A4: Millions | B4: 1000000
A5: Lakhs | B5: 100000
A6: Ten Thousands | B6: 10000
A7: Thousands | B7: 1000
A8: Hundreds | B8: 100
A9: Tens | B9: 10
A10: Ones | B10: 1

Sheet Sheet1
A2: As per RBI Prevailing Rates
A3: Date | B3: Currency | C3: Rate/ INR
A4: 45747 | B4: USD | C4: 85.424
A5: 45747 | B5: EUR | C5: 92.415
A6: 45747 | B6: GBP | C6: 110.53

Sheet Audit entry
B2: Audit Entry for FY 2025-26 | E2: =+D3-E3 -> 0
D3: =+SUM(D5:D1048576) -> 2880221.6 | E3: =+SUM(E5:E1048576) -> 2880221.6
B4: SI no | C4: Particulars | D4: Debit | E4: Credit | F4: Remarks | M4: Check
M5: Income Tax payable | N5: ='Statement of Income'!E44 -> 0 | O5: =E135 -> 3.4924597e-10 | P5: =N5-O5 -> -3.4924597e-10
B6: 1 | C6: PREPAID INSURANCES | D6: =K8 -> 180753.41 | G6: Insurance Amount | H6: Assest break ups | K6: 433808.19 | M6: TDS Receivables | N6: ='Statement of Income'!E47 -> 3660953 | O6: ='TB 25-26'!I62 -> 3434574.7 | P6: =N6-O6 -> 226378.33
C7: INSURANCE. | E7: =D6 -> 180753.41 | G7: Prepaid Months | H7: 44109 | I7: NETWORK CHSING PURCHSED FOR MAA NEW OFFICE | J7: 2928 | K7: 5
C8: (Marine Insurance of Rs.4,33,808.19 for the period 30th August 2025 to 29th August 2026) | G8: Prepaid Amount | H8: 44119 | I8: AC INSTALATION CHARGES | J8: 1500 | K8: =K6*K7/12 -> 180753.41
B10: 2 | C10: PREPAID SUBSCRIPTION | D10: =K12 -> 59381 | G10: Membership Amount | H10: 44119 | I10: PLUG - INR 60 1/2" NUTS - INR 150 ANGLR FLANZ - INR 90 | J10: 400 | K10: 296905
C11: SUBSCRIPTION & MEMBERSHIP | E11: =D10 -> 59381 | G11: Prepaid days | H11: 44119 | I11: NETWORKING ACCESSORIES | J11: 1684 | K11: =30+31+12 -> 73
C12: (WCA USA, INC.- Lognet Global Annual Membership Fees of Rs. 2,96,905 for the Period June 13, 2025 to June 13, 2026) | G12: Prepaid Amount | H12: 44119 | I12: AC INSTALATION CHARGES | J12: 1500 | K12: =K10*K11/365 -> 59381
H13: 44989 | I13: Stablizer FOR AC | J13: 1550
B14: 3 | C14: INSURANCE. | D14: 130788.23
C15: PREPAID INSURANCES | E15: =D14 -> 130788.23 | H15: 44032 | J15: 4287.05
C16: (Last year Prepaid Expenses brought forward as Current year Expenses) | H16: 44119 | I16: STABLIZER | J16: 1100
H17: 44124 | I17: Stabiliser | J17: 2400
B18: 4 | C18: DEPRECIATION ON COMPUTER | D18: 90412 | H18: 44965 | I18: AIRTEL DONGLE | J18: 2200
C19: DEPRECIATION OFFICE EQUIPMENTS | D19: 19308 | H19: 44983 | I19: Window Curtain | J19: 2500
C20: DEPRECIATION FURNITURE & FIXTURES | D20: 32819 | H20: 44162 | J20: 960
C21: DEPRECIATION ELECTRICAL INSTALLATIONS | D21: 22039
C22: DEPRECIATION ON INTERIOR DECORATION | D22: 99731
C23: COMPUTER | E23: =+D18 -> 90412
C24: OFFICE EQUIPMENTS | E24: =+D19 -> 19308
C25: FURNITURE & FIXTURES | E25: =+D20 -> 32819
C26: ELECTRICAL INSTALLATIONS | E26: =+D21 -> 22039
C27: OFFICE EQUIP | E27: =+D22 -> 99731
C28: (Depreciation FY 25-26 - Refer Dep Working file)
B30: 5 | C30: LIFT FREIGHT SERVICES B.V. | D30: 754.87
C31: DYJ LOGISTICS | E31: 8139.017
C32: FOCUS GLOBAL LOGISTICS (HK) CORPORATION LIMITED | E32: 2436.018
C33: QCS QUICK CARGO SERVICE GMBH | E33: 12149.65
C34: TRANSCARGO WORLDWIDE (M) SDN BHD | E34: 782.108
C35: VECTOR SPA | E35: 1622.4
C36: AIR INTERNATIONAL FREIGHT CO., LTD | E36: 497.83
C37: GENEL TRANSPORT LTD. STI. | E37: 6808.102
C38: TAZMANIAN FREIGHT SYSTEMS INC | D38: 355.59
C39: FOREIGN EXCHANGE GAIN/LOSS | D39: =+SUM(E30:E38)-SUM(D30:D38) -> 31324.665
C40: (Reversal of Reinstatement of FY 22-23 - Refer Payable ageing file)
B43: 6 | C43: TEAM GLOBAL LOGISITICS PVT.LTD. | D43: 38844.76
C44: TEAM GLOBAL LOGISTICS PVT LTD HYD | E44: =+D43 -> 38844.76
C45: (Reclass from Debtors to Creditors)
...

Sheet TB 25-26
F1: =+F2-E2 -> 500000 | H1: =+H2-G2 -> 725000 | J1: =+J2-I2 -> -235000 | L1: =+L2-K2 -> 490000 | N1: =+N2-M2 -> 10000 | P1: =(O2-P2)*Deno -> -500000 | Q1: 75015376 | R1: =+P1-Q1 -> -75515376
E2: =SUBTOTAL(9,E6:E344) -> 225000 | F2: =SUBTOTAL(9,F6:F344) -> 725000 | G2: =SUBTOTAL(9,G6:G344) -> 0 | H2: =SUBTOTAL(9,H6:H344) -> 725000 | I2: =SUBTOTAL(9,I6:I344) -> 235000 | J2: =SUBTOTAL(9,J6:J344) -> 0 | K2: =SUBTOTAL(9,K6:K344) -> 235000 | L2: =SUBTOTAL(9,L6:L344) -> 725000 | ... P2: =SUBTOTAL(9,P6:P344) -> 725000
E3: Closing Balance after AR | G3: Opening Balance | I3: During the Year Transaction | K3: Closing Balance | M3: Audit entries | O3: Closing Balance after AR
D4: Particulars | E4: FY 24-25 | G4: FY 25-26 | I4: FY 25-26 | K4: FY 25-26 | M4: FY 25-26 | O4: FY 25-26
E5: Debit | F5: Credit | G5: Debit | H5: Credit | I5: Debit | J5: Credit | K5: Debit | L5: Credit | M5: Debit | N5: Credit | O5: Debit | P5: Credit | Q5: Sumif | R5: B/P | S5: Note no | T5: CY Grouping | U5: Sub sch Ref
A6: ASSETS
B7: FIXED ASSETS
C8: FIXED ASSETS AT COST
D9: COMPUTER | E9: 123688.09 | F9: 0 | G9: =+E9 -> 123688.09 | H9: =+F9 -> 0 | I9: 162329 | J9: 0 | K9: =+IF((G9+I9-H9-J9>0),G9+I9-H9-J9,0) -> 286017.09 | L9: =+IF((H9+J9-G9-I9)>0,H9+J9-G9-I9,0) -> 0 | M9: =SUMIF('Audit entry'!$C:$C,'TB 25-26'!$D9,'Audit entry'!$D:$D) -> 0 | N9: =SUMIF('Audit entry'!$C:$C,'TB 25-26'!$D9,'Audit entry'!$E:$E) -> 90412 | O9: =+IF((K9+M9-L9-N9>0),K9+M9-L9-N9,0)/Deno -> 195605.09 | P9: =+IF((L9+N9-K9-M9)>0,L9+N9-K9-M9,0)/Deno -> 0 | Q9: Fixed Assets | R9: BS | S9: 9 | T9: Fixed Assets
D10: OFFICE EQUIPMENTS | E10: 45020.486 | F10: 0 | G10: =+E10 -> 45020.486 | H10: =+F10 -> 0 | I10: 0 | J10: 0 | K10: =+IF((G10+I10-H10-J10>0),G10+I10-H10-J10,0) -> 45020.486 | L10: =+IF((H10+J10-G10-I10)>0,H10+J10-G10-I10,0) -> 0 | M10: =SUMIF('Audit entry'!$C:$C,'TB 25-26'!$D10,'Audit entry'!$D:$D) -> 0 | N10: =SUMIF('Audit entry'!$C:$C,'TB 25-26'!$D10,'Audit entry'!$E:$E) -> 19308 | O10: =+IF((K10+M10-L10-N10>0),K10+M10-L10-N10,0)/Deno -> 25712.486 | P10: =+IF((L10+N10-K10-M10)>0,L10+N10-K10-M10,0)/Deno -> 0 | Q10: Fixed Assets | R10: BS | S10: 9 | T10: Fixed Assets
D11: FURNITURE & FIXTURES | E11: 93521.861 | F11: 0 | G11: =+E11 -> 93521.861 | H11: =+F11 -> 0 | I11: 94800 | J11: 0 | K11: =+IF((G11+I11-H11-J11>0),G11+I11-H11-J11,0) -> 188321.86 | L11: =+IF((H11+J11-G11-I11)>0,H11+J11-G11-I11,0) -> 0 | M11: =SUMIF('Audit entry'!$C:$C,'TB 25-26'!$D11,'Audit entry'!$D:$D) -> 0 | N11: =SUMIF('Audit entry'!$C:$C,'TB 25-26'!$D11,'Audit entry'!$E:$E) -> 32819 | O11: =+IF((K11+M11-L11-N11>0),K11+M11-L11-N11,0)/Deno -> 155502.86 | P11: =+IF((L11+N11-K11-M11)>0,L11+N11-K11-M11,0)/Deno -> 0 | Q11: Fixed Assets | R11: BS | S11: 9 | T11: Fixed Assets
D12: MOTOR VEHICLES - CAR | E12: 0 | F12: 0 | G12: =+E12 -> 0 | H12: =+F12 -> 0 | I12: 0 | J12: 0 | K12: =+IF((G12+I12-H12-J12>0),G12+I12-H12-J12,0) -> 0 | L12: =+IF((H12+J12-G12-I12)>0,H12+J12-G12-I12,0) -> 0 | M12: =SUMIF('Audit entry'!$C:$C,'TB 25-26'!$D12,'Audit entry'!$D:$D) -> 0 | N12: =SUMIF('Audit entry'!$C:$C,'TB 25-26'!$D12,'Audit entry'!$E:$E) -> 0 | O12: =+IF((K12+M12-L12-N12>0),K12+M12-L12-N12,0)/Deno -> 0 | P12: =+IF((L12+N12-K12-M12)>0,L12+N12-K12-M12,0)/Deno -> 0 | Q12: Fixed Assets | R12: BS | S12: 9 | T12: Fixed Assets
D13: ELECTRICAL INSTALLATIONS | E13: 70456.555 | F13: 0 | G13: =+E13 -> 70456.555 | H13: =+F13 -> 0 | I13: 35178 | J13: 0 | K13: =+IF((G13+I13-H13-J13>0),G13+I13-H13-J13,0) -> 105634.55 | L13: =+IF((H13+J13-G13-I13)>0,H13+J13-G13-I13,0) -> 0 | M13: =SUMIF('Audit entry'!$C:$C,'TB 25-26'!$D13,'Audit entry'!$D:$D) -> 0 | N13: =SUMIF('Audit entry'!$C:$C,'TB 25-26'!$D13,'Audit entry'!$E:$E) -> 22039 | O13: =+IF((K13+M13-L13-N13>0),K13+M13-L13-N13,0)/Deno -> 83595.555 | P13: =+IF((L13+N13-K13-M13)>0,L13+N13-K13-M13,0)/Deno -> 0 | Q13: Fixed Assets | R13: BS | S13: 9 | T13: Fixed Assets
D14: MOBILE PURCHASE | E14: 19061 | F14: 0 | G14: =+E14 -> 19061 | H14: =+F14 -> 0 | I14: 0 | J14: 0 | K14: =+IF((G14+I14-H14-J14>0),G14+I14-H14-J14,0) -> 19061 | L14: =+IF((H14+J14-G14-I14)>0,H14+J14-G14-I14,0) -> 0 | M14: =SUMIF('Audit entry'!$C:$C,'TB 25-26'!$D14,'Audit entry'!$D:$D) -> 0 | N14: =SUMIF('Audit entry'!$C:$C,'TB 25-26'!$D14,'Audit entry'!$E:$E) -> 0 | O14: =+IF((K14+M14-L14-N14>0),K14+M14-L14-N14,0)/Deno -> 19061 | P14: =+IF((L14+N14-K14-M14)>0,L14+N14-K14-M14,0)/Deno -> 0 | Q14: Fixed Assets | R14: BS | S14: 9 | T14: Fixed Assets
D15: OFFICE EQUIPMENTS | E15: 0 | F15: 0 | G15: =+E15 -> 0 | H15: =+F15 -> 0 | I15: 0 | J15: 0 | K15: =+IF((G15+I15-H15-J15>0),G15+I15-H15-J15,0) -> 0 | L15: =+IF((H15+J15-G15-I15)>0,H15+J15-G15-I15,0) -> 0 | M15: =SUMIF('Audit entry'!$C:$C,'TB 25-26'!$D15,'Audit entry'!$D:$D) -> 0 | N15: 0 | O15: =+IF((K15+M15-L15-N15>0),K15+M15-L15-N15,0)/Deno -> 0 | P15: =+IF((L15+N15-K15-M15)>0,L15+N15-K15-M15,0)/Deno -> 0 | Q15: Fixed Assets | R15: BS | S15: 9 | T15: Fixed Assets
D16: OFFICE EQUIP | E16: 381461.26 | F16: 0 | G16: =+E16 -> 381461.26 | H16: =+F16 -> 0 | I16: 82020.06 | J16: 0 | K16: =+IF((G16+I16-H16-J16>0),G16+I16-H16-J16,0) -> 463481.32 | L16: =+IF((H16+J16-G16-I16)>0,H16+J16-G16-I16,0) -> 0 | M16: =SUMIF('Audit entry'!$C:$C,'TB 25-26'!$D16,'Audit entry'!$D:$D) -> 0 | N16: =SUMIF('Audit entry'!$C:$C,'TB 25-26'!$D16,'Audit entry'!$E:$E) -> 99731 | O16: =+IF((K16+M16-L16-N16>0),K16+M16-L16-N16,0)/Deno -> 363750.32 | P16: =+IF((L16+N16-K16-M16)>0,L16+N16-K16-M16,0)/Deno -> 0 | Q16: Fixed Assets | R16: BS | S16: 9 | T16: Fixed Assets
D17: MACHINERY & ELECTRICAL | E17: 0 | F17: 0 | G17: =+E17 -> 0 | H17: =+F17 -> 0 | I17: 0 | J17: 0 | K17: =+IF((G17+I17-H17-J17>0),G17+I17-H17-J17,0) -> 0 | L17: =+IF((H17+J17-G17-I17)>0,H17+J17-G17-I17,0) -> 0 | M17: =SUMIF('Audit entry'!$C:$C,'TB 25-26'!$D17,'Audit entry'!$D:$D) -> 0 | N17: =SUMIF('Audit entry'!$C:$C,'TB 25-26'!$D17,'Audit entry'!$E:$E) -> 0 | O17: =+IF((K17+M17-L17-N17>0),K17+M17-L17-N17,0)/Deno -> 0 | P17: =+IF((L17+N17-K17-M17)>0,L17+N17-K17-M17,0)/Deno -> 0 | Q17: Fixed Assets | R17: BS | S17: 9 | T17: Fixed Assets
B18: CURRENT ASSETS | E18: 0 | F18: 0 | G18: =+E18 -> 0 | H18: =+F18 -> 0 | I18: 0 | J18: 0 | K18: =+IF((G18+I18-H18-J18>0),G18+I18-H18-J18,0) -> 0 | L18: =+IF((H18+J18-G18-I18)>0,H18+J18-G18-I18,0) -> 0 | M18: =SUMIF('Audit entry'!$C:$C,'TB 25-26'!$D18,'Audit entry'!$D:$D) -> 0 | N18: =SUMIF('Audit entry'!$C:$C,'TB 25-26'!$D18,'Audit entry'!$E:$E) -> 0 | O18: =+IF((K18+M18-L18-N18>0),K18+M18-L18-N18,0)/Deno -> 0 | P18: =+IF((L18+N18-K18-M18)>0,L18+N18-K18-M18,0)/Deno -> 0
C19: SUNDRY DEBTORS | E19: 0 | F19: 0 | G19: =+E19 -> 0 | H19: =+F19 -> 0 | I19: 0 | J19: 0 | K19: =+IF((G19+I19-H19-J19>0),G19+I19-H19-J19,0) -> 0 | L19: =+IF((H19+J19-G19-I19)>0,H19+J19-G19-I19,0) -> 0 | M19: =SUMIF('Audit entry'!$C:$C,'TB 25-26'!$D19,'Audit entry'!$D:$D) -> 0 | N19: =SUMIF('Audit entry'!$C:$C,'TB 25-26'!$D19,'Audit entry'!$E:$E) -> 0 | O19: =+IF((K19+M19-L19-N19>0),K19+M19-L19-N19,0)/Deno -> 0 | P19: =+IF((L19+N19-K19-M19)>0,L19+N19-K19-M19,0)/Deno -> 0
D20: OVERSEAS DEBTORS - FREIGHT FORWARDING | E20: 32440135 | F20: 0 | G20: =+E20 -> 32440135 | H20: =+F20 -> 0 | I20: 6292794.7 | J20: 0 | K20: =+IF((G20+I20-H20-J20>0),G20+I20-H20-J20,0) -> 38732930 | L20: =+IF((H20+J20-G20-I20)>0,H20+J20-G20-I20,0) -> 0 | M20: =+SUM('Audit entry'!D216:D217)+SUM('Audit entry'!D221:D231)-SUM('Audit entry'!E221:E231) -> 117689.93 | N20: =+SUM('Audit entry'!E211:E212) -> 42904.38 | O20: =+IF((K20+M20-L20-N20>0),K20+M20-L20-N20,0)/Deno -> 38807715 | P20: =+IF((L20+N20-K20-M20)>0,L20+N20-K20-M20,0)/Deno -> 0 | R20: BS | S20: 12 | T20: Trade Receivable
D21: LOCAL DEBTORS - FREIGHT FORWARDING | E21: 57465461 | F21: 0 | G21: =+E21 -> 57465461 | H21: =+F21 -> 0 | I21: 0 | J21: 21213806 | K21: =+IF((G21+I21-H21-J21>0),G21+I21-H21-J21,0) -> 36251654 | L21: =+IF((H21+J21-G21-I21)>0,H21+J21-G21-I21,0) -> 0 | M21: =SUMIF('Audit entry'!$C:$C,'TB 25-26'!$D21,'Audit entry'!$D:$D) -> 0 | N21: =+'Audit entry'!E44+'Audit entry'!E210-'Audit entry'!D209+SUM('Audit entry'!E232:E235)-SUM('Audit entry'!D232:D235) -> 43327.22 | O21: =+IF((K21+M21-L21-N21>0),K21+M21-L21-N21,0)/Deno -> 36208327 | P21: =+IF((L21+N21-K21-M21)>0,L21+N21-K21-M21,0)/Deno -> 0 | R21: BS | S21: 12 | T21: Trade Receivable
C22: CASH AND BANK BALANCE | E22: 0 | F22: 0 | G22: =+E22 -> 0 | H22: =+F22 -> 0 | I22: 0 | J22: 0 | K22: =+IF((G22+I22-H22-J22>0),G22+I22-H22-J22,0) -> 0 | L22: =+IF((H22+J22-G22-I22)>0,H22+J22-G22-I22,0) -> 0 | M22: =SUMIF('Audit entry'!$C:$C,'TB 25-26'!$D22,'Audit entry'!$D:$D) -> 0 | N22: =SUMIF('Audit entry'!$C:$C,'TB 25-26'!$D22,'Audit entry'!$E:$E) -> 0 | O22: =+IF((K22+M22-L22-N22>0),K22+M22-L22-N22,0)/Deno -> 0 | P22: =+IF((L22+N22-K22-M22)>0,L22+N22-K22-M22,0)/Deno -> 0
D23: CASH IN HAND | E23: 0 | F23: 0 | G23: =+E23 -> 0 | H23: =+F23 -> 0 | I23: 0 | J23: 0 | K23: =+IF((G23+I23-H23-J23>0),G23+I23-H23-J23,0) -> 0 | L23: =+IF((H23+J23-G23-I23)>0,H23+J23-G23-I23,0) -> 0 | M23: =SUMIF('Audit entry'!$C:$C,'TB 25-26'!$D23,'Audit entry'!$D:$D) -> 0 | N23: =SUMIF('Audit entry'!$C:$C,'TB 25-26'!$D23,'Audit entry'!$E:$E) -> 0 | O23: =+IF((K23+M23-L23-N23>0),K23+M23-L23-N23,0)/Deno -> 0 | P23: =+IF((L23+N23-K23-M23)>0,L23+N23-K23-M23,0)/Deno -> 0 | Q23: Cash in hand | R23: BS | S23: 13 | T23: Cash and cash equivalents
D24: BANK BALANCE LOCAL CURRENCY | E24: 21436133 | F24: 0 | G24: =+E24 -> 21436133 | H24: =+F24 -> 0 | I24: 11152456 | J24: 0 | K24: =+IF((G24+I24-H24-J24>0),G24+I24-H24-J24,0) -> 32588589 | L24: =+IF((H24+J24-G24-I24)>0,H24+J24-G24-I24,0) -> 0 | M24: =SUMIF('Audit entry'!$C:$C,'TB 25-26'!$D24,'Audit entry'!$D:$D) -> 0 | N24: =SUMIF('Audit entry'!$C:$C,'TB 25-26'!$D24,'Audit entry'!$E:$E) -> 0 | O24: =+IF((K24+M24-L24-N24>0),K24+M24-L24-N24,0)/Deno -> 32588589 | P24: =+IF((L24+N24-K24-M24)>0,L24+N24-K24-M24,0)/Deno -> 0 | Q24: Cash at Bank - Local Currency | R24: BS | S24: 13 | T24: Cash and cash equivalents
D25: FIXED DEPOSIT IN BANK | E25: 0 | F25: 0 | G25: =+E25 -> 0 | H25: =+F25 -> 0 | I25: 0 | J25: 0 | K25: =+IF((G25+I25-H25-J25>0),G25+I25-H25-J25,0) -> 0 | L25: =+IF((H25+J25-G25-I25)>0,H25+J25-G25-I25,0) -> 0 | M25: =SUMIF('Audit entry'!$C:$C,'TB 25-26'!$D25,'Audit entry'!$D:$D) -> 0 | N25: =SUMIF('Audit entry'!$C:$C,'TB 25-26'!$D25,'Audit entry'!$E:$E) -> 0 | O25: =+IF((K25+M25-L25-N25>0),K25+M25-L25-N25,0)/Deno -> 0 | P25: =+IF((L25+N25-K25-M25)>0,L25+N25-K25-M25,0)/Deno -> 0 | Q25: Cash at Bank - Local Currency | R25: BS | S25: 13 | T25: Cash and cash equivalents
D26: MAA PETTY CASH | E26: 5161 | F26: 0 | G26: =+E26 -> 5161 | H26: =+F26 -> 0 | I26: 731 | J26: 0 | K26: =+IF((G26+I26-H26-J26>0),G26+I26-H26-J26,0) -> 5892 | L26: =+IF((H26+J26-G26-I26)>0,H26+J26-G26-I26,0) -> 0 | M26: =SUMIF('Audit entry'!$C:$C,'TB 25-26'!$D26,'Audit entry'!$D:$D) -> 0 | N26: =SUMIF('Audit entry'!$C:$C,'TB 25-26'!$D26,'Audit entry'!$E:$E) -> 0 | O26: =+IF((K26+M26-L26-N26>0),K26+M26-L26-N26,0)/Deno -> 5892 | P26: =+IF((L26+N26-K26-M26)>0,L26+N26-K26-M26,0)/Deno -> 0 | Q26: Petty Cash | R26: BS | S26: 13 | T26: Cash and cash equivalents
D27: AIRPORT PETTY CASH | E27: 0 | F27: 0 | G27: =+E27 -> 0 | H27: =+F27 -> 0 | I27: 0 | J27: 0 | K27: =+IF((G27+I27-H27-J27>0),G27+I27-H27-J27,0) -> 0 | L27: =+IF((H27+J27-G27-I27)>0,H27+J27-G27-I27,0) -> 0 | M27: =SUMIF('Audit entry'!$C:$C,'TB 25-26'!$D27,'Audit entry'!$D:$D) -> 0 | N27: =SUMIF('Audit entry'!$C:$C,'TB 25-26'!$D27,'Audit entry'!$E:$E) -> 0 | O27: =+IF((K27+M27-L27-N27>0),K27+M27-L27-N27,0)/Deno -> 0 | P27: =+IF((L27+N27-K27-M27)>0,L27+N27-K27-M27,0)/Deno -> 0 | Q27: Petty Cash | R27: BS | S27: 13 | T27: Cash and cash equivalents
D28: BANK BALANCE OVERSEAS CURRENCY | E28: 241111.49 | F28: 0 | G28: =+E28 -> 241111.49 | H28: =+F28 -> 0 | I28: 1335622.7 | J28: 0 | K28: =+IF((G28+I28-H28-J28>0),G28+I28-H28-J28,0) -> 1576734.2 | L28: =+IF((H28+J28-G28-I28)>0,H28+J28-G28-I28,0) -> 0 | M28: =SUMIF('Audit entry'!$C:$C,'TB 25-26'!$D28,'Audit entry'!$D:$D) -> 0 | N28: =SUMIF('Audit entry'!$C:$C,'TB 25-26'!$D28,'Audit entry'!$E:$E) -> 0 | O28: =+IF((K28+M28-L28-N28>0),K28+M28-L28-N28,0)/Deno -> 1576734.2 | P28: =+IF((L28+N28-K28-M28)>0,L28+N28-K28-M28,0)/Deno -> 0 | Q28: Cash at Bank - Foreign Currency | R28: BS | S28: 13 | T28: Cash and cash equivalents
D29: ATM CASH W/D | E29: 0 | F29: 0 | G29: =+E29 -> 0 | H29: =+F29 -> 0 | I29: 0 | J29: 0 | K29: =+IF((G29+I29-H29-J29>0),G29+I29-H29-J29,0) -> 0 | L29: =+IF((H29+J29-G29-I29)>0,H29+J29-G29-I29,0) -> 0 | M29: =SUMIF('Audit entry'!$C:$C,'TB 25-26'!$D29,'Audit entry'!$D:$D) -> 0 | N29: =SUMIF('Audit entry'!$C:$C,'TB 25-26'!$D29,'Audit entry'!$E:$E) -> 0 | O29: =+IF((K29+M29-L29-N29>0),K29+M29-L29-N29,0)/Deno -> 0 | P29: =+IF((L29+N29-K29-M29)>0,L29+N29-K29-M29,0)/Deno -> 0 | Q29: Cash in hand | R29: BS | S29: 13 | T29: Cash and cash equivalents
D30: INTER BANK ACCOUNT TRANSFER | E30: 0 | F30: 0 | G30: =+E30 -> 0 | H30: =+F30 -> 0 | I30: 0 | J30: 0 | K30: =+IF((G30+I30-H30-J30>0),G30+I30-H30-J30,0) -> 0 | L30: =+IF((H30+J30-G30-I30)>0,H30+J30-G30-I30,0) -> 0 | M30: =SUMIF('Audit entry'!$C:$C,'TB 25-26'!$D30,'Audit entry'!$D:$D) -> 0 | N30: =SUMIF('Audit entry'!$C:$C,'TB 25-26'!$D30,'Audit entry'!$E:$E) -> 0 | O30: =+IF((K30+M30-L30-N30>0),K30+M30-L30-N30,0)/Deno -> 0 | P30: =+IF((L30+N30-K30-M30)>0,L30+N30-K30-M30,0)/Deno -> 0 | Q30: Cash at Bank - Local Currency | R30: BS | S30: 13 | T30: Cash and cash equivalents
D31: SECURITY DEPOSIT | E31: 0 | F31: 0 | G31: =+E31 -> 0 | H31: =+F31 -> 0 | I31: 0 | J31: 0 | K31: =+IF((G31+I31-H31-J31>0),G31+I31-H31-J31,0) -> 0 | L31: =+IF((H31+J31-G31-I31)>0,H31+J31-G31-I31,0) -> 0 | M31: =SUMIF('Audit entry'!$C:$C,'TB 25-26'!$D31,'Audit entry'!$D:$D) -> 0 | N31: =SUMIF('Audit entry'!$C:$C,'TB 25-26'!$D31,'Audit entry'!$E:$E) -> 0 | O31: =+IF((K31+M31-L31-N31>0),K31+M31-L31-N31,0)/Deno -> 0 | P31: =+IF((L31+N31-K31-M31)>0,L31+N31-K31-M31,0)/Deno -> 0 | Q31: Security Deposit | R31: BS | S31: 13 | T31: Cash and cash equivalents
D32: TUT PETTY CASH | E32: 1988 | F32: 0 | G32: =+E32 -> 1988 | H32: =+F32 -> 0 | I32: 0 | J32: 0 | K32: =+IF((G32+I32-H32-J32>0),G32+I32-H32-J32,0) -> 1988 | L32: =+IF((H32+J32-G32-I32)>0,H32+J32-G32-I32,0) -> 0 | M32: =SUMIF('Audit entry'!$C:$C,'TB 25-26'!$D32,'Audit entry'!$D:$D) -> 0 | N32: =SUMIF('Audit entry'!$C:$C,'TB 25-26'!$D32,'Audit entry'!$E:$E) -> 0 | O32: =+IF((K32+M32-L32-N32>0),K32+M32-L32-N32,0)/Deno -> 1988 | P32: =+IF((L32+N32-K32-M32)>0,L32+N32-K32-M32,0)/Deno -> 0 | Q32: Petty Cash | R32: BS | S32: 13 | T32: Cash and cash equivalents
D33: HYD PETTY CASH | E33: 8691.15 | F33: 0 | G33: =+E33 -> 8691.15 | H33: =+F33 -> 0 | I33: 0 | J33: 5776.06 | K33: =+IF((G33+I33-H33-J33>0),G33+I33-H33-J33,0) -> 2915.09 | L33: =+IF((H33+J33-G33-I33)>0,H33+J33-G33-I33,0) -> 0 | M33: =SUMIF('Audit entry'!$C:$C,'TB 25-26'!$D33,'Audit entry'!$D:$D) -> 0 | N33: =SUMIF('Audit entry'!$C:$C,'TB 25-26'!$D33,'Audit entry'!$E:$E) -> 0 | O33: =+IF((K33+M33-L33-N33>0),K33+M33-L33-N33,0)/Deno -> 2915.09 | P33: =+IF((L33+N33-K33-M33)>0,L33+N33-K33-M33,0)/Deno -> 0 | Q33: Petty Cash | R33: BS | S33: 13 | T33: Cash and cash equivalents
D34: BLR PETTY CASH | E34: 0 | F34: 0 | G34: =+E34 -> 0 | H34: =+F34 -> 0 | I34: 17165 | J34: 0 | K34: =+IF((G34+I34-H34-J34>0),G34+I34-H34-J34,0) -> 17165 | L34: =+IF((H34+J34-G34-I34)>0,H34+J34-G34-I34,0) -> 0 | M34: =SUMIF('Audit entry'!$C:$C,'TB 25-26'!$D34,'Audit entry'!$D:$D) -> 0 | N34: =SUMIF('Audit entry'!$C:$C,'TB 25-26'!$D34,'Audit entry'!$E:$E) -> 0 | O34: =+IF((K34+M34-L34-N34>0),K34+M34-L34-N34,0)/Deno -> 17165 | P34: =+IF((L34+N34-K34-M34)>0,L34+N34-K34-M34,0)/Deno -> 0 | Q34: Petty Cash | R34: BS | S34: 13 | T34: Cash and cash equivalents
D35: CBE PETTY CASH | E35: 459.5 | F35: 0 | G35: =+E35 -> 459.5 | H35: =+F35 -> 0 | I35: 29965.19 | J35: 0 | K35: =+IF((G35+I35-H35-J35>0),G35+I35-H35-J35,0) -> 30424.69 | L35: =+IF((H35+J35-G35-I35)>0,H35+J35-G35-I35,0) -> 0 | M35: =SUMIF('Audit entry'!$C:$C,'TB 25-26'!$D35,'Audit entry'!$D:$D) -> 0 | N35: =SUMIF('Audit entry'!$C:$C,'TB 25-26'!$D35,'Audit entry'!$E:$E) -> 0 | O35: =+IF((K35+M35-L35-N35>0),K35+M35-L35-N35,0)/Deno -> 30424.69 | P35: =+IF((L35+N35-K35-M35)>0,L35+N35-K35-M35,0)/Deno -> 0 | Q35: Petty Cash | R35: BS | S35: 13 | T35: Cash and cash equivalents
C36: WORK IN PROGRESS JOBS | E36: 0 | F36: 0 | G36: =+E36 -> 0 | H36: =+F36 -> 0 | I36: 0 | J36: 0 | K36: =+IF((G36+I36-H36-J36>0),G36+I36-H36-J36,0) -> 0 | L36: =+IF((H36+J36-G36-I36)>0,H36+J36-G36-I36,0) -> 0 | M36: =SUMIF('Audit entry'!$C:$C,'TB 25-26'!$D36,'Audit entry'!$D:$D) -> 0 | N36: =SUMIF('Audit entry'!$C:$C,'TB 25-26'!$D36,'Audit entry'!$E:$E) -> 0 | O36: =+IF((K36+M36-L36-N36>0),K36+M36-L36-N36,0)/Deno -> 0 | P36: =+IF((L36+N36-K36-M36)>0,L36+N36-K36-M36,0)/Deno -> 0
D37: WORK IN PROGRESS JOBS | E37: 0 | F37: 0 | G37: =+E37 -> 0 | H37: =+F37 -> 0 | I37: 0 | J37: 0 | K37: =+IF((G37+I37-H37-J37>0),G37+I37-H37-J37,0) -> 0 | L37: =+IF((H37+J37-G37-I37)>0,H37+J37-G37-I37,0) -> 0 | M37: =SUMIF('Audit entry'!$C:$C,'TB 25-26'!$D37,'Audit entry'!$D:$D) -> 0 | N37: =SUMIF('Audit entry'!$C:$C,'TB 25-26'!$D37,'Audit entry'!$E:$E) -> 0 | O37: =+IF((K37+M37-L37-N37>0),K37+M37-L37-N37,0)/Deno -> 0 | P37: =+IF((L37+N37-K37-M37)>0,L37+N37-K37-M37,0)/Deno -> 0 | Q37: Unbilled Income | R37: BS | S37: 14 | T37: Short-term loans and advances
D38: WORK IN PROGRESS JOBS REV | E38: 0 | F38: 0 | G38: =+E38 -> 0 | H38: =+F38 -> 0 | I38: 0 | J38: 0 | K38: =+IF((G38+I38-H38-J38>0),G38+I38-H38-J38,0) -> 0 | L38: =+IF((H38+J38-G38-I38)>0,H38+J38-G38-I38,0) -> 0 | M38: =SUMIF('Audit entry'!$C:$C,'TB 25-26'!$D38,'Audit entry'!$D:$D) -> 0 | N38: =SUMIF('Audit entry'!$C:$C,'TB 25-26'!$D38,'Audit entry'!$E:$E) -> 0 | O38: =+IF((K38+M38-L38-N38>0),K38+M38-L38-N38,0)/Deno -> 0 | P38: =+IF((L38+N38-K38-M38)>0,L38+N38-K38-M38,0)/Deno -> 0 | Q38: Unbilled Income | R38: BS | S38: 14 | T38: Short-term loans and advances
C39: ACCRUALS | E39: 0 | F39: 0 | G39: =+E39 -> 0 | H39: =+F39 -> 0 | I39: 0 | J39: 0 | K39: =+IF((G39+I39-H39-J39>0),G39+I39-H39-J39,0) -> 0 | L39: =+IF((H39+J39-G39-I39)>0,H39+J39-G39-I39,0) -> 0 | M39: =SUMIF('Audit entry'!$C:$C,'TB 25-26'!$D39,'Audit entry'!$D:$D) -> 0 | N39: =SUMIF('Audit entry'!$C:$C,'TB 25-26'!$D39,'Audit entry'!$E:$E) -> 0 | O39: =+IF((K39+M39-L39-N39>0),K39+M39-L39-N39,0)/Deno -> 0 | P39: =+IF((L39+N39-K39-M39)>0,L39+N39-K39-M39,0)/Deno -> 0
D40: PREPAID INTERNET EXPESES | E40: 0 | F40: 0 | G40: =+E40 -> 0 | H40: =+F40 -> 0 | I40: 0 | J40: 0 | K40: =+IF((G40+I40-H40-J40>0),G40+I40-H40-J40,0) -> 0 | L40: =+IF((H40+J40-G40-I40)>0,H40+J40-G40-I40,0) -> 0 | M40: =SUMIF('Audit entry'!$C:$C,'TB 25-26'!$D40,'Audit entry'!$D:$D) -> 0 | N40: =SUMIF('Audit entry'!$C:$C,'TB 25-26'!$D40,'Audit entry'!$E:$E) -> 0 | O40: =+IF((K40+M40-L40-N40>0),K40+M40-L40-N40,0)/Deno -> 0 | P40: =+IF((L40+N40-K40-M40)>0,L40+N40-K40-M40,0)/Deno -> 0 | Q40: Prepaid Expenses | R40: BS | S40: 14 | T40: Short-term loans and advances
...

Sheet BS
A1: CARGO INTERNATIONAL (INDIA) PRIVATE LIMITED
A2: BALANCE SHEET AS AT 31ST MARCH, 2026
A3: CIN : U63000TN2010PTC077296
A4: Old No.7 / New No.13, First Floor, First Cross Street, Trustpuram, Kodambakkam, Chennai - 600024, India
A5: =+"(Unless otherwise specified, all amounts are "&IF('Master data'!A2="Ones","Indian Rupees","in "&'Master data'!A2&" of INR)") -> (Unless otherwise specified, all amounts are Indian Rupees
A6: Particulars | B6: Note No. | C6: As on | D6: As on
C7: 31st March, 2026 | D7: 31st March, 2025
A9: I.EQUITY AND LIABILITIES
A10: SHARE HOLDERS FUNDS
A11: a. Share capital | B11: 3 | C11: =+'NOTE 3'!D15 -> 200000 | D11: =+'NOTE 3'!E15 -> 200000
A12: b. Reserve and surplus | B12: 4 | C12: =+'NOTE 4-8'!B15 -> 10342049 | D12: =+'NOTE 4-8'!C15 -> 19774662
C13: =SUM(C11:C12) -> 10542049 | D13: =SUM(D11:D12) -> 19974662
A14: NON CURRENT LIABILITIES
A15: a. Other Long term Liabilities | B15: 5 | C15: =+'NOTE 4-8'!B20 -> 14085282 | D15: =+'NOTE 4-8'!C20 -> 14844185
C16: =+C15 -> 14085282 | D16: =+D15 -> 14844185
A17: CURRENT LIABILITIES
A18: a. Trade payables | B18: 6
A19: i. Outstanding due against MSME | C19: =+'NOTE 6'!G12 -> 0 | D19: =+'NOTE 6'!G24 -> 0
A20: ii.Outstanding due against Other than MSME | C20: =+'NOTE 6'!G17 -> 1.1079895e+08 | D20: =+SUM('NOTE 6'!G25:G27) -> 90428354
A21: b. Other current liabilities | B21: 7 | C21: =+'NOTE 4-8'!B28 -> 7211333.7 | D21: =+'NOTE 4-8'!C28 -> 8950195.1
A22: c. Short term provisions | B22: 8 | C22: =+'NOTE 4-8'!B36 -> 6752023 | D22: =+'NOTE 4-8'!C36 -> 6755308.8
C23: =SUM(C18:C22) -> 1.2476231e+08 | D23: =SUM(D18:D22) -> 1.0613386e+08
A25: TOTAL | C25: =C13+C16+C23 -> 1.4938964e+08 | D25: =D13+D16+D23 -> 1.409527e+08
A27: II.ASSETS
A28: NON-CURRENT ASSETS
A29: a. Property, Plant & Equipment | B29: 9
A30: (i) Tangible assets | C30: =+'Note 9'!J20 -> 843227.31 | D30: =+'Note 9'!K20 -> 733209.25
C31: =SUM(C30:C30) -> 843227.31 | D31: =SUM(D30:D30) -> 733209.25
A33: b. Long-term loans and advances | B33: 10 | C33: =+'NOTE 10-14'!B12 -> 26182475 | D33: =+'NOTE 10-14'!C12 -> 22783878
A34: c. Deffered Tax Assets | B34: 11 | C34: =+'NOTE 10-14'!B18 -> 597436.01 | D34: =+'NOTE 10-14'!C18 -> 597436.01
C35: =+C33+C34 -> 26779911 | D35: =D33+D34 -> 23381314
A36: CURRENT ASSETS
A37: a. Trade receivables | B37: 12 | C37: =+'NOTE 12'!G18 -> 75016042 | D37: =+'NOTE 12'!G30 -> 89905595
A38: b. cash and cash equivalents | B38: 13 | C38: =+'NOTE 10-14'!B24+(1.99/Deno) -> 34223710 | D38: =+'NOTE 10-14'!C24+(1.99/Deno) -> 21693546
A39: c. Short-term loans and advances | B39: 14 | C39: =+'NOTE 10-14'!B31 -> 12526748 | D39: =+'NOTE 10-14'!C31 -> 5239040
C40: =SUM(C37:C39) -> 1.217665e+08 | D40: =SUM(D37:D39) -> 1.1683818e+08
A42: TOTAL | C42: =C31+C35+C40 -> 1.4938964e+08 | D42: =D31+D35+D40 -> 1.409527e+08 | E42: =+C25-C42 -> -0.53688774 | F42: =+D25-D42 -> -0.54755875
E43: =+E42*Deno -> -0.53688774 | F43: =+F42*Deno -> -0.54755875
A44: Significant Accounting Policies in Note 1 & 2
A45: The accompanying notes are integral part of the financial statements
...

Sheet PL
A1: CARGO INTERNATIONAL (INDIA) PRIVATE LIMITED
A2: STATEMENT OF PROFIT AND LOSS FOR YEAR ENDED 31ST MARCH, 2026
A3: CIN: U63000TN2010PTC077296
A4: =+BS!A4 -> Old No.7 / New No.13, First Floor, First Cross Street, Trustpuram, Kodambakkam, Chennai - 600024, India
A5: =+"(Unless otherwise specified, all amounts are "&IF('Master data'!A2="Ones","Indian Rupees","in "&'Master data'!A2&" of INR)") -> (Unless otherwise specified, all amounts are Indian Rupees
A6: Particulars | C6: Note | D6: For Year Ended | E6: For Year Ended
D7: =BS!C7 -> 31st March, 2026 | E7: =BS!D7 -> 31st March, 2025
A9: I | B9: Revenue from Operation | C9: 15 | D9: ='NOTE 15-20'!B14 -> 1.9086401e+08 | E9: ='NOTE 15-20'!C14 -> 2.5105688e+08
A10: II | B10: Other Income | C10: 16 | D10: ='NOTE 15-20'!B20 -> 5016550.7 | E10: ='NOTE 15-20'!C20 -> 6275069.8
A12: III | B12: TOTAL | D12: =SUM(D9:D11) -> 1.9588056e+08 | E12: =SUM(E9:E11) -> 2.5733195e+08
F13: ..
A14: IV | B14: EXPENSES
B15: Operating expenses | C15: 17 | D15: ='NOTE 15-20'!B28 -> 1.5920151e+08 | E15: ='NOTE 15-20'!C28 -> 2.1536675e+08
B16: Employee Benefit Expenses | C16: 18 | D16: ='NOTE 15-20'!B34 -> 19826121 | E16: ='NOTE 15-20'!C34 -> 23047531
B17: Finance cost | C17: 19 | D17: =+'NOTE 15-20'!B41 -> 251861.01 | E17: =+'NOTE 15-20'!C41 -> 266439.7
B18: Administrative expenses | C18: 20 | D18: ='NOTE 15-20'!B57 -> 25769376 | E18: ='NOTE 15-20'!C57 -> 15728139
B19: Depreciation | C19: 9 | D19: ='Note 9'!G20 -> 264309 | E19: =+'Note 9'!G22 -> 269898.93
A21: V | B21: TOTAL | D21: =SUM(D15:D20) -> 2.0531317e+08 | E21: =SUM(E15:E20) -> 2.5467876e+08
A23: VI | B23: Profit before exceptional and extraordinary item and tax (III - V) | D23: =D12-D21 -> -9432613.1 | E23: =E12-E21 -> 2653190.3
A25: VII | B25: Exceptional items/extra-ordinary items | D25: 0 | E25: 0
A27: VIII | B27: Profit before extra-ordinary item and tax (VI - VII) | D27: =D23-D25 -> -9432613.1 | E27: =E23-E25 -> 2653190.3
A29: IX | B29: Profit before tax (VIII) | D29: =D27 -> -9432613.1 | E29: =E27 -> 2653190.3
A30: X | B30: Tax expenses
B31: (1) Current Tax | D31: 0 | E31: =654762.486071762/Deno -> 654762.49
B32: (2) Deferred Tax | D32: 0 | E32: =-37521.6847891985/Deno -> -37521.685
B33: Prior period items
A34: XI | B34: Profit/(Loss) for the period from continuing operation (IX-X) | D34: =D29-D31+D32+D33 -> -9432613.1 | E34: =E29-E31+E32+E33 -> 1960906.2
A36: XII | B36: EPS
B37: Basic | D37: =+(D34/'NOTE 3'!D40)*Deno -> -471.63065 | E37: =+(E34/'NOTE 3'!D30)*Deno -> 98.055113
B38: Diluted | D38: =+D37 -> -471.63065 | E38: =+E37 -> 98.055113
A40: =BS!A44 -> Significant Accounting Policies in Note 1 & 2
A41: The accompanying notes are integral part of the financial statements
A43: As per our report of even date | C43: For and on behalf of
A44: For Kalyanasundaram & Associates | C44: =+BS!B48 -> CARGO INTERNATIONAL (INDIA) PVT. LTD
A45: Chartered accountants
A46: FRN : 005455S
A50: K M Sethu | C50: =+BS!B54 -> Suresh Padmanabhan | E50: =+BS!D54 -> Vignesh Natarajan
A51: Partner | C51: =+BS!B55 -> Director | E51: =+BS!D55 -> Director
A52: M.No.231703 | C52: =+BS!B56 -> DIN: 08284074 | E52: =+BS!D56 -> DIN: 08284068
A53: Place : Chennai | C53: =+BS!B57 -> Place : Birmingham | E53: =+BS!D57 -> Place : Chennai
...

Sheet Sub-Schedule
A1: Advance Paid/Received | B1: Closing Balance as of FY 2025-26 | D1: Closing Balance as of FY 2024-25
A2: Particulars | B2: Debit Rs. | C2: Credit Rs. | D2: Debit Rs. | E2: Credit Rs.
A3: Advance From Debtors
A4: CARGO INTERNATIONAL (INDIA) PRIVATE LTD | B4: 0 | C4: =+'TB 25-26'!P59 -> 14085282 | D4: 0 | E4: 1750 | F4: RPT | G4: Non current
A5: CIL Dubai | B5: 0 | C5: 0 | D5: 0 | E5: 10067831 | F5: RPT | G5: Non current
A6: CARGO INTERNATIONAL LTD | B6: 0 | C6: 0 | D6: 0 | E6: 5866971.3 | F6: RPT | G6: Non current
A7: CARGO INTERNATIONAL (INDIA) PRIVATE LTD | B7: 0 | C7: 0 | D7: 0 | E7: 110628 | F7: RPT | G7: Non current
A8: ADVANCE TO CREDITORS
A9: CARGO INTERNATIONAL LTD | B9: 0 | C9: 0 | D9: 214646.99 | E9: 0 | F9: RPT | G9: Non current
A10: CATHAY PACIFIC | B10: 0 | C10: 0 | D10: 0.3 | E10: 0 | F10: Others | G10: Current
A11: CMA CGM | B11: 0 | C11: 0 | D11: 198625.57 | E11: 0 | F11: Others | G11: Current
A12: CONTAINER CORPORATION OF INDIA LIMITED | B12: 0 | C12: 0 | D12: 193519.1 | E12: 0 | F12: Others | G12: Current
A13: MAERSK | B13: 0 | C13: 0 | D13: 31739.96 | E13: 0 | F13: Others | G13: Current
A14: CARGO INTERNATIONAL (INDIA) PRIVATE LTD | B14: 0 | C14: 0 | D14: 988348 | E14: 0 | F14: RPT | G14: Non current
A15: ASHA LUBE SOLUTIONS PVT LTD | B15: 0 | C15: 0 | D15: 0.18 | E15: 0 | F15: Others | G15: Current
A16: BELL PRINTERS (P) LTD | B16: 0 | C16: 0 | D16: 0 | E16: 9732 | F16: Others | G16: Current
A17: RL FINE CHEM PVT LTD | B17: 0 | C17: 0 | D17: 0 | E17: 19072 | F17: Others | G17: Current
A18: AURONATURE | B18: 0 | C18: 0 | D18: 0 | E18: 33 | F18: Others | G18: Current
A19: EXPRESS CARGO MOVERS | B19: 0 | C19: 0 | D19: 0 | E19: 5220 | F19: Others | G19: Current
A20: SRI VBL ASSOCIATES | B20: 0 | C20: 0 | D20: 0 | E20: 270 | F20: Others | G20: Current
... A32: COGENT EXPORTS | B32: 0 | C32: 0 | D32: 236 | E32: 0 | F32: Others | G32: Current
A34: TOTAL | B34: =SUBTOTAL(9,B4:B33) -> 0 | C34: =SUBTOTAL(9,C4:C33) -> 14085282 | D34: =SUBTOTAL(9,D4:D33) -> 1627116.1 | E34: =SUBTOTAL(9,E4:E33) -> 16474587
C35: =+B34-C34 -> -14085282 | E35: =+D34-E34 -> -14847471 | F35: 14844185
C38: =+C39-B39 -> 0 | E38: =+E39-D39 -> 0 | G38: =+G39-F39 -> 0
B39: =+_xlfn.AGGREGATE(9,0,B42:B42) -> 0 | C39: =+_xlfn.AGGREGATE(9,0,C42:C42) -> 0 | D39: =+_xlfn.AGGREGATE(9,0,D42:D42) -> 0 | E39: =+_xlfn.AGGREGATE(9,0,E42:E42) -> 0 | F39: =+_xlfn.AGGREGATE(9,0,F42:F42) -> 0 | G39: =+_xlfn.AGGREGATE(9,0,G42:G42) -> 0
A40: Provision for Operation | B40: Closing Balance as of FY 2023-24 | D40: During the yr Transaction/Audit entry | F40: Closing Balance as of FY 2024-25
A41: Particulars | B41: Debit Rs. | C41: Credit Rs. | D41: Debit Rs. | E41: Credit Rs. | F41: Debit Rs. | G41: Credit Rs.
A42: Creditors From Provisions GL
A44: Note : Balance in Provision operation has been closed and transferred to reserves

Sheet CFS
A1: =+PL!A1 -> CARGO INTERNATIONAL (INDIA) PRIVATE LIMITED
A2: CASH FLOW STATEMENT FOR THE YEAR ENDED ON 31ST MARCH 2026
A3: CIN: U63000TN2010PTC077296
A4: =+PL!A4 -> Old No.7 / New No.13, First Floor, First Cross Street, Trustpuram, Kodambakkam, Chennai - 600024, India
A5: =+"(Unless otherwise specified, all amounts are "&IF('Master data'!A2="Ones","Indian Rupees","in "&'Master data'!A2&" of INR)") -> (Unless otherwise specified, all amounts are Indian Rupees
A6: Particulars | C6: For Year Ended | D6: For Year Ended
C7: =PL!D7 -> 31st March, 2026 | D7: =PL!E7 -> 31st March, 2025
A9: [A] Cash Flow from Operating Activities:
A11: Profit before Tax | C11: =+PL!D27 -> -9432613.1 | D11: =+PL!E27 -> 2653190.3
A12: Adjustments for non cash items & Non operating activity:
A13: Depreciation | C13: =+PL!D19 -> 264309 | D13: =+PL!E19 -> 269898.93
A14: GST Input reversal | C14: =+'NOTE 4-8'!B12 -> 0 | D14: 0
A15: Provision Operation reversal | C15: =+'NOTE 4-8'!B13 -> 5.8207661e-11 | D15: =+'NOTE 4-8'!C13 -> 14106836
A16: Interest & Finance Charges | C16: =+PL!D17 -> 251861.01 | D16: =+PL!E17 -> 266439.7
A17: Operating Profit before Working Capital changes | C17: =SUM(C11:C16) -> -8916443 | D17: =SUM(D11:D16) -> 17296365
A19: Adjusted for :
A20: (Increase)/Decrease in Loans & Advances | C20: =-BS!C39+BS!D39 -> -7287708.5 | D20: =2222413.90333331/Deno -> 2222413.9
A21: (Increase)/Decrease in Sundry Debtors | C21: =-BS!C37+BS!D37 -> 14889553 | D21: =-36525991.49/Deno -> -36525991
A22: Increase/(Decrease) in Current liabilities | C22: =+BS!C23-BS!D23 -> 18628450 | D22: =35894501.36/Deno -> 35894501
A24: Current year Tax: | C24: =-PL!D31 -> 0 | D24: =-PL!E31 -> -654762.49
A26: Net Cash from Operating Activities | C26: =SUM(C17:C24) -> 17313852 | D26: =SUM(D17:D24) -> 18232527
A28: [B] Cash flow from Investing Activities
A29: Additions to fixed assets | C29: =-'Note 9'!C20+'Note 9'!D20 -> -374327.06 | D29: =-88966.11/Deno -> -88966.11
A30: Increase in Long term loans and advances | C30: =-BS!C33+BS!D33 -> -3398597.2 | D30: =-2301145.87392824/Deno -> -2301145.9
A31: Net cash from/(used in) investing activities | C31: =SUM(C29:C30) -> -3772924.3 | D31: =SUM(D29:D30) -> -2390112
A33: [C] Cash flow from Financing Activities
A34: Interest & Finance Charges | C34: =-C16 -> -251861.01 | D34: =-D16 -> -266439.7
A36: Net cash from/(used in) Financing activities | C36: =SUM(C34:C35) -> -251861.01 | D36: =SUM(D34:D35) -> -266439.7
A38: Net Cash flow during the year [A + B + C] | C38: =C26+C31+C36 -> 13289066 | D38: =D26+D31+D36 -> 15575975
A40: Cash & Cash equivalents (Opening Balance) | C40: =+D41 -> 21693546 | D40: =6117571.56499107/Deno -> 6117571.6
A41: Cash & Cash equivalents (Closing Balance) | C41: =+BS!C38 -> 34223710 | D41: =+BS!D38 -> 21693546
A43: Net Cash flow during the year | C43: =C41-C40 -> 12530164 | D43: =D41-D40 -> 15575975 | E43: =+C38-C43 -> 758902.76 | F43: =+D38-D43 -> 0.30745534
A45: Significant Accounting Policies in Note 1 & 2 | E45: =+E43*Deno -> 758902.76 | F45: =+F43*Deno -> 0.30745534
A46: The accompanying notes are integral part of the financial statements
A48: As per our report of even date | B48: For and on behalf of
A49: For Kalyanasundaram & Associates | B49: =+PL!C44 -> CARGO INTERNATIONAL (INDIA) PVT. LTD
A50: Chartered accountants
A51: FRN : 05455s
A55: K M Sethu | B55: =+PL!C50 -> Suresh Padmanabhan | D55: =+PL!E50 -> Vignesh Natarajan
A56: Partner | B56: Director | D56: =+PL!E51 -> Director
...

Sheet NOTE 3
A1: CARGO INTERNATIONAL (INDIA) PRIVATE LIMITED
A2: NOTES TO THE FINANCIAL STATEMENTS FOR THE YEAR ENDED 31st MARCH, 2026
A3: =+CFS!A4 -> Old No.7 / New No.13, First Floor, First Cross Street, Trustpuram, Kodambakkam, Chennai - 600024, India
E4: =+"(Unless otherwise specified, all amounts are "&IF('Master data'!A2="Ones","Indian Rupees","in "&'Master data'!A2&" of INR)") -> (Unless otherwise specified, all amounts are Indian Rupees
A5: =+'NOTE 4-8'!A5 -> Particulars | D5: As on | E5: As on
D6: =CFS!C7 -> 31st March, 2026 | E6: =CFS!D7 -> 31st March, 2025
A7: NOTE 3 : SHARE CAPITAL
A8: Authorised share capital
A9: Equity Share Capital | D9: =5000000/Deno -> 5000000 | E9: =5000000/Deno -> 5000000 | G9: =10^5 -> 100000
A10: (500,000 equity shares of Rs.10 each)
D11: =D9 -> 5000000 | E11: =E9 -> 5000000
A12: Issued, subscribed and paid up capital
A13: Equity Share Capital | D13: =200000/Deno -> 200000 | E13: =200000/Deno -> 200000
A14: (20,000 equity shares of Rs.10 each)
D15: =SUM(D12:D13) -> 200000 | E15: =SUM(E12:E13) -> 200000
A17: A. Terms and Rights attached to equity shares
A18: The company has only one class of equity shares having a par value of Rs. 10 per share. Each holder of equity share entitled to one vote per share. The company declares and pays dividend in Indian Rupees The dividend proposed by the Board of directors is subject o the approval of the shareholders in the ensuring Annual General Meeting.
A20: During the year ended 31st March 2025, the amount per share dividend recognised as distrubition to shareholders was Rs. NIL (31st march 2024 - NIL)
A23: B. Shareholders holding more than 5 percent of equity shares
A24: Name of the Shareholder | B24: =+D6 -> 31st March, 2026 | D24: =+E6 -> 31st March, 2025
B25: No. Of Shares | C25: % holding | D25: No. Of Shares | E25: % holding
A26: Suresh Padmanabhan | B26: 15998 | C26: =+B26/$B$30 -> 0.79998 | D26: 15998 | E26: =+D26/$B$30 -> 0.79998 | G26: =+D26/20000 -> 0.7999
A27: Ramkumar | B27: 2000 | C27: =+B27/$B$30 -> 0.10001 | D27: 2000 | E27: =+D27/$B$30 -> 0.10001
A28: Prasath | B28: 2000 | C28: =+B28/$B$30 -> 0.10001 | D28: 2000 | E28: =+D28/$B$30 -> 0.10001
A30: Total | B30: =SUM(B26:B29) -> 19998 | C30: =SUM(C26:C29) -> 1 | D30: =SUM(D26:D29) -> 19998 | E30: =SUM(E26:E29) -> 1
A33: C. Reconciliation of shares outstanding at the beginning and at the end of the reporting period.
A35: Particulars | B35: =+B24 -> 31st March, 2026 | D35: =+D24 -> 31st March, 2025
B36: No. Of Shares | C36: Amount | D36: No. Of Shares | E36: Amount
A37: Shares outstanding at the beginning of the year | B37: 20000 | C37: =+B37*10 -> 200000 | D37: 20000 | E37: =+D37*10 -> 200000
A38: Shares issued during the year | B38: 0 | C38: 0 | D38: 0 | E38: =+D38*10 -> 0
A39: Shares bought back during the year | B39: 0 | C39: =+B39*10 -> 0 | D39: 0 | E39: =+D39*10 -> 0
A40: Shares outstanding at the end of the year | B40: =SUM(B37:B39) -> 20000 | C40: =SUM(C37:C39) -> 200000 | D40: =SUM(D37:D39) -> 20000 | E40: =SUM(E37:E39) -> 200000
A43: D. Shares held by promoters at the end of the year
A44: Shares held by promoters at the end of the year 31st March 2026
A45: Name of the Promoter | B45: No. Of Shares | C45: Amount (Rs.) | D45: % of Total shares | E45: % Change during the year 2025
A46: Suresh Padmanabhan | B46: 15998 | C46: =+B46*10 -> 159980 | D46: =+B46/$B$50 -> 0.79998 | E46: =+(C55-C46)/C46 -> 0
A47: Ramkumar | B47: 2000 | C47: =+B47*10 -> 20000 | D47: =+B47/$B$50 -> 0.10001 | E47: =+(C56-C47)/C47 -> 0
A48: Prasath | B48: 2000 | C48: =+B48*10 -> 20000 | D48: =+B48/$B$50 -> 0.10001 | E48: =+(C57-C48)/C48 -> 0
A50: Total | B50: =SUM(B46:B48) -> 19998 | C50: =SUM(C46:C48) -> 199980 | D50: =SUM(D46:D48) -> 1
A53: Shares held by promoters at the end of the year 31st March 2025
...

Sheet Note 1-2
A1: CARGO INTERNATIONAL (INDIA) PRIVATE LIMITED
A2: NOTES TO THE FINANCIAL STATEMENTS FOR THE YEAR ENDED 31st MARCH, 2026
A3: CAPITAL TOWERS, NO.G-3/1, G-3/2 & G-2 DOOR NO.180 KODAMBAKKAM HIGH ROAD, NUNGAMBAKKAM CHENNAI 600034
A5: NOTE 1: GENERAL INFORMATION
A6: CARGO INTERNATIONAL (INDIA) PVT LTD is a Private Limited Company incorporated under the provisions of Companies Act 2013. The company is providing clearing and Forwarding services. The company is providing clearing & forwarding Transport Services to their clients through Air, Road and Sea Transport
A8: NOTE 2: SIGNIFICANT ACCOUNTING POLICIES
A9: 2.1) Basis of preparation of Financial statements:
A10: All financial transactions have been recognized on accrual basis in accordance of companies Act 2013 and Accounting Standards as adopted consistently by the company. The preparation of financial statements in conformity with the GAAP requires that the management makes estimates and assumptions that affect the reported amounts of assets and liabilities, disclosure of contingent liabilities as at the date of the financial statements and the reported amounts of revenue and expenses during the period.
A12: 2.2) Use of Estimates
A13: The preparation of financial statements requires management to make estimates and assumptions that affect the reported amount of asset and liabilities, the disclosure of contingent assets and liabilities on the date of financial statements and the reported amount of revenue and expenses during the period reported. Actual result could differ from those estimates.
A15: 2.3) Property, Plant and Equipment
A16: Property, Plant and Equipment has been accounted at their cost including all expenses such as transportation charges, installation expenses etc., incurred wholly and exclusively for the purpose of putting the assets into the use.
... A40: Contingent Assets are neither disclosed nor provided for in the financial statements.

Sheet NOTE 4-8
A1: =BS!A1 -> CARGO INTERNATIONAL (INDIA) PRIVATE LIMITED
A2: NOTES TO THE FINANCIAL STATEMENTS FOR THE YEAR ENDED 31st MARCH, 2026
A3: CAPITAL TOWERS, NO.G-3/1, G-3/2 & G-2 ,DOOR NO.180 KODAMBAKKAM HIGH ROAD, NUNGAMBAKKAM, CHENNAI - 600034
C4: =+"(Unless otherwise specified, all amounts are "&IF('Master data'!A2="Ones","Indian Rupees","in "&'Master data'!A2&" of INR)") -> (Unless otherwise specified, all amounts are Indian Rupees
A5: Particulars | B5: As on | C5: As on
B6: ='NOTE 3'!D6 -> 31st March, 2026 | C6: ='NOTE 3'!E6 -> 31st March, 2025
A8: NOTE 4 : RESERVES AND SURPLUS
A9: General Reserve
A10: Opening balance | B10: =+C15 -> 19774662 | C10: =3706919.29565958/Deno -> 3706919.3
A11: Add:Net Profit/(Loss) for the current year | B11: =PL!D34 -> -9432613.1 | C11: =PL!E34 -> 1960906.2
A12: Less: GST Input reversal | B12: 0 | C12: 0
A13: Add: Provision operation reversal | B13: =+'Audit entry'!E113/Deno -> 5.8207661e-11 | C13: =14106836.38/Deno -> 14106836
A14: (Refer Note. 21(9))
B15: =SUM(B10:B14) -> 10342049 | C15: =SUM(C10:C14) -> 19774662
A17: NOTE 5 : NON CURRENT LIABILITIES
A18: Other Long term Liabilities | B18: =(SUMIF('Sub-Schedule'!F4:F32,"RPT",'Sub-Schedule'!C4:C32)-SUMIF('Sub-Schedule'!F4:F32,"RPT",'Sub-Schedule'!B4:B32))/(+Deno) -> 14085282 | C18: =(SUMIF('Sub-Schedule'!F4:F32,"RPT",'Sub-Schedule'!E4:E32)-SUMIF('Sub-Schedule'!F4:F32,"RPT",'Sub-Schedule'!D4:D32))/(+Deno) -> 14844185
B20: =SUM(B18:B19) -> 14085282 | C20: =SUM(C18:C19) -> 14844185
A23: NOTE 7 : OTHER CURRENT LIABILITIES
A24: Expense payable | B24: =(+'Sub Sch - BS'!B12) -> 2591375.3 | C24: =(+'Sub Sch - BS'!C12) -> 3730924.3
A25: Other Liabilities | B25: =(SUMIF('TB 25-26'!$Q:$Q,$A25,'TB 25-26'!$P:$P)-SUMIF('TB 25-26'!$Q:$Q,$A25,'TB 25-26'!$O:$O)) -> 38412.64 | C25: =(SUMIF('TB 25-26'!$Q:$Q,$A25,'TB 25-26'!$F:$F)-SUMIF('TB 25-26'!$Q:$Q,$A25,'TB 25-26'!$E:$E)) -> 797544.98
A26: Statutory Dues payables | B26: =(+'Sub Sch - BS'!B25) -> 4581545.8 | C26: =(+'Sub Sch - BS'!C25) -> 4421725.8
B28: =SUM(B24:B27) -> 7211333.7 | C28: =SUM(C24:C27) -> 8950195.1
A30: NOTE 8 : SHORT TERM PROVISIONS
A31: Provision for income tax | B31: =(SUMIF('TB 25-26'!$Q:$Q,$A31,'TB 25-26'!$P:$P)-SUMIF('TB 25-26'!$Q:$Q,$A31,'TB 25-26'!$O:$O)) -> 6752023 | C31: =(SUMIF('TB 25-26'!$Q:$Q,$A31,'TB 25-26'!$F:$F)-SUMIF('TB 25-26'!$Q:$Q,$A31,'TB 25-26'!$E:$E)) -> 6752023
A32: Provisions non business | B32: =(SUMIF('TB 25-26'!$Q:$Q,$A32,'TB 25-26'!$P:$P)-SUMIF('TB 25-26'!$Q:$Q,$A32,'TB 25-26'!$O:$O)) -> 0 | C32: =(SUMIF('TB 25-26'!$Q:$Q,$A32,'TB 25-26'!$F:$F)-SUMIF('TB 25-26'!$Q:$Q,$A32,'TB 25-26'!$E:$E)) -> 0
A33: Provisions operations | B33: =(SUMIF('TB 25-26'!$Q:$Q,$A33,'TB 25-26'!$P:$P)-SUMIF('TB 25-26'!$Q:$Q,$A33,'TB 25-26'!$O:$O)) -> 0 | C33: =(SUMIF('TB 25-26'!$Q:$Q,$A33,'TB 25-26'!$F:$F)-SUMIF('TB 25-26'!$Q:$Q,$A33,'TB 25-26'!$E:$E)) -> 0 | D33: CY tax included
A34: Advance paid \ received | B34: =(SUMIF('Sub-Schedule'!F4:F32,"others",'Sub-Schedule'!C4:C32)-SUMIF('Sub-Schedule'!F4:F32,"others",'Sub-Schedule'!B4:B32))/(+Deno) -> 0 | C34: =(SUMIF('Sub-Schedule'!F4:F32,"Others",'Sub-Schedule'!E4:E32)-SUMIF('Sub-Schedule'!F4:F32,"Others",'Sub-Schedule'!D4:D32))/(+Deno) -> 3285.8
B36: =SUM(B31:B35) -> 6752023 | C36: =SUM(C31:C35) -> 6755308.8

Sheet NOTE 6
A1: =BS!A1 -> CARGO INTERNATIONAL (INDIA) PRIVATE LIMITED
A2: NOTES TO THE FINANCIAL STATEMENTS FOR THE YEAR ENDED 31st MARCH, 2026
A3: CAPITAL TOWERS, NO.G-3/1, G-3/2 & G-2 ,DOOR NO.180 KODAMBAKKAM HIGH ROAD, NUNGAMBAKKAM, CHENNAI - 600034
A5: NOTE 6 : TRADE PAYABLES
A6: Sundry creditors
G7: =+"(Unless otherwise specified, all amounts are "&IF('Master data'!A2="Ones","Indian Rupees","in "&'Master data'!A2&" of INR)") -> (Unless otherwise specified, all amounts are Indian Rupees
A8: Particulars | B8: As on Mar 31,2026
B9: Outstanding for following periods from due date of payment
B10: Less than 6 months | C10: 6 months to 1 year | D10: 1 - 2 years | E10: 2 - 3 years | F10: more than 3 years | G10: TOTAL
I11: Checking
A12: MSME | B12: =0/(+Deno) -> 0 | C12: =0/(+Deno) -> 0 | D12: =0/(+Deno) -> 0 | E12: =0/(+Deno) -> 0 | F12: =0/(+Deno) -> 0 | G12: 0 | H12: Ageing | I12: =+G17 -> 1.1079895e+08
A13: Others | B13: =0/(+Deno) -> 0 | C13: 78071781 | D13: 31486478 | E13: 86142.71 | F13: 1154548.9 | G13: =+SUM(B13:F13) -> 1.1079895e+08 | H13: TB | I13: =+'TB 25-26'!P88+'TB 25-26'!P89+'TB 25-26'!P91-'TB 25-26'!O90 -> 1.1079895e+08
A14: Disputed Dues (MSME) | B14: =0/(+Deno) -> 0 | C14: =0/(+Deno) -> 0 | D14: =0/(+Deno) -> 0 | E14: =0/(+Deno) -> 0 | F14: =0/(+Deno) -> 0 | G14: 0 | I14: =+I12-I13 -> 0.30817801
A15: Disputed Dues (Others) | B15: =0/(+Deno) -> 0 | C15: =0/(+Deno) -> 0 | D15: =0/(+Deno) -> 0 | E15: =0/(+Deno) -> 0 | F15: =0/(+Deno) -> 0 | G15: 0
A17: TOTAL | B17: =SUM(B12:B16) -> 0 | C17: =SUM(C12:C16) -> 78071781 | D17: =SUM(D12:D16) -> 31486478 | E17: =SUM(E12:E16) -> 86142.71 | F17: =SUM(F12:F16) -> 1154548.9 | G17: =SUM(G12:G16) -> 1.1079895e+08
A20: Particulars | B20: As on Mar 31, 2025
B21: Outstanding for following periods from due date of payment
B22: Less than 6 months | C22: 6 months to 1 year | D22: 1 - 2 years | E22: 2 - 3 years | F22: more than 3 years | G22: TOTAL
A24: MSME | B24: =0/(+Deno) -> 0 | C24: =0/(+Deno) -> 0 | D24: =0/(+Deno) -> 0 | E24: =0/(+Deno) -> 0 | F24: =0/(+Deno) -> 0 | G24: =+SUM(B24:F24) -> 0
A25: Others | B25: 0 | C25: =87765031.46/Deno -> 87765031 | D25: =1246926.2/Deno -> 1246926.2 | E25: =431714.91/Deno -> 431714.91 | F25: =984680.99/Deno -> 984680.99 | G25: =+SUM(B25:F25) -> 90428354
A26: Disputed Dues (MSME) | B26: =0/(+Deno) -> 0 | C26: =0/(+Deno) -> 0 | D26: =0/(+Deno) -> 0 | E26: =0/(+Deno) -> 0 | F26: =0/(+Deno) -> 0 | G26: =+SUM(B26:F26) -> 0
A27: Disputed Dues (Others) | B27: =0/(+Deno) -> 0 | C27: =0/(+Deno) -> 0 | D27: =0/(+Deno) -> 0 | E27: =0/(+Deno) -> 0 | F27: =0/(+Deno) -> 0 | G27: =+SUM(B27:F27) -> 0
A29: TOTAL | B29: =SUM(B24:B28) -> 0 | C29: =SUM(C24:C28) -> 87765031 | D29: =SUM(D24:D28) -> 1246926.2 | E29: =SUM(E24:E28) -> 431714.91 | F29: =SUM(F24:F28) -> 984680.99 | G29: =SUM(G24:G28) -> 90428354
B33: Note : Amount is derived from TP reconcilation from Ageing folder
C35: =+Deno -> 1

Sheet NOTE 12
A1: =BS!A1 -> CARGO INTERNATIONAL (INDIA) PRIVATE LIMITED
A2: NOTES TO THE FINANCIAL STATEMENTS FOR THE YEAR ENDED 31st MARCH, 2026
A3: CAPITAL TOWERS, NO.G-3/1, G-3/2 & G-2 ,DOOR NO.180 KODAMBAKKAM HIGH ROAD, NUNGAMBAKKAM, CHENNAI - 600034
A5: NOTE 12 : TRADE RECEIVABLES
A6: Sundry Debtors
G8: =+"(Unless otherwise specified, all amounts are "&IF('Master data'!A2="Ones","Indian Rupees","in "&'Master data'!A2&" of INR)") -> (Unless otherwise specified, all amounts are Indian Rupees
A9: Particulars | B9: As on Mar 31,2026
B10: Outstanding for following periods from due date of payment
B11: Less than 6 months | C11: 6 months to 1 year | D11: 1 - 2 years | E11: 2 - 3 years | F11: more than 3 years | G11: TOTAL | I11: Checking
H12: Ageing | I12: =+G18 -> 75016042
A13: Undisputed Trade receivables considered Good | B13: 72503775 | C13: 322480.64 | D13: 25493.98 | E13: 2164293.1 | F13: 0 | G13: =SUM(B13:F13) -> 75016042 | H13: TB | I13: =+'TB 25-26'!O20+'TB 25-26'!O21 -> 75016042
A14: Undisputed Trade receivables considered doubtful | B14: 0 | C14: 0 | D14: 0 | E14: 0 | F14: 0 | G14: =SUM(B14:F14) -> 0 | I14: =+I12-I13 -> 0
A15: Disputed Trade receivable considered Good | B15: 0 | C15: 0 | D15: 0 | E15: 0 | F15: 0 | G15: =SUM(B15:F15) -> 0
A16: Disputed Trade receivable considered doubtful | B16: 0 | C16: 0 | D16: 0 | E16: 0 | F16: 0 | G16: =SUM(B16:F16) -> 0
A18: TOTAL | B18: =SUM(B13:B17) -> 72503775 | C18: =SUM(C13:C17) -> 322480.64 | D18: =SUM(D13:D17) -> 25493.98 | E18: =SUM(E13:E17) -> 2164293.1 | F18: =SUM(F13:F17) -> 0 | G18: =SUM(G13:G17) -> 75016042
A21: Particulars | B21: As on Mar 31, 2025
B22: Outstanding for following periods from due date of payment
B23: Less than 6 months | C23: 6 months to 1 year | D23: 1 - 2 years | E23: 2 - 3 years | F23: more than 3 years | G23: TOTAL
A25: Undisputed Trade receivables considered Good | B25: 0 | C25: =61414470.29/Deno -> 61414470 | D25: =149040.24/Deno -> 149040.24 | E25: =19056.25/Deno -> 19056.25 | F25: =28323028.71/Deno -> 28323029 | G25: =SUM(B25:F25) -> 89905595
A26: Undisputed Trade receivables considered doubtful | B26: =0/(+Deno) -> 0 | C26: =0/(+Deno) -> 0 | D26: =0/(+Deno) -> 0 | E26: =0/(+Deno) -> 0 | F26: =0/(+Deno) -> 0 | G26: =SUM(B26:F26) -> 0
A27: Disputed Trade receivable considered Good | B27: =0/(+Deno) -> 0 | C27: =0/(+Deno) -> 0 | D27: =0/(+Deno) -> 0 | E27: 0 | F27: =0/(+Deno) -> 0 | G27: =SUM(B27:F27) -> 0
A28: Disputed Trade receivable considered doubtful | B28: =0/(+Deno) -> 0 | C28: =0/(+Deno) -> 0 | D28: =0/(+Deno) -> 0 | E28: =0/(+Deno) -> 0 | F28: =0/(+Deno) -> 0 | G28: =SUM(B28:F28) -> 0
A30: TOTAL | B30: =SUM(B25:B29) -> 0 | C30: =SUM(C25:C29) -> 61414470 | D30: =SUM(D25:D29) -> 149040.24 | E30: =SUM(E25:E29) -> 19056.25 | F30: =SUM(F25:F29) -> 28323029 | G30: =SUM(G25:G29) -> 89905595

Sheet Note 9
A1: CARGO INTERNATIONAL (INDIA) PRIVATE LIMITED
A2: =+'NOTE 4-8'!A2:C2 -> NOTES TO THE FINANCIAL STATEMENTS FOR THE YEAR ENDED 31st MARCH, 2026
A3: =+'NOTE 4-8'!A3:C3 -> CAPITAL TOWERS, NO.G-3/1, G-3/2 & G-2 ,DOOR NO.180 KODAMBAKKAM HIGH ROAD, NUNGAMBAKKAM, CHENNAI - 600034
A5: Note 9 - Property, Plant & Equipment
K6: =+"(Unless otherwise specified, all amounts are "&IF('Master data'!A2="Ones","Indian Rupees","in "&'Master data'!A2&" of INR)") -> (Unless otherwise specified, all amounts are Indian Rupees
A7: Asset Category | B7: Gross Block | F7: Depreciation | J7: Net Block
B8: As on 01.04.2025 | C8: Additions | D8: Deletion | E8: As on 31.03.2026 | F8: =+B8 -> As on 01.04.2025 | G8: For the Year | H8: Deletion | I8: =+E8 -> As on 31.03.2026 | J8: =+I8 -> As on 31.03.2026 | K8: =+B8 -> As on 01.04.2025
A11: Tangible Assets
A12: Motor Car | B12: =0/(Deno) -> 0 | C12: 0 | D12: =(0/(+Deno))/(Deno) -> 0 | E12: =B12+C12-D12 -> 0 | F12: =0/Deno -> 0 | G12: 0 | H12: =(0/(+Deno))/(Deno) -> 0 | I12: =F12+G12-H12 -> 0 | J12: =+E12-I12 -> 0 | K12: =+B12-F12 -> 0
A13: Interior Decoration | B13: =4191829.7/Deno -> 4191829.7 | C13: 0 | D13: =(0/(+Deno))/(Deno) -> 0 | E13: =B13+C13-D13 -> 4191829.7 | F13: =3810368.44087299/Deno -> 3810368.4 | G13: =99731/Deno -> 99731 | H13: =(0/(+Deno))/(Deno) -> 0 | I13: =F13+G13-H13 -> 3910099.4 | J13: =+E13-I13 -> 281730.26 | K13: =+B13-F13 -> 381461.26
A14: Computers | B14: =1880526.16/Deno -> 1880526.2 | C14: =162329/Deno -> 162329 | D14: =(0/(+Deno))/(Deno) -> 0 | E14: =B14+C14-D14 -> 2042855.2 | F14: =1756838.07066679/Deno -> 1756838.1 | G14: =90412/Deno -> 90412 | H14: =(0/(+Deno))/(Deno) -> 0 | I14: =F14+G14-H14 -> 1847250.1 | J14: =+E14-I14 -> 195605.09 | K14: =+B14-F14 -> 123688.09
A15: Communication Equiptments | B15: =381194/Deno -> 381194 | C15: 0 | D15: =(0/(+Deno))/(Deno) -> 0 | E15: =B15+C15-D15 -> 381194 | F15: =362133/Deno -> 362133 | G15: 0 | H15: =(0/(+Deno))/(Deno) -> 0 | I15: =F15+G15-H15 -> 362133 | J15: =+E15-I15 -> 19061 | K15: =+B15-F15 -> 19061
A16: Furniture and fixtures | B16: =1288569.39/Deno -> 1288569.4 | C16: =94800/Deno -> 94800 | D16: =(0/(+Deno))/(Deno) -> 0 | E16: =B16+C16-D16 -> 1383369.4 | F16: =1195047.52885793/Deno -> 1195047.5 | G16: =32819/Deno -> 32819 | H16: =(0/(+Deno))/(Deno) -> 0 | I16: =F16+G16-H16 -> 1227866.5 | J16: =+E16-I16 -> 155502.86 | K16: =+B16-F16 -> 93521.861
A17: Electrical equipments | B17: =720330.5/Deno -> 720330.5 | C17: =35178/Deno -> 35178 | D17: =(0/(+Deno))/(Deno) -> 0 | E17: =B17+C17-D17 -> 755508.5 | F17: =649873.945150916/Deno -> 649873.95 | G17: =22039/Deno -> 22039 | H17: =(0/(+Deno))/(Deno) -> 0 | I17: =F17+G17-H17 -> 671912.95 | J17: =+E17-I17 -> 83595.555 | K17: =+B17-F17 -> 70456.555
A18: Office Equipments | B18: =571389.5/Deno -> 571389.5 | C18: =82020.06/Deno -> 82020.06 | D18: =(0/(+Deno))/(Deno) -> 0 | E18: =B18+C18-D18 -> 653409.56 | F18: =526369.013742537/Deno -> 526369.01 | G18: =19308/Deno -> 19308 | H18: =(0/(+Deno))/(Deno) -> 0 | I18: =F18+G18-H18 -> 545677.01 | J18: =+E18-I18 -> 107732.55 | K18: =+B18-F18 -> 45020.486
A20: Total | B20: =SUM(B12:B18) -> 9033839.2 | C20: =SUM(C12:C18) -> 374327.06 | D20: =SUM(D12:D18) -> 0 | E20: =SUM(E12:E18) -> 9408166.3 | F20: =SUM(F12:F18) -> 8300630 | G20: =SUM(G12:G18) -> 264309 | H20: =SUM(H12:H18) -> 0 | I20: =SUM(I12:I18) -> 8564939 | ... K20: =SUM(K12:K18) -> 733209.25
A22: Previous Year figure | B22: =8944873.14/Deno -> 8944873.1 | C22: =88966.11/Deno -> 88966.11 | D22: 0 | E22: =9033839.25/Deno -> 9033839.2 | F22: =8030731.06929116/Deno -> 8030731.1 | G22: =269898.93/Deno -> 269898.93 | H22: 0 | I22: =8300629.99929116/Deno -> 8300630 | J22: =733209.250708837/Deno -> 733209.25 | K22: =914142.070708837/Deno -> 914142.07

Sheet NOTE 10-14
A1: =BS!A1 -> CARGO INTERNATIONAL (INDIA) PRIVATE LIMITED
A2: NOTES TO THE FINANCIAL STATEMENTS FOR THE YEAR ENDED 31st MARCH, 2026
A3: CAPITAL TOWERS, NO.G-3/1, G-3/2 & G-2 ,DOOR NO.180 KODAMBAKKAM HIGH ROAD, NUNGAMBAKKAM, CHENNAI - 600034
C4: =+"(Unless otherwise specified, all amounts are "&IF('Master data'!A2="Ones","Indian Rupees","in "&'Master data'!A2&" of INR)") -> (Unless otherwise specified, all amounts are Indian Rupees
A5: Particulars | B5: As on | C5: As on
B6: ='NOTE 4-8'!B6 -> 31st March, 2026 | C6: ='NOTE 4-8'!C6 -> 31st March, 2025
A8: NOTE 10 : LONG TERM LOANS AND ADVANCES
A9: Rental Deposit | B9: =(SUMIF('TB 25-26'!$Q:$Q,$A9,'TB 25-26'!$O:$O)-SUMIF('TB 25-26'!$Q:$Q,$A9,'TB 25-26'!$P:$P)) -> 1633680.5 | C9: =(SUMIF('TB 25-26'!$Q:$Q,$A9,'TB 25-26'!$E:$E)-SUMIF('TB 25-26'!$Q:$Q,$A9,'TB 25-26'!$F:$F)) -> 1669658
A10: TDS Receivable | B10: =(SUMIF('TB 25-26'!$Q:$Q,$A10,'TB 25-26'!$O:$O)-SUMIF('TB 25-26'!$Q:$Q,$A10,'TB 25-26'!$P:$P)) -> 24548794 | C10: =(SUMIF('TB 25-26'!$Q:$Q,$A10,'TB 25-26'!$E:$E)-SUMIF('TB 25-26'!$Q:$Q,$A10,'TB 25-26'!$F:$F)) -> 21114220
B12: =SUM(B9:B11) -> 26182475 | C12: =SUM(C9:C11) -> 22783878
A14: NOTE 11 : DEFERRED TAX ASSETS
A15: Opening Balance | B15: =+C18 -> 597436.01 | C15: =634957.698/Deno -> 634957.7
A16: Add: Current year | B16: =PL!D32 -> 0 | C16: =PL!E32 -> -37521.685
A18: Deferred Tax Assets/(Liabilty) | B18: =SUM(B15:B17) -> 597436.01 | C18: =SUM(C15:C17) -> 597436.01
A20: NOTE 13 : CASH AND CASH EQUIVALENTS
A21: Balance with banks | B21: =(+'Sub Sch - BS'!B38) -> 34165323 | C21: =(+'Sub Sch - BS'!C38) -> 21677245
A22: Cash on hand | B22: =(+'Sub Sch - BS'!B32) -> 58384.78 | C22: =(+'Sub Sch - BS'!C32) -> 16299.65
B24: =SUM(B21:B23) -> 34223708 | C24: =SUM(C21:C23) -> 21693544
A26: NOTE 14 : SHORT TERM LOANS AND ADVANCES
A27: GST Input tax credit | B27: =(+'Sub Sch - BS'!B44) -> 12185083 | C27: =(+'Sub Sch - BS'!C44) -> 5065070
A28: Prepaid Expenses | B28: =(SUMIF('TB 25-26'!$Q:$Q,$A28,'TB 25-26'!$O:$O)-SUMIF('TB 25-26'!$Q:$Q,$A28,'TB 25-26'!$P:$P)) -> 246134.41 | C28: =(SUMIF('TB 25-26'!$Q:$Q,$A28,'TB 25-26'!$E:$E)-SUMIF('TB 25-26'!$Q:$Q,$A28,'TB 25-26'!$F:$F)) -> 130788.23
A29: Staff Advance | B29: =(SUMIF('TB 25-26'!$Q:$Q,$A29,'TB 25-26'!$O:$O)-SUMIF('TB 25-26'!$Q:$Q,$A29,'TB 25-26'!$P:$P)) -> 95531.24 | C29: =(SUMIF('TB 25-26'!$Q:$Q,$A29,'TB 25-26'!$E:$E)-SUMIF('TB 25-26'!$Q:$Q,$A29,'TB 25-26'!$F:$F)) -> 43181.74
B31: =SUM(B27:B30) -> 12526748 | C31: =SUM(C27:C30) -> 5239040

Sheet NOTE 15-20
A1: CARGO INTERNATIONAL (INDIA) PRIVATE LIMITED
A2: =+'NOTE 3'!A2:E2 -> NOTES TO THE FINANCIAL STATEMENTS FOR THE YEAR ENDED 31st MARCH, 2026
C4: =+"(Unless otherwise specified, all amounts are "&IF('Master data'!A2="Ones","Indian Rupees","in "&'Master data'!A2&" of INR)") -> (Unless otherwise specified, all amounts are Indian Rupees
A5: Particulars | B5: For Year Ended | C5: For Year Ended
B6: ='NOTE 10-14'!B6 -> 31st March, 2026 | C6: ='NOTE 10-14'!C6 -> 31st March, 2025
A8: NOTE 15 : REVENUE FROM OPERATIONS
A9: Export Operating Income | B9: =(SUMIF('TB 25-26'!$Q:$Q,'NOTE 15-20'!$A9,'TB 25-26'!$P:$P)-SUMIF('TB 25-26'!$Q:$Q,'NOTE 15-20'!$A9,'TB 25-26'!$O:$O)) -> 96649856 | C9: =(SUMIF('TB 25-26'!$Q:$Q,'NOTE 15-20'!$A9,'TB 25-26'!$F:$F)-SUMIF('TB 25-26'!$Q:$Q,'NOTE 15-20'!$A9,'TB 25-26'!$E:$E)) -> 1.414428e+08
A10: Import Operating Income | B10: =(SUMIF('TB 25-26'!$Q:$Q,'NOTE 15-20'!$A10,'TB 25-26'!$P:$P)-SUMIF('TB 25-26'!$Q:$Q,'NOTE 15-20'!$A10,'TB 25-26'!$O:$O)) -> 26473503 | C10: =(SUMIF('TB 25-26'!$Q:$Q,'NOTE 15-20'!$A10,'TB 25-26'!$F:$F)-SUMIF('TB 25-26'!$Q:$Q,'NOTE 15-20'!$A10,'TB 25-26'!$E:$E)) -> 27374244
A11: Air Export Revenue Account | B11: =(SUMIF('TB 25-26'!$Q:$Q,'NOTE 15-20'!$A11,'TB 25-26'!$P:$P)-SUMIF('TB 25-26'!$Q:$Q,'NOTE 15-20'!$A11,'TB 25-26'!$O:$O)) -> 54512717 | C11: =(SUMIF('TB 25-26'!$Q:$Q,'NOTE 15-20'!$A11,'TB 25-26'!$F:$F)-SUMIF('TB 25-26'!$Q:$Q,'NOTE 15-20'!$A11,'TB 25-26'!$E:$E)) -> 72299417
A12: Air Import Revenue Account | B12: =(SUMIF('TB 25-26'!$Q:$Q,'NOTE 15-20'!$A12,'TB 25-26'!$P:$P)-SUMIF('TB 25-26'!$Q:$Q,'NOTE 15-20'!$A12,'TB 25-26'!$O:$O)) -> 13227934 | C12: =(SUMIF('TB 25-26'!$Q:$Q,'NOTE 15-20'!$A12,'TB 25-26'!$F:$F)-SUMIF('TB 25-26'!$Q:$Q,'NOTE 15-20'!$A12,'TB 25-26'!$E:$E)) -> 9940420.3
B14: =SUM(B9:B13) -> 1.9086401e+08 | C14: =SUM(C9:C13) -> 2.5105688e+08
A16: NOTE 16 : OTHER INCOME
A17: Service Job Revenue | B17: =(SUMIF('TB 25-26'!$Q:$Q,'NOTE 15-20'!$A17,'TB 25-26'!$P:$P)-SUMIF('TB 25-26'!$Q:$Q,'NOTE 15-20'!$A17,'TB 25-26'!$O:$O)) -> 5007389.7 | C17: =(SUMIF('TB 25-26'!$Q:$Q,'NOTE 15-20'!$A17,'TB 25-26'!$F:$F)-SUMIF('TB 25-26'!$Q:$Q,'NOTE 15-20'!$A17,'TB 25-26'!$E:$E)) -> 6273672.8
A18: Interest Income | B18: =(SUMIF('TB 25-26'!$Q:$Q,'NOTE 15-20'!$A18,'TB 25-26'!$P:$P)-SUMIF('TB 25-26'!$Q:$Q,'NOTE 15-20'!$A18,'TB 25-26'!$O:$O)) -> 9161 | C18: =(SUMIF('TB 25-26'!$Q:$Q,'NOTE 15-20'!$A18,'TB 25-26'!$F:$F)-SUMIF('TB 25-26'!$Q:$Q,'NOTE 15-20'!$A18,'TB 25-26'!$E:$E)) -> 1397
B20: =SUM(B17:B19) -> 5016550.7 | C20: =SUM(C17:C19) -> 6275069.8
A22: NOTE 17 : OPERATING EXPENSES
A23: Export Operating Expenses | B23: =(SUMIF('TB 25-26'!$Q:$Q,'NOTE 15-20'!$A23,'TB 25-26'!$O:$O)-SUMIF('TB 25-26'!$Q:$Q,'NOTE 15-20'!$A23,'TB 25-26'!$P:$P)) -> 80535247 | C23: =(SUMIF('TB 25-26'!$Q:$Q,'NOTE 15-20'!$A23,'TB 25-26'!$E:$E)-SUMIF('TB 25-26'!$Q:$Q,'NOTE 15-20'!$A23,'TB 25-26'!$F:$F)) -> 1.1760631e+08
A24: Import Operating Expenses | B24: =(SUMIF('TB 25-26'!$Q:$Q,'NOTE 15-20'!$A24,'TB 25-26'!$O:$O)-SUMIF('TB 25-26'!$Q:$Q,'NOTE 15-20'!$A24,'TB 25-26'!$P:$P)) -> 22075934 | C24: =(SUMIF('TB 25-26'!$Q:$Q,'NOTE 15-20'!$A24,'TB 25-26'!$E:$E)-SUMIF('TB 25-26'!$Q:$Q,'NOTE 15-20'!$A24,'TB 25-26'!$F:$F)) -> 24087738
A25: Air Export Operating Expenses | B25: =(SUMIF('TB 25-26'!$Q:$Q,'NOTE 15-20'!$A25,'TB 25-26'!$O:$O)-SUMIF('TB 25-26'!$Q:$Q,'NOTE 15-20'!$A25,'TB 25-26'!$P:$P)) -> 46072304 | C25: =(SUMIF('TB 25-26'!$Q:$Q,'NOTE 15-20'!$A25,'TB 25-26'!$E:$E)-SUMIF('TB 25-26'!$Q:$Q,'NOTE 15-20'!$A25,'TB 25-26'!$F:$F)) -> 65618241
A26: Air Import Operating Expenses | B26: =(SUMIF('TB 25-26'!$Q:$Q,'NOTE 15-20'!$A26,'TB 25-26'!$O:$O)-SUMIF('TB 25-26'!$Q:$Q,'NOTE 15-20'!$A26,'TB 25-26'!$P:$P)) -> 10518022 | C26: =(SUMIF('TB 25-26'!$Q:$Q,'NOTE 15-20'!$A26,'TB 25-26'!$E:$E)-SUMIF('TB 25-26'!$Q:$Q,'NOTE 15-20'!$A26,'TB 25-26'!$F:$F)) -> 8054463.1
