Workbook
Name _Hlk135152171: 'Accounting Polices'!$C$26
Name _Hlk525235484: 'Accounting Polices'!$C$44
Name OLE_LINK1: 'Balance Sheet Notes'!#REF!

Sheet About Sheet
A1: TallyOnWheels - Financial Report
A2: Thank you for using Tallyonwheels.
A3: This file is an Excel output of your Financial Report.
A5: Company Name | B5: K.U.M. India Private Limited - (from 1-Apr-23)
A6: Entity Name | B6: Ramanujam & Boovarahan
A7: Financial year | B7: 01-APR-2023 - 31-MAR-2024
A8: Last Synced | B8: 16-MAY-2024 11:27:32AM

Sheet Master Sheet
A1: Basic Details | C1: Data Entry
A2: Company Name | C2: K.U.M. India Private Limited - (from 1-Apr-24)
A3: Current Financial Year | C3: 01-Apr-2024 - 31-Mar-2025
A4: Assessment Year
A5: Rounding Off | C5: Amount in ₹.
A6: Divisor | C6: =VLOOKUP(C5,A40:B45,2,0) -> 1
A7: Name of the Auditee
A8: Nature of Organisation of the Auditee
A9: Address of the Auditee | B9: Line 1 | C9: A5 second floor,
B10: Line 2 | C10: Rajeswari Apartments, 45 Vellalar street,
B11: Line 3 | C11: Kodambakkam,
B12: Line 4 | C12: Chennai- 600024.
A13: PAN
A14: Name of the Person Signing the Auditee's FS | B14: Signatory 1
B15: Signatory 2
B16: Signatory 3
A17: Designation of the Sigining Person | B17: Signatory 1
B18: Signatory 2
B19: Signatory 3
A20: DIN of | B20: Signatory 1
B21: Signatory 2
B22: Signatory 3
A23: Firm Name
A24: ICAI Firm Reg No.
A25: Name of the Signing Partner
A26: Designation of the Signing CA
A27: Membership Number of the Signing Partner
A28: UDIN
A29: Date of Signing the Financials by auditor
A30: Date of Signing the Financials by | B30: Signatory 1
B31: Signatory 2
B32: Signatory 3
A33: Place of Signing the Financials by auditor
A34: Place of Signing the Financials by signatories
A35: Sector (of the Auditee)
A36: Sub-Sector (of the Auditee)
A37: Code (as per Form 3CD)
A38: CIN of Company | C38: U29100TN2020PTC135386
A39: Date of Incorporation | C39: 43972
A40: Amount in ₹. | B40: 1
...

Sheet TB
A1: K.U.M. India Private Limited 24-25
A2: Trial Balance
A3: 1-Apr-24 to 31-Mar-25
B4: K.U.M. India Private Limited 24-25
A5: Particulars | B5: 1-Apr-24 to 31-Mar-25
B6: Opening | C6: Transactions | E6: Closing
B7: Balance | C7: Debit | D7: Credit | E7: Balance
A8: Capital Account | B8: 1500000 | E8: 1500000
A9: Authorised Share Capital | B9: 1500000 | E9: 1500000
A10: Loans (Liability) | B10: 11277225 | E10: 11277225
A11: External Commercial Borrowings | B11: 11277225 | E11: 11277225 | K11: will be repaid after 5 years
A12: Current Liabilities | B12: 22642240 | C12: 24428651 | D12: 1840733.9 | E12: 54323.08
A13: Duties & Taxes | B13: 3433207.7 | C13: 3754082.7 | D13: 326355.5 | E13: 5480.5
A14: GST Liability | C14: 284050 | D14: 284050
A15: GST RCM Payable | B15: 3421681.7 | C15: 3441481.7 | D15: 21600 | E15: 1800
A16: Professional Tax | C16: 2500 | D16: 2500
A17: TDS - Contracts | B17: 616 | C17: 2241 | D17: 1855.5 | E17: 230.5
A18: TDS-Professional Services | B18: 10910 | C18: 23810 | D18: 16350 | E18: 3450
A19: Sundry Creditors | B19: 18999343 | C19: 19207390 | D19: 208047.33
A20: Expenses O/s | B20: 208082.4 | C20: 1443321.9 | D20: 1282239.1 | E20: 46999.58
A21: Audit Fee Payable A/c | B21: 67500 | C21: 67500
A22: DB Schenker A/c | C22: 133884.1 | D22: 133884.1
A23: Dinesh A/c | C23: 162604 | D23: 162604 | L23: He is not taking any remuneration
A24: ECB2 Return Filing Charges Payable | B24: 1500 | C24: 1500 | D24: 1000 | E24: 1000
A25: Hapag Lloyd A/c | B25: 85904 | C25: 85904
A26: ICEGATE | C26: 53732 | D26: 53732 | L26: customs duty
A27: Integrated Registry Management Services | C27: 5900 | D27: 5900
A28: Ms.Subhashini | B28: 41178.4 | C28: 538678.82 | D28: 537500 | E28: 39999.58
A29: Professional Fees Payable A/c | B29: 12000 | C29: 12000 | D29: 6000 | E29: 6000
A30: RBCA | C30: 103140 | D30: 103140
A31: RBJV Associates | C31: 158479 | D31: 158479
A32: Vanitha A/c | C32: 120000 | D32: 120000
A33: Deferred Tax Liability | B33: 1607 | E33: 1607
A34: DHL Express | C34: 5310 | D34: 5310
A35: Ms Rajarajeshwari | C35: 2000 | D35: 2000
A36: Ms Subhashini - Reimbursement | C36: 16545.98 | D36: 16781.98 | E36: 236
A37: Fixed Assets | B37: 18426.28 | D37: 15914 | E37: 2512.28
A38: Laptop A/c | B38: 18426.28 | D38: 15914 | E38: 2512.28
A39: Current Assets | B39: 31634446 | C39: 4.1666863e+08 | D39: 4.3891241e+08 | E39: 9390663.6
A40: Deposits (Asset) | C40: 191200000 | D40: 191200000
...

Sheet Sheet1
B2: K.U.M. India Private Limited 25-26
B3: Trial Balance
B4: 1-Apr-25 to 31-Mar-26
C5: K.U.M. India Private Limited 25-26
B6: Particulars | C6: 1-Apr-25 to 31-Mar-26
C7: Opening | D7: Transactions | F7: Closing
C8: Balance | D8: Debit | E8: Credit | F8: Balance
B9: Capital Account | C9: 1500000 | F9: 1500000
B10: Authorised Share Capital | C10: 1500000 | F10: 1500000
B11: Loans (Liability) | C11: 11540575 | D11: 11540575
B12: External Commercial Borrowings | C12: 11540575 | D12: 11540575
B13: Current Liabilities | C13: 135216.5 | D13: 52555948 | E13: 52557032 | F13: 136300
B14: Duties & Taxes | C14: 13730.5 | D14: 13450598 | E14: 13454667 | F14: 17800
B15: GST RCM Payable | C15: 1800 | D15: 5616712 | E15: 5616712 | F15: 1800
B16: Output CGST Payable A/c | D16: 3897000 | E16: 3897000
B17: Output SGST Payable A/c | D17: 3897000 | E17: 3897000
B18: Professional Tax | D18: 2500 | E18: 2500
B19: TDS - Contracts | C19: 230.5 | D19: 10185.5 | E19: 9955
B20: TDS-Professional Services | C20: 11700 | D20: 27200 | E20: 31500 | F20: 16000
B21: Sundry Creditors | D21: 27181386 | E21: 31083954 | F21: 3902568
B22: KUM Germany Creditors-Lease Charges | D22: 27181386 | E22: 27181386
B23: KUM Germany Creditors-Mobalisation Charges | E23: 3902568
B24: Expenses O/s | C24: 121250 | D24: 11906635 | E24: 8001317.1 | F24: 3784068
B25: 6 LABS EUROPE GMBH | D25: 6558750 | E25: 6558750
B26: Airtel | D26: 236 | E26: 236
B27: Audit Fee Payable A/c | C27: 74250 | D27: 74250 | E27: 112500 | F27: 112500
B28: ECB2 Return Filing Charges Payable | C28: 1000 | D28: 1000
B29: ICEGATE | D29: 1000 | E29: 1000
B30: Integrated Registry Management Services | D30: 5900 | E30: 5900
B31: KUM Germany Creditors- Mobilisation Charges Payable | D31: 3902568 | F31: 3902568
B32: Ms.Subhashini | C32: 40000 | D32: 357500 | E32: 317500
B33: NSDL | D33: 5900 | E33: 5900
B34: Professional Fees Payable A/c | C34: 6000 | D34: 6000 | E34: 6000 | F34: 6000
B35: RBCA | D35: 89100 | E35: 89100
B36: RBJV Associates | D36: 207054 | E36: 207054
B37: Tripadam Logistics Private Limited | D37: 484577.08 | E37: 484577.08
B38: Vanitha A/c | D38: 120000 | E38: 120000
B39: Virogreen | D39: 92800 | E39: 92800
B40: Deepika | D40: 10000 | E40: 10000
B41: Ms Subhashini - Reimbursement | C41: 236 | D41: 7329.46 | E41: 7093.46
...

Sheet Working TB
B2: K.U.M India Private Limited
B3: ='Master Sheet'!C9&'Master Sheet'!C10&'Master Sheet'!C11&'Master Sheet'!C12 -> A5 second floor,Rajeswari Apartments, 45 Vellalar street, Kodambakkam,Chennai- 600024.
B4: ='Master Sheet'!C38 -> U29100TN2020PTC135386
B5: Trial Balance for the Year ended March 31, 2026
B7: Particulars | C7: Opening Balance as on 01.04.2025 | E7: Current Transactions | G7: Closing Balance as on 31.03.2026
C8: Debit | D8: Credit | E8: Debit | F8: Credit | G8: Debit | H8: Credit
B10: Capital Account
B11: Issued and Paidup Share Capital | D11: =Sheet1!C10 -> 1500000 | E11: =TB!C8 -> 0 | F11: =TB!D8 -> 0 | G11: =C11+E11-F11 -> 0 | H11: =D11+F11-E11 -> 1500000
B12: Loans (Liability) | E12: =TB!C9 -> 0 | F12: =TB!D9 -> 0 | G12: =C12+E12-F12 -> 0 | H12: =D12+F12-E12 -> 0
B13: External Commercial Borrowings | D13: =Sheet1!C12 -> 11540575 | E13: =Sheet1!D12 -> 11540575 | G13: 0 | H13: =D13+F13-E13 -> 0
B14: Current Liabilities | G14: =C14+E14-F14 -> 0 | H14: =D14+F14-E14 -> 0
B15: Duties & Taxes | G15: =C15+E15-F15 -> 0 | H15: =D15+F15-E15 -> 0
B16: GST RCM Payable | D16: =Sheet1!C15 -> 1800 | E16: =Sheet1!D15 -> 5616712 | F16: =Sheet1!E15 -> 5616712 | H16: =D16+F16-E16 -> 1800
B17: Output CGST Payable | E17: =Sheet1!D16 -> 3897000 | F17: =Sheet1!E16 -> 3897000
B18: Output SGST Payable | E18: =Sheet1!D17 -> 3897000 | F18: =Sheet1!E17 -> 3897000
B19: Professional Tax | E19: =Sheet1!D18 -> 2500 | F19: =Sheet1!E18 -> 2500 | G19: =C19+E19-F19 -> 0 | H19: =D19+F19-E19 -> 0
B20: Provision for Tax FY 25-26 | C20: 0 | D20: 0 | F20: =D134 -> 1255554 | G20: 0 | H20: =D20+F20-E20 -> 1255554
B21: TDS - Contracts | D21: =Sheet1!C19 -> 230.5 | E21: =Sheet1!D19 -> 10185.5 | F21: =Sheet1!E19 -> 9955 | H21: =D21+F21-E21 -> 0
B22: TDS-Professional Services | D22: =Sheet1!C20 -> 11700 | E22: =Sheet1!D20 -> 27200 | F22: =Sheet1!E20 -> 31500 | H22: =D22+F22-E22 -> 16000
B23: Sundry Creditors | H23: =D23+F23-E23 -> 0
B24: KUM Germany Creditors-Lease Charges | E24: =Sheet1!D22 -> 27181386 | F24: =Sheet1!E22 -> 27181386
B25: KUM Germany Creditors-Mobalisation Charges | E25: =C128 -> 3902568 | F25: =Sheet1!E23 -> 3902568
B26: Expenses O/s | G26: =C26+E26-F26 -> 0 | H26: =D26+F26-E26 -> 0
B27: Audit Fee Payable A/c | D27: =Sheet1!C27 -> 74250 | E27: =Sheet1!D27 -> 74250 | F27: =Sheet1!E27 -> 112500 | H27: =D27+F27-E27 -> 112500
B28: 6LABS EUROPH GMBH | E28: =Sheet1!D25 -> 6558750 | F28: =Sheet1!E25 -> 6558750 | G28: =C28+E28-F28 -> 0 | H28: =D28+F28-E28 -> 0
B29: AIRTEL | E29: =Sheet1!D26 -> 236 | F29: =Sheet1!E26+D124 -> 1414.82 | H29: =D29+F29-E29 -> 1178.82
B30: ECB2 Return Filing Charges Payable | D30: =Sheet1!C28 -> 1000 | E30: =Sheet1!D28 -> 1000 | F30: =D119 -> 1000 | H30: =D30+F30-E30 -> 1000
B31: ICEGATE | E31: =Sheet1!D29 -> 1000 | F31: =Sheet1!E29 -> 1000 | G31: =C31+E31-F31 -> 0 | H31: =D31+F31-E31 -> 0
B32: Integrated Registry Management Services | E32: =Sheet1!D30 -> 5900 | F32: =Sheet1!E30 -> 5900 | G32: =C32+E32-F32 -> 0 | H32: =D32+F32-E32 -> 0
B33: Ms.Subhashini | D33: =Sheet1!C32 -> 40000 | E33: =Sheet1!D32 -> 357500 | F33: =Sheet1!E32 -> 317500 | H33: =D33+F33-E33 -> 0
B34: Professional Fees Payable A/c | D34: =Sheet1!C34 -> 6000 | E34: =Sheet1!D34 -> 6000 | F34: =Sheet1!E34 -> 6000 | H34: =D34+F34-E34 -> 6000
B35: RBCA | D35: 0 | E35: =Sheet1!D35 -> 89100 | F35: =Sheet1!E35 -> 89100 | G35: =C35+E35-F35 -> 0 | H35: =D35+F35-E35 -> 0
B36: RBJV Associates | D36: 0 | E36: =Sheet1!D36 -> 207054 | F36: =Sheet1!E36 -> 207054 | G36: =C36+E36-F36 -> 0 | H36: =D36+F36-E36 -> 0
B37: Vanitha A/c | E37: =Sheet1!D38 -> 120000 | F37: =Sheet1!E38 -> 120000 | G37: =C37+E37-F37 -> 0 | H37: =D37+F37-E37 -> 0 | I37: =G36+G37 -> 0
B38: Virogreen | E38: =Sheet1!D39 -> 92800 | F38: =Sheet1!E39 -> 92800 | G38: =C38+E38-F38 -> 0 | H38: =D38+F38-E38 -> 0
B39: KUM Germany Creditors-Mobalisation Charges Payable | E39: =Sheet1!D31 -> 3902568 | F39: =D129 -> 3902568 | G39: =E39-F39 -> 0
B40: NSDL | E40: =Sheet1!D33 -> 5900 | F40: =Sheet1!E33 -> 5900 | H40: =D40+F40-E40 -> 0
B41: Tripadam Logistics Private Limited | E41: =Sheet1!D37 -> 484577.08 | F41: =Sheet1!E37 -> 484577.08 | H41: =D41+F41-E41 -> 0
B42: Deepika | E42: =Sheet1!D40 -> 10000 | F42: =Sheet1!E40 -> 10000 | H42: =D42+F42-E42 -> 0
B43: Ms Subhashini - Reimbursement | D43: =Sheet1!C41 -> 236 | E43: =Sheet1!D41 -> 7329.46 | F43: =Sheet1!E41 -> 7093.46 | H43: =D43+F43-E43 -> 0 | I43: =G43-H38 -> 0
...

Sheet Balance Sheet
B2: K.U.M. India Private Limited
B3: ='Working TB'!B3 -> A5 second floor,Rajeswari Apartments, 45 Vellalar street, Kodambakkam,Chennai- 600024.
B4: ='Working TB'!B4 -> U29100TN2020PTC135386
E5: ='Master Sheet'!$C$5 -> Amount in ₹.
B6: Balance Sheet as on 31st March 2026
B7: Particulars | C7: Note no | D7: As at 31st Mar 2026 | E7: As at 31st Mar 2025
B9: I EQUITY AND LIABILITIES
B11: 1. Shareholder's funds
B12: (a) Share capital | C12: 3 | D12: ='Balance Sheet Notes'!C16 -> 1500000 | E12: ='Balance Sheet Notes'!D16 -> 1500000
B13: (b) Reserves and surplus | C13: 4 | D13: =('Balance Sheet Notes'!C121) -> 3646361.7 | E13: ='Balance Sheet Notes'!D121 -> -3782365.8
B14: (c) Money received against share warrants | D14: 0 | E14: 0
D15: =SUM(D12:D14) -> 5146361.7 | E15: =SUM(E12:E13) -> -2282365.8
B16: 2. Share application money pending allotment
B18: 3. Non-current liabilities
B19: (a) Long-term borrowings | C19: 5 | D19: =+'Balance Sheet Notes'!C127 -> 0 | E19: =+'Balance Sheet Notes'!D127 -> 11540575
B20: (b) Deferred tax liabilities (Net) | C20: 6 | D20: ='Balance Sheet Notes'!C140 -> 1040 | E20: ='Balance Sheet Notes'!D139 -> 0
B21: (c) Other Long-term liabilities | D21: 0 | E21: 0
B22: (d) Long-term provisions | D22: 0 | E22: 0
D23: =SUM(D19:D22) -> 1040 | E23: =SUM(E19:E22) -> 11540575
B24: 4. Current liabilities
B25: (a) Short-term borrowings | D25: 0 | E25: 0
B26: (b) Trade payables | D26: 0 | E26: 0
B27: (i) Total outstanding dues of micro enterprises and small enterprises | D27: 0 | E27: 0
B28: (ii) Total outstanding dues of creditors other than micro enterprises and small enterprises | D28: 0 | E28: 0
B29: (c) Other current liabilities | C29: 7 | D29: ='Balance Sheet Notes'!C148 -> 138478.82 | E29: ='Balance Sheet Notes'!D148 -> 135214.94
B30: (d) Short-term provisions | C30: 8 | D30: ='Balance Sheet Notes'!C153 -> 1255554 | E30: 0
D31: =SUM(D25:D30) -> 1394032.8 | E31: =SUM(E25:E30) -> 135214.94
B32: TOTAL | D32: =D31+D23+D15 -> 6541434.5 | E32: =(E31+E23+E15) -> 9393424.1
B34: II ASSETS
B36: 1. Non-current assets
B37: (a) Property, Plant and Equipment and Intangible assets | C37: 9 | D37: ='Balance Sheet Notes'!L159 -> 2512 | E37: ='Balance Sheet Notes'!L162 -> 2512
B38: (i) Property, Plant and Equipment | D38: 0 | E38: 0
B39: (ii) Intangible assets | D39: 0 | E39: 0
B40: (iii) Capital work-in-progress | E40: 0
B41: (iv) Intangible assets under development | D41: 0 | E41: 0
B42: (b) Non-current investments | D42: 0 | E42: 0
B43: (c) Deferred tax assets (net) | C43: 10 | D43: ='Balance Sheet Notes'!C169 -> 0 | E43: ='Balance Sheet Notes'!D170 -> 249
B44: (d) Long-term loans and advances | D44: 0 | E44: 0
B45: (e) Other non-current assets | D45: 0 | E45: 0
D46: =SUM(D37:D45) -> 2512 | E46: =SUM(E37:E45) -> 2761
...

Sheet Profit and Loss
B2: =+'Balance Sheet'!B2 -> K.U.M. India Private Limited
B3: ='Balance Sheet'!B3 -> A5 second floor,Rajeswari Apartments, 45 Vellalar street, Kodambakkam,Chennai- 600024.
B4: ='Balance Sheet'!B4 -> U29100TN2020PTC135386
E5: ='Master Sheet'!$C$5 -> Amount in ₹.
B6: Profit & Loss for the year ended 31st March 2026
B7: Particulars | C7: Note no | D7: For the Year Ended 31st Mar 2026 | E7: For the Year Ended 31st Mar 2025
B8: INCOME
B9: I. Revenue from operations | C9: 13 | D9: =+'Profit and Loss Notes'!C12 -> 43300000 | E9: ='Profit and Loss Notes'!D9+'Profit and Loss Notes'!D10+'Profit and Loss Notes'!D11 -> 1578059
B10: II. Other Income | C10: 14 | D10: ='Profit and Loss Notes'!C20 -> 896843.74 | E10: ='Profit and Loss Notes'!D20 -> 492263.33
B11: III. TOTAL INCOME (I+II) | D11: ='Profit and Loss'!D9+'Profit and Loss'!D10 -> 44196844 | E11: ='Profit and Loss'!E9+'Profit and Loss'!E10 -> 2070322.3
B12: IV. EXPENSES
B13: (a) Cost of materials consumed | D13: 0 | E13: 0
B14: (b) Purchases of Stock-in-Trade | D14: 0 | E14: 0
B15: (c)Changes in inventories of finished goods, work-in-progress and Stock-in-Trade | D15: 0 | E15: 0
B16: (d) Employee benefit expenses | C16: 15 | D16: ='Profit and Loss Notes'!C28 -> 320000 | E16: ='Profit and Loss Notes'!D28 -> 540000
B17: (e) Finance costs | C17: 16 | D17: ='Profit and Loss Notes'!C34 -> 0 | E17: ='Profit and Loss Notes'!D34 -> 263350
B18: (f) Depreciation and amortisation | C18: 17 | D18: ='Profit and Loss Notes'!C41 -> 0 | E18: ='Profit and Loss Notes'!D41 -> 15914
B19: (g) Other expenses | C19: 18 | D19: =+'Profit and Loss Notes'!C69 -> 35191273 | E19: ='Profit and Loss Notes'!D69 -> 1268688.1
B21: TOTAL EXPENSES | D21: ='Profit and Loss'!D13+'Profit and Loss'!D14+'Profit and Loss'!D15+'Profit and Loss'!D16+'Profit and Loss'!D17+'Profit and Loss'!D18+'Profit and Loss'!D19 -> 35511273 | E21: ='Profit and Loss'!E13+'Profit and Loss'!E14+'Profit and Loss'!E15+'Profit and Loss'!E16+'Profit and Loss'!E17+'Profit and Loss'!E18+'Profit and Loss'!E19 -> 2087952.1
B22: V. Profit/(Loss) before exceptional and extraordinary items and tax (III - IV) | D22: ='Profit and Loss'!D11-'Profit and Loss'!D21 -> 8685570.5 | E22: ='Profit and Loss'!E11-'Profit and Loss'!E21 -> -17629.8
B23: VI. Exceptional items
B24: Loss on Sale of Tangible assets
B25: VII. Profit/(Loss) before extraordinary items and tax (V-VI) | D25: ='Profit and Loss'!D22-'Profit and Loss'!D24 -> 8685570.5 | E25: ='Profit and Loss'!E22-'Profit and Loss'!E24 -> -17629.8
B26: VIII. Extraordinary Items
B27: IX. Profit/(Loss) before tax (VII - VIII) | D27: ='Profit and Loss'!D25-'Profit and Loss'!D26 -> 8685570.5 | E27: ='Profit and Loss'!E25-'Profit and Loss'!E26 -> -17629.8
B28: X. Tax Expenses | D28: =+D29+D30 -> 1256843 | E28: =(+E29+E30) -> -1856
B29: (a) Current tax | C29: 19 | D29: ='Working TB'!C133 -> 1255554
B30: (b) Deferred tax | C30: 20 | D30: ='Profit and Loss Notes'!C81 -> 1289 | E30: =-'Profit and Loss Notes'!D81 -> -1856
B31: XI. Profit/(Loss) for the period from continuing operations | D31: ='Profit and Loss'!D27-'Profit and Loss'!D28 -> 7428727.5 | E31: ='Profit and Loss'!E27-'Profit and Loss'!E28 -> -15773.8
B32: XII. Profit/(Loss) for the period from discontinuing operations | D32: 0 | E32: 0
B33: XIII. Tax expense of discontinuing operations | D33: 0 | E33: 0
B34: XIV. Profit/(Loss) for the period from discontinuing operations (after tax) | D34: ='Profit and Loss'!D32-'Profit and Loss'!D33 -> 0 | E34: ='Profit and Loss'!E32-'Profit and Loss'!E33 -> 0
B35: XV. Profit/(Loss) for the period | D35: ='Profit and Loss'!D31+'Profit and Loss'!D34 -> 7428727.5 | E35: ='Profit and Loss'!E31+'Profit and Loss'!E34 -> -15773.8
B36: Earnings per equity share | C36: 21
B37: (a) Basic | D37: =+'Profit and Loss Notes'!C90 -> 49.52485 | E37: =+'Profit and Loss Notes'!D90 -> -0.10515867
B38: (b) Diluted | D38: =+'Profit and Loss Notes'!C94 -> 49.52485 | E38: =+'Profit and Loss Notes'!D94 -> -0.10515867
B39: Number of Shares Used in Computing Earnings Per Share
B40: (a) Basic | D40: 150000 | E40: 150000
B41: (b) Diluted | D41: 150000 | E41: 150000
B42: See accompanying notes forming part of the financial statements 1 & 2
...

Sheet CFS
B2: =+'Balance Sheet'!B2 -> K.U.M. India Private Limited | C2: =IF('Master Sheet'!$C$34="", "", "CIN: "&'Master Sheet'!$C$34)
B3: ='Profit and Loss'!B3 -> A5 second floor,Rajeswari Apartments, 45 Vellalar street, Kodambakkam,Chennai- 600024.
B4: ='Profit and Loss'!B4 -> U29100TN2020PTC135386
B6: Cash Flow Statements For The Year Ended 31st March 2026 | E6: ='Master Sheet'!$C$5 -> Amount in ₹.
B7: Particulars | D7: For the year ended 31st March 2026 | E7: For the year ended 31st March 2025
B9: Cash flow from Operating Activities
B10: Net profit as per profit and loss a/c | D10: ='Profit and Loss'!D27 -> 8685570.5 | E10: =-17630 -> -17630
B11: Add: Depreciation and amortisation | D11: ='Profit and Loss'!D18 -> 0 | E11: ='Profit and Loss'!E18 -> 15914
B12: Add: Unrealised Forex Loss | D12: ='Working TB'!H107 -> 0 | E12: =263350 -> 263350
D13: =SUM(D10:D12) -> 8685570.5 | E13: =SUM(E10:E12) -> 261634
B14: Less: Dividend/Interest income received | D14: =-'Working TB'!H77-'Working TB'!H78 -> -224177 | E14: =-463966 -> -463966
B15: Operating profit before working capital changes | D15: =D14+D13 -> 8461393.5 | E15: =SUM(E13:E14) -> -202332
B16: Changes in working capital
B17: Increase/(Decrease) in Trade Payables | D17: ='Balance Sheet'!D26-'Balance Sheet'!E26 -> 0 | E17: =-19085247 -> -19085247
B18: Increase/(Decrease) in Long term Provisions | D18: ='Balance Sheet'!D22-'Balance Sheet'!E22 -> 0
B19: Increase/(Decrease) in Other Current Liabilities | D19: ='Balance Sheet'!D29-'Balance Sheet'!E29 -> 3263.88 | E19: =-3420170.06 -> -3420170.1
B20: (Increase)/Decrease in Inventories | D20: ='Balance Sheet'!E49-'Balance Sheet'!D49 -> 0
B21: (Increase)/Decrease in Other Current Assets | D21: ='Balance Sheet'!E53-'Balance Sheet'!D53 -> 0 | E21: =607 -> 607
B22: (Increase)/Decrease in Trade Receivables | D22: ='Balance Sheet'!E50-'Balance Sheet'!D50 -> 0 | E22: =28248000 -> 28248000
B23: (Increase)/Decrease in Short Term Loans And Advance | D23: ='Balance Sheet'!$E$52-'Balance Sheet'!$D$52 -> -444948.03 | E23: =-316595.25 -> -316595.25
B24: Net change in working capital | D24: =SUM(D17:D23) -> -441684.15 | E24: =SUM(E17:E23) -> 5426594.7
B25: Cash generated from operations | D25: =D15+D24 -> 8019709.4 | E25: =E15+E24 -> 5224262.7
B26: Direct taxes paid
B27: Net cash from / (used in) Operating Activities (A) | D27: =D25-D26 -> 8019709.4 | E27: =SUM(E25:E26) -> 5224262.7
B29: Cash flow from Investing Activities
B30: Purchase / (Sale) of fixed assets
B31: (i) Tangible Assets | D31: 0 | E31: 0
B32: (ii) Intangible Assets | D32: =-('Balance Sheet'!D39-'Balance Sheet'!E39) -> 0 | E32: 0
B33: (iii) Capital work in progress | D33: =-('Balance Sheet'!D40-'Balance Sheet'!E40) -> 0 | E33: 0
B34: (iv) Intangible assets under development | D34: =-('Balance Sheet'!D41-'Balance Sheet'!E41) -> 0 | E34: 0
B35: Proceeds from sale of fixed assets
B36: Purchase / (Sale) of Non Current Investments | D36: ='Balance Sheet'!E42-'Balance Sheet'!D42 -> 0 | E36: 0
B37: Purchase / (Sale) of Current Investments | D37: ='Balance Sheet'!E48-'Balance Sheet'!D48 -> 0 | E37: 0
B38: Dividend/Interest income received | D38: ='Working TB'!H77+'Working TB'!H78 -> 224177 | E38: =463966 -> 463966
B40: Net cash from / (used in) Investing Activities (B) | D40: =SUM(D31:D38) -> 224177 | E40: =SUM(E31:E38) -> 463966
B42: Cash flow from Financing Activities
B43: Share capital raised | D43: ='Balance Sheet'!D12-'Balance Sheet'!E12 -> 0
B44: Money received from share warrants | D44: ='Balance Sheet'!D14-'Balance Sheet'!E14 -> 0
B45: Changes in Reserves and surplus
B46: (Increase)/Decrease in Short term loans and advances
...

Sheet Accounting Polices
C2: ='Balance Sheet'!B2 -> K.U.M. India Private Limited
C3: =CFS!B3 -> A5 second floor,Rajeswari Apartments, 45 Vellalar street, Kodambakkam,Chennai- 600024.
C4: =CFS!B4 -> U29100TN2020PTC135386
C6: Notes to Financial statements for the year ended 31st March 2026
C8: Note No. 1 Corporate Information
C10: K.U.M India Private Limited ('K.U.M'/'the Company') incorporated on 21 May 2020 under the Companies Act, 2013.
C11: The Company is a subsidiary of 6Labs Europe GmbH, Germany ('Holding Company'). The primary objective of the Company is to provide custom solutions in marine research and development, and innovative turnkey marine solutions.
C13: Note No. 2 Significant Accounting Policies
C15: 2.1 Accounting Conversion
C16: The financial statements have been prepared in accordance with the historical cost convention on an accrual basis and comply with the applicable Accounting Standards specified under section 133 of the Companies Act, 2013 read with Rule 7 of the Companies (Accounts) Rules, 2014.
C17: These financial statements have been prepared as required under relevant provision of the Companies Act, 2013 and the presentation is based on Schedule III of the Companies Act, 2013. All assets and liabilities are classified into current and non-current generally based on the criteria of realization / settlement within twelve months’ period from the balance sheet date
C19: 2.2 Use of Estimates
C20: The preparation of financial statements in conformity with Indian GAAP requires the Management to make estimates and assumptions considered in the reported amounts of assets and liabilities (including contingent liabilities) as of the date of the financial statements and the reported income and expenses during the reporting period like provision for employee benefits, provisioning for receivables, useful lives of fixed assets, provisioning for taxation etc. Management believes that the estimates used in the preparation of the financial statements are prudent and reasonable. Future results could differ from these estimates and the differences between the actual results and the estimates are recognised in the periods in which the results are known / materialise.
C22: 2.3 Cash Flow Statement
C23: Cash flows are reported using the indirect method, whereby profit / (loss) before extraordinary items and tax is adjusted for the effects of transactions of non-cash nature and any deferrals or accruals of past or future cash receipts or payments. The cash flows from operating, investing and financing activities of the Company are segregated based on the available information.
... C55: Assets and Liabilities are classified as Current and Non-Current based on the Operating Cycle which has been estimated to be 12 months. All assets and liabilities which are expected to be realised and settled, within a period of 12 months from the date of Balance Sheet have been classified as Current and other assets and liabilities are classified as Non-current.

Sheet Balance Sheet Notes
B1: K.U.M. India Private Limited
B2: A5 second floor,Rajeswari Apartments, 45 Vellalar street, Kodambakkam,Chennai- 600024.
B3: U29100TN2020PTC135386
B4: Notes forming part of the Financial Statements for the Year ended 31 March 2026
D5: ='Master Sheet'!$C$5 -> Amount in ₹.
B6: =IF(ISBLANK('Balance Sheet'!C12), "", "Note number: "& 'Balance Sheet'!C12) -> Note number: 3
B7: Share Capital
B8: Particulars | C8: As at 31st Mar 2026 | D8: As at 31st Mar 2025
B10: (A) Authorized
B12: 1,50,000 Equity Shares Of Rs. 10/- Each | C12: =Sheet1!C9 -> 1500000 | D12: 1500000
B13: (B) Issued , Subscribed And Fully Paid Up
B14: 1,50,000 Equity Shares Of Rs. 10/- Each | C14: =Sheet1!F9 -> 1500000 | D14: 1500000
B16: TOTAL | C16: ='Balance Sheet Notes'!C11+'Balance Sheet Notes'!C14 -> 1500000 | D16: ='Balance Sheet Notes'!D11+'Balance Sheet Notes'!D14 -> 1500000
D19: ='Master Sheet'!$C$5 -> Amount in ₹.
B20: Reconciliation
B21: Particulars | C21: As at 31st Mar 2026 | D21: As at 31st Mar 2025
B23: 1,50,000 Equity Shares of Rs. 10/- Each | C23: =+C24+C25-C26 -> 1500000 | D23: =+D24+D25-D26 -> 1500000
B24: Opening Balance | C24: =150000*10 -> 1500000 | D24: =150000*10 -> 1500000
B25: Add: Fresh Issue | C25: 0 | D25: 0
B26: Add/(Less) Other Changes | C26: 0 | D26: 0
B28: Rights, Preferences and Restrictions
B30: Equity Shares
B32: The Company has one class of equity shares having a par value of Rs.10/- per share. The equity shares are attached with voting rights. Each shareholder is eligible for one vote per share held. In the event of liquidation, the equity shareholders are eligible to receive the remaining assets of the Company after distribution of all preferential amount, in proportion to their shareholding.
B35: Shares held by shareholders holding more than 5%
B36: Particulars | C36: Typoe of Shares | D36: As at 31 March 2026 | F36: As at 31 March 2025
D37: Number of Shares held | E37: Percentage of Holding | F37: Number of Shares held | G37: Percentage of Holding
B39: 6Labs Europe GmbH (Holding Company) | C39: Equity | D39: 112500 | E39: 0.75 | F39: 112500 | G39: 0.75
B40: Sutti Omnath Dinesh Babu | C40: Equity | D40: 37500 | E40: 0.25 | F40: 37500 | G40: 0.25
B42: Total | D42: =SUM(D39:D40) -> 150000 | E42: =SUM(E39:E40) -> 1 | F42: =SUM(F39:F40) -> 150000 | G42: =SUM(G39:G40) -> 1
B44: Shares held by promoters at the end of the year 31st March 2026
B46: Promoter Name | E46: Number of Shares held | F46: Percentage of Holding | G46: Percentage Change during the year
B48: 6Labs Europe GmbH (Holding Company) | E48: 112500 | F48: 0.75 | G48: 0
B49: Sutti Omnath Dinesh Babu | E49: 37500 | F49: 0.25 | G49: 0
B52: Shares held by promoters at the end of the year 31st March 2025
B54: Promoter Name | E54: Number of Shares held | F54: Percentage of Holding | G54: Percentage Change during the year
B56: 6Labs Europe GmbH (Holding Company) | E56: 112500 | F56: 0.75 | G56: 0
B57: Sutti Omnath Dinesh Babu | E57: 37500 | F57: 0.25 | G57: 0
D60: ='Master Sheet'!$C$5 -> Amount in ₹.
B61: =IF(ISBLANK('Balance Sheet'!C13), "", "Note number: "& 'Balance Sheet'!C13) -> Note number: 4
B62: Reserves and Surplus
...

Sheet Profit and Loss Notes
B1: K.U.M. India Private Limited
B2: A5 second floor,Rajeswari Apartments, 45 Vellalar street, Kodambakkam,Chennai- 600024.
B3: U29100TN2020PTC135386
B4: ='Balance Sheet Notes'!B4 -> Notes forming part of the Financial Statements for the Year ended 31 March 2026
B6: =IF(ISBLANK('Profit and Loss'!C9), "", "Note number: "& 'Profit and Loss'!C9) -> Note number: 13 | D6: ='Master Sheet'!$C$5 -> Amount in ₹.
B7: Revenue from Operations
B8: Particulars | C8: For the Year Ended 31st Mar 2026 | D8: For the Year Ended 31st Mar 2025
B9: Sale of products | C9: 0 | D9: 0
B10: Revenue From Services | C10: =+'Annexure PnL'!C9 -> 43300000 | D10: =+'Annexure PnL'!D9 -> 1578059
B11: Other operating revenues | C11: 0 | D11: 0
B12: Total | C12: ='Profit and Loss Notes'!C9+'Profit and Loss Notes'!C10+'Profit and Loss Notes'!C11 -> 43300000 | D12: ='Profit and Loss Notes'!D9+'Profit and Loss Notes'!D10+'Profit and Loss Notes'!D11 -> 1578059
B14: =IF(ISBLANK('Profit and Loss'!C10), "", "Note number: "& 'Profit and Loss'!C10) -> Note number: 14 | D14: ='Master Sheet'!$C$5 -> Amount in ₹.
B15: Other Income
B16: Particulars | C16: For the Year Ended 31st Mar 2026 | D16: For the Year Ended 31st Mar 2025
B17: Forex gains | C17: ='Annexure PnL'!C15 -> 0 | D17: ='Annexure PnL'!D15 -> 4747.33
B18: Other non-operating income | C18: ='Annexure PnL'!C22 -> 730213.74 | D18: ='Annexure PnL'!D22 -> 23550
B19: Interest on FD | C19: ='Annexure PnL'!C26 -> 166630 | D19: ='Annexure PnL'!D26 -> 463966
B20: Total | C20: =SUM(C17:C19) -> 896843.74 | D20: =SUM(D17:D19) -> 492263.33
B22: =IF(ISBLANK('Profit and Loss'!C16), "", "Note number: "& 'Profit and Loss'!C16) -> Note number: 15 | D22: ='Master Sheet'!$C$5 -> Amount in ₹.
B23: Employee Benefits expenses
B24: Particulars | C24: For the Year Ended 31st Mar 2026 | D24: For the Year Ended 31st Mar 2025
B25: Salary and Wages | C25: ='Annexure PnL'!C38 -> 320000 | D25: =+'Annexure PnL'!D39 -> 480000
B26: Bonus & Incentivies | C26: =+'Annexure PnL'!C35 -> 0 | D26: ='Annexure PnL'!D35 -> 60000
B28: Total | C28: =SUM(C25:C27) -> 320000 | D28: =SUM(D25:D27) -> 540000
B30: =IF(ISBLANK('Profit and Loss'!C17),"","Note number:"&'Profit and Loss'!C17) -> Note number:16 | D30: ='Master Sheet'!$C$5 -> Amount in ₹.
B31: Finance Cost
B32: Particulars | C32: For the Year Ended 31st Mar 2026 | D32: For the Year Ended 31st Mar 2025
B33: Unrealised Loss On Forex | C33: =0 -> 0 | D33: ='Annexure PnL'!D45 -> 263350
B34: Total | C34: ='Profit and Loss Notes'!C33 -> 0 | D34: ='Profit and Loss Notes'!D33 -> 263350
B36: =IF(ISBLANK('Profit and Loss'!C18), "", "Note number: "& 'Profit and Loss'!C18) -> Note number: 17 | D36: ='Master Sheet'!$C$5 -> Amount in ₹.
B37: Depreciation and Amortisation expenses
B38: Particulars | C38: For the Year Ended 31st Mar 2026 | D38: For the Year Ended 31st Mar 2025
B39: Depreciation | C39: ='Annexure PnL'!C51 -> 0 | D39: =+'Annexure PnL'!D51 -> 15914
B41: Total | C41: ='Profit and Loss Notes'!C39 -> 0 | D41: ='Profit and Loss Notes'!D39 -> 15914
B43: =IF(ISBLANK('Profit and Loss'!C19), "", "Note number: "& 'Profit and Loss'!C19) -> Note number: 18 | D43: ='Master Sheet'!$C$5 -> Amount in ₹.
B44: Other Expenses
B45: Particulars | C45: For the Year Ended 31st Mar 2026 | D45: For the Year Ended 31st Mar 2025
B46: Bank Charges | C46: ='Annexure PnL'!C56 -> 46387.17 | D46: ='Annexure PnL'!D56 -> 35615.74
B47: ECB2 Return Filing Charges | C47: ='Annexure PnL'!C57 -> 6000 | D47: ='Annexure PnL'!D57 -> 6000
B48: OBS Air Shipment Expense | C48: ='Annexure PnL'!C63 -> 0 | D48: ='Annexure PnL'!D63 -> 27508
...

Sheet Other Notes
B1: K.U.M. India Private Limited
B2: A5 second floor,Rajeswari Apartments, 45 Vellalar street, Kodambakkam,Chennai- 600024.
B3: U29100TN2020PTC135386
B4: ='Profit and Loss Notes'!B4 -> Notes forming part of the Financial Statements for the Year ended 31 March 2026
B6: Note No. 24 Related Party Disclosures as per AS-18
B8: Note No. 24 (a) Names of Related Parties and Nature of Relationship
B10: S. No. | C10: Name of the Related Party | F10: Nature of Relationship
B11: 1 | C11: 6Labs Europe GmbH | F11: Holding Company
B12: 2 | C12: Sutti Omnath Dinesh Babu | F12: Director/KMP
B13: 3 | C13: Vanitha S.D | F13: Relative of the Director
B14: 4 | C14: Samhitha Marine Private Limited | F14: Common Director
B15: 5 | C15: K.U.M. Unwelt- und Meerestechnik Kiel GmbH | F15: Common Director
B17: Note: Related party relationships are as identified by the Management.
B19: Note No. 24 (b) Transactions with Related Parties
B21: Name of the Related Party | D21: Nature of Relationship | E21: Nature of the Transaction | F21: For the year ended 31 March 2026 | G21: For the year ended 31 March 2025
B22: 6Labs Europe GmbH | D22: Holding Company | E22: Repayment of External Commercial Borrowings | F22: ='Working TB'!E13 -> 11540575 | G22: 0
B23: K.U.M. Unwelt- und Meerestechnik Kiel GmbH | D23: Common Director | E23: Repayment to Sundry Creditors | F23: ='Working TB'!E24+'Working TB'!E25 -> 31083954 | G23: 18999343
B24: Vanitha S.D | D24: Relative of the Director | E24: Rent | F24: ='Profit and Loss Notes'!C64 -> 141600 | G24: 141600
B25: Samhitha Marine Private Limited | D25: Common Director | E25: Revenue From Operations | F25: ='Working TB'!H70 -> 43300000 | G25: 0
B26: K.U.M. Unwelt- und Meerestechnik Kiel GmbH | D26: Common Director | E26: Revenue From Operations | F26: 0 | G26: 1578059
B27: TOTAL | F27: =SUM(F23:F26) -> 74525554 | G27: =SUM(G23:G26) -> 20719002
B28: Note No. 24 (c) Outstanding Balance with the Related Parties
B30: Name of the Related Party | D30: Nature of Relationship | E30: Nature of the Transaction | F30: As at 31 March 2026 | G30: As at 31 March 2025
B31: 6Labs Europe GmbH | D31: Holding Company | E31: Long Term Borrowings | F31: ='Working TB'!H13 -> 0 | G31: 11540575
B32: TOTAL | F32: =SUM(F31:F31) -> 0 | G32: =SUM(G31:G31) -> 11540575
B33: Note No. 25 Disclosures required under Section 22 of the Micro, Small and Medium Enterprises
B34: Development Act, 2006
B35: Based on and to the extent of information received by the Company from the suppliers during the year
B36: regarding their status under the Micro Small and Medium Enterprises Development Act, 2006 (MSMED
B37: Act), the relevant particulars for the period ended March 31, 2026 is furnished below:
B39: Particulars | G39: 46112
B40: Principal amount remaining unpaid to any supplier as at the end of the accounting year. | G40: 0
B41: Interest due thereon remaining unpaid to any supplier as at the end of the accounting year. | G41: 0
B42: The amount of interest paid along with the amounts of the payment made to the supplier beyond the appointed day | G42: 0
B43: The amount of interest due and payable for the year. | G43: 0
B44: The amount of interest accrued and remaining unpaid at the end of the accounting year. | G44: 0
B45: The amount of further interest due and payable even in the succeeding year, until such date when the interest dues as above are actually paid. | G45: 0
B46: Total | G46: 0
B48: Note No. 26 Derivative instruments and unhedged foreign currency exposure
B49: a) The Company did not have any derivative contracts during the current year and previous period.
...

Sheet Annexure BS
B1: K.U.M. India Private Limited
B2: A5 second floor,Rajeswari Apartments, 45 Vellalar street, Kodambakkam,Chennai- 600024.
B3: U29100TN2020PTC135386
B5: 1. Share Capital
B6: Equity Shares Of Rs. 10/- Each | C6: As at 31st Mar 2026 | D6: As at 31st Mar 2025
B7: Authorised Share Capital | C7: 1500000 | D7: 1500000
B8: Total | C8: =SUM(C7:C7) -> 1500000 | D8: =SUM(D7:D7) -> 1500000
B11: 2. Deferred Tax Liabilities (Net)
B12: Deferred tax liabilities | C12: As at 31st Mar 2026 | D12: As at 31st Mar 2025
B13: Deferred Tax Liabilities | C13: =-'Deferred Tax'!G25 -> 1040 | D13: =0 -> 0
B14: Total | C14: =SUM(C13:C13) -> 1040 | D14: =SUM(D13:D13) -> 0
B17: 3. Short-term Borrowings
B18: (ii) from other parties(ST) | C18: As at 31st Mar 2026 | D18: As at 31st Mar 2025
B19: External Commercial Borrowings | C19: ='Working TB'!H13 -> 0 | D19: ='Working TB'!D13 -> 11540575
B20: Total | C20: =SUM(C19:C19) -> 0 | D20: =SUM(D19:D19) -> 11540575
B23: 4. Trade Payables
B24: (b) Total Outstanding dues of creditors other than Micro Enterprises and Small Enterprises | C24: As at 31st Mar 2026 | D24: As at 31st Mar 2025
B25: K.U.M. Germany Creditors | C25: ='Working TB'!G39 -> 0 | D25: =0 -> 0
B26: Hapag Lloyd | C26: 0
B27: Total | C27: =C25+C26 -> 0 | D27: =SUM(D25:D26) -> 0
B30: 5. Other Current Liabilities
B31: Income received in advance | C31: As at 31st Mar 2026 | D31: As at 31st Mar 2025
B32: SMPL - Advance | C32: 0 | D32: 0
B33: Total | C33: =SUM(C32:C32) -> 0 | D33: =SUM(D32:D32) -> 0
B35: Other current Liabilities | C35: As at 31st Mar 2026 | D35: As at 31st Mar 2025
B36: Airtel | C36: ='Working TB'!H29 -> 1178.82 | D36: 0
B37: CIPET | C37: 0 | D37: 0
B38: DB Schenker A/c | C38: 0 | D38: 0
B39: DHL Express | C39: 0 | D39: 0
B40: Darjen Tours & Travels | C40: 0 | D40: 0
B41: Deepika | C41: 0 | D41: 0
B42: Delhivery Ltd | C42: 0 | D42: 0
B43: Dinesh A/c | C43: 0 | D43: 0
B44: EMudhra | C44: 0 | D44: 0
B45: GeM Portal | C45: 0 | D45: 0
B46: Greater Chennai Corporation | C46: 0 | D46: 0
B47: Hapag Lloyd A/c | C47: 0 | D47: 0
B48: ICEGATE | C48: 0 | D48: 0
... B53: Matrics Consultancy | C53: 0 | D53: 0
B54: Ms.Subhashini | C54: ='Working TB'!H33 -> 0 | D54: =39999.18 -> 39999.18
...

Sheet Annexure PnL
B1: K.U.M. India Private Limited
B2: A5 second floor,Rajeswari Apartments, 45 Vellalar street, Kodambakkam,Chennai- 600024.
B3: U29100TN2020PTC135386
B5: 1. Revenue from Operations
B6: Sale of services | C6: As at 31st Mar 2026 | D6: As at 31st Mar 2025
B7: Business Support Services | C7: ='Working TB'!H70 -> 43300000 | D7: 1578059
B8: Service Charges - Domestic
B9: Total | C9: =SUM(C7:C8) -> 43300000 | D9: =SUM(D7:D8) -> 1578059
B12: 2. Other Income
B13: Forex gains | C13: As at 31st Mar 2026 | D13: As at 31st Mar 2025
B14: Gain on Forex | C14: =0 -> 0 | D14: =4747.33 -> 4747.33
B15: Total | C15: =SUM(C14:C14) -> 0 | D15: =SUM(D14:D14) -> 4747.33
B17: Other non-operating income | C17: As at 31st Mar 2026 | D17: As at 31st Mar 2025
B18: Discount Received | C18: =0 -> 0 | D18: =6870 -> 6870
B19: Interest Received on IT Refund | C19: ='Working TB'!H78 -> 57547 | D19: =16680 -> 16680
B20: Duty Drawback Refund | C20: ='Working TB'!H79 -> 672666.74
B22: Total | C22: =SUM(C18:C21) -> 730213.74 | D22: =SUM(D18:D21) -> 23550
B24: Interest on FD | C24: As at 31st Mar 2026 | D24: As at 31st Mar 2025
B25: Interest on ICICI FD | C25: ='Working TB'!H77 -> 166630 | D25: =463966 -> 463966
B26: Total | C26: =C25 -> 166630 | D26: =D25 -> 463966
B31: 3. Employee Benefits
B32: Employee benefits and compensation | C32: As at 31st Mar 2026 | D32: As at 31st Mar 2025
B33: Festival Bonus | C33: =0 -> 0 | D33: =20000 -> 20000
B34: Performance Incentive A/c | C34: =0 -> 0 | D34: =40000 -> 40000
B35: Total | C35: =SUM(C33:C34) -> 0 | D35: =SUM(D33:D34) -> 60000
B37: Salary and Wages | C37: As at 31st Mar 2026 | D37: As at 31st Mar 2025
B38: Salary A/c | C38: ='Working TB'!G100 -> 320000 | D38: =480000 -> 480000
B39: Total | C39: =SUM(C38:C38) -> 320000 | D39: =SUM(D38:D38) -> 480000
B42: 4. Finance Costs
B43: Forex loss | C43: As at 31st Mar 2026 | D43: As at 31st Mar 2025
B44: Realised Loss On Forex | C44: ='Working TB'!G95 -> 3593664 | D44: =263350 -> 263350
B45: Total | C45: =SUM(C44:C44) -> 3593664 | D45: =SUM(D44:D44) -> 263350
B48: 5. Depreciation and Amortisation
B49: Depreciation | C49: As at 31st Mar 2026 | D49: As at 31st Mar 2025
B50: Depreciation | C50: ='Working TB'!G94 -> 0 | D50: =15914 -> 15914
B51: Total | C51: =SUM(C50:C50) -> 0 | D51: =SUM(D50:D50) -> 15914
B54: 6. Other Expenses
B55: Bank charges | C55: As at 31st Mar 2026 | D55: As at 31st Mar 2025
B56: Bank Charges | C56: ='Working TB'!G82 -> 46387.17 | D56: =35615.74 -> 35615.74
B57: ECB2 Return Filing Charges | C57: ='Working TB'!G83 -> 6000 | D57: =6000 -> 6000
...

Sheet TB PY
A1: Ledger Name | B1: Ledger Parent Name | C1: Ledger Grandparent Name | D1: Primary Group Name | E1: Ledger Ultimate Parent Name | F1: Ledger Type | G1: Opening balance | H1: Debit Transaction | I1: Credit Transaction | J1: Net Transaction | K1: Closing Balance | L1: Balance sheet Primary Classification Display Name | M1: Balance sheet Classification Display Name | N1: PNL Primary Classification Display Name | O1: PNL Classification Display Name | P1: Tally Company Name | Q1: Balance sheet User Defined Classification (Update the customer defined value here) | R1: PnL User Defined Classfication | S1: guid

Sheet Deferred Tax
B3: K.U.M. India Private Limited - 01.04.2024-31.3.2025
B4: ='Annexure PnL'!B2 -> A5 second floor,Rajeswari Apartments, 45 Vellalar street, Kodambakkam,Chennai- 600024.
B5: ='Annexure PnL'!B3 -> U29100TN2020PTC135386
B8: Deferred Tax Caculation
B10: Opening Deffered Tax Asset on account of depreciation and Gratuity | G10: 249
B12: Depreciation | K12: Tax u/s 115BAC | M12: 0.22
B13: Depreciation as per Books | C13: =+'Profit and Loss Notes'!C41 -> 0 | K13: Surcharge @ 10% | M13: =M12*10% -> 0.022
B14: Depreciation as per Income Tax Act | C14: =+'IT Dep'!M12 -> 5123.52
D15: =C13-C14 -> -5123.52 | E15: =M18 -> 0.25168 | M15: =SUM(M12:M14) -> 0.242
F16: =ROUND(D15*E15,0) -> -1289 | K16: HEC @ 4% | M16: =M15*4% -> 0.00968
B18: Performance Incentivies | M18: =SUM(M15:M17) -> 0.25168
B19: Performance Incentivies as per Books | C19: 0
B20: Performance Incentivies as per Income Tax Act | C20: 0
D21: =C19-C20 -> 0 | E21: =M18 -> 0.25168
F22: =ROUND(D21*E21,0) -> 0
B23: Deferred Tax Expense for the year 2024-25 | G23: =SUM(F16:F22) -> -1289
B25: Closing Deffered Tax Liability on account of depreciation and Gratuity | G25: =+G10+G23 -> -1040

Sheet IT Dep
B1: K.U.M India Private Limited
B2: A5 Second Floor Rajeshwari Apartments, 45 Vellalar Street, Kodambakkam,
B3: Assessment Year 2025-26
B4: Depreciation as per Income Tax Act, 1961
B6: S. No. | C6: Name of the Asset | D6: Rate | E6: WDV As at 31 March 2025 | F6: Additions | H6: Deletions | J6: Total | K6: Depreciation | M6: Total Depreciation | N6: WDV as on 31 March 2026
F7: More than 180 Days | G7: Less than 180 Days | H7: Less than 180 Days | I7: More than 180 Days | K7: More than 180 Days | L7: Less than 180 Days
B9: 1 | C9: BLOCK I
C10: Computers- Laptops | D10: 0.4 | E10: 12808.8 | F10: 0 | G10: 0 | H10: 0 | I10: 0 | J10: =+E10+F10+G10-H10-I10 -> 12808.8 | K10: =J10*40% -> 5123.52 | L10: 0 | M10: =+K10+L10 -> 5123.52 | N10: =J10-M10 -> 7685.28
E12: =SUM(E10:E11) -> 12808.8 | F12: =SUM(F10:F11) -> 0 | G12: =SUM(G10:G11) -> 0 | H12: =SUM(H10:H11) -> 0 | I12: =SUM(I10:I11) -> 0 | J12: =SUM(J10:J11) -> 12808.8 | K12: =SUM(K10:K11) -> 5123.52 | L12: =SUM(L10:L11) -> 0 | ... N12: =SUM(N10:N11) -> 7685.28

Sheet IT Computation
B3: Assessment Year | F3: 2026-2027
B5: Opted for Taxation u/s Section 115BAA | F5: YES
B7: I | C7: Income from Business or Profession (Chapter IV D)
D9: Profit as per Profit and Loss Account | F9: =+'Profit and Loss'!D27 -> 8685570.5
D11: Add: Depreciation debited in P&L | E11: =+'Annexure PnL'!C51 -> 0
D12: Add: Donation- Disallowed u/s 37 | E12: 0
D13: Add: Provision for Gratuity -Disallowed u/s 43B | E13: 0
F15: =SUM(E11:E13) -> 0
F17: =SUM(F9:F15) -> 8685570.5
D19: Less: Incomes Considered seperately
D20: (a) Interest Received | E20: ='Annexure PnL'!C25+'Annexure PnL'!C19 -> 224177
D21: (b) Rent Received | E21: 0
F23: =-SUM(E20:E22) -> -224177
D25: Less: Provision for Gratuity (Paid) | E25: 0
D26: Less: Profit on Sale of Fixed Asset | E26: 0
F28: =-SUM(E25:E27) -> 0
D30: Less: Depreciation as per Income Tax Act, 1961 | E30: =IF(F17<0,(0),(+'IT Dep'!K12)) -> 5123.52
F32: =E30 -> 5123.52
F33: =+F17-F32+F23 -> 8456270
D35: Less:Brought Forward Unabsorbed Depreciation
D36: AY 2023-24 | E36: 23720
D37: AY 2025-26 | E37: 8539
F38: =E36+E37 -> 32259
D39: Less:Brought Forward Loss adjsuted
D41: AY 2022-23 | E41: 2333770
D42: AY 2023-24 | E42: 1324008
D43: AY 2025-26 | E43: 1716
F44: =SUM(E41:E43) -> 3659494
G45: =+F33-F44-F38 -> 4764517
B49: II | C49: Capital Gain | G49: 0
B51: III | C51: Income from Other Sources
D52: Interest Received on FD | F52: ='Annexure PnL'!C25 -> 166630
D53: Interest on IT Refund | F53: ='Annexure PnL'!C19 -> 57547
G54: =SUM(F52:F53) -> 224177
C56: Gross Total Income | G56: =SUM(G7:G54) -> 4988694
C58: Less: Deduction
D59: U/s 80JJAA
D60: Employment of New Employees | F60: 0
G61: =-F60 -> 0
C63: Total Income | G63: =SUM(G56:G62) -> 4988694
...

Sheet TB CY
A1: Ledger Name | B1: Ledger Parent Name | C1: Ledger Grandparent Name | D1: Primary Group Name | E1: Ledger Ultimate Parent Name | F1: Ledger Type | G1: Opening balance | H1: Debit Transaction | I1: Credit Transaction | J1: Net Transaction | K1: Closing Balance | L1: Balance sheet Primary Classification Display Name | M1: Balance sheet Classification Display Name | N1: PNL Primary Classification Display Name | O1: PNL Classification Display Name | P1: Tally Company Name | Q1: Balance sheet User Defined Classification (Update the customer defined value here) | R1: PnL User Defined Classfication | S1: guid
A2: Authorised Share Capital | B2: Capital Account | C2: _x0004_ Primary | D2: Capital Account | E2: Capital Account | F2: Liability | G2: 1500000 | H2: 0 | I2: 0 | J2: 0 | K2: 1500000 | L2: Share Capital | M2: Equity Shares Of Rs. 10/- Each | P2: K.U.M. India Private Limited - (from 1-Apr-23) | S2: e1c68af5-de76-4b79-88f9-add67b8d3461-000000ab
A3: ICICI Bank | B3: Bank Accounts | C3: Current Assets | D3: Bank Accounts | E3: Current Assets | F3: Asset | G3: -972030.58 | H3: -5760422.5 | I3: 5055383 | J3: -705039.51 | K3: 1677070.1 | L3: Cash and Cash Equivalents | M3: In current account | P3: K.U.M. India Private Limited - (from 1-Apr-23) | S3: e1c68af5-de76-4b79-88f9-add67b8d3461-000000c2
A4: Cash | B4: Cash-in-Hand | C4: Current Assets | D4: Cash-in-Hand | E4: Current Assets | F4: Asset | G4: 0 | H4: 0 | I4: 0 | J4: 0 | K4: 0 | L4: Cash and Cash Equivalents | M4: Cash on hand | P4: K.U.M. India Private Limited - (from 1-Apr-23) | S4: e1c68af5-de76-4b79-88f9-add67b8d3461-0000001f
A5: ICICI FD A/c | B5: Current Assets | C5: _x0004_ Primary | D5: Current Assets | E5: Current Assets | F5: Asset | G5: 0 | H5: 0 | I5: 0 | J5: 0 | K5: 0 | L5: Other Current Assets | M5: Other current assets | P5: K.U.M. India Private Limited - (from 1-Apr-23) | S5: e1c68af5-de76-4b79-88f9-add67b8d3461-000000c3
A6: Superior Computer | B6: Current Assets | C6: _x0004_ Primary | D6: Current Assets | E6: Current Assets | F6: Asset | G6: 0 | H6: 0 | I6: 0 | J6: 0 | K6: 0 | L6: Other Current Assets | M6: Other current assets | P6: K.U.M. India Private Limited - (from 1-Apr-23) | S6: e1c68af5-de76-4b79-88f9-add67b8d3461-000000e7
A7: Duty IGST Receivable | B7: GST | C7: Current Assets | D7: Current Assets | E7: Current Assets | F7: Asset | G7: 0 | H7: -2699029 | I7: 0 | J7: -2699029 | K7: 2699029 | L7: Short-term Loans & Advances | M7: Balance with Government Authorities-IT Refund | P7: K.U.M. India Private Limited - (from 1-Apr-23) | S7: e1c68af5-de76-4b79-88f9-add67b8d3461-00000174
A8: Input CGST | B8: GST | C8: Current Assets | D8: Current Assets | E8: Current Assets | F8: Asset | G8: -62763.8 | H8: -20268.94 | I8: 79432.74 | J8: 59163.8 | K8: 3600 | L8: Short-term Loans & Advances | M8: Balance with Government Authorities-IT Refund | P8: K.U.M. India Private Limited - (from 1-Apr-23) | S8: e1c68af5-de76-4b79-88f9-add67b8d3461-000000c4
A9: Input CGST Receivable A/c | B9: GST | C9: Current Assets | D9: Current Assets | E9: Current Assets | F9: Asset | G9: -9675 | H9: 0 | I9: 9675 | J9: 9675 | K9: 0 | L9: Short-term Loans & Advances | M9: Balance with Government Authorities-IT Refund | P9: K.U.M. India Private Limited - (from 1-Apr-23) | S9: e1c68af5-de76-4b79-88f9-add67b8d3461-000000ea
A10: Input IGST | B10: GST | C10: Current Assets | D10: Current Assets | E10: Current Assets | F10: Asset | G10: -450 | H10: -628 | I10: 1078 | J10: 450 | K10: 0 | L10: Short-term Loans & Advances | M10: Balance with Government Authorities-IT Refund | P10: K.U.M. India Private Limited - (from 1-Apr-23) | S10: e1c68af5-de76-4b79-88f9-add67b8d3461-000000c5
A11: Input IGST Receivable A/c | B11: GST | C11: Current Assets | D11: Current Assets | E11: Current Assets | F11: Asset | G11: 0 | H11: 0 | I11: 0 | J11: 0 | K11: 0 | L11: Short-term Loans & Advances | M11: Balance with Government Authorities-IT Refund | P11: K.U.M. India Private Limited - (from 1-Apr-23) | S11: e1c68af5-de76-4b79-88f9-add67b8d3461-00000183
A12: Input SGST | B12: GST | C12: Current Assets | D12: Current Assets | E12: Current Assets | F12: Asset | G12: -59681.8 | H12: -20268.94 | I12: 76350.74 | J12: 56081.8 | K12: 3600 | L12: Short-term Loans & Advances | M12: Balance with Government Authorities-IT Refund | P12: K.U.M. India Private Limited - (from 1-Apr-23) | S12: e1c68af5-de76-4b79-88f9-add67b8d3461-000000c6
A13: Input SGST Receivable A/c | B13: GST | C13: Current Assets | D13: Current Assets | E13: Current Assets | F13: Asset | G13: -9675 | H13: 0 | I13: 9675 | J13: 9675 | K13: 0 | L13: Short-term Loans & Advances | M13: Balance with Government Authorities-IT Refund | P13: K.U.M. India Private Limited - (from 1-Apr-23) | S13: e1c68af5-de76-4b79-88f9-add67b8d3461-000000eb
... A58: K.U.M. Germany Creditors | B58: Sundry Creditors | C58: Current Liabilities | D58: Sundry Creditors | E58: Current Liabilities | F58: Liability | G58: 0 | H58: 0 | I58: 18999343 | J58: 18999343 | K58: 18999343 | L58: Trade Payables | M58: (b) Total Outstanding dues of creditors other than Micro Enterprises and Small Enterprises | P58: K.U.M. India Private Limited - (from 1-Apr-23) | S58: e1c68af5-de76-4b79-88f9-add67b8d3461-00000182
A59: Clearance Charges | B59: Direct Expenses | C59: _x0004_ Primary | D59: Direct Expenses | E59: Direct Expenses | F59: Expense | G59: 0 | H59: -4720 | I59: 4720 | J59: 0 | K59: 0 | N59: Other Expenses | O59: Rates and taxes | P59: K.U.M. India Private Limited - (from 1-Apr-23) | S59: e1c68af5-de76-4b79-88f9-add67b8d3461-0000016f
A60: OBS Rental A/c | B60: Direct Expenses | C60: _x0004_ Primary | D60: Direct Expenses | E60: Direct Expenses | F60: Expense | G60: 0 | H60: -22419225 | I60: 0 | J60: -22419225 | K60: 22419225 | N60: Other Expenses | O60: Rent | P60: K.U.M. India Private Limited - (from 1-Apr-23) | S60: e1c68af5-de76-4b79-88f9-add67b8d3461-00000181
A61: Project Expenses A/c | B61: Direct Expenses | C61: _x0004_ Primary | D61: Direct Expenses | E61: Direct Expenses | F61: Expense | G61: 0 | H61: -23138.89 | I61: 520 | J61: -22618.89 | K61: 22618.89 | N61: Other Expenses | O61: Bussiness support services | P61: K.U.M. India Private Limited - (from 1-Apr-23) | S61: e1c68af5-de76-4b79-88f9-add67b8d3461-000000e8
A62: Tender Fee & Registration Charges | B62: Direct Expenses | C62: _x0004_ Primary | D62: Direct Expenses | E62: Direct Expenses | F62: Expense | G62: 0 | H62: -5000 | I62: 0 | J62: -5000 | K62: 5000 | N62: Other Expenses | O62: Legal and professional | P62: K.U.M. India Private Limited - (from 1-Apr-23) | S62: e1c68af5-de76-4b79-88f9-add67b8d3461-000000e2
A63: OBS Air Shipment Expense | B63: Project Expense A/c | C63: Direct Expenses | D63: Direct Expenses | E63: Direct Expenses | F63: Expense | G63: 0 | H63: -68416.82 | I63: 720 | J63: -67696.82 | K63: 67696.82 | N63: Other Expenses | O63: Bussiness support services | P63: K.U.M. India Private Limited - (from 1-Apr-23) | S63: e1c68af5-de76-4b79-88f9-add67b8d3461-00000171
A64: OBS Sea Shipment Expense | B64: Project Expense A/c | C64: Direct Expenses | D64: Direct Expenses | E64: Direct Expenses | F64: Expense | G64: 0 | H64: -1188789.2 | I64: 34821.82 | J64: -1153967.4 | K64: 1153967.4 | N64: Other Expenses | O64: Bussiness support services | P64: K.U.M. India Private Limited - (from 1-Apr-23) | S64: e1c68af5-de76-4b79-88f9-add67b8d3461-00000172
A65: Sales | B65: Direct Incomes | C65: _x0004_ Primary | D65: Direct Incomes | E65: Direct Incomes | F65: Income | G65: 0 | H65: 0 | I65: 0 | J65: 0 | K65: 0 | P65: K.U.M. India Private Limited - (from 1-Apr-23) | S65: e1c68af5-de76-4b79-88f9-add67b8d3461-000000ed
A66: Depreciation Reserve - Panasonic Phone | B66: Fixed Assets | C66: _x0004_ Primary | D66: Fixed Assets | E66: Fixed Assets | F66: Asset | G66: 0 | H66: 0 | I66: 0 | J66: 0 | K66: 0 | L66: Property, Plant and Equipment | M66: Property, Plant and Equipment | P66: K.U.M. India Private Limited - (from 1-Apr-23) | S66: e1c68af5-de76-4b79-88f9-add67b8d3461-000000b7
A67: Laptop A/c | B67: Fixed Assets | C67: _x0004_ Primary | D67: Fixed Assets | E67: Fixed Assets | F67: Asset | G67: -34340.28 | H67: 0 | I67: 15914 | J67: 15914 | K67: 18426.28 | L67: Property, Plant and Equipment | M67: Property, Plant and Equipment | P67: K.U.M. India Private Limited - (from 1-Apr-23) | S67: e1c68af5-de76-4b79-88f9-add67b8d3461-000000e6
A68: Panasonic Phone | B68: Fixed Assets | C68: _x0004_ Primary | D68: Fixed Assets | E68: Fixed Assets | F68: Asset | G68: 0 | H68: 0 | I68: 0 | J68: 0 | K68: 0 | L68: Property, Plant and Equipment | M68: Property, Plant and Equipment | P68: K.U.M. India Private Limited - (from 1-Apr-23) | S68: e1c68af5-de76-4b79-88f9-add67b8d3461-000000d3
A69: Audit Fees | B69: Indirect Expenses | C69: _x0004_ Primary | D69: Indirect Expenses | E69: Indirect Expenses | F69: Expense | G69: 0 | H69: -88500 | I69: 13500 | J69: -75000 | K69: 75000 | N69: Auditor Remuneration | O69: for audit | P69: K.U.M. India Private Limited - (from 1-Apr-23) | S69: e1c68af5-de76-4b79-88f9-add67b8d3461-000000aa
A70: Business Promotion Expenses | B70: Indirect Expenses | C70: _x0004_ Primary | D70: Indirect Expenses | E70: Indirect Expenses | F70: Expense | G70: 0 | H70: 0 | I70: 0 | J70: 0 | K70: 0 | P70: K.U.M. India Private Limited - (from 1-Apr-23) | S70: e1c68af5-de76-4b79-88f9-add67b8d3461-000000ad
A71: Communication Expenses | B71: Indirect Expenses | C71: _x0004_ Primary | D71: Indirect Expenses | E71: Indirect Expenses | F71: Expense | G71: 0 | H71: -13391.4 | I71: 1178 | J71: -12213.4 | K71: 12213.4 | N71: Other Expenses | O71: Communication | P71: K.U.M. India Private Limited - (from 1-Apr-23) | S71: e1c68af5-de76-4b79-88f9-add67b8d3461-000000b0
A72: Company Tax | B72: Indirect Expenses | C72: _x0004_ Primary | D72: Indirect Expenses | E72: Indirect Expenses | F72: Expense | G72: 0 | H72: -2000 | I72: 0 | J72: -2000 | K72: 2000 | N72: Other Expenses | O72: Rates and taxes | P72: K.U.M. India Private Limited - (from 1-Apr-23) | S72: e1c68af5-de76-4b79-88f9-add67b8d3461-000000b1
A73: Compliance Cost | B73: Indirect Expenses | C73: _x0004_ Primary | D73: Indirect Expenses | E73: Indirect Expenses | F73: Expense | G73: 0 | H73: -824 | I73: 0 | J73: -824 | K73: 824 | N73: Other Expenses | O73: Legal and professional | P73: K.U.M. India Private Limited - (from 1-Apr-23) | S73: e1c68af5-de76-4b79-88f9-add67b8d3461-000000b2
A74: Courier Charges | B74: Indirect Expenses | C74: _x0004_ Primary | D74: Indirect Expenses | E74: Indirect Expenses | F74: Expense | G74: 0 | H74: -235 | I74: 105 | J74: -130 | K74: 130 | N74: Other Expenses | O74: Postal and courier charges | P74: K.U.M. India Private Limited - (from 1-Apr-23) | S74: e1c68af5-de76-4b79-88f9-add67b8d3461-000000b3
A75: Depreciation | B75: Indirect Expenses | C75: _x0004_ Primary | D75: Indirect Expenses | E75: Indirect Expenses | F75: Expense | G75: 0 | H75: -15914 | I75: 0 | J75: -15914 | K75: 15914 | N75: Depreciation and Amortisation | O75: Depreciation | P75: K.U.M. India Private Limited - (from 1-Apr-23) | S75: e1c68af5-de76-4b79-88f9-add67b8d3461-000000b6
A76: Festival Bonus | B76: Indirect Expenses | C76: _x0004_ Primary | D76: Indirect Expenses | E76: Indirect Expenses | F76: Expense | G76: 0 | H76: -33750 | I76: 0 | J76: -33750 | K76: 33750 | N76: Employee Benefits | O76: Contribution to providend and other funds | P76: K.U.M. India Private Limited - (from 1-Apr-23) | S76: e1c68af5-de76-4b79-88f9-add67b8d3461-000000be
A77: Interest on TDS | B77: Indirect Expenses | C77: _x0004_ Primary | D77: Indirect Expenses | E77: Indirect Expenses | F77: Expense | G77: 0 | H77: 0 | I77: 0 | J77: 0 | K77: 0 | P77: K.U.M. India Private Limited - (from 1-Apr-23) | S77: e1c68af5-de76-4b79-88f9-add67b8d3461-000000c8
A78: Loss on Forex | B78: Indirect Expenses | C78: _x0004_ Primary | D78: Indirect Expenses | E78: Indirect Expenses | F78: Expense | G78: 0 | H78: -3475 | I78: 0 | J78: -3475 | K78: 3475 | N78: Other Expenses | O78: Forex loss | P78: K.U.M. India Private Limited - (from 1-Apr-23) | S78: e1c68af5-de76-4b79-88f9-add67b8d3461-000000ee
A79: MGT Filing Fee | B79: Indirect Expenses | C79: _x0004_ Primary | D79: Indirect Expenses | E79: Indirect Expenses | F79: Expense | G79: 0 | H79: 0 | I79: 0 | J79: 0 | K79: 0 | P79: K.U.M. India Private Limited - (from 1-Apr-23) | S79: e1c68af5-de76-4b79-88f9-add67b8d3461-000000cd
A80: Performance Incentive A/c | B80: Indirect Expenses | C80: _x0004_ Primary | D80: Indirect Expenses | E80: Indirect Expenses | F80: Expense | G80: 0 | H80: -40000 | I80: 0 | J80: -40000 | K80: 40000 | N80: Employee Benefits | O80: Contribution to providend and other funds | P80: K.U.M. India Private Limited - (from 1-Apr-23) | S80: e1c68af5-de76-4b79-88f9-add67b8d3461-00000184
A81: Printing & Stationery | B81: Indirect Expenses | C81: _x0004_ Primary | D81: Indirect Expenses | E81: Indirect Expenses | F81: Expense | G81: 0 | H81: 0 | I81: 0 | J81: 0 | K81: 0 | P81: K.U.M. India Private Limited - (from 1-Apr-23) | S81: e1c68af5-de76-4b79-88f9-add67b8d3461-000000d5
A82: Professional Fees | B82: Indirect Expenses | C82: _x0004_ Primary | D82: Indirect Expenses | E82: Indirect Expenses | F82: Expense | G82: 0 | H82: -182529 | I82: 30914 | J82: -151615 | K82: 151615 | N82: Other Expenses | O82: Legal and professional | P82: K.U.M. India Private Limited - (from 1-Apr-23) | S82: e1c68af5-de76-4b79-88f9-add67b8d3461-000000d6
A83: Rent A/c | B83: Indirect Expenses | C83: _x0004_ Primary | D83: Indirect Expenses | E83: Indirect Expenses | F83: Expense | G83: 0 | H83: -141600 | I83: 0 | J83: -141600 | K83: 141600 | N83: Other Expenses | O83: Rent | P83: K.U.M. India Private Limited - (from 1-Apr-23) | S83: e1c68af5-de76-4b79-88f9-add67b8d3461-000000da
A84: Salary A/c | B84: Indirect Expenses | C84: _x0004_ Primary | D84: Indirect Expenses | E84: Indirect Expenses | F84: Expense | G84: 0 | H84: -405000 | I84: 0 | J84: -405000 | K84: 405000 | N84: Employee Benefits | O84: Salary and Wages | P84: K.U.M. India Private Limited - (from 1-Apr-23) | S84: e1c68af5-de76-4b79-88f9-add67b8d3461-000000dd
...
